2024-06-09 08:09:09,913 - DEBUG - GET request to login: 
2024-06-09 08:09:15,894 - DEBUG - POST request to login: 
2024-06-09 08:15:01,662 - INFO - /Users/janrydzewski/Developer/Studies/Django/workout_logger/workout/views.py changed, reloading.: 
2024-06-09 08:15:13,263 - INFO - /Users/janrydzewski/Developer/Studies/Django/workout_logger/workout/views.py changed, reloading.: 
2024-06-09 08:15:55,118 - INFO - /Users/janrydzewski/Developer/Studies/Django/workout_logger/workout/views.py changed, reloading.: 
2024-06-09 08:15:56,499 - INFO - /Users/janrydzewski/Developer/Studies/Django/workout_logger/workout/views.py changed, reloading.: 
2024-06-09 08:16:13,984 - INFO - /Users/janrydzewski/Developer/Studies/Django/workout_logger/workout/views.py changed, reloading.: 
2024-06-09 08:16:21,405 - INFO - /Users/janrydzewski/Developer/Studies/Django/workout_logger/workout/views.py changed, reloading.: 
2024-06-09 08:16:29,862 - INFO - /Users/janrydzewski/Developer/Studies/Django/workout_logger/workout/views.py changed, reloading.: 
2024-06-09 08:16:32,174 - INFO - /Users/janrydzewski/Developer/Studies/Django/workout_logger/workout/views.py changed, reloading.: 
2024-06-09 08:18:35,507 - ERROR - Internal Server Error: /history: 
Traceback (most recent call last):
  File "/Library/Frameworks/Python.framework/Versions/3.12/lib/python3.12/site-packages/django/core/handlers/exception.py", line 47, in inner
    response = get_response(request)
               ^^^^^^^^^^^^^^^^^^^^^
  File "/Library/Frameworks/Python.framework/Versions/3.12/lib/python3.12/site-packages/django/core/handlers/base.py", line 181, in _get_response
    response = wrapped_callback(request, *callback_args, **callback_kwargs)
               ^^^^^^^^^^^^^^^^^^^^^^^^^^^^^^^^^^^^^^^^^^^^^^^^^^^^^^^^^^^^
  File "/Users/janrydzewski/Developer/Studies/Django/workout_logger/workout/views.py", line 200, in view_all
    return render(request, "workout/view_all.html", data)
           ^^^^^^^^^^^^^^^^^^^^^^^^^^^^^^^^^^^^^^^^^^^^^^
  File "/Library/Frameworks/Python.framework/Versions/3.12/lib/python3.12/site-packages/django/shortcuts.py", line 19, in render
    content = loader.render_to_string(template_name, context, request, using=using)
              ^^^^^^^^^^^^^^^^^^^^^^^^^^^^^^^^^^^^^^^^^^^^^^^^^^^^^^^^^^^^^^^^^^^^^
  File "/Library/Frameworks/Python.framework/Versions/3.12/lib/python3.12/site-packages/django/template/loader.py", line 61, in render_to_string
    template = get_template(template_name, using=using)
               ^^^^^^^^^^^^^^^^^^^^^^^^^^^^^^^^^^^^^^^^
  File "/Library/Frameworks/Python.framework/Versions/3.12/lib/python3.12/site-packages/django/template/loader.py", line 15, in get_template
    return engine.get_template(template_name)
           ^^^^^^^^^^^^^^^^^^^^^^^^^^^^^^^^^^
  File "/Library/Frameworks/Python.framework/Versions/3.12/lib/python3.12/site-packages/django/template/backends/django.py", line 34, in get_template
    return Template(self.engine.get_template(template_name), self)
                    ^^^^^^^^^^^^^^^^^^^^^^^^^^^^^^^^^^^^^^^
  File "/Library/Frameworks/Python.framework/Versions/3.12/lib/python3.12/site-packages/django/template/engine.py", line 163, in get_template
    template, origin = self.find_template(template_name)
                       ^^^^^^^^^^^^^^^^^^^^^^^^^^^^^^^^^
  File "/Library/Frameworks/Python.framework/Versions/3.12/lib/python3.12/site-packages/django/template/engine.py", line 145, in find_template
    template = loader.get_template(name, skip=skip)
               ^^^^^^^^^^^^^^^^^^^^^^^^^^^^^^^^^^^^
  File "/Library/Frameworks/Python.framework/Versions/3.12/lib/python3.12/site-packages/django/template/loaders/base.py", line 29, in get_template
    return Template(
           ^^^^^^^^^
  File "/Library/Frameworks/Python.framework/Versions/3.12/lib/python3.12/site-packages/django/template/base.py", line 155, in __init__
    self.nodelist = self.compile_nodelist()
                    ^^^^^^^^^^^^^^^^^^^^^^^
  File "/Library/Frameworks/Python.framework/Versions/3.12/lib/python3.12/site-packages/django/template/base.py", line 199, in compile_nodelist
    return parser.parse()
           ^^^^^^^^^^^^^^
  File "/Library/Frameworks/Python.framework/Versions/3.12/lib/python3.12/site-packages/django/template/base.py", line 508, in parse
    raise self.error(token, e)
  File "/Library/Frameworks/Python.framework/Versions/3.12/lib/python3.12/site-packages/django/template/base.py", line 506, in parse
    compiled_result = compile_func(self, token)
                      ^^^^^^^^^^^^^^^^^^^^^^^^^
  File "/Library/Frameworks/Python.framework/Versions/3.12/lib/python3.12/site-packages/django/template/defaulttags.py", line 905, in do_if
    nodelist = parser.parse(('elif', 'else', 'endif'))
               ^^^^^^^^^^^^^^^^^^^^^^^^^^^^^^^^^^^^^^^
  File "/Library/Frameworks/Python.framework/Versions/3.12/lib/python3.12/site-packages/django/template/base.py", line 508, in parse
    raise self.error(token, e)
  File "/Library/Frameworks/Python.framework/Versions/3.12/lib/python3.12/site-packages/django/template/base.py", line 506, in parse
    compiled_result = compile_func(self, token)
                      ^^^^^^^^^^^^^^^^^^^^^^^^^
  File "/Library/Frameworks/Python.framework/Versions/3.12/lib/python3.12/site-packages/django/template/defaulttags.py", line 810, in do_for
    nodelist_loop = parser.parse(('empty', 'endfor',))
                    ^^^^^^^^^^^^^^^^^^^^^^^^^^^^^^^^^^
  File "/Library/Frameworks/Python.framework/Versions/3.12/lib/python3.12/site-packages/django/template/base.py", line 479, in parse
    raise self.error(token, e)
  File "/Library/Frameworks/Python.framework/Versions/3.12/lib/python3.12/site-packages/django/template/base.py", line 477, in parse
    filter_expression = self.compile_filter(token.contents)
                        ^^^^^^^^^^^^^^^^^^^^^^^^^^^^^^^^^^^
  File "/Library/Frameworks/Python.framework/Versions/3.12/lib/python3.12/site-packages/django/template/base.py", line 593, in compile_filter
    return FilterExpression(token, self)
           ^^^^^^^^^^^^^^^^^^^^^^^^^^^^^
  File "/Library/Frameworks/Python.framework/Versions/3.12/lib/python3.12/site-packages/django/template/base.py", line 692, in __init__
    raise TemplateSyntaxError("Could not parse the remainder: '%s' "
django.template.exceptions.TemplateSyntaxError: Could not parse the remainder: ' ?? "Workout"' from 'info.exercise_name ?? "Workout"'
2024-06-09 08:21:35,938 - DEBUG - GET request to new exercise: 
2024-06-09 08:23:37,468 - DEBUG - GET request to login: 
2024-06-09 08:23:41,622 - DEBUG - POST request to login: 
2024-06-09 08:26:55,891 - DEBUG - GET request to login: 
2024-06-09 08:27:04,014 - DEBUG - POST request to login: 
2024-06-09 08:27:04,973 - WARNING - User could not be logged in.: 
2024-06-09 08:27:04,973 - ERROR - Username or password is incorrect.: 
2024-06-09 08:27:04,987 - DEBUG - GET request to login: 
2024-06-09 08:27:10,197 - DEBUG - POST request to login: 
2024-06-09 08:27:16,717 - DEBUG - GET request to new workout: 
2024-06-09 08:29:08,999 - DEBUG - GET request to login: 
2024-06-09 08:29:10,626 - DEBUG - GET request to register: 
2024-06-09 08:29:37,207 - DEBUG - POST request to register: 
2024-06-09 08:30:21,915 - DEBUG - GET request to login: 
2024-06-09 08:30:29,771 - DEBUG - POST request to login: 
2024-06-09 08:30:34,742 - WARNING - Not Found: /challenge: 
2024-06-09 08:30:37,956 - DEBUG - GET request to new workout: 
2024-06-09 08:30:41,110 - DEBUG - GET request to new workout: 
2024-06-09 08:30:41,893 - DEBUG - GET request to new exercise: 
2024-06-09 08:30:43,040 - DEBUG - GET request to new exercise: 
2024-06-09 08:30:46,784 - WARNING - Not Found: /challenge: 
2024-06-09 08:30:50,302 - DEBUG - GET request to new workout: 
2024-06-09 08:31:51,595 - DEBUG - GET request to login: 
2024-06-09 08:32:15,120 - DEBUG - GET request to new workout: 
2024-06-09 08:33:04,943 - INFO - /Users/janrydzewski/Developer/Studies/Django/workout_logger/workout/views.py changed, reloading.: 
2024-06-09 08:33:06,359 - INFO - /Users/janrydzewski/Developer/Studies/Django/workout_logger/workout/views.py changed, reloading.: 
2024-06-09 08:35:30,923 - INFO - /Users/janrydzewski/Developer/Studies/Django/workout_logger/workout/views.py changed, reloading.: 
2024-06-09 08:35:54,566 - INFO - /Users/janrydzewski/Developer/Studies/Django/workout_logger/workout/views.py changed, reloading.: 
2024-06-09 08:35:59,091 - INFO - /Users/janrydzewski/Developer/Studies/Django/workout_logger/workout/views.py changed, reloading.: 
2024-06-09 08:36:15,148 - ERROR - User does not have permission to view workout.: 
2024-06-09 08:36:15,166 - DEBUG - GET request to new workout: 
2024-06-09 08:36:33,888 - DEBUG - GET request to new workout: 
2024-06-09 08:36:35,768 - WARNING - Not Found: /challenge: 
2024-06-09 08:39:11,388 - INFO - /Users/janrydzewski/Developer/Studies/Django/workout_logger/workout/views.py changed, reloading.: 
2024-06-09 08:39:12,774 - INFO - /Users/janrydzewski/Developer/Studies/Django/workout_logger/workout/views.py changed, reloading.: 
2024-06-09 08:39:14,052 - INFO - /Users/janrydzewski/Developer/Studies/Django/workout_logger/workout/views.py changed, reloading.: 
2024-06-09 08:40:11,752 - INFO - /Users/janrydzewski/Developer/Studies/Django/workout_logger/workout/urls.py changed, reloading.: 
2024-06-09 08:40:30,586 - WARNING - Not Found: /challenge: 
2024-06-09 08:41:03,852 - INFO - /Users/janrydzewski/Developer/Studies/Django/workout_logger/workout/urls.py changed, reloading.: 
2024-06-09 08:41:07,250 - INFO - /Users/janrydzewski/Developer/Studies/Django/workout_logger/workout/urls.py changed, reloading.: 
2024-06-09 08:41:11,490 - INFO - /Users/janrydzewski/Developer/Studies/Django/workout_logger/workout/views.py changed, reloading.: 
2024-06-09 08:41:13,778 - INFO - /Users/janrydzewski/Developer/Studies/Django/workout_logger/workout/views.py changed, reloading.: 
2024-06-09 08:41:16,790 - WARNING - Not Found: /challenge: 
2024-06-09 08:42:05,934 - INFO - /Users/janrydzewski/Developer/Studies/Django/workout_logger/workout/views.py changed, reloading.: 
2024-06-09 08:42:30,541 - INFO - /Users/janrydzewski/Developer/Studies/Django/workout_logger/workout/urls.py changed, reloading.: 
2024-06-09 08:42:31,866 - INFO - /Users/janrydzewski/Developer/Studies/Django/workout_logger/workout/urls.py changed, reloading.: 
2024-06-09 08:42:40,785 - WARNING - Not Found: /challenges: 
2024-06-09 08:42:51,255 - DEBUG - GET request to login: 
2024-06-09 08:42:55,928 - DEBUG - POST request to login: 
2024-06-09 08:42:57,869 - WARNING - Not Found: /challenges: 
2024-06-09 08:43:20,900 - INFO - /Users/janrydzewski/Developer/Studies/Django/workout_logger/workout/urls.py changed, reloading.: 
2024-06-09 08:44:18,203 - INFO - /Users/janrydzewski/Developer/Studies/Django/workout_logger/workout/views.py changed, reloading.: 
2024-06-09 08:45:07,598 - DEBUG - GET request to new workout: 
2024-06-09 08:45:10,504 - DEBUG - GET request to new workout: 
2024-06-09 08:45:30,808 - WARNING - Not Found: /challenge/1: 
2024-06-09 08:45:33,509 - WARNING - Not Found: /challenge/1: 
2024-06-09 08:45:36,971 - WARNING - Not Found: /challenge/1: 
2024-06-09 08:45:56,952 - DEBUG - GET request to new workout: 
2024-06-09 08:48:14,333 - INFO - /Users/janrydzewski/Developer/Studies/Django/workout_logger/workout/views.py changed, reloading.: 
2024-06-09 08:48:31,012 - INFO - /Users/janrydzewski/Developer/Studies/Django/workout_logger/workout/urls.py changed, reloading.: 
2024-06-09 08:48:32,320 - INFO - /Users/janrydzewski/Developer/Studies/Django/workout_logger/workout/urls.py changed, reloading.: 
2024-06-09 08:48:47,713 - INFO - /Users/janrydzewski/Developer/Studies/Django/workout_logger/workout/urls.py changed, reloading.: 
2024-06-09 08:48:50,069 - INFO - /Users/janrydzewski/Developer/Studies/Django/workout_logger/workout/urls.py changed, reloading.: 
2024-06-09 08:48:55,377 - INFO - /Users/janrydzewski/Developer/Studies/Django/workout_logger/workout/urls.py changed, reloading.: 
2024-06-09 08:48:57,708 - INFO - /Users/janrydzewski/Developer/Studies/Django/workout_logger/workout/urls.py changed, reloading.: 
2024-06-09 08:49:03,091 - WARNING - Not Found: /challenge/join/1: 
2024-06-09 08:54:29,180 - INFO - /Users/janrydzewski/Developer/Studies/Django/workout_logger/workout/views.py changed, reloading.: 
2024-06-09 08:54:33,622 - INFO - /Users/janrydzewski/Developer/Studies/Django/workout_logger/workout/views.py changed, reloading.: 
2024-06-09 08:55:56,278 - INFO - /Users/janrydzewski/Developer/Studies/Django/workout_logger/workout/views.py changed, reloading.: 
2024-06-09 08:56:28,231 - INFO - /Users/janrydzewski/Developer/Studies/Django/workout_logger/workout/urls.py changed, reloading.: 
2024-06-09 08:56:31,622 - INFO - /Users/janrydzewski/Developer/Studies/Django/workout_logger/workout/urls.py changed, reloading.: 
2024-06-09 08:56:34,913 - INFO - /Users/janrydzewski/Developer/Studies/Django/workout_logger/workout/urls.py changed, reloading.: 
2024-06-09 08:56:36,179 - INFO - /Users/janrydzewski/Developer/Studies/Django/workout_logger/workout/urls.py changed, reloading.: 
2024-06-09 08:56:40,382 - ERROR - Internal Server Error: /challenges: 
Traceback (most recent call last):
  File "/Library/Frameworks/Python.framework/Versions/3.12/lib/python3.12/site-packages/django/core/handlers/exception.py", line 47, in inner
    response = get_response(request)
               ^^^^^^^^^^^^^^^^^^^^^
  File "/Library/Frameworks/Python.framework/Versions/3.12/lib/python3.12/site-packages/django/core/handlers/base.py", line 181, in _get_response
    response = wrapped_callback(request, *callback_args, **callback_kwargs)
               ^^^^^^^^^^^^^^^^^^^^^^^^^^^^^^^^^^^^^^^^^^^^^^^^^^^^^^^^^^^^
  File "/Users/janrydzewski/Developer/Studies/Django/workout_logger/workout/views.py", line 234, in challenges
    return render(request, "workout/challenges.html", data)
           ^^^^^^^^^^^^^^^^^^^^^^^^^^^^^^^^^^^^^^^^^^^^^^^^
  File "/Library/Frameworks/Python.framework/Versions/3.12/lib/python3.12/site-packages/django/shortcuts.py", line 19, in render
    content = loader.render_to_string(template_name, context, request, using=using)
              ^^^^^^^^^^^^^^^^^^^^^^^^^^^^^^^^^^^^^^^^^^^^^^^^^^^^^^^^^^^^^^^^^^^^^
  File "/Library/Frameworks/Python.framework/Versions/3.12/lib/python3.12/site-packages/django/template/loader.py", line 62, in render_to_string
    return template.render(context, request)
           ^^^^^^^^^^^^^^^^^^^^^^^^^^^^^^^^^
  File "/Library/Frameworks/Python.framework/Versions/3.12/lib/python3.12/site-packages/django/template/backends/django.py", line 61, in render
    return self.template.render(context)
           ^^^^^^^^^^^^^^^^^^^^^^^^^^^^^
  File "/Library/Frameworks/Python.framework/Versions/3.12/lib/python3.12/site-packages/django/template/base.py", line 176, in render
    return self._render(context)
           ^^^^^^^^^^^^^^^^^^^^^
  File "/Library/Frameworks/Python.framework/Versions/3.12/lib/python3.12/site-packages/django/template/base.py", line 168, in _render
    return self.nodelist.render(context)
           ^^^^^^^^^^^^^^^^^^^^^^^^^^^^^
  File "/Library/Frameworks/Python.framework/Versions/3.12/lib/python3.12/site-packages/django/template/base.py", line 978, in render
    node.render_annotated(context) for node in self
    ^^^^^^^^^^^^^^^^^^^^^^^^^^^^^^
  File "/Library/Frameworks/Python.framework/Versions/3.12/lib/python3.12/site-packages/django/template/base.py", line 938, in render_annotated
    return self.render(context)
           ^^^^^^^^^^^^^^^^^^^^
  File "/Library/Frameworks/Python.framework/Versions/3.12/lib/python3.12/site-packages/django/template/defaulttags.py", line 295, in render
    return nodelist.render(context)
           ^^^^^^^^^^^^^^^^^^^^^^^^
  File "/Library/Frameworks/Python.framework/Versions/3.12/lib/python3.12/site-packages/django/template/base.py", line 978, in render
    node.render_annotated(context) for node in self
    ^^^^^^^^^^^^^^^^^^^^^^^^^^^^^^
  File "/Library/Frameworks/Python.framework/Versions/3.12/lib/python3.12/site-packages/django/template/base.py", line 938, in render_annotated
    return self.render(context)
           ^^^^^^^^^^^^^^^^^^^^
  File "/Library/Frameworks/Python.framework/Versions/3.12/lib/python3.12/site-packages/django/template/defaulttags.py", line 214, in render
    nodelist.append(node.render_annotated(context))
                    ^^^^^^^^^^^^^^^^^^^^^^^^^^^^^^
  File "/Library/Frameworks/Python.framework/Versions/3.12/lib/python3.12/site-packages/django/template/base.py", line 938, in render_annotated
    return self.render(context)
           ^^^^^^^^^^^^^^^^^^^^
  File "/Library/Frameworks/Python.framework/Versions/3.12/lib/python3.12/site-packages/django/template/defaulttags.py", line 442, in render
    url = reverse(view_name, args=args, kwargs=kwargs, current_app=current_app)
          ^^^^^^^^^^^^^^^^^^^^^^^^^^^^^^^^^^^^^^^^^^^^^^^^^^^^^^^^^^^^^^^^^^^^^
  File "/Library/Frameworks/Python.framework/Versions/3.12/lib/python3.12/site-packages/django/urls/base.py", line 86, in reverse
    return resolver._reverse_with_prefix(view, prefix, *args, **kwargs)
           ^^^^^^^^^^^^^^^^^^^^^^^^^^^^^^^^^^^^^^^^^^^^^^^^^^^^^^^^^^^^
  File "/Library/Frameworks/Python.framework/Versions/3.12/lib/python3.12/site-packages/django/urls/resolvers.py", line 729, in _reverse_with_prefix
    raise NoReverseMatch(msg)
django.urls.exceptions.NoReverseMatch: Reverse for 'join_challenge' not found. 'join_challenge' is not a valid view function or pattern name.
2024-06-09 08:56:48,687 - INFO - /Users/janrydzewski/Developer/Studies/Django/workout_logger/workout/urls.py changed, reloading.: 
2024-06-09 08:57:01,302 - DEBUG - POST request to complete workout: 
2024-06-09 08:57:04,676 - DEBUG - GET request to new workout: 
2024-06-09 10:49:38,152 - DEBUG - GET request to login: 
2024-06-09 10:49:41,909 - DEBUG - POST request to login: 
2024-06-09 10:57:41,912 - INFO - /Users/janrydzewski/Developer/Studies/Django/workout_logger/workout/models.py changed, reloading.: 
2024-06-09 10:58:16,921 - INFO - /Users/janrydzewski/Developer/Studies/Django/workout_logger/workout/views.py changed, reloading.: 
2024-06-09 10:58:30,408 - INFO - /Users/janrydzewski/Developer/Studies/Django/workout_logger/workout/views.py changed, reloading.: 
2024-06-09 10:58:57,258 - INFO - /Users/janrydzewski/Developer/Studies/Django/workout_logger/workout/views.py changed, reloading.: 
2024-06-09 10:59:03,656 - INFO - /Users/janrydzewski/Developer/Studies/Django/workout_logger/workout/views.py changed, reloading.: 
2024-06-09 11:01:05,694 - INFO - /Users/janrydzewski/Developer/Studies/Django/workout_logger/workout/urls.py changed, reloading.: 
2024-06-09 11:01:11,392 - DEBUG - GET request to login: 
2024-06-09 11:01:43,507 - DEBUG - GET request to login: 
2024-06-09 11:01:47,798 - DEBUG - POST request to login: 
2024-06-09 11:01:56,755 - DEBUG - GET request to new workout: 
2024-06-09 11:02:52,744 - DEBUG - GET request to login: 
2024-06-09 11:02:57,480 - DEBUG - POST request to login: 
2024-06-09 11:03:02,907 - WARNING - Not Found: /challenge: 
2024-06-09 11:03:05,018 - DEBUG - GET request to new exercise: 
2024-06-09 11:03:07,449 - WARNING - Not Found: /challenge/1: 
2024-06-09 11:03:11,599 - ERROR - Internal Server Error: /challenge/join/1/: 
Traceback (most recent call last):
  File "/Library/Frameworks/Python.framework/Versions/3.12/lib/python3.12/site-packages/django/core/handlers/exception.py", line 47, in inner
    response = get_response(request)
               ^^^^^^^^^^^^^^^^^^^^^
  File "/Library/Frameworks/Python.framework/Versions/3.12/lib/python3.12/site-packages/django/core/handlers/base.py", line 181, in _get_response
    response = wrapped_callback(request, *callback_args, **callback_kwargs)
               ^^^^^^^^^^^^^^^^^^^^^^^^^^^^^^^^^^^^^^^^^^^^^^^^^^^^^^^^^^^^
  File "/Users/janrydzewski/Developer/Studies/Django/workout_logger/workout/views.py", line 248, in join_challenge
    user_progress, created = UserProgress.objects.get_or_create(user=request.user, challenge=challenge)
                             ^^^^^^^^^^^^^^^^^^^^^^^^^^^^^^^^^^^^^^^^^^^^^^^^^^^^^^^^^^^^^^^^^^^^^^^^^^
  File "/Library/Frameworks/Python.framework/Versions/3.12/lib/python3.12/site-packages/django/db/models/manager.py", line 85, in manager_method
    return getattr(self.get_queryset(), name)(*args, **kwargs)
           ^^^^^^^^^^^^^^^^^^^^^^^^^^^^^^^^^^^^^^^^^^^^^^^^^^^
  File "/Library/Frameworks/Python.framework/Versions/3.12/lib/python3.12/site-packages/django/db/models/query.py", line 588, in get_or_create
    return self.get(**kwargs), False
           ^^^^^^^^^^^^^^^^^^
  File "/Library/Frameworks/Python.framework/Versions/3.12/lib/python3.12/site-packages/django/db/models/query.py", line 428, in get
    clone = self._chain() if self.query.combinator else self.filter(*args, **kwargs)
                                                        ^^^^^^^^^^^^^^^^^^^^^^^^^^^^
  File "/Library/Frameworks/Python.framework/Versions/3.12/lib/python3.12/site-packages/django/db/models/query.py", line 974, in filter
    return self._filter_or_exclude(False, args, kwargs)
           ^^^^^^^^^^^^^^^^^^^^^^^^^^^^^^^^^^^^^^^^^^^^
  File "/Library/Frameworks/Python.framework/Versions/3.12/lib/python3.12/site-packages/django/db/models/query.py", line 992, in _filter_or_exclude
    clone._filter_or_exclude_inplace(negate, args, kwargs)
  File "/Library/Frameworks/Python.framework/Versions/3.12/lib/python3.12/site-packages/django/db/models/query.py", line 999, in _filter_or_exclude_inplace
    self._query.add_q(Q(*args, **kwargs))
  File "/Library/Frameworks/Python.framework/Versions/3.12/lib/python3.12/site-packages/django/db/models/sql/query.py", line 1375, in add_q
    clause, _ = self._add_q(q_object, self.used_aliases)
                ^^^^^^^^^^^^^^^^^^^^^^^^^^^^^^^^^^^^^^^^
  File "/Library/Frameworks/Python.framework/Versions/3.12/lib/python3.12/site-packages/django/db/models/sql/query.py", line 1396, in _add_q
    child_clause, needed_inner = self.build_filter(
                                 ^^^^^^^^^^^^^^^^^^
  File "/Library/Frameworks/Python.framework/Versions/3.12/lib/python3.12/site-packages/django/db/models/sql/query.py", line 1302, in build_filter
    self.check_related_objects(join_info.final_field, value, join_info.opts)
  File "/Library/Frameworks/Python.framework/Versions/3.12/lib/python3.12/site-packages/django/db/models/sql/query.py", line 1134, in check_related_objects
    self.check_query_object_type(value, opts, field)
  File "/Library/Frameworks/Python.framework/Versions/3.12/lib/python3.12/site-packages/django/db/models/sql/query.py", line 1115, in check_query_object_type
    raise ValueError(
ValueError: Cannot query "admin": Must be "User" instance.
2024-06-09 11:07:41,999 - DEBUG - GET request to login: 
2024-06-09 11:07:47,846 - DEBUG - POST request to login: 
2024-06-09 11:07:51,951 - WARNING - Not Found: /challenge: 
2024-06-09 11:07:58,542 - WARNING - Not Found: /challenge/1: 
2024-06-09 11:08:03,472 - ERROR - Internal Server Error: /challenge/join/1/: 
Traceback (most recent call last):
  File "/Library/Frameworks/Python.framework/Versions/3.12/lib/python3.12/site-packages/django/core/handlers/exception.py", line 47, in inner
    response = get_response(request)
               ^^^^^^^^^^^^^^^^^^^^^
  File "/Library/Frameworks/Python.framework/Versions/3.12/lib/python3.12/site-packages/django/core/handlers/base.py", line 181, in _get_response
    response = wrapped_callback(request, *callback_args, **callback_kwargs)
               ^^^^^^^^^^^^^^^^^^^^^^^^^^^^^^^^^^^^^^^^^^^^^^^^^^^^^^^^^^^^
  File "/Users/janrydzewski/Developer/Studies/Django/workout_logger/workout/views.py", line 248, in join_challenge
    user_progress, created = UserProgress.objects.get_or_create(user=request.user, challenge=challenge)
                             ^^^^^^^^^^^^^^^^^^^^^^^^^^^^^^^^^^^^^^^^^^^^^^^^^^^^^^^^^^^^^^^^^^^^^^^^^^
  File "/Library/Frameworks/Python.framework/Versions/3.12/lib/python3.12/site-packages/django/db/models/manager.py", line 85, in manager_method
    return getattr(self.get_queryset(), name)(*args, **kwargs)
           ^^^^^^^^^^^^^^^^^^^^^^^^^^^^^^^^^^^^^^^^^^^^^^^^^^^
  File "/Library/Frameworks/Python.framework/Versions/3.12/lib/python3.12/site-packages/django/db/models/query.py", line 588, in get_or_create
    return self.get(**kwargs), False
           ^^^^^^^^^^^^^^^^^^
  File "/Library/Frameworks/Python.framework/Versions/3.12/lib/python3.12/site-packages/django/db/models/query.py", line 428, in get
    clone = self._chain() if self.query.combinator else self.filter(*args, **kwargs)
                                                        ^^^^^^^^^^^^^^^^^^^^^^^^^^^^
  File "/Library/Frameworks/Python.framework/Versions/3.12/lib/python3.12/site-packages/django/db/models/query.py", line 974, in filter
    return self._filter_or_exclude(False, args, kwargs)
           ^^^^^^^^^^^^^^^^^^^^^^^^^^^^^^^^^^^^^^^^^^^^
  File "/Library/Frameworks/Python.framework/Versions/3.12/lib/python3.12/site-packages/django/db/models/query.py", line 992, in _filter_or_exclude
    clone._filter_or_exclude_inplace(negate, args, kwargs)
  File "/Library/Frameworks/Python.framework/Versions/3.12/lib/python3.12/site-packages/django/db/models/query.py", line 999, in _filter_or_exclude_inplace
    self._query.add_q(Q(*args, **kwargs))
  File "/Library/Frameworks/Python.framework/Versions/3.12/lib/python3.12/site-packages/django/db/models/sql/query.py", line 1375, in add_q
    clause, _ = self._add_q(q_object, self.used_aliases)
                ^^^^^^^^^^^^^^^^^^^^^^^^^^^^^^^^^^^^^^^^
  File "/Library/Frameworks/Python.framework/Versions/3.12/lib/python3.12/site-packages/django/db/models/sql/query.py", line 1396, in _add_q
    child_clause, needed_inner = self.build_filter(
                                 ^^^^^^^^^^^^^^^^^^
  File "/Library/Frameworks/Python.framework/Versions/3.12/lib/python3.12/site-packages/django/db/models/sql/query.py", line 1302, in build_filter
    self.check_related_objects(join_info.final_field, value, join_info.opts)
  File "/Library/Frameworks/Python.framework/Versions/3.12/lib/python3.12/site-packages/django/db/models/sql/query.py", line 1134, in check_related_objects
    self.check_query_object_type(value, opts, field)
  File "/Library/Frameworks/Python.framework/Versions/3.12/lib/python3.12/site-packages/django/db/models/sql/query.py", line 1115, in check_query_object_type
    raise ValueError(
ValueError: Cannot query "admin": Must be "User" instance.
2024-06-09 11:08:33,302 - INFO - /Users/janrydzewski/Developer/Studies/Django/workout_logger/workout/urls.py changed, reloading.: 
2024-06-09 11:08:34,604 - INFO - /Users/janrydzewski/Developer/Studies/Django/workout_logger/workout/urls.py changed, reloading.: 
2024-06-09 11:08:35,878 - INFO - /Users/janrydzewski/Developer/Studies/Django/workout_logger/workout/urls.py changed, reloading.: 
2024-06-09 11:08:41,140 - INFO - /Users/janrydzewski/Developer/Studies/Django/workout_logger/workout/urls.py changed, reloading.: 
2024-06-09 11:09:21,033 - INFO - /Users/janrydzewski/Developer/Studies/Django/workout_logger/workout/urls.py changed, reloading.: 
2024-06-09 11:09:44,671 - INFO - /Users/janrydzewski/Developer/Studies/Django/workout_logger/workout/views.py changed, reloading.: 
2024-06-09 11:09:48,996 - INFO - /Users/janrydzewski/Developer/Studies/Django/workout_logger/workout/views.py changed, reloading.: 
2024-06-09 11:09:50,227 - INFO - /Users/janrydzewski/Developer/Studies/Django/workout_logger/workout/views.py changed, reloading.: 
2024-06-09 11:09:57,623 - INFO - /Users/janrydzewski/Developer/Studies/Django/workout_logger/workout/views.py changed, reloading.: 
2024-06-09 11:10:04,948 - DEBUG - GET request to login: 
2024-06-09 11:10:30,316 - DEBUG - POST request to login: 
2024-06-09 11:10:34,694 - DEBUG - GET request to new workout: 
2024-06-09 11:10:36,646 - ERROR - Internal Server Error: /challenge/join/1/: 
Traceback (most recent call last):
  File "/Library/Frameworks/Python.framework/Versions/3.12/lib/python3.12/site-packages/django/core/handlers/exception.py", line 47, in inner
    response = get_response(request)
               ^^^^^^^^^^^^^^^^^^^^^
  File "/Library/Frameworks/Python.framework/Versions/3.12/lib/python3.12/site-packages/django/core/handlers/base.py", line 181, in _get_response
    response = wrapped_callback(request, *callback_args, **callback_kwargs)
               ^^^^^^^^^^^^^^^^^^^^^^^^^^^^^^^^^^^^^^^^^^^^^^^^^^^^^^^^^^^^
  File "/Users/janrydzewski/Developer/Studies/Django/workout_logger/workout/views.py", line 247, in join_challenge
    user_progress, created = UserProgress.objects.get_or_create(user=request.user, challenge=challenge)
                             ^^^^^^^^^^^^^^^^^^^^^^^^^^^^^^^^^^^^^^^^^^^^^^^^^^^^^^^^^^^^^^^^^^^^^^^^^^
  File "/Library/Frameworks/Python.framework/Versions/3.12/lib/python3.12/site-packages/django/db/models/manager.py", line 85, in manager_method
    return getattr(self.get_queryset(), name)(*args, **kwargs)
           ^^^^^^^^^^^^^^^^^^^^^^^^^^^^^^^^^^^^^^^^^^^^^^^^^^^
  File "/Library/Frameworks/Python.framework/Versions/3.12/lib/python3.12/site-packages/django/db/models/query.py", line 588, in get_or_create
    return self.get(**kwargs), False
           ^^^^^^^^^^^^^^^^^^
  File "/Library/Frameworks/Python.framework/Versions/3.12/lib/python3.12/site-packages/django/db/models/query.py", line 428, in get
    clone = self._chain() if self.query.combinator else self.filter(*args, **kwargs)
                                                        ^^^^^^^^^^^^^^^^^^^^^^^^^^^^
  File "/Library/Frameworks/Python.framework/Versions/3.12/lib/python3.12/site-packages/django/db/models/query.py", line 974, in filter
    return self._filter_or_exclude(False, args, kwargs)
           ^^^^^^^^^^^^^^^^^^^^^^^^^^^^^^^^^^^^^^^^^^^^
  File "/Library/Frameworks/Python.framework/Versions/3.12/lib/python3.12/site-packages/django/db/models/query.py", line 992, in _filter_or_exclude
    clone._filter_or_exclude_inplace(negate, args, kwargs)
  File "/Library/Frameworks/Python.framework/Versions/3.12/lib/python3.12/site-packages/django/db/models/query.py", line 999, in _filter_or_exclude_inplace
    self._query.add_q(Q(*args, **kwargs))
  File "/Library/Frameworks/Python.framework/Versions/3.12/lib/python3.12/site-packages/django/db/models/sql/query.py", line 1375, in add_q
    clause, _ = self._add_q(q_object, self.used_aliases)
                ^^^^^^^^^^^^^^^^^^^^^^^^^^^^^^^^^^^^^^^^
  File "/Library/Frameworks/Python.framework/Versions/3.12/lib/python3.12/site-packages/django/db/models/sql/query.py", line 1396, in _add_q
    child_clause, needed_inner = self.build_filter(
                                 ^^^^^^^^^^^^^^^^^^
  File "/Library/Frameworks/Python.framework/Versions/3.12/lib/python3.12/site-packages/django/db/models/sql/query.py", line 1302, in build_filter
    self.check_related_objects(join_info.final_field, value, join_info.opts)
  File "/Library/Frameworks/Python.framework/Versions/3.12/lib/python3.12/site-packages/django/db/models/sql/query.py", line 1134, in check_related_objects
    self.check_query_object_type(value, opts, field)
  File "/Library/Frameworks/Python.framework/Versions/3.12/lib/python3.12/site-packages/django/db/models/sql/query.py", line 1115, in check_query_object_type
    raise ValueError(
ValueError: Cannot query "admin": Must be "User" instance.
2024-06-09 11:10:41,372 - ERROR - Internal Server Error: /challenge/1/: 
Traceback (most recent call last):
  File "/Library/Frameworks/Python.framework/Versions/3.12/lib/python3.12/site-packages/django/core/handlers/exception.py", line 47, in inner
    response = get_response(request)
               ^^^^^^^^^^^^^^^^^^^^^
  File "/Library/Frameworks/Python.framework/Versions/3.12/lib/python3.12/site-packages/django/core/handlers/base.py", line 181, in _get_response
    response = wrapped_callback(request, *callback_args, **callback_kwargs)
               ^^^^^^^^^^^^^^^^^^^^^^^^^^^^^^^^^^^^^^^^^^^^^^^^^^^^^^^^^^^^
  File "/Users/janrydzewski/Developer/Studies/Django/workout_logger/workout/views.py", line 258, in view_challenge
    user_progress = UserProgress.objects.filter(user=request.user, challenge=challenge).first()
                    ^^^^^^^^^^^^^^^^^^^^^^^^^^^^^^^^^^^^^^^^^^^^^^^^^^^^^^^^^^^^^^^^^^^
  File "/Library/Frameworks/Python.framework/Versions/3.12/lib/python3.12/site-packages/django/db/models/manager.py", line 85, in manager_method
    return getattr(self.get_queryset(), name)(*args, **kwargs)
           ^^^^^^^^^^^^^^^^^^^^^^^^^^^^^^^^^^^^^^^^^^^^^^^^^^^
  File "/Library/Frameworks/Python.framework/Versions/3.12/lib/python3.12/site-packages/django/db/models/query.py", line 974, in filter
    return self._filter_or_exclude(False, args, kwargs)
           ^^^^^^^^^^^^^^^^^^^^^^^^^^^^^^^^^^^^^^^^^^^^
  File "/Library/Frameworks/Python.framework/Versions/3.12/lib/python3.12/site-packages/django/db/models/query.py", line 992, in _filter_or_exclude
    clone._filter_or_exclude_inplace(negate, args, kwargs)
  File "/Library/Frameworks/Python.framework/Versions/3.12/lib/python3.12/site-packages/django/db/models/query.py", line 999, in _filter_or_exclude_inplace
    self._query.add_q(Q(*args, **kwargs))
  File "/Library/Frameworks/Python.framework/Versions/3.12/lib/python3.12/site-packages/django/db/models/sql/query.py", line 1375, in add_q
    clause, _ = self._add_q(q_object, self.used_aliases)
                ^^^^^^^^^^^^^^^^^^^^^^^^^^^^^^^^^^^^^^^^
  File "/Library/Frameworks/Python.framework/Versions/3.12/lib/python3.12/site-packages/django/db/models/sql/query.py", line 1396, in _add_q
    child_clause, needed_inner = self.build_filter(
                                 ^^^^^^^^^^^^^^^^^^
  File "/Library/Frameworks/Python.framework/Versions/3.12/lib/python3.12/site-packages/django/db/models/sql/query.py", line 1302, in build_filter
    self.check_related_objects(join_info.final_field, value, join_info.opts)
  File "/Library/Frameworks/Python.framework/Versions/3.12/lib/python3.12/site-packages/django/db/models/sql/query.py", line 1134, in check_related_objects
    self.check_query_object_type(value, opts, field)
  File "/Library/Frameworks/Python.framework/Versions/3.12/lib/python3.12/site-packages/django/db/models/sql/query.py", line 1115, in check_query_object_type
    raise ValueError(
ValueError: Cannot query "admin": Must be "User" instance.
2024-06-09 11:13:47,912 - INFO - /Users/janrydzewski/Developer/Studies/Django/workout_logger/workout/views.py changed, reloading.: 
2024-06-09 11:14:43,341 - INFO - /Users/janrydzewski/Developer/Studies/Django/workout_logger/workout/urls.py changed, reloading.: 
2024-06-09 11:15:41,593 - DEBUG - GET request to login: 
2024-06-09 11:15:45,515 - DEBUG - POST request to login: 
2024-06-09 11:15:48,487 - DEBUG - GET request to new workout: 
2024-06-09 11:15:49,882 - ERROR - Internal Server Error: /challenges: 
Traceback (most recent call last):
  File "/Library/Frameworks/Python.framework/Versions/3.12/lib/python3.12/site-packages/django/template/smartif.py", line 175, in translate_token
    op = OPERATORS[token]
         ~~~~~~~~~^^^^^^^
KeyError: 'user_challenges|filter:'

During handling of the above exception, another exception occurred:

Traceback (most recent call last):
  File "/Library/Frameworks/Python.framework/Versions/3.12/lib/python3.12/site-packages/django/core/handlers/exception.py", line 47, in inner
    response = get_response(request)
               ^^^^^^^^^^^^^^^^^^^^^
  File "/Library/Frameworks/Python.framework/Versions/3.12/lib/python3.12/site-packages/django/core/handlers/base.py", line 181, in _get_response
    response = wrapped_callback(request, *callback_args, **callback_kwargs)
               ^^^^^^^^^^^^^^^^^^^^^^^^^^^^^^^^^^^^^^^^^^^^^^^^^^^^^^^^^^^^
  File "/Users/janrydzewski/Developer/Studies/Django/workout_logger/workout/views.py", line 239, in challenges
    return render(request, "workout/challenges.html", data)
           ^^^^^^^^^^^^^^^^^^^^^^^^^^^^^^^^^^^^^^^^^^^^^^^^
  File "/Library/Frameworks/Python.framework/Versions/3.12/lib/python3.12/site-packages/django/shortcuts.py", line 19, in render
    content = loader.render_to_string(template_name, context, request, using=using)
              ^^^^^^^^^^^^^^^^^^^^^^^^^^^^^^^^^^^^^^^^^^^^^^^^^^^^^^^^^^^^^^^^^^^^^
  File "/Library/Frameworks/Python.framework/Versions/3.12/lib/python3.12/site-packages/django/template/loader.py", line 61, in render_to_string
    template = get_template(template_name, using=using)
               ^^^^^^^^^^^^^^^^^^^^^^^^^^^^^^^^^^^^^^^^
  File "/Library/Frameworks/Python.framework/Versions/3.12/lib/python3.12/site-packages/django/template/loader.py", line 15, in get_template
    return engine.get_template(template_name)
           ^^^^^^^^^^^^^^^^^^^^^^^^^^^^^^^^^^
  File "/Library/Frameworks/Python.framework/Versions/3.12/lib/python3.12/site-packages/django/template/backends/django.py", line 34, in get_template
    return Template(self.engine.get_template(template_name), self)
                    ^^^^^^^^^^^^^^^^^^^^^^^^^^^^^^^^^^^^^^^
  File "/Library/Frameworks/Python.framework/Versions/3.12/lib/python3.12/site-packages/django/template/engine.py", line 163, in get_template
    template, origin = self.find_template(template_name)
                       ^^^^^^^^^^^^^^^^^^^^^^^^^^^^^^^^^
  File "/Library/Frameworks/Python.framework/Versions/3.12/lib/python3.12/site-packages/django/template/engine.py", line 145, in find_template
    template = loader.get_template(name, skip=skip)
               ^^^^^^^^^^^^^^^^^^^^^^^^^^^^^^^^^^^^
  File "/Library/Frameworks/Python.framework/Versions/3.12/lib/python3.12/site-packages/django/template/loaders/base.py", line 29, in get_template
    return Template(
           ^^^^^^^^^
  File "/Library/Frameworks/Python.framework/Versions/3.12/lib/python3.12/site-packages/django/template/base.py", line 155, in __init__
    self.nodelist = self.compile_nodelist()
                    ^^^^^^^^^^^^^^^^^^^^^^^
  File "/Library/Frameworks/Python.framework/Versions/3.12/lib/python3.12/site-packages/django/template/base.py", line 199, in compile_nodelist
    return parser.parse()
           ^^^^^^^^^^^^^^
  File "/Library/Frameworks/Python.framework/Versions/3.12/lib/python3.12/site-packages/django/template/base.py", line 508, in parse
    raise self.error(token, e)
  File "/Library/Frameworks/Python.framework/Versions/3.12/lib/python3.12/site-packages/django/template/base.py", line 506, in parse
    compiled_result = compile_func(self, token)
                      ^^^^^^^^^^^^^^^^^^^^^^^^^
  File "/Library/Frameworks/Python.framework/Versions/3.12/lib/python3.12/site-packages/django/template/defaulttags.py", line 905, in do_if
    nodelist = parser.parse(('elif', 'else', 'endif'))
               ^^^^^^^^^^^^^^^^^^^^^^^^^^^^^^^^^^^^^^^
  File "/Library/Frameworks/Python.framework/Versions/3.12/lib/python3.12/site-packages/django/template/base.py", line 508, in parse
    raise self.error(token, e)
  File "/Library/Frameworks/Python.framework/Versions/3.12/lib/python3.12/site-packages/django/template/base.py", line 506, in parse
    compiled_result = compile_func(self, token)
                      ^^^^^^^^^^^^^^^^^^^^^^^^^
  File "/Library/Frameworks/Python.framework/Versions/3.12/lib/python3.12/site-packages/django/template/defaulttags.py", line 810, in do_for
    nodelist_loop = parser.parse(('empty', 'endfor',))
                    ^^^^^^^^^^^^^^^^^^^^^^^^^^^^^^^^^^
  File "/Library/Frameworks/Python.framework/Versions/3.12/lib/python3.12/site-packages/django/template/base.py", line 508, in parse
    raise self.error(token, e)
  File "/Library/Frameworks/Python.framework/Versions/3.12/lib/python3.12/site-packages/django/template/base.py", line 506, in parse
    compiled_result = compile_func(self, token)
                      ^^^^^^^^^^^^^^^^^^^^^^^^^
  File "/Library/Frameworks/Python.framework/Versions/3.12/lib/python3.12/site-packages/django/template/defaulttags.py", line 904, in do_if
    condition = TemplateIfParser(parser, bits).parse()
                ^^^^^^^^^^^^^^^^^^^^^^^^^^^^^^
  File "/Library/Frameworks/Python.framework/Versions/3.12/lib/python3.12/site-packages/django/template/defaulttags.py", line 837, in __init__
    super().__init__(*args, **kwargs)
  File "/Library/Frameworks/Python.framework/Versions/3.12/lib/python3.12/site-packages/django/template/smartif.py", line 166, in __init__
    mapped_tokens.append(self.translate_token(token))
                         ^^^^^^^^^^^^^^^^^^^^^^^^^^^
  File "/Library/Frameworks/Python.framework/Versions/3.12/lib/python3.12/site-packages/django/template/smartif.py", line 177, in translate_token
    return self.create_var(token)
           ^^^^^^^^^^^^^^^^^^^^^^
  File "/Library/Frameworks/Python.framework/Versions/3.12/lib/python3.12/site-packages/django/template/defaulttags.py", line 840, in create_var
    return TemplateLiteral(self.template_parser.compile_filter(value), value)
                           ^^^^^^^^^^^^^^^^^^^^^^^^^^^^^^^^^^^^^^^^^^
  File "/Library/Frameworks/Python.framework/Versions/3.12/lib/python3.12/site-packages/django/template/base.py", line 593, in compile_filter
    return FilterExpression(token, self)
           ^^^^^^^^^^^^^^^^^^^^^^^^^^^^^
  File "/Library/Frameworks/Python.framework/Versions/3.12/lib/python3.12/site-packages/django/template/base.py", line 687, in __init__
    filter_func = parser.find_filter(filter_name)
                  ^^^^^^^^^^^^^^^^^^^^^^^^^^^^^^^
  File "/Library/Frameworks/Python.framework/Versions/3.12/lib/python3.12/site-packages/django/template/base.py", line 599, in find_filter
    raise TemplateSyntaxError("Invalid filter: '%s'" % filter_name)
django.template.exceptions.TemplateSyntaxError: Invalid filter: 'filter'
2024-06-09 11:16:54,837 - INFO - /Users/janrydzewski/Developer/Studies/Django/workout_logger/workout/views.py changed, reloading.: 
2024-06-09 11:17:43,598 - DEBUG - GET request to login: 
2024-06-09 11:17:49,098 - DEBUG - POST request to login: 
2024-06-09 11:17:50,957 - ERROR - Internal Server Error: /challenges: 
Traceback (most recent call last):
  File "/Library/Frameworks/Python.framework/Versions/3.12/lib/python3.12/site-packages/django/core/handlers/exception.py", line 47, in inner
    response = get_response(request)
               ^^^^^^^^^^^^^^^^^^^^^
  File "/Library/Frameworks/Python.framework/Versions/3.12/lib/python3.12/site-packages/django/core/handlers/base.py", line 181, in _get_response
    response = wrapped_callback(request, *callback_args, **callback_kwargs)
               ^^^^^^^^^^^^^^^^^^^^^^^^^^^^^^^^^^^^^^^^^^^^^^^^^^^^^^^^^^^^
  File "/Users/janrydzewski/Developer/Studies/Django/workout_logger/workout/views.py", line 231, in challenges
    user_challenges = UserProgress.objects.filter(user=request.user).values_list('challenge_id', flat=True)
                      ^^^^^^^^^^^^^^^^^^^^^^^^^^^^^^^^^^^^^^^^^^^^^^
  File "/Library/Frameworks/Python.framework/Versions/3.12/lib/python3.12/site-packages/django/db/models/manager.py", line 85, in manager_method
    return getattr(self.get_queryset(), name)(*args, **kwargs)
           ^^^^^^^^^^^^^^^^^^^^^^^^^^^^^^^^^^^^^^^^^^^^^^^^^^^
  File "/Library/Frameworks/Python.framework/Versions/3.12/lib/python3.12/site-packages/django/db/models/query.py", line 974, in filter
    return self._filter_or_exclude(False, args, kwargs)
           ^^^^^^^^^^^^^^^^^^^^^^^^^^^^^^^^^^^^^^^^^^^^
  File "/Library/Frameworks/Python.framework/Versions/3.12/lib/python3.12/site-packages/django/db/models/query.py", line 992, in _filter_or_exclude
    clone._filter_or_exclude_inplace(negate, args, kwargs)
  File "/Library/Frameworks/Python.framework/Versions/3.12/lib/python3.12/site-packages/django/db/models/query.py", line 999, in _filter_or_exclude_inplace
    self._query.add_q(Q(*args, **kwargs))
  File "/Library/Frameworks/Python.framework/Versions/3.12/lib/python3.12/site-packages/django/db/models/sql/query.py", line 1375, in add_q
    clause, _ = self._add_q(q_object, self.used_aliases)
                ^^^^^^^^^^^^^^^^^^^^^^^^^^^^^^^^^^^^^^^^
  File "/Library/Frameworks/Python.framework/Versions/3.12/lib/python3.12/site-packages/django/db/models/sql/query.py", line 1396, in _add_q
    child_clause, needed_inner = self.build_filter(
                                 ^^^^^^^^^^^^^^^^^^
  File "/Library/Frameworks/Python.framework/Versions/3.12/lib/python3.12/site-packages/django/db/models/sql/query.py", line 1302, in build_filter
    self.check_related_objects(join_info.final_field, value, join_info.opts)
  File "/Library/Frameworks/Python.framework/Versions/3.12/lib/python3.12/site-packages/django/db/models/sql/query.py", line 1134, in check_related_objects
    self.check_query_object_type(value, opts, field)
  File "/Library/Frameworks/Python.framework/Versions/3.12/lib/python3.12/site-packages/django/db/models/sql/query.py", line 1115, in check_query_object_type
    raise ValueError(
ValueError: Cannot query "admin": Must be "User" instance.
2024-06-09 11:18:13,644 - INFO - /Users/janrydzewski/Developer/Studies/Django/workout_logger/workout/views.py changed, reloading.: 
2024-06-09 11:18:16,080 - INFO - /Users/janrydzewski/Developer/Studies/Django/workout_logger/workout/views.py changed, reloading.: 
2024-06-09 11:18:26,431 - INFO - /Users/janrydzewski/Developer/Studies/Django/workout_logger/workout/views.py changed, reloading.: 
2024-06-09 11:18:28,726 - INFO - /Users/janrydzewski/Developer/Studies/Django/workout_logger/workout/views.py changed, reloading.: 
2024-06-09 11:18:42,372 - DEBUG - GET request to login: 
2024-06-09 11:18:46,510 - DEBUG - POST request to login: 
2024-06-09 11:18:50,203 - ERROR - Internal Server Error: /challenges: 
Traceback (most recent call last):
  File "/Library/Frameworks/Python.framework/Versions/3.12/lib/python3.12/site-packages/django/core/handlers/exception.py", line 47, in inner
    response = get_response(request)
               ^^^^^^^^^^^^^^^^^^^^^
  File "/Library/Frameworks/Python.framework/Versions/3.12/lib/python3.12/site-packages/django/core/handlers/base.py", line 181, in _get_response
    response = wrapped_callback(request, *callback_args, **callback_kwargs)
               ^^^^^^^^^^^^^^^^^^^^^^^^^^^^^^^^^^^^^^^^^^^^^^^^^^^^^^^^^^^^
  File "/Users/janrydzewski/Developer/Studies/Django/workout_logger/workout/views.py", line 231, in challenges
    user_challenges = UserProgress.objects.filter(user=request.user).values_list('challenge_id', flat=True)
                      ^^^^^^^^^^^^^^^^^^^^^^^^^^^^^^^^^^^^^^^^^^^^^^
  File "/Library/Frameworks/Python.framework/Versions/3.12/lib/python3.12/site-packages/django/db/models/manager.py", line 85, in manager_method
    return getattr(self.get_queryset(), name)(*args, **kwargs)
           ^^^^^^^^^^^^^^^^^^^^^^^^^^^^^^^^^^^^^^^^^^^^^^^^^^^
  File "/Library/Frameworks/Python.framework/Versions/3.12/lib/python3.12/site-packages/django/db/models/query.py", line 974, in filter
    return self._filter_or_exclude(False, args, kwargs)
           ^^^^^^^^^^^^^^^^^^^^^^^^^^^^^^^^^^^^^^^^^^^^
  File "/Library/Frameworks/Python.framework/Versions/3.12/lib/python3.12/site-packages/django/db/models/query.py", line 992, in _filter_or_exclude
    clone._filter_or_exclude_inplace(negate, args, kwargs)
  File "/Library/Frameworks/Python.framework/Versions/3.12/lib/python3.12/site-packages/django/db/models/query.py", line 999, in _filter_or_exclude_inplace
    self._query.add_q(Q(*args, **kwargs))
  File "/Library/Frameworks/Python.framework/Versions/3.12/lib/python3.12/site-packages/django/db/models/sql/query.py", line 1375, in add_q
    clause, _ = self._add_q(q_object, self.used_aliases)
                ^^^^^^^^^^^^^^^^^^^^^^^^^^^^^^^^^^^^^^^^
  File "/Library/Frameworks/Python.framework/Versions/3.12/lib/python3.12/site-packages/django/db/models/sql/query.py", line 1396, in _add_q
    child_clause, needed_inner = self.build_filter(
                                 ^^^^^^^^^^^^^^^^^^
  File "/Library/Frameworks/Python.framework/Versions/3.12/lib/python3.12/site-packages/django/db/models/sql/query.py", line 1302, in build_filter
    self.check_related_objects(join_info.final_field, value, join_info.opts)
  File "/Library/Frameworks/Python.framework/Versions/3.12/lib/python3.12/site-packages/django/db/models/sql/query.py", line 1134, in check_related_objects
    self.check_query_object_type(value, opts, field)
  File "/Library/Frameworks/Python.framework/Versions/3.12/lib/python3.12/site-packages/django/db/models/sql/query.py", line 1115, in check_query_object_type
    raise ValueError(
ValueError: Cannot query "admin": Must be "User" instance.
2024-06-09 11:19:51,539 - INFO - /Users/janrydzewski/Developer/Studies/Django/workout_logger/workout/models.py changed, reloading.: 
2024-06-09 11:19:59,247 - INFO - /Users/janrydzewski/Developer/Studies/Django/workout_logger/workout/views.py changed, reloading.: 
2024-06-09 11:20:00,530 - INFO - /Users/janrydzewski/Developer/Studies/Django/workout_logger/workout/views.py changed, reloading.: 
2024-06-09 11:20:13,950 - DEBUG - GET request to login: 
2024-06-09 11:20:20,044 - DEBUG - GET request to new workout: 
2024-06-09 11:20:20,517 - ERROR - Internal Server Error: /challenges: 
Traceback (most recent call last):
  File "/Library/Frameworks/Python.framework/Versions/3.12/lib/python3.12/site-packages/django/core/handlers/exception.py", line 47, in inner
    response = get_response(request)
               ^^^^^^^^^^^^^^^^^^^^^
  File "/Library/Frameworks/Python.framework/Versions/3.12/lib/python3.12/site-packages/django/core/handlers/base.py", line 181, in _get_response
    response = wrapped_callback(request, *callback_args, **callback_kwargs)
               ^^^^^^^^^^^^^^^^^^^^^^^^^^^^^^^^^^^^^^^^^^^^^^^^^^^^^^^^^^^^
  File "/Users/janrydzewski/Developer/Studies/Django/workout_logger/workout/views.py", line 236, in challenges
    return render(request, "challenges.html", context)
           ^^^^^^^^^^^^^^^^^^^^^^^^^^^^^^^^^^^^^^^^^^^
  File "/Library/Frameworks/Python.framework/Versions/3.12/lib/python3.12/site-packages/django/shortcuts.py", line 19, in render
    content = loader.render_to_string(template_name, context, request, using=using)
              ^^^^^^^^^^^^^^^^^^^^^^^^^^^^^^^^^^^^^^^^^^^^^^^^^^^^^^^^^^^^^^^^^^^^^
  File "/Library/Frameworks/Python.framework/Versions/3.12/lib/python3.12/site-packages/django/template/loader.py", line 61, in render_to_string
    template = get_template(template_name, using=using)
               ^^^^^^^^^^^^^^^^^^^^^^^^^^^^^^^^^^^^^^^^
  File "/Library/Frameworks/Python.framework/Versions/3.12/lib/python3.12/site-packages/django/template/loader.py", line 19, in get_template
    raise TemplateDoesNotExist(template_name, chain=chain)
django.template.exceptions.TemplateDoesNotExist: challenges.html
2024-06-09 11:21:40,294 - INFO - /Users/janrydzewski/Developer/Studies/Django/workout_logger/workout/views.py changed, reloading.: 
2024-06-09 11:21:41,156 - ERROR - Internal Server Error: /challenges: 
Traceback (most recent call last):
  File "/Library/Frameworks/Python.framework/Versions/3.12/lib/python3.12/site-packages/django/core/handlers/exception.py", line 47, in inner
    response = get_response(request)
               ^^^^^^^^^^^^^^^^^^^^^
  File "/Library/Frameworks/Python.framework/Versions/3.12/lib/python3.12/site-packages/django/core/handlers/base.py", line 181, in _get_response
    response = wrapped_callback(request, *callback_args, **callback_kwargs)
               ^^^^^^^^^^^^^^^^^^^^^^^^^^^^^^^^^^^^^^^^^^^^^^^^^^^^^^^^^^^^
  File "/Users/janrydzewski/Developer/Studies/Django/workout_logger/workout/views.py", line 236, in challenges
    return render(request, "challenges.html", context)
           ^^^^^^^^^^^^^^^^^^^^^^^^^^^^^^^^^^^^^^^^^^^
  File "/Library/Frameworks/Python.framework/Versions/3.12/lib/python3.12/site-packages/django/shortcuts.py", line 19, in render
    content = loader.render_to_string(template_name, context, request, using=using)
              ^^^^^^^^^^^^^^^^^^^^^^^^^^^^^^^^^^^^^^^^^^^^^^^^^^^^^^^^^^^^^^^^^^^^^
  File "/Library/Frameworks/Python.framework/Versions/3.12/lib/python3.12/site-packages/django/template/loader.py", line 61, in render_to_string
    template = get_template(template_name, using=using)
               ^^^^^^^^^^^^^^^^^^^^^^^^^^^^^^^^^^^^^^^^
  File "/Library/Frameworks/Python.framework/Versions/3.12/lib/python3.12/site-packages/django/template/loader.py", line 19, in get_template
    raise TemplateDoesNotExist(template_name, chain=chain)
django.template.exceptions.TemplateDoesNotExist: challenges.html
2024-06-09 11:21:42,008 - ERROR - Internal Server Error: /challenges: 
Traceback (most recent call last):
  File "/Library/Frameworks/Python.framework/Versions/3.12/lib/python3.12/site-packages/django/core/handlers/exception.py", line 47, in inner
    response = get_response(request)
               ^^^^^^^^^^^^^^^^^^^^^
  File "/Library/Frameworks/Python.framework/Versions/3.12/lib/python3.12/site-packages/django/core/handlers/base.py", line 181, in _get_response
    response = wrapped_callback(request, *callback_args, **callback_kwargs)
               ^^^^^^^^^^^^^^^^^^^^^^^^^^^^^^^^^^^^^^^^^^^^^^^^^^^^^^^^^^^^
  File "/Users/janrydzewski/Developer/Studies/Django/workout_logger/workout/views.py", line 236, in challenges
    return render(request, "challenges.html", context)
           ^^^^^^^^^^^^^^^^^^^^^^^^^^^^^^^^^^^^^^^^^^^
  File "/Library/Frameworks/Python.framework/Versions/3.12/lib/python3.12/site-packages/django/shortcuts.py", line 19, in render
    content = loader.render_to_string(template_name, context, request, using=using)
              ^^^^^^^^^^^^^^^^^^^^^^^^^^^^^^^^^^^^^^^^^^^^^^^^^^^^^^^^^^^^^^^^^^^^^
  File "/Library/Frameworks/Python.framework/Versions/3.12/lib/python3.12/site-packages/django/template/loader.py", line 61, in render_to_string
    template = get_template(template_name, using=using)
               ^^^^^^^^^^^^^^^^^^^^^^^^^^^^^^^^^^^^^^^^
  File "/Library/Frameworks/Python.framework/Versions/3.12/lib/python3.12/site-packages/django/template/loader.py", line 19, in get_template
    raise TemplateDoesNotExist(template_name, chain=chain)
django.template.exceptions.TemplateDoesNotExist: challenges.html
2024-06-09 11:21:42,510 - ERROR - Internal Server Error: /challenges: 
Traceback (most recent call last):
  File "/Library/Frameworks/Python.framework/Versions/3.12/lib/python3.12/site-packages/django/core/handlers/exception.py", line 47, in inner
    response = get_response(request)
               ^^^^^^^^^^^^^^^^^^^^^
  File "/Library/Frameworks/Python.framework/Versions/3.12/lib/python3.12/site-packages/django/core/handlers/base.py", line 181, in _get_response
    response = wrapped_callback(request, *callback_args, **callback_kwargs)
               ^^^^^^^^^^^^^^^^^^^^^^^^^^^^^^^^^^^^^^^^^^^^^^^^^^^^^^^^^^^^
  File "/Users/janrydzewski/Developer/Studies/Django/workout_logger/workout/views.py", line 236, in challenges
    return render(request, "challenges.html", context)
           ^^^^^^^^^^^^^^^^^^^^^^^^^^^^^^^^^^^^^^^^^^^
  File "/Library/Frameworks/Python.framework/Versions/3.12/lib/python3.12/site-packages/django/shortcuts.py", line 19, in render
    content = loader.render_to_string(template_name, context, request, using=using)
              ^^^^^^^^^^^^^^^^^^^^^^^^^^^^^^^^^^^^^^^^^^^^^^^^^^^^^^^^^^^^^^^^^^^^^
  File "/Library/Frameworks/Python.framework/Versions/3.12/lib/python3.12/site-packages/django/template/loader.py", line 61, in render_to_string
    template = get_template(template_name, using=using)
               ^^^^^^^^^^^^^^^^^^^^^^^^^^^^^^^^^^^^^^^^
  File "/Library/Frameworks/Python.framework/Versions/3.12/lib/python3.12/site-packages/django/template/loader.py", line 19, in get_template
    raise TemplateDoesNotExist(template_name, chain=chain)
django.template.exceptions.TemplateDoesNotExist: challenges.html
2024-06-09 11:22:07,010 - INFO - /Users/janrydzewski/Developer/Studies/Django/workout_logger/workout/urls.py changed, reloading.: 
2024-06-09 11:22:12,419 - INFO - /Users/janrydzewski/Developer/Studies/Django/workout_logger/workout/urls.py changed, reloading.: 
2024-06-09 11:22:14,711 - INFO - /Users/janrydzewski/Developer/Studies/Django/workout_logger/workout/urls.py changed, reloading.: 
2024-06-09 11:22:23,284 - ERROR - Internal Server Error: /challenges: 
Traceback (most recent call last):
  File "/Library/Frameworks/Python.framework/Versions/3.12/lib/python3.12/site-packages/django/core/handlers/exception.py", line 47, in inner
    response = get_response(request)
               ^^^^^^^^^^^^^^^^^^^^^
  File "/Library/Frameworks/Python.framework/Versions/3.12/lib/python3.12/site-packages/django/core/handlers/base.py", line 181, in _get_response
    response = wrapped_callback(request, *callback_args, **callback_kwargs)
               ^^^^^^^^^^^^^^^^^^^^^^^^^^^^^^^^^^^^^^^^^^^^^^^^^^^^^^^^^^^^
  File "/Users/janrydzewski/Developer/Studies/Django/workout_logger/workout/views.py", line 236, in challenges
    return render(request, "challenges.html", context)
           ^^^^^^^^^^^^^^^^^^^^^^^^^^^^^^^^^^^^^^^^^^^
  File "/Library/Frameworks/Python.framework/Versions/3.12/lib/python3.12/site-packages/django/shortcuts.py", line 19, in render
    content = loader.render_to_string(template_name, context, request, using=using)
              ^^^^^^^^^^^^^^^^^^^^^^^^^^^^^^^^^^^^^^^^^^^^^^^^^^^^^^^^^^^^^^^^^^^^^
  File "/Library/Frameworks/Python.framework/Versions/3.12/lib/python3.12/site-packages/django/template/loader.py", line 61, in render_to_string
    template = get_template(template_name, using=using)
               ^^^^^^^^^^^^^^^^^^^^^^^^^^^^^^^^^^^^^^^^
  File "/Library/Frameworks/Python.framework/Versions/3.12/lib/python3.12/site-packages/django/template/loader.py", line 19, in get_template
    raise TemplateDoesNotExist(template_name, chain=chain)
django.template.exceptions.TemplateDoesNotExist: challenges.html
2024-06-09 11:22:51,432 - INFO - /Users/janrydzewski/Developer/Studies/Django/workout_logger/workout/views.py changed, reloading.: 
2024-06-09 11:23:04,842 - INFO - /Users/janrydzewski/Developer/Studies/Django/workout_logger/workout/views.py changed, reloading.: 
2024-06-09 11:23:11,430 - INFO - /Users/janrydzewski/Developer/Studies/Django/workout_logger/workout/views.py changed, reloading.: 
2024-06-09 11:23:37,882 - INFO - /Users/janrydzewski/Developer/Studies/Django/workout_logger/workout/urls.py changed, reloading.: 
2024-06-09 11:23:50,337 - INFO - /Users/janrydzewski/Developer/Studies/Django/workout_logger/workout/urls.py changed, reloading.: 
2024-06-09 11:24:00,633 - INFO - /Users/janrydzewski/Developer/Studies/Django/workout_logger/workout/views.py changed, reloading.: 
2024-06-09 11:24:23,407 - INFO - /Users/janrydzewski/Developer/Studies/Django/workout_logger/workout/models.py changed, reloading.: 
2024-06-09 11:35:37,531 - DEBUG - GET request to login: 
2024-06-09 11:35:41,636 - DEBUG - GET request to new workout: 
2024-06-09 11:35:50,445 - WARNING - Not Found: /challenge: 
2024-06-09 11:37:24,936 - DEBUG - GET request to new workout: 
2024-06-09 11:38:03,338 - INFO - /Users/janrydzewski/Developer/Studies/Django/workout_logger/workout/views.py changed, reloading.: 
2024-06-09 11:38:07,775 - INFO - /Users/janrydzewski/Developer/Studies/Django/workout_logger/workout/views.py changed, reloading.: 
2024-06-09 11:38:14,101 - INFO - /Users/janrydzewski/Developer/Studies/Django/workout_logger/workout/views.py changed, reloading.: 
2024-06-09 11:38:23,474 - INFO - /Users/janrydzewski/Developer/Studies/Django/workout_logger/workout/views.py changed, reloading.: 
2024-06-09 11:38:26,769 - INFO - /Users/janrydzewski/Developer/Studies/Django/workout_logger/workout/views.py changed, reloading.: 
2024-06-09 11:38:28,026 - INFO - /Users/janrydzewski/Developer/Studies/Django/workout_logger/workout/views.py changed, reloading.: 
2024-06-09 11:39:12,215 - INFO - /Users/janrydzewski/Developer/Studies/Django/workout_logger/workout/views.py changed, reloading.: 
2024-06-09 11:39:55,248 - INFO - /Users/janrydzewski/Developer/Studies/Django/workout_logger/workout/views.py changed, reloading.: 
2024-06-09 11:40:33,363 - INFO - /Users/janrydzewski/Developer/Studies/Django/workout_logger/workout/views.py changed, reloading.: 
2024-06-09 11:40:47,923 - INFO - /Users/janrydzewski/Developer/Studies/Django/workout_logger/workout/views.py changed, reloading.: 
2024-06-09 11:41:11,751 - INFO - /Users/janrydzewski/Developer/Studies/Django/workout_logger/workout/views.py changed, reloading.: 
2024-06-09 11:41:37,061 - DEBUG - GET request to login: 
2024-06-09 11:42:53,257 - DEBUG - GET request to new workout: 
2024-06-09 11:42:53,752 - DEBUG - GET request to new exercise: 
2024-06-09 11:43:22,108 - INFO - /Users/janrydzewski/Developer/Studies/Django/workout_logger/workout/views.py changed, reloading.: 
2024-06-09 11:43:24,526 - INFO - /Users/janrydzewski/Developer/Studies/Django/workout_logger/workout/views.py changed, reloading.: 
2024-06-09 11:43:27,839 - INFO - /Users/janrydzewski/Developer/Studies/Django/workout_logger/workout/views.py changed, reloading.: 
2024-06-09 11:43:34,409 - INFO - /Users/janrydzewski/Developer/Studies/Django/workout_logger/workout/views.py changed, reloading.: 
2024-06-09 11:43:39,808 - INFO - /Users/janrydzewski/Developer/Studies/Django/workout_logger/workout/views.py changed, reloading.: 
2024-06-09 11:44:50,262 - INFO - /Users/janrydzewski/Developer/Studies/Django/workout_logger/workout/views.py changed, reloading.: 
2024-06-09 11:47:07,702 - WARNING - Not Found: /challenge/7: 
2024-06-09 11:47:09,033 - WARNING - Not Found: /challenge/join/7: 
2024-06-09 11:47:54,372 - DEBUG - GET request to new workout: 
2024-06-09 11:52:55,055 - INFO - /Users/janrydzewski/Developer/Studies/Django/workout_logger/workout/views.py changed, reloading.: 
2024-06-09 11:53:03,817 - DEBUG - GET request to new workout: 
2024-06-09 11:53:05,965 - DEBUG - GET request to new workout: 
2024-06-09 11:54:28,318 - INFO - /Users/janrydzewski/Developer/Studies/Django/workout_logger/workout/views.py changed, reloading.: 
2024-06-09 11:54:31,746 - INFO - /Users/janrydzewski/Developer/Studies/Django/workout_logger/workout/views.py changed, reloading.: 
2024-06-09 11:54:46,248 - WARNING - Not Found: /challenge/join/7: 
2024-06-09 11:54:48,082 - WARNING - Not Found: /challenge/7: 
2024-06-09 14:38:26,996 - DEBUG - GET request to login: 
2024-06-09 14:38:32,959 - DEBUG - POST request to login: 
2024-06-09 14:41:31,475 - DEBUG - GET request to new exercise: 
2024-06-09 14:46:19,792 - INFO - /Users/janrydzewski/Developer/Studies/Django/workout_logger/workout/models.py changed, reloading.: 
2024-06-09 14:46:21,190 - INFO - /Users/janrydzewski/Developer/Studies/Django/workout_logger/workout/models.py changed, reloading.: 
2024-06-09 14:46:57,966 - INFO - /Users/janrydzewski/Developer/Studies/Django/workout_logger/workout/views.py changed, reloading.: 
2024-06-09 14:47:20,484 - INFO - /Users/janrydzewski/Developer/Studies/Django/workout_logger/workout/views.py changed, reloading.: 
2024-06-09 14:47:24,901 - INFO - /Users/janrydzewski/Developer/Studies/Django/workout_logger/workout/views.py changed, reloading.: 
2024-06-09 14:48:25,606 - ERROR - Internal Server Error: /dashboard: 
Traceback (most recent call last):
  File "/Library/Frameworks/Python.framework/Versions/3.12/lib/python3.12/site-packages/django/db/backends/utils.py", line 85, in _execute
    return self.cursor.execute(sql, params)
           ^^^^^^^^^^^^^^^^^^^^^^^^^^^^^^^^
  File "/Library/Frameworks/Python.framework/Versions/3.12/lib/python3.12/site-packages/django/db/backends/sqlite3/base.py", line 416, in execute
    return Database.Cursor.execute(self, query, params)
           ^^^^^^^^^^^^^^^^^^^^^^^^^^^^^^^^^^^^^^^^^^^^
sqlite3.OperationalError: no such table: workout_userchallenge

The above exception was the direct cause of the following exception:

Traceback (most recent call last):
  File "/Library/Frameworks/Python.framework/Versions/3.12/lib/python3.12/site-packages/django/core/handlers/exception.py", line 47, in inner
    response = get_response(request)
               ^^^^^^^^^^^^^^^^^^^^^
  File "/Library/Frameworks/Python.framework/Versions/3.12/lib/python3.12/site-packages/django/core/handlers/base.py", line 181, in _get_response
    response = wrapped_callback(request, *callback_args, **callback_kwargs)
               ^^^^^^^^^^^^^^^^^^^^^^^^^^^^^^^^^^^^^^^^^^^^^^^^^^^^^^^^^^^^
  File "/Users/janrydzewski/Developer/Studies/Django/workout_logger/workout/views.py", line 146, in dashboard
    return render(request, "workout/dashboard.html", data)
           ^^^^^^^^^^^^^^^^^^^^^^^^^^^^^^^^^^^^^^^^^^^^^^^
  File "/Library/Frameworks/Python.framework/Versions/3.12/lib/python3.12/site-packages/django/shortcuts.py", line 19, in render
    content = loader.render_to_string(template_name, context, request, using=using)
              ^^^^^^^^^^^^^^^^^^^^^^^^^^^^^^^^^^^^^^^^^^^^^^^^^^^^^^^^^^^^^^^^^^^^^
  File "/Library/Frameworks/Python.framework/Versions/3.12/lib/python3.12/site-packages/django/template/loader.py", line 62, in render_to_string
    return template.render(context, request)
           ^^^^^^^^^^^^^^^^^^^^^^^^^^^^^^^^^
  File "/Library/Frameworks/Python.framework/Versions/3.12/lib/python3.12/site-packages/django/template/backends/django.py", line 61, in render
    return self.template.render(context)
           ^^^^^^^^^^^^^^^^^^^^^^^^^^^^^
  File "/Library/Frameworks/Python.framework/Versions/3.12/lib/python3.12/site-packages/django/template/base.py", line 176, in render
    return self._render(context)
           ^^^^^^^^^^^^^^^^^^^^^
  File "/Library/Frameworks/Python.framework/Versions/3.12/lib/python3.12/site-packages/django/template/base.py", line 168, in _render
    return self.nodelist.render(context)
           ^^^^^^^^^^^^^^^^^^^^^^^^^^^^^
  File "/Library/Frameworks/Python.framework/Versions/3.12/lib/python3.12/site-packages/django/template/base.py", line 978, in render
    node.render_annotated(context) for node in self
    ^^^^^^^^^^^^^^^^^^^^^^^^^^^^^^
  File "/Library/Frameworks/Python.framework/Versions/3.12/lib/python3.12/site-packages/django/template/base.py", line 938, in render_annotated
    return self.render(context)
           ^^^^^^^^^^^^^^^^^^^^
  File "/Library/Frameworks/Python.framework/Versions/3.12/lib/python3.12/site-packages/django/template/defaulttags.py", line 294, in render
    if match:
       ^^^^^
  File "/Library/Frameworks/Python.framework/Versions/3.12/lib/python3.12/site-packages/django/db/models/query.py", line 284, in __bool__
    self._fetch_all()
  File "/Library/Frameworks/Python.framework/Versions/3.12/lib/python3.12/site-packages/django/db/models/query.py", line 1354, in _fetch_all
    self._result_cache = list(self._iterable_class(self))
                         ^^^^^^^^^^^^^^^^^^^^^^^^^^^^^^^^
  File "/Library/Frameworks/Python.framework/Versions/3.12/lib/python3.12/site-packages/django/db/models/query.py", line 51, in __iter__
    results = compiler.execute_sql(chunked_fetch=self.chunked_fetch, chunk_size=self.chunk_size)
              ^^^^^^^^^^^^^^^^^^^^^^^^^^^^^^^^^^^^^^^^^^^^^^^^^^^^^^^^^^^^^^^^^^^^^^^^^^^^^^^^^^
  File "/Library/Frameworks/Python.framework/Versions/3.12/lib/python3.12/site-packages/django/db/models/sql/compiler.py", line 1202, in execute_sql
    cursor.execute(sql, params)
  File "/Library/Frameworks/Python.framework/Versions/3.12/lib/python3.12/site-packages/django/db/backends/utils.py", line 99, in execute
    return super().execute(sql, params)
           ^^^^^^^^^^^^^^^^^^^^^^^^^^^^
  File "/Library/Frameworks/Python.framework/Versions/3.12/lib/python3.12/site-packages/django/db/backends/utils.py", line 67, in execute
    return self._execute_with_wrappers(sql, params, many=False, executor=self._execute)
           ^^^^^^^^^^^^^^^^^^^^^^^^^^^^^^^^^^^^^^^^^^^^^^^^^^^^^^^^^^^^^^^^^^^^^^^^^^^^
  File "/Library/Frameworks/Python.framework/Versions/3.12/lib/python3.12/site-packages/django/db/backends/utils.py", line 76, in _execute_with_wrappers
    return executor(sql, params, many, context)
           ^^^^^^^^^^^^^^^^^^^^^^^^^^^^^^^^^^^^
  File "/Library/Frameworks/Python.framework/Versions/3.12/lib/python3.12/site-packages/django/db/backends/utils.py", line 80, in _execute
    with self.db.wrap_database_errors:
  File "/Library/Frameworks/Python.framework/Versions/3.12/lib/python3.12/site-packages/django/db/utils.py", line 90, in __exit__
    raise dj_exc_value.with_traceback(traceback) from exc_value
  File "/Library/Frameworks/Python.framework/Versions/3.12/lib/python3.12/site-packages/django/db/backends/utils.py", line 85, in _execute
    return self.cursor.execute(sql, params)
           ^^^^^^^^^^^^^^^^^^^^^^^^^^^^^^^^
  File "/Library/Frameworks/Python.framework/Versions/3.12/lib/python3.12/site-packages/django/db/backends/sqlite3/base.py", line 416, in execute
    return Database.Cursor.execute(self, query, params)
           ^^^^^^^^^^^^^^^^^^^^^^^^^^^^^^^^^^^^^^^^^^^^
django.db.utils.OperationalError: no such table: workout_userchallenge
2024-06-09 14:49:05,086 - ERROR - Internal Server Error: /dashboard: 
Traceback (most recent call last):
  File "/Library/Frameworks/Python.framework/Versions/3.12/lib/python3.12/site-packages/django/template/base.py", line 500, in parse
    compile_func = self.tags[command]
                   ~~~~~~~~~^^^^^^^^^
KeyError: 'else'

During handling of the above exception, another exception occurred:

Traceback (most recent call last):
  File "/Library/Frameworks/Python.framework/Versions/3.12/lib/python3.12/site-packages/django/core/handlers/exception.py", line 47, in inner
    response = get_response(request)
               ^^^^^^^^^^^^^^^^^^^^^
  File "/Library/Frameworks/Python.framework/Versions/3.12/lib/python3.12/site-packages/django/core/handlers/base.py", line 181, in _get_response
    response = wrapped_callback(request, *callback_args, **callback_kwargs)
               ^^^^^^^^^^^^^^^^^^^^^^^^^^^^^^^^^^^^^^^^^^^^^^^^^^^^^^^^^^^^
  File "/Users/janrydzewski/Developer/Studies/Django/workout_logger/workout/views.py", line 146, in dashboard
    return render(request, "workout/dashboard.html", data)
           ^^^^^^^^^^^^^^^^^^^^^^^^^^^^^^^^^^^^^^^^^^^^^^^
  File "/Library/Frameworks/Python.framework/Versions/3.12/lib/python3.12/site-packages/django/shortcuts.py", line 19, in render
    content = loader.render_to_string(template_name, context, request, using=using)
              ^^^^^^^^^^^^^^^^^^^^^^^^^^^^^^^^^^^^^^^^^^^^^^^^^^^^^^^^^^^^^^^^^^^^^
  File "/Library/Frameworks/Python.framework/Versions/3.12/lib/python3.12/site-packages/django/template/loader.py", line 61, in render_to_string
    template = get_template(template_name, using=using)
               ^^^^^^^^^^^^^^^^^^^^^^^^^^^^^^^^^^^^^^^^
  File "/Library/Frameworks/Python.framework/Versions/3.12/lib/python3.12/site-packages/django/template/loader.py", line 15, in get_template
    return engine.get_template(template_name)
           ^^^^^^^^^^^^^^^^^^^^^^^^^^^^^^^^^^
  File "/Library/Frameworks/Python.framework/Versions/3.12/lib/python3.12/site-packages/django/template/backends/django.py", line 34, in get_template
    return Template(self.engine.get_template(template_name), self)
                    ^^^^^^^^^^^^^^^^^^^^^^^^^^^^^^^^^^^^^^^
  File "/Library/Frameworks/Python.framework/Versions/3.12/lib/python3.12/site-packages/django/template/engine.py", line 163, in get_template
    template, origin = self.find_template(template_name)
                       ^^^^^^^^^^^^^^^^^^^^^^^^^^^^^^^^^
  File "/Library/Frameworks/Python.framework/Versions/3.12/lib/python3.12/site-packages/django/template/engine.py", line 145, in find_template
    template = loader.get_template(name, skip=skip)
               ^^^^^^^^^^^^^^^^^^^^^^^^^^^^^^^^^^^^
  File "/Library/Frameworks/Python.framework/Versions/3.12/lib/python3.12/site-packages/django/template/loaders/base.py", line 29, in get_template
    return Template(
           ^^^^^^^^^
  File "/Library/Frameworks/Python.framework/Versions/3.12/lib/python3.12/site-packages/django/template/base.py", line 155, in __init__
    self.nodelist = self.compile_nodelist()
                    ^^^^^^^^^^^^^^^^^^^^^^^
  File "/Library/Frameworks/Python.framework/Versions/3.12/lib/python3.12/site-packages/django/template/base.py", line 199, in compile_nodelist
    return parser.parse()
           ^^^^^^^^^^^^^^
  File "/Library/Frameworks/Python.framework/Versions/3.12/lib/python3.12/site-packages/django/template/base.py", line 502, in parse
    self.invalid_block_tag(token, command, parse_until)
  File "/Library/Frameworks/Python.framework/Versions/3.12/lib/python3.12/site-packages/django/template/base.py", line 561, in invalid_block_tag
    raise self.error(
django.template.exceptions.TemplateSyntaxError: Invalid block tag on line 116: 'else'. Did you forget to register or load this tag?
2024-06-09 14:50:23,724 - ERROR - Internal Server Error: /dashboard: 
Traceback (most recent call last):
  File "/Library/Frameworks/Python.framework/Versions/3.12/lib/python3.12/site-packages/django/db/backends/utils.py", line 85, in _execute
    return self.cursor.execute(sql, params)
           ^^^^^^^^^^^^^^^^^^^^^^^^^^^^^^^^
  File "/Library/Frameworks/Python.framework/Versions/3.12/lib/python3.12/site-packages/django/db/backends/sqlite3/base.py", line 416, in execute
    return Database.Cursor.execute(self, query, params)
           ^^^^^^^^^^^^^^^^^^^^^^^^^^^^^^^^^^^^^^^^^^^^
sqlite3.OperationalError: no such table: workout_userchallenge

The above exception was the direct cause of the following exception:

Traceback (most recent call last):
  File "/Library/Frameworks/Python.framework/Versions/3.12/lib/python3.12/site-packages/django/core/handlers/exception.py", line 47, in inner
    response = get_response(request)
               ^^^^^^^^^^^^^^^^^^^^^
  File "/Library/Frameworks/Python.framework/Versions/3.12/lib/python3.12/site-packages/django/core/handlers/base.py", line 181, in _get_response
    response = wrapped_callback(request, *callback_args, **callback_kwargs)
               ^^^^^^^^^^^^^^^^^^^^^^^^^^^^^^^^^^^^^^^^^^^^^^^^^^^^^^^^^^^^
  File "/Users/janrydzewski/Developer/Studies/Django/workout_logger/workout/views.py", line 146, in dashboard
    return render(request, "workout/dashboard.html", data)
           ^^^^^^^^^^^^^^^^^^^^^^^^^^^^^^^^^^^^^^^^^^^^^^^
  File "/Library/Frameworks/Python.framework/Versions/3.12/lib/python3.12/site-packages/django/shortcuts.py", line 19, in render
    content = loader.render_to_string(template_name, context, request, using=using)
              ^^^^^^^^^^^^^^^^^^^^^^^^^^^^^^^^^^^^^^^^^^^^^^^^^^^^^^^^^^^^^^^^^^^^^
  File "/Library/Frameworks/Python.framework/Versions/3.12/lib/python3.12/site-packages/django/template/loader.py", line 62, in render_to_string
    return template.render(context, request)
           ^^^^^^^^^^^^^^^^^^^^^^^^^^^^^^^^^
  File "/Library/Frameworks/Python.framework/Versions/3.12/lib/python3.12/site-packages/django/template/backends/django.py", line 61, in render
    return self.template.render(context)
           ^^^^^^^^^^^^^^^^^^^^^^^^^^^^^
  File "/Library/Frameworks/Python.framework/Versions/3.12/lib/python3.12/site-packages/django/template/base.py", line 176, in render
    return self._render(context)
           ^^^^^^^^^^^^^^^^^^^^^
  File "/Library/Frameworks/Python.framework/Versions/3.12/lib/python3.12/site-packages/django/template/base.py", line 168, in _render
    return self.nodelist.render(context)
           ^^^^^^^^^^^^^^^^^^^^^^^^^^^^^
  File "/Library/Frameworks/Python.framework/Versions/3.12/lib/python3.12/site-packages/django/template/base.py", line 978, in render
    node.render_annotated(context) for node in self
    ^^^^^^^^^^^^^^^^^^^^^^^^^^^^^^
  File "/Library/Frameworks/Python.framework/Versions/3.12/lib/python3.12/site-packages/django/template/base.py", line 938, in render_annotated
    return self.render(context)
           ^^^^^^^^^^^^^^^^^^^^
  File "/Library/Frameworks/Python.framework/Versions/3.12/lib/python3.12/site-packages/django/template/defaulttags.py", line 294, in render
    if match:
       ^^^^^
  File "/Library/Frameworks/Python.framework/Versions/3.12/lib/python3.12/site-packages/django/db/models/query.py", line 284, in __bool__
    self._fetch_all()
  File "/Library/Frameworks/Python.framework/Versions/3.12/lib/python3.12/site-packages/django/db/models/query.py", line 1354, in _fetch_all
    self._result_cache = list(self._iterable_class(self))
                         ^^^^^^^^^^^^^^^^^^^^^^^^^^^^^^^^
  File "/Library/Frameworks/Python.framework/Versions/3.12/lib/python3.12/site-packages/django/db/models/query.py", line 51, in __iter__
    results = compiler.execute_sql(chunked_fetch=self.chunked_fetch, chunk_size=self.chunk_size)
              ^^^^^^^^^^^^^^^^^^^^^^^^^^^^^^^^^^^^^^^^^^^^^^^^^^^^^^^^^^^^^^^^^^^^^^^^^^^^^^^^^^
  File "/Library/Frameworks/Python.framework/Versions/3.12/lib/python3.12/site-packages/django/db/models/sql/compiler.py", line 1202, in execute_sql
    cursor.execute(sql, params)
  File "/Library/Frameworks/Python.framework/Versions/3.12/lib/python3.12/site-packages/django/db/backends/utils.py", line 99, in execute
    return super().execute(sql, params)
           ^^^^^^^^^^^^^^^^^^^^^^^^^^^^
  File "/Library/Frameworks/Python.framework/Versions/3.12/lib/python3.12/site-packages/django/db/backends/utils.py", line 67, in execute
    return self._execute_with_wrappers(sql, params, many=False, executor=self._execute)
           ^^^^^^^^^^^^^^^^^^^^^^^^^^^^^^^^^^^^^^^^^^^^^^^^^^^^^^^^^^^^^^^^^^^^^^^^^^^^
  File "/Library/Frameworks/Python.framework/Versions/3.12/lib/python3.12/site-packages/django/db/backends/utils.py", line 76, in _execute_with_wrappers
    return executor(sql, params, many, context)
           ^^^^^^^^^^^^^^^^^^^^^^^^^^^^^^^^^^^^
  File "/Library/Frameworks/Python.framework/Versions/3.12/lib/python3.12/site-packages/django/db/backends/utils.py", line 80, in _execute
    with self.db.wrap_database_errors:
  File "/Library/Frameworks/Python.framework/Versions/3.12/lib/python3.12/site-packages/django/db/utils.py", line 90, in __exit__
    raise dj_exc_value.with_traceback(traceback) from exc_value
  File "/Library/Frameworks/Python.framework/Versions/3.12/lib/python3.12/site-packages/django/db/backends/utils.py", line 85, in _execute
    return self.cursor.execute(sql, params)
           ^^^^^^^^^^^^^^^^^^^^^^^^^^^^^^^^
  File "/Library/Frameworks/Python.framework/Versions/3.12/lib/python3.12/site-packages/django/db/backends/sqlite3/base.py", line 416, in execute
    return Database.Cursor.execute(self, query, params)
           ^^^^^^^^^^^^^^^^^^^^^^^^^^^^^^^^^^^^^^^^^^^^
django.db.utils.OperationalError: no such table: workout_userchallenge
2024-06-09 14:51:26,595 - DEBUG - GET request to login: 
2024-06-09 14:51:31,245 - DEBUG - POST request to login: 
2024-06-09 14:51:59,068 - INFO - /Users/janrydzewski/Developer/Studies/Django/workout_logger/workout/views.py changed, reloading.: 
2024-06-09 14:55:56,691 - INFO - /Users/janrydzewski/Developer/Studies/Django/workout_logger/workout/views.py changed, reloading.: 
2024-06-09 14:55:58,108 - INFO - /Users/janrydzewski/Developer/Studies/Django/workout_logger/workout/views.py changed, reloading.: 
2024-06-09 14:56:03,428 - INFO - /Users/janrydzewski/Developer/Studies/Django/workout_logger/workout/views.py changed, reloading.: 
2024-06-09 14:56:20,870 - INFO - /Users/janrydzewski/Developer/Studies/Django/workout_logger/workout/views.py changed, reloading.: 
2024-06-09 14:56:22,242 - INFO - /Users/janrydzewski/Developer/Studies/Django/workout_logger/workout/views.py changed, reloading.: 
2024-06-09 14:57:08,870 - ERROR - Internal Server Error: /challenges: 
Traceback (most recent call last):
  File "/Library/Frameworks/Python.framework/Versions/3.12/lib/python3.12/site-packages/django/core/handlers/exception.py", line 47, in inner
    response = get_response(request)
               ^^^^^^^^^^^^^^^^^^^^^
  File "/Library/Frameworks/Python.framework/Versions/3.12/lib/python3.12/site-packages/django/core/handlers/base.py", line 181, in _get_response
    response = wrapped_callback(request, *callback_args, **callback_kwargs)
               ^^^^^^^^^^^^^^^^^^^^^^^^^^^^^^^^^^^^^^^^^^^^^^^^^^^^^^^^^^^^
  File "/Users/janrydzewski/Developer/Studies/Django/workout_logger/workout/views.py", line 232, in challenges
    return render(request, "workout/challenges.html", data)
           ^^^^^^^^^^^^^^^^^^^^^^^^^^^^^^^^^^^^^^^^^^^^^^^^
  File "/Library/Frameworks/Python.framework/Versions/3.12/lib/python3.12/site-packages/django/shortcuts.py", line 19, in render
    content = loader.render_to_string(template_name, context, request, using=using)
              ^^^^^^^^^^^^^^^^^^^^^^^^^^^^^^^^^^^^^^^^^^^^^^^^^^^^^^^^^^^^^^^^^^^^^
  File "/Library/Frameworks/Python.framework/Versions/3.12/lib/python3.12/site-packages/django/template/loader.py", line 62, in render_to_string
    return template.render(context, request)
           ^^^^^^^^^^^^^^^^^^^^^^^^^^^^^^^^^
  File "/Library/Frameworks/Python.framework/Versions/3.12/lib/python3.12/site-packages/django/template/backends/django.py", line 61, in render
    return self.template.render(context)
           ^^^^^^^^^^^^^^^^^^^^^^^^^^^^^
  File "/Library/Frameworks/Python.framework/Versions/3.12/lib/python3.12/site-packages/django/template/base.py", line 176, in render
    return self._render(context)
           ^^^^^^^^^^^^^^^^^^^^^
  File "/Library/Frameworks/Python.framework/Versions/3.12/lib/python3.12/site-packages/django/template/base.py", line 168, in _render
    return self.nodelist.render(context)
           ^^^^^^^^^^^^^^^^^^^^^^^^^^^^^
  File "/Library/Frameworks/Python.framework/Versions/3.12/lib/python3.12/site-packages/django/template/base.py", line 978, in render
    node.render_annotated(context) for node in self
    ^^^^^^^^^^^^^^^^^^^^^^^^^^^^^^
  File "/Library/Frameworks/Python.framework/Versions/3.12/lib/python3.12/site-packages/django/template/base.py", line 938, in render_annotated
    return self.render(context)
           ^^^^^^^^^^^^^^^^^^^^
  File "/Library/Frameworks/Python.framework/Versions/3.12/lib/python3.12/site-packages/django/template/defaulttags.py", line 295, in render
    return nodelist.render(context)
           ^^^^^^^^^^^^^^^^^^^^^^^^
  File "/Library/Frameworks/Python.framework/Versions/3.12/lib/python3.12/site-packages/django/template/base.py", line 978, in render
    node.render_annotated(context) for node in self
    ^^^^^^^^^^^^^^^^^^^^^^^^^^^^^^
  File "/Library/Frameworks/Python.framework/Versions/3.12/lib/python3.12/site-packages/django/template/base.py", line 938, in render_annotated
    return self.render(context)
           ^^^^^^^^^^^^^^^^^^^^
  File "/Library/Frameworks/Python.framework/Versions/3.12/lib/python3.12/site-packages/django/template/defaulttags.py", line 214, in render
    nodelist.append(node.render_annotated(context))
                    ^^^^^^^^^^^^^^^^^^^^^^^^^^^^^^
  File "/Library/Frameworks/Python.framework/Versions/3.12/lib/python3.12/site-packages/django/template/base.py", line 938, in render_annotated
    return self.render(context)
           ^^^^^^^^^^^^^^^^^^^^
  File "/Library/Frameworks/Python.framework/Versions/3.12/lib/python3.12/site-packages/django/template/defaulttags.py", line 442, in render
    url = reverse(view_name, args=args, kwargs=kwargs, current_app=current_app)
          ^^^^^^^^^^^^^^^^^^^^^^^^^^^^^^^^^^^^^^^^^^^^^^^^^^^^^^^^^^^^^^^^^^^^^
  File "/Library/Frameworks/Python.framework/Versions/3.12/lib/python3.12/site-packages/django/urls/base.py", line 86, in reverse
    return resolver._reverse_with_prefix(view, prefix, *args, **kwargs)
           ^^^^^^^^^^^^^^^^^^^^^^^^^^^^^^^^^^^^^^^^^^^^^^^^^^^^^^^^^^^^
  File "/Library/Frameworks/Python.framework/Versions/3.12/lib/python3.12/site-packages/django/urls/resolvers.py", line 729, in _reverse_with_prefix
    raise NoReverseMatch(msg)
django.urls.exceptions.NoReverseMatch: Reverse for 'join_challenge' not found. 'join_challenge' is not a valid view function or pattern name.
2024-06-09 15:00:57,291 - ERROR - Internal Server Error: /challenges: 
Traceback (most recent call last):
  File "/Library/Frameworks/Python.framework/Versions/3.12/lib/python3.12/site-packages/django/core/handlers/exception.py", line 47, in inner
    response = get_response(request)
               ^^^^^^^^^^^^^^^^^^^^^
  File "/Library/Frameworks/Python.framework/Versions/3.12/lib/python3.12/site-packages/django/core/handlers/base.py", line 181, in _get_response
    response = wrapped_callback(request, *callback_args, **callback_kwargs)
               ^^^^^^^^^^^^^^^^^^^^^^^^^^^^^^^^^^^^^^^^^^^^^^^^^^^^^^^^^^^^
  File "/Users/janrydzewski/Developer/Studies/Django/workout_logger/workout/views.py", line 232, in challenges
    return render(request, "workout/challenges.html", data)
           ^^^^^^^^^^^^^^^^^^^^^^^^^^^^^^^^^^^^^^^^^^^^^^^^
  File "/Library/Frameworks/Python.framework/Versions/3.12/lib/python3.12/site-packages/django/shortcuts.py", line 19, in render
    content = loader.render_to_string(template_name, context, request, using=using)
              ^^^^^^^^^^^^^^^^^^^^^^^^^^^^^^^^^^^^^^^^^^^^^^^^^^^^^^^^^^^^^^^^^^^^^
  File "/Library/Frameworks/Python.framework/Versions/3.12/lib/python3.12/site-packages/django/template/loader.py", line 62, in render_to_string
    return template.render(context, request)
           ^^^^^^^^^^^^^^^^^^^^^^^^^^^^^^^^^
  File "/Library/Frameworks/Python.framework/Versions/3.12/lib/python3.12/site-packages/django/template/backends/django.py", line 61, in render
    return self.template.render(context)
           ^^^^^^^^^^^^^^^^^^^^^^^^^^^^^
  File "/Library/Frameworks/Python.framework/Versions/3.12/lib/python3.12/site-packages/django/template/base.py", line 176, in render
    return self._render(context)
           ^^^^^^^^^^^^^^^^^^^^^
  File "/Library/Frameworks/Python.framework/Versions/3.12/lib/python3.12/site-packages/django/template/base.py", line 168, in _render
    return self.nodelist.render(context)
           ^^^^^^^^^^^^^^^^^^^^^^^^^^^^^
  File "/Library/Frameworks/Python.framework/Versions/3.12/lib/python3.12/site-packages/django/template/base.py", line 978, in render
    node.render_annotated(context) for node in self
    ^^^^^^^^^^^^^^^^^^^^^^^^^^^^^^
  File "/Library/Frameworks/Python.framework/Versions/3.12/lib/python3.12/site-packages/django/template/base.py", line 938, in render_annotated
    return self.render(context)
           ^^^^^^^^^^^^^^^^^^^^
  File "/Library/Frameworks/Python.framework/Versions/3.12/lib/python3.12/site-packages/django/template/defaulttags.py", line 295, in render
    return nodelist.render(context)
           ^^^^^^^^^^^^^^^^^^^^^^^^
  File "/Library/Frameworks/Python.framework/Versions/3.12/lib/python3.12/site-packages/django/template/base.py", line 978, in render
    node.render_annotated(context) for node in self
    ^^^^^^^^^^^^^^^^^^^^^^^^^^^^^^
  File "/Library/Frameworks/Python.framework/Versions/3.12/lib/python3.12/site-packages/django/template/base.py", line 938, in render_annotated
    return self.render(context)
           ^^^^^^^^^^^^^^^^^^^^
  File "/Library/Frameworks/Python.framework/Versions/3.12/lib/python3.12/site-packages/django/template/defaulttags.py", line 214, in render
    nodelist.append(node.render_annotated(context))
                    ^^^^^^^^^^^^^^^^^^^^^^^^^^^^^^
  File "/Library/Frameworks/Python.framework/Versions/3.12/lib/python3.12/site-packages/django/template/base.py", line 938, in render_annotated
    return self.render(context)
           ^^^^^^^^^^^^^^^^^^^^
  File "/Library/Frameworks/Python.framework/Versions/3.12/lib/python3.12/site-packages/django/template/defaulttags.py", line 442, in render
    url = reverse(view_name, args=args, kwargs=kwargs, current_app=current_app)
          ^^^^^^^^^^^^^^^^^^^^^^^^^^^^^^^^^^^^^^^^^^^^^^^^^^^^^^^^^^^^^^^^^^^^^
  File "/Library/Frameworks/Python.framework/Versions/3.12/lib/python3.12/site-packages/django/urls/base.py", line 86, in reverse
    return resolver._reverse_with_prefix(view, prefix, *args, **kwargs)
           ^^^^^^^^^^^^^^^^^^^^^^^^^^^^^^^^^^^^^^^^^^^^^^^^^^^^^^^^^^^^
  File "/Library/Frameworks/Python.framework/Versions/3.12/lib/python3.12/site-packages/django/urls/resolvers.py", line 729, in _reverse_with_prefix
    raise NoReverseMatch(msg)
django.urls.exceptions.NoReverseMatch: Reverse for 'join_challenge' not found. 'join_challenge' is not a valid view function or pattern name.
2024-06-09 15:03:21,772 - INFO - /Users/janrydzewski/Developer/Studies/Django/workout_logger/workout/urls.py changed, reloading.: 
2024-06-09 15:03:24,149 - INFO - /Users/janrydzewski/Developer/Studies/Django/workout_logger/workout/urls.py changed, reloading.: 
2024-06-09 15:03:25,429 - INFO - /Users/janrydzewski/Developer/Studies/Django/workout_logger/workout/urls.py changed, reloading.: 
2024-06-09 15:03:27,695 - INFO - /Users/janrydzewski/Developer/Studies/Django/workout_logger/workout/urls.py changed, reloading.: 
2024-06-09 15:04:05,510 - INFO - /Users/janrydzewski/Developer/Studies/Django/workout_logger/workout/urls.py changed, reloading.: 
2024-06-09 15:04:23,406 - INFO - /Users/janrydzewski/Developer/Studies/Django/workout_logger/workout/urls.py changed, reloading.: 
2024-06-09 15:04:29,860 - ERROR - Internal Server Error: /challenge/join/7: 
Traceback (most recent call last):
  File "/Library/Frameworks/Python.framework/Versions/3.12/lib/python3.12/site-packages/django/core/handlers/exception.py", line 47, in inner
    response = get_response(request)
               ^^^^^^^^^^^^^^^^^^^^^
  File "/Library/Frameworks/Python.framework/Versions/3.12/lib/python3.12/site-packages/django/core/handlers/base.py", line 181, in _get_response
    response = wrapped_callback(request, *callback_args, **callback_kwargs)
               ^^^^^^^^^^^^^^^^^^^^^^^^^^^^^^^^^^^^^^^^^^^^^^^^^^^^^^^^^^^^
  File "/Users/janrydzewski/Developer/Studies/Django/workout_logger/workout/views.py", line 240, in join_challenge
    user_challenge, created = UserChallenge.objects.get_or_create(user=current_user, challenge_id=challenge_id)
                              ^^^^^^^^^^^^^^^^^^^^^^^^^^^^^^^^^^^^^^^^^^^^^^^^^^^^^^^^^^^^^^^^^^^^^^^^^^^^^^^^^
  File "/Library/Frameworks/Python.framework/Versions/3.12/lib/python3.12/site-packages/django/db/models/manager.py", line 85, in manager_method
    return getattr(self.get_queryset(), name)(*args, **kwargs)
           ^^^^^^^^^^^^^^^^^^^^^^^^^^^^^^^^^^^^^^^^^^^^^^^^^^^
  File "/Library/Frameworks/Python.framework/Versions/3.12/lib/python3.12/site-packages/django/db/models/query.py", line 588, in get_or_create
    return self.get(**kwargs), False
           ^^^^^^^^^^^^^^^^^^
  File "/Library/Frameworks/Python.framework/Versions/3.12/lib/python3.12/site-packages/django/db/models/query.py", line 428, in get
    clone = self._chain() if self.query.combinator else self.filter(*args, **kwargs)
                                                        ^^^^^^^^^^^^^^^^^^^^^^^^^^^^
  File "/Library/Frameworks/Python.framework/Versions/3.12/lib/python3.12/site-packages/django/db/models/query.py", line 974, in filter
    return self._filter_or_exclude(False, args, kwargs)
           ^^^^^^^^^^^^^^^^^^^^^^^^^^^^^^^^^^^^^^^^^^^^
  File "/Library/Frameworks/Python.framework/Versions/3.12/lib/python3.12/site-packages/django/db/models/query.py", line 992, in _filter_or_exclude
    clone._filter_or_exclude_inplace(negate, args, kwargs)
  File "/Library/Frameworks/Python.framework/Versions/3.12/lib/python3.12/site-packages/django/db/models/query.py", line 999, in _filter_or_exclude_inplace
    self._query.add_q(Q(*args, **kwargs))
  File "/Library/Frameworks/Python.framework/Versions/3.12/lib/python3.12/site-packages/django/db/models/sql/query.py", line 1375, in add_q
    clause, _ = self._add_q(q_object, self.used_aliases)
                ^^^^^^^^^^^^^^^^^^^^^^^^^^^^^^^^^^^^^^^^
  File "/Library/Frameworks/Python.framework/Versions/3.12/lib/python3.12/site-packages/django/db/models/sql/query.py", line 1396, in _add_q
    child_clause, needed_inner = self.build_filter(
                                 ^^^^^^^^^^^^^^^^^^
  File "/Library/Frameworks/Python.framework/Versions/3.12/lib/python3.12/site-packages/django/db/models/sql/query.py", line 1302, in build_filter
    self.check_related_objects(join_info.final_field, value, join_info.opts)
  File "/Library/Frameworks/Python.framework/Versions/3.12/lib/python3.12/site-packages/django/db/models/sql/query.py", line 1134, in check_related_objects
    self.check_query_object_type(value, opts, field)
  File "/Library/Frameworks/Python.framework/Versions/3.12/lib/python3.12/site-packages/django/db/models/sql/query.py", line 1115, in check_query_object_type
    raise ValueError(
ValueError: Cannot query "admin": Must be "User" instance.
2024-06-09 15:08:05,440 - INFO - /Users/janrydzewski/Developer/Studies/Django/workout_logger/workout/views.py changed, reloading.: 
2024-06-09 15:08:07,876 - INFO - /Users/janrydzewski/Developer/Studies/Django/workout_logger/workout/views.py changed, reloading.: 
2024-06-09 15:08:09,875 - ERROR - Internal Server Error: /challenge/join/7: 
Traceback (most recent call last):
  File "/Library/Frameworks/Python.framework/Versions/3.12/lib/python3.12/site-packages/django/core/handlers/exception.py", line 47, in inner
    response = get_response(request)
               ^^^^^^^^^^^^^^^^^^^^^
  File "/Library/Frameworks/Python.framework/Versions/3.12/lib/python3.12/site-packages/django/core/handlers/base.py", line 181, in _get_response
    response = wrapped_callback(request, *callback_args, **callback_kwargs)
               ^^^^^^^^^^^^^^^^^^^^^^^^^^^^^^^^^^^^^^^^^^^^^^^^^^^^^^^^^^^^
  File "/Users/janrydzewski/Developer/Studies/Django/workout_logger/workout/views.py", line 240, in join_challenge
    user_challenge, created = UserChallenge.objects.get_or_create(user=current_user, challenge_id=challenge_id)
                              ^^^^^^^^^^^^^^^^^^^^^^^^^^^^^^^^^^^^^^^^^^^^^^^^^^^^^^^^^^^^^^^^^^^^^^^^^^^^^^^^^
  File "/Library/Frameworks/Python.framework/Versions/3.12/lib/python3.12/site-packages/django/db/models/manager.py", line 85, in manager_method
    return getattr(self.get_queryset(), name)(*args, **kwargs)
           ^^^^^^^^^^^^^^^^^^^^^^^^^^^^^^^^^^^^^^^^^^^^^^^^^^^
  File "/Library/Frameworks/Python.framework/Versions/3.12/lib/python3.12/site-packages/django/db/models/query.py", line 588, in get_or_create
    return self.get(**kwargs), False
           ^^^^^^^^^^^^^^^^^^
  File "/Library/Frameworks/Python.framework/Versions/3.12/lib/python3.12/site-packages/django/db/models/query.py", line 428, in get
    clone = self._chain() if self.query.combinator else self.filter(*args, **kwargs)
                                                        ^^^^^^^^^^^^^^^^^^^^^^^^^^^^
  File "/Library/Frameworks/Python.framework/Versions/3.12/lib/python3.12/site-packages/django/db/models/query.py", line 974, in filter
    return self._filter_or_exclude(False, args, kwargs)
           ^^^^^^^^^^^^^^^^^^^^^^^^^^^^^^^^^^^^^^^^^^^^
  File "/Library/Frameworks/Python.framework/Versions/3.12/lib/python3.12/site-packages/django/db/models/query.py", line 992, in _filter_or_exclude
    clone._filter_or_exclude_inplace(negate, args, kwargs)
  File "/Library/Frameworks/Python.framework/Versions/3.12/lib/python3.12/site-packages/django/db/models/query.py", line 999, in _filter_or_exclude_inplace
    self._query.add_q(Q(*args, **kwargs))
  File "/Library/Frameworks/Python.framework/Versions/3.12/lib/python3.12/site-packages/django/db/models/sql/query.py", line 1375, in add_q
    clause, _ = self._add_q(q_object, self.used_aliases)
                ^^^^^^^^^^^^^^^^^^^^^^^^^^^^^^^^^^^^^^^^
  File "/Library/Frameworks/Python.framework/Versions/3.12/lib/python3.12/site-packages/django/db/models/sql/query.py", line 1396, in _add_q
    child_clause, needed_inner = self.build_filter(
                                 ^^^^^^^^^^^^^^^^^^
  File "/Library/Frameworks/Python.framework/Versions/3.12/lib/python3.12/site-packages/django/db/models/sql/query.py", line 1302, in build_filter
    self.check_related_objects(join_info.final_field, value, join_info.opts)
  File "/Library/Frameworks/Python.framework/Versions/3.12/lib/python3.12/site-packages/django/db/models/sql/query.py", line 1134, in check_related_objects
    self.check_query_object_type(value, opts, field)
  File "/Library/Frameworks/Python.framework/Versions/3.12/lib/python3.12/site-packages/django/db/models/sql/query.py", line 1115, in check_query_object_type
    raise ValueError(
ValueError: Cannot query "admin": Must be "User" instance.
2024-06-09 15:08:12,827 - ERROR - Internal Server Error: /challenge/join/7: 
Traceback (most recent call last):
  File "/Library/Frameworks/Python.framework/Versions/3.12/lib/python3.12/site-packages/django/core/handlers/exception.py", line 47, in inner
    response = get_response(request)
               ^^^^^^^^^^^^^^^^^^^^^
  File "/Library/Frameworks/Python.framework/Versions/3.12/lib/python3.12/site-packages/django/core/handlers/base.py", line 181, in _get_response
    response = wrapped_callback(request, *callback_args, **callback_kwargs)
               ^^^^^^^^^^^^^^^^^^^^^^^^^^^^^^^^^^^^^^^^^^^^^^^^^^^^^^^^^^^^
  File "/Users/janrydzewski/Developer/Studies/Django/workout_logger/workout/views.py", line 240, in join_challenge
    user_challenge, created = UserChallenge.objects.get_or_create(user=current_user, challenge_id=challenge_id)
                              ^^^^^^^^^^^^^^^^^^^^^^^^^^^^^^^^^^^^^^^^^^^^^^^^^^^^^^^^^^^^^^^^^^^^^^^^^^^^^^^^^
  File "/Library/Frameworks/Python.framework/Versions/3.12/lib/python3.12/site-packages/django/db/models/manager.py", line 85, in manager_method
    return getattr(self.get_queryset(), name)(*args, **kwargs)
           ^^^^^^^^^^^^^^^^^^^^^^^^^^^^^^^^^^^^^^^^^^^^^^^^^^^
  File "/Library/Frameworks/Python.framework/Versions/3.12/lib/python3.12/site-packages/django/db/models/query.py", line 588, in get_or_create
    return self.get(**kwargs), False
           ^^^^^^^^^^^^^^^^^^
  File "/Library/Frameworks/Python.framework/Versions/3.12/lib/python3.12/site-packages/django/db/models/query.py", line 428, in get
    clone = self._chain() if self.query.combinator else self.filter(*args, **kwargs)
                                                        ^^^^^^^^^^^^^^^^^^^^^^^^^^^^
  File "/Library/Frameworks/Python.framework/Versions/3.12/lib/python3.12/site-packages/django/db/models/query.py", line 974, in filter
    return self._filter_or_exclude(False, args, kwargs)
           ^^^^^^^^^^^^^^^^^^^^^^^^^^^^^^^^^^^^^^^^^^^^
  File "/Library/Frameworks/Python.framework/Versions/3.12/lib/python3.12/site-packages/django/db/models/query.py", line 992, in _filter_or_exclude
    clone._filter_or_exclude_inplace(negate, args, kwargs)
  File "/Library/Frameworks/Python.framework/Versions/3.12/lib/python3.12/site-packages/django/db/models/query.py", line 999, in _filter_or_exclude_inplace
    self._query.add_q(Q(*args, **kwargs))
  File "/Library/Frameworks/Python.framework/Versions/3.12/lib/python3.12/site-packages/django/db/models/sql/query.py", line 1375, in add_q
    clause, _ = self._add_q(q_object, self.used_aliases)
                ^^^^^^^^^^^^^^^^^^^^^^^^^^^^^^^^^^^^^^^^
  File "/Library/Frameworks/Python.framework/Versions/3.12/lib/python3.12/site-packages/django/db/models/sql/query.py", line 1396, in _add_q
    child_clause, needed_inner = self.build_filter(
                                 ^^^^^^^^^^^^^^^^^^
  File "/Library/Frameworks/Python.framework/Versions/3.12/lib/python3.12/site-packages/django/db/models/sql/query.py", line 1302, in build_filter
    self.check_related_objects(join_info.final_field, value, join_info.opts)
  File "/Library/Frameworks/Python.framework/Versions/3.12/lib/python3.12/site-packages/django/db/models/sql/query.py", line 1134, in check_related_objects
    self.check_query_object_type(value, opts, field)
  File "/Library/Frameworks/Python.framework/Versions/3.12/lib/python3.12/site-packages/django/db/models/sql/query.py", line 1115, in check_query_object_type
    raise ValueError(
ValueError: Cannot query "admin": Must be "User" instance.
2024-06-09 15:08:39,816 - ERROR - Internal Server Error: /challenge/join/7: 
Traceback (most recent call last):
  File "/Library/Frameworks/Python.framework/Versions/3.12/lib/python3.12/site-packages/django/core/handlers/exception.py", line 47, in inner
    response = get_response(request)
               ^^^^^^^^^^^^^^^^^^^^^
  File "/Library/Frameworks/Python.framework/Versions/3.12/lib/python3.12/site-packages/django/core/handlers/base.py", line 181, in _get_response
    response = wrapped_callback(request, *callback_args, **callback_kwargs)
               ^^^^^^^^^^^^^^^^^^^^^^^^^^^^^^^^^^^^^^^^^^^^^^^^^^^^^^^^^^^^
  File "/Users/janrydzewski/Developer/Studies/Django/workout_logger/workout/views.py", line 240, in join_challenge
    user_challenge, created = UserChallenge.objects.get_or_create(user=current_user, challenge_id=challenge_id)
                              ^^^^^^^^^^^^^^^^^^^^^^^^^^^^^^^^^^^^^^^^^^^^^^^^^^^^^^^^^^^^^^^^^^^^^^^^^^^^^^^^^
  File "/Library/Frameworks/Python.framework/Versions/3.12/lib/python3.12/site-packages/django/db/models/manager.py", line 85, in manager_method
    return getattr(self.get_queryset(), name)(*args, **kwargs)
           ^^^^^^^^^^^^^^^^^^^^^^^^^^^^^^^^^^^^^^^^^^^^^^^^^^^
  File "/Library/Frameworks/Python.framework/Versions/3.12/lib/python3.12/site-packages/django/db/models/query.py", line 588, in get_or_create
    return self.get(**kwargs), False
           ^^^^^^^^^^^^^^^^^^
  File "/Library/Frameworks/Python.framework/Versions/3.12/lib/python3.12/site-packages/django/db/models/query.py", line 428, in get
    clone = self._chain() if self.query.combinator else self.filter(*args, **kwargs)
                                                        ^^^^^^^^^^^^^^^^^^^^^^^^^^^^
  File "/Library/Frameworks/Python.framework/Versions/3.12/lib/python3.12/site-packages/django/db/models/query.py", line 974, in filter
    return self._filter_or_exclude(False, args, kwargs)
           ^^^^^^^^^^^^^^^^^^^^^^^^^^^^^^^^^^^^^^^^^^^^
  File "/Library/Frameworks/Python.framework/Versions/3.12/lib/python3.12/site-packages/django/db/models/query.py", line 992, in _filter_or_exclude
    clone._filter_or_exclude_inplace(negate, args, kwargs)
  File "/Library/Frameworks/Python.framework/Versions/3.12/lib/python3.12/site-packages/django/db/models/query.py", line 999, in _filter_or_exclude_inplace
    self._query.add_q(Q(*args, **kwargs))
  File "/Library/Frameworks/Python.framework/Versions/3.12/lib/python3.12/site-packages/django/db/models/sql/query.py", line 1375, in add_q
    clause, _ = self._add_q(q_object, self.used_aliases)
                ^^^^^^^^^^^^^^^^^^^^^^^^^^^^^^^^^^^^^^^^
  File "/Library/Frameworks/Python.framework/Versions/3.12/lib/python3.12/site-packages/django/db/models/sql/query.py", line 1396, in _add_q
    child_clause, needed_inner = self.build_filter(
                                 ^^^^^^^^^^^^^^^^^^
  File "/Library/Frameworks/Python.framework/Versions/3.12/lib/python3.12/site-packages/django/db/models/sql/query.py", line 1302, in build_filter
    self.check_related_objects(join_info.final_field, value, join_info.opts)
  File "/Library/Frameworks/Python.framework/Versions/3.12/lib/python3.12/site-packages/django/db/models/sql/query.py", line 1134, in check_related_objects
    self.check_query_object_type(value, opts, field)
  File "/Library/Frameworks/Python.framework/Versions/3.12/lib/python3.12/site-packages/django/db/models/sql/query.py", line 1115, in check_query_object_type
    raise ValueError(
ValueError: Cannot query "admin": Must be "User" instance.
2024-06-09 15:08:41,533 - ERROR - Internal Server Error: /challenge/join/7: 
Traceback (most recent call last):
  File "/Library/Frameworks/Python.framework/Versions/3.12/lib/python3.12/site-packages/django/core/handlers/exception.py", line 47, in inner
    response = get_response(request)
               ^^^^^^^^^^^^^^^^^^^^^
  File "/Library/Frameworks/Python.framework/Versions/3.12/lib/python3.12/site-packages/django/core/handlers/base.py", line 181, in _get_response
    response = wrapped_callback(request, *callback_args, **callback_kwargs)
               ^^^^^^^^^^^^^^^^^^^^^^^^^^^^^^^^^^^^^^^^^^^^^^^^^^^^^^^^^^^^
  File "/Users/janrydzewski/Developer/Studies/Django/workout_logger/workout/views.py", line 240, in join_challenge
    user_challenge, created = UserChallenge.objects.get_or_create(user=current_user, challenge_id=challenge_id)
                              ^^^^^^^^^^^^^^^^^^^^^^^^^^^^^^^^^^^^^^^^^^^^^^^^^^^^^^^^^^^^^^^^^^^^^^^^^^^^^^^^^
  File "/Library/Frameworks/Python.framework/Versions/3.12/lib/python3.12/site-packages/django/db/models/manager.py", line 85, in manager_method
    return getattr(self.get_queryset(), name)(*args, **kwargs)
           ^^^^^^^^^^^^^^^^^^^^^^^^^^^^^^^^^^^^^^^^^^^^^^^^^^^
  File "/Library/Frameworks/Python.framework/Versions/3.12/lib/python3.12/site-packages/django/db/models/query.py", line 588, in get_or_create
    return self.get(**kwargs), False
           ^^^^^^^^^^^^^^^^^^
  File "/Library/Frameworks/Python.framework/Versions/3.12/lib/python3.12/site-packages/django/db/models/query.py", line 428, in get
    clone = self._chain() if self.query.combinator else self.filter(*args, **kwargs)
                                                        ^^^^^^^^^^^^^^^^^^^^^^^^^^^^
  File "/Library/Frameworks/Python.framework/Versions/3.12/lib/python3.12/site-packages/django/db/models/query.py", line 974, in filter
    return self._filter_or_exclude(False, args, kwargs)
           ^^^^^^^^^^^^^^^^^^^^^^^^^^^^^^^^^^^^^^^^^^^^
  File "/Library/Frameworks/Python.framework/Versions/3.12/lib/python3.12/site-packages/django/db/models/query.py", line 992, in _filter_or_exclude
    clone._filter_or_exclude_inplace(negate, args, kwargs)
  File "/Library/Frameworks/Python.framework/Versions/3.12/lib/python3.12/site-packages/django/db/models/query.py", line 999, in _filter_or_exclude_inplace
    self._query.add_q(Q(*args, **kwargs))
  File "/Library/Frameworks/Python.framework/Versions/3.12/lib/python3.12/site-packages/django/db/models/sql/query.py", line 1375, in add_q
    clause, _ = self._add_q(q_object, self.used_aliases)
                ^^^^^^^^^^^^^^^^^^^^^^^^^^^^^^^^^^^^^^^^
  File "/Library/Frameworks/Python.framework/Versions/3.12/lib/python3.12/site-packages/django/db/models/sql/query.py", line 1396, in _add_q
    child_clause, needed_inner = self.build_filter(
                                 ^^^^^^^^^^^^^^^^^^
  File "/Library/Frameworks/Python.framework/Versions/3.12/lib/python3.12/site-packages/django/db/models/sql/query.py", line 1302, in build_filter
    self.check_related_objects(join_info.final_field, value, join_info.opts)
  File "/Library/Frameworks/Python.framework/Versions/3.12/lib/python3.12/site-packages/django/db/models/sql/query.py", line 1134, in check_related_objects
    self.check_query_object_type(value, opts, field)
  File "/Library/Frameworks/Python.framework/Versions/3.12/lib/python3.12/site-packages/django/db/models/sql/query.py", line 1115, in check_query_object_type
    raise ValueError(
ValueError: Cannot query "admin": Must be "User" instance.
2024-06-09 15:12:48,604 - INFO - /Users/janrydzewski/Developer/Studies/Django/workout_logger/workout/views.py changed, reloading.: 
2024-06-09 15:13:00,231 - INFO - /Users/janrydzewski/Developer/Studies/Django/workout_logger/workout/views.py changed, reloading.: 
2024-06-09 15:13:54,626 - INFO - /Users/janrydzewski/Developer/Studies/Django/workout_logger/workout/urls.py changed, reloading.: 
2024-06-09 15:14:09,158 - INFO - /Users/janrydzewski/Developer/Studies/Django/workout_logger/workout/urls.py changed, reloading.: 
2024-06-09 15:14:20,052 - DEBUG - GET request to login: 
2024-06-09 15:14:26,994 - DEBUG - POST request to login: 
2024-06-09 15:14:31,906 - WARNING - Not Found: /challenge/join/7: 
2024-06-09 15:15:08,469 - WARNING - Not Found: /challenge/join/7: 
2024-06-09 15:16:39,178 - INFO - /Users/janrydzewski/Developer/Studies/Django/workout_logger/workout/views.py changed, reloading.: 
2024-06-09 15:16:40,598 - INFO - /Users/janrydzewski/Developer/Studies/Django/workout_logger/workout/views.py changed, reloading.: 
2024-06-09 15:16:56,234 - WARNING - Not Found: /challenge/join/7: 
2024-06-09 15:17:14,494 - INFO - /Users/janrydzewski/Developer/Studies/Django/workout_logger/workout/views.py changed, reloading.: 
2024-06-09 15:17:18,162 - WARNING - Not Found: /challenge/join/7: 
2024-06-09 15:19:38,173 - INFO - /Users/janrydzewski/Developer/Studies/Django/workout_logger/workout/views.py changed, reloading.: 
2024-06-09 15:20:35,902 - WARNING - Not Found: /challenge/join/7: 
2024-06-09 15:20:51,093 - DEBUG - GET request to login: 
2024-06-09 15:20:59,072 - DEBUG - POST request to login: 
2024-06-09 15:21:01,619 - DEBUG - GET request to new workout: 
2024-06-09 15:21:03,133 - WARNING - Not Found: /challenge/join/7: 
2024-06-09 15:21:06,789 - WARNING - Not Found: /challenge/join/7: 
2024-06-09 15:21:10,654 - DEBUG - GET request to new workout: 
2024-06-09 15:23:19,483 - INFO - /Users/janrydzewski/Developer/Studies/Django/workout_logger/workout/urls.py changed, reloading.: 
2024-06-09 15:23:22,914 - INFO - /Users/janrydzewski/Developer/Studies/Django/workout_logger/workout/urls.py changed, reloading.: 
2024-06-09 15:23:24,128 - INFO - /Users/janrydzewski/Developer/Studies/Django/workout_logger/workout/urls.py changed, reloading.: 
2024-06-09 15:23:59,024 - ERROR - Internal Server Error: /challenge/join/7: 
Traceback (most recent call last):
  File "/Library/Frameworks/Python.framework/Versions/3.12/lib/python3.12/site-packages/django/core/handlers/exception.py", line 47, in inner
    response = get_response(request)
               ^^^^^^^^^^^^^^^^^^^^^
  File "/Library/Frameworks/Python.framework/Versions/3.12/lib/python3.12/site-packages/django/core/handlers/base.py", line 181, in _get_response
    response = wrapped_callback(request, *callback_args, **callback_kwargs)
               ^^^^^^^^^^^^^^^^^^^^^^^^^^^^^^^^^^^^^^^^^^^^^^^^^^^^^^^^^^^^
TypeError: join_challenge() got an unexpected keyword argument 'id'
2024-06-09 15:24:45,792 - INFO - /Users/janrydzewski/Developer/Studies/Django/workout_logger/workout/views.py changed, reloading.: 
2024-06-09 15:24:48,195 - INFO - /Users/janrydzewski/Developer/Studies/Django/workout_logger/workout/views.py changed, reloading.: 
2024-06-09 15:24:52,866 - WARNING - Not Found: /challenge/join/7: 
2024-06-09 15:25:19,097 - INFO - /Users/janrydzewski/Developer/Studies/Django/workout_logger/workout/urls.py changed, reloading.: 
2024-06-09 15:25:25,549 - INFO - /Users/janrydzewski/Developer/Studies/Django/workout_logger/workout/urls.py changed, reloading.: 
2024-06-09 15:25:27,877 - INFO - /Users/janrydzewski/Developer/Studies/Django/workout_logger/workout/urls.py changed, reloading.: 
2024-06-09 15:27:22,778 - INFO - /Users/janrydzewski/Developer/Studies/Django/workout_logger/workout/views.py changed, reloading.: 
2024-06-09 15:28:33,412 - INFO - /Users/janrydzewski/Developer/Studies/Django/workout_logger/workout/urls.py changed, reloading.: 
2024-06-09 15:28:39,313 - WARNING - Not Found: /challenge/7/join: 
2024-06-09 15:28:55,200 - INFO - /Users/janrydzewski/Developer/Studies/Django/workout_logger/workout/urls.py changed, reloading.: 
2024-06-09 15:28:57,557 - INFO - /Users/janrydzewski/Developer/Studies/Django/workout_logger/workout/urls.py changed, reloading.: 
2024-06-09 15:28:58,710 - ERROR - Internal Server Error: /challenges: 
Traceback (most recent call last):
  File "/Library/Frameworks/Python.framework/Versions/3.12/lib/python3.12/site-packages/django/core/handlers/exception.py", line 47, in inner
    response = get_response(request)
               ^^^^^^^^^^^^^^^^^^^^^
  File "/Library/Frameworks/Python.framework/Versions/3.12/lib/python3.12/site-packages/django/core/handlers/base.py", line 181, in _get_response
    response = wrapped_callback(request, *callback_args, **callback_kwargs)
               ^^^^^^^^^^^^^^^^^^^^^^^^^^^^^^^^^^^^^^^^^^^^^^^^^^^^^^^^^^^^
  File "/Users/janrydzewski/Developer/Studies/Django/workout_logger/workout/views.py", line 234, in challenges
    return render(request, "workout/challenges.html", data)
           ^^^^^^^^^^^^^^^^^^^^^^^^^^^^^^^^^^^^^^^^^^^^^^^^
  File "/Library/Frameworks/Python.framework/Versions/3.12/lib/python3.12/site-packages/django/shortcuts.py", line 19, in render
    content = loader.render_to_string(template_name, context, request, using=using)
              ^^^^^^^^^^^^^^^^^^^^^^^^^^^^^^^^^^^^^^^^^^^^^^^^^^^^^^^^^^^^^^^^^^^^^
  File "/Library/Frameworks/Python.framework/Versions/3.12/lib/python3.12/site-packages/django/template/loader.py", line 62, in render_to_string
    return template.render(context, request)
           ^^^^^^^^^^^^^^^^^^^^^^^^^^^^^^^^^
  File "/Library/Frameworks/Python.framework/Versions/3.12/lib/python3.12/site-packages/django/template/backends/django.py", line 61, in render
    return self.template.render(context)
           ^^^^^^^^^^^^^^^^^^^^^^^^^^^^^
  File "/Library/Frameworks/Python.framework/Versions/3.12/lib/python3.12/site-packages/django/template/base.py", line 176, in render
    return self._render(context)
           ^^^^^^^^^^^^^^^^^^^^^
  File "/Library/Frameworks/Python.framework/Versions/3.12/lib/python3.12/site-packages/django/template/base.py", line 168, in _render
    return self.nodelist.render(context)
           ^^^^^^^^^^^^^^^^^^^^^^^^^^^^^
  File "/Library/Frameworks/Python.framework/Versions/3.12/lib/python3.12/site-packages/django/template/base.py", line 978, in render
    node.render_annotated(context) for node in self
    ^^^^^^^^^^^^^^^^^^^^^^^^^^^^^^
  File "/Library/Frameworks/Python.framework/Versions/3.12/lib/python3.12/site-packages/django/template/base.py", line 938, in render_annotated
    return self.render(context)
           ^^^^^^^^^^^^^^^^^^^^
  File "/Library/Frameworks/Python.framework/Versions/3.12/lib/python3.12/site-packages/django/template/defaulttags.py", line 295, in render
    return nodelist.render(context)
           ^^^^^^^^^^^^^^^^^^^^^^^^
  File "/Library/Frameworks/Python.framework/Versions/3.12/lib/python3.12/site-packages/django/template/base.py", line 978, in render
    node.render_annotated(context) for node in self
    ^^^^^^^^^^^^^^^^^^^^^^^^^^^^^^
  File "/Library/Frameworks/Python.framework/Versions/3.12/lib/python3.12/site-packages/django/template/base.py", line 938, in render_annotated
    return self.render(context)
           ^^^^^^^^^^^^^^^^^^^^
  File "/Library/Frameworks/Python.framework/Versions/3.12/lib/python3.12/site-packages/django/template/defaulttags.py", line 214, in render
    nodelist.append(node.render_annotated(context))
                    ^^^^^^^^^^^^^^^^^^^^^^^^^^^^^^
  File "/Library/Frameworks/Python.framework/Versions/3.12/lib/python3.12/site-packages/django/template/base.py", line 938, in render_annotated
    return self.render(context)
           ^^^^^^^^^^^^^^^^^^^^
  File "/Library/Frameworks/Python.framework/Versions/3.12/lib/python3.12/site-packages/django/template/defaulttags.py", line 442, in render
    url = reverse(view_name, args=args, kwargs=kwargs, current_app=current_app)
          ^^^^^^^^^^^^^^^^^^^^^^^^^^^^^^^^^^^^^^^^^^^^^^^^^^^^^^^^^^^^^^^^^^^^^
  File "/Library/Frameworks/Python.framework/Versions/3.12/lib/python3.12/site-packages/django/urls/base.py", line 86, in reverse
    return resolver._reverse_with_prefix(view, prefix, *args, **kwargs)
           ^^^^^^^^^^^^^^^^^^^^^^^^^^^^^^^^^^^^^^^^^^^^^^^^^^^^^^^^^^^^
  File "/Library/Frameworks/Python.framework/Versions/3.12/lib/python3.12/site-packages/django/urls/resolvers.py", line 729, in _reverse_with_prefix
    raise NoReverseMatch(msg)
django.urls.exceptions.NoReverseMatch: Reverse for 'join_challenge' not found. 'join_challenge' is not a valid view function or pattern name.
2024-06-09 15:29:06,965 - INFO - /Users/janrydzewski/Developer/Studies/Django/workout_logger/workout/urls.py changed, reloading.: 
2024-06-09 15:29:08,267 - INFO - /Users/janrydzewski/Developer/Studies/Django/workout_logger/workout/urls.py changed, reloading.: 
2024-06-09 15:29:12,613 - WARNING - Not Found: /challenge/7/join: 
2024-06-09 15:31:17,262 - INFO - /Users/janrydzewski/Developer/Studies/Django/workout_logger/workout/views.py changed, reloading.: 
2024-06-09 15:31:34,559 - WARNING - Not Found: /challenge/1/: 
2024-06-09 15:33:07,201 - INFO - /Users/janrydzewski/Developer/Studies/Django/workout_logger/workout/views.py changed, reloading.: 
2024-06-09 15:33:10,657 - INFO - /Users/janrydzewski/Developer/Studies/Django/workout_logger/workout/views.py changed, reloading.: 
2024-06-09 15:33:13,966 - INFO - /Users/janrydzewski/Developer/Studies/Django/workout_logger/workout/views.py changed, reloading.: 
2024-06-09 15:33:16,246 - INFO - /Users/janrydzewski/Developer/Studies/Django/workout_logger/workout/views.py changed, reloading.: 
2024-06-09 15:33:20,551 - INFO - /Users/janrydzewski/Developer/Studies/Django/workout_logger/workout/views.py changed, reloading.: 
2024-06-09 15:35:19,214 - INFO - /Users/janrydzewski/Developer/Studies/Django/workout_logger/workout/views.py changed, reloading.: 
2024-06-09 15:35:23,649 - INFO - /Users/janrydzewski/Developer/Studies/Django/workout_logger/workout/views.py changed, reloading.: 
2024-06-09 15:35:24,984 - ERROR - Internal Server Error: /dashboard: 
Traceback (most recent call last):
  File "/Library/Frameworks/Python.framework/Versions/3.12/lib/python3.12/site-packages/django/core/handlers/exception.py", line 47, in inner
    response = get_response(request)
               ^^^^^^^^^^^^^^^^^^^^^
  File "/Library/Frameworks/Python.framework/Versions/3.12/lib/python3.12/site-packages/django/core/handlers/base.py", line 181, in _get_response
    response = wrapped_callback(request, *callback_args, **callback_kwargs)
               ^^^^^^^^^^^^^^^^^^^^^^^^^^^^^^^^^^^^^^^^^^^^^^^^^^^^^^^^^^^^
  File "/Users/janrydzewski/Developer/Studies/Django/workout_logger/workout/views.py", line 140, in dashboard
    print(user_challenges.challenge)
          ^^^^^^^^^^^^^^^^^^^^^^^^^
AttributeError: 'QuerySet' object has no attribute 'challenge'
2024-06-09 15:35:31,108 - INFO - /Users/janrydzewski/Developer/Studies/Django/workout_logger/workout/views.py changed, reloading.: 
2024-06-09 15:37:06,009 - INFO - /Users/janrydzewski/Developer/Studies/Django/workout_logger/workout/models.py changed, reloading.: 
2024-06-09 15:37:15,454 - INFO - /Users/janrydzewski/Developer/Studies/Django/workout_logger/workout/models.py changed, reloading.: 
2024-06-09 15:38:00,026 - INFO - /Users/janrydzewski/Developer/Studies/Django/workout_logger/workout/views.py changed, reloading.: 
2024-06-09 15:41:04,360 - WARNING - Not Found: /challenge/: 
2024-06-09 15:41:07,012 - DEBUG - GET request to new workout: 
2024-06-09 15:41:55,360 - INFO - /Users/janrydzewski/Developer/Studies/Django/workout_logger/workout/models.py changed, reloading.: 
2024-06-09 15:41:57,780 - INFO - /Users/janrydzewski/Developer/Studies/Django/workout_logger/workout/models.py changed, reloading.: 
2024-06-09 15:42:00,046 - INFO - /Users/janrydzewski/Developer/Studies/Django/workout_logger/workout/models.py changed, reloading.: 
2024-06-09 15:43:23,336 - INFO - /Users/janrydzewski/Developer/Studies/Django/workout_logger/workout/views.py changed, reloading.: 
2024-06-09 15:43:26,719 - INFO - /Users/janrydzewski/Developer/Studies/Django/workout_logger/workout/views.py changed, reloading.: 
2024-06-09 15:43:31,053 - INFO - /Users/janrydzewski/Developer/Studies/Django/workout_logger/workout/views.py changed, reloading.: 
2024-06-09 15:43:36,341 - INFO - /Users/janrydzewski/Developer/Studies/Django/workout_logger/workout/views.py changed, reloading.: 
2024-06-09 15:44:45,749 - DEBUG - GET request to login: 
2024-06-09 15:45:20,023 - ERROR - Internal Server Error: /admin/workout/workout/7/delete/: 
Traceback (most recent call last):
  File "/Library/Frameworks/Python.framework/Versions/3.12/lib/python3.12/site-packages/django/db/backends/utils.py", line 85, in _execute
    return self.cursor.execute(sql, params)
           ^^^^^^^^^^^^^^^^^^^^^^^^^^^^^^^^
  File "/Library/Frameworks/Python.framework/Versions/3.12/lib/python3.12/site-packages/django/db/backends/sqlite3/base.py", line 416, in execute
    return Database.Cursor.execute(self, query, params)
           ^^^^^^^^^^^^^^^^^^^^^^^^^^^^^^^^^^^^^^^^^^^^
sqlite3.OperationalError: no such column: workout_userchallenge.workout_id

The above exception was the direct cause of the following exception:

Traceback (most recent call last):
  File "/Library/Frameworks/Python.framework/Versions/3.12/lib/python3.12/site-packages/django/core/handlers/exception.py", line 47, in inner
    response = get_response(request)
               ^^^^^^^^^^^^^^^^^^^^^
  File "/Library/Frameworks/Python.framework/Versions/3.12/lib/python3.12/site-packages/django/core/handlers/base.py", line 181, in _get_response
    response = wrapped_callback(request, *callback_args, **callback_kwargs)
               ^^^^^^^^^^^^^^^^^^^^^^^^^^^^^^^^^^^^^^^^^^^^^^^^^^^^^^^^^^^^
  File "/Library/Frameworks/Python.framework/Versions/3.12/lib/python3.12/site-packages/django/contrib/admin/options.py", line 622, in wrapper
    return self.admin_site.admin_view(view)(*args, **kwargs)
           ^^^^^^^^^^^^^^^^^^^^^^^^^^^^^^^^^^^^^^^^^^^^^^^^^
  File "/Library/Frameworks/Python.framework/Versions/3.12/lib/python3.12/site-packages/django/utils/decorators.py", line 130, in _wrapped_view
    response = view_func(request, *args, **kwargs)
               ^^^^^^^^^^^^^^^^^^^^^^^^^^^^^^^^^^^
  File "/Library/Frameworks/Python.framework/Versions/3.12/lib/python3.12/site-packages/django/views/decorators/cache.py", line 56, in _wrapped_view_func
    response = view_func(request, *args, **kwargs)
               ^^^^^^^^^^^^^^^^^^^^^^^^^^^^^^^^^^^
  File "/Library/Frameworks/Python.framework/Versions/3.12/lib/python3.12/site-packages/django/contrib/admin/sites.py", line 236, in inner
    return view(request, *args, **kwargs)
           ^^^^^^^^^^^^^^^^^^^^^^^^^^^^^^
  File "/Library/Frameworks/Python.framework/Versions/3.12/lib/python3.12/site-packages/django/utils/decorators.py", line 43, in _wrapper
    return bound_method(*args, **kwargs)
           ^^^^^^^^^^^^^^^^^^^^^^^^^^^^^
  File "/Library/Frameworks/Python.framework/Versions/3.12/lib/python3.12/site-packages/django/utils/decorators.py", line 130, in _wrapped_view
    response = view_func(request, *args, **kwargs)
               ^^^^^^^^^^^^^^^^^^^^^^^^^^^^^^^^^^^
  File "/Library/Frameworks/Python.framework/Versions/3.12/lib/python3.12/site-packages/django/contrib/admin/options.py", line 1864, in delete_view
    return self._delete_view(request, object_id, extra_context)
           ^^^^^^^^^^^^^^^^^^^^^^^^^^^^^^^^^^^^^^^^^^^^^^^^^^^^
  File "/Library/Frameworks/Python.framework/Versions/3.12/lib/python3.12/site-packages/django/contrib/admin/options.py", line 1885, in _delete_view
    deleted_objects, model_count, perms_needed, protected = self.get_deleted_objects([obj], request)
                                                            ^^^^^^^^^^^^^^^^^^^^^^^^^^^^^^^^^^^^^^^^
  File "/Library/Frameworks/Python.framework/Versions/3.12/lib/python3.12/site-packages/django/contrib/admin/options.py", line 1859, in get_deleted_objects
    return get_deleted_objects(objs, request, self.admin_site)
           ^^^^^^^^^^^^^^^^^^^^^^^^^^^^^^^^^^^^^^^^^^^^^^^^^^^
  File "/Library/Frameworks/Python.framework/Versions/3.12/lib/python3.12/site-packages/django/contrib/admin/utils.py", line 120, in get_deleted_objects
    collector.collect(objs)
  File "/Library/Frameworks/Python.framework/Versions/3.12/lib/python3.12/site-packages/django/contrib/admin/utils.py", line 183, in collect
    return super().collect(objs, source_attr=source_attr, **kwargs)
           ^^^^^^^^^^^^^^^^^^^^^^^^^^^^^^^^^^^^^^^^^^^^^^^^^^^^^^^^
  File "/Library/Frameworks/Python.framework/Versions/3.12/lib/python3.12/site-packages/django/db/models/deletion.py", line 294, in collect
    if sub_objs:
       ^^^^^^^^
  File "/Library/Frameworks/Python.framework/Versions/3.12/lib/python3.12/site-packages/django/db/models/query.py", line 284, in __bool__
    self._fetch_all()
  File "/Library/Frameworks/Python.framework/Versions/3.12/lib/python3.12/site-packages/django/db/models/query.py", line 1354, in _fetch_all
    self._result_cache = list(self._iterable_class(self))
                         ^^^^^^^^^^^^^^^^^^^^^^^^^^^^^^^^
  File "/Library/Frameworks/Python.framework/Versions/3.12/lib/python3.12/site-packages/django/db/models/query.py", line 51, in __iter__
    results = compiler.execute_sql(chunked_fetch=self.chunked_fetch, chunk_size=self.chunk_size)
              ^^^^^^^^^^^^^^^^^^^^^^^^^^^^^^^^^^^^^^^^^^^^^^^^^^^^^^^^^^^^^^^^^^^^^^^^^^^^^^^^^^
  File "/Library/Frameworks/Python.framework/Versions/3.12/lib/python3.12/site-packages/django/db/models/sql/compiler.py", line 1202, in execute_sql
    cursor.execute(sql, params)
  File "/Library/Frameworks/Python.framework/Versions/3.12/lib/python3.12/site-packages/django/db/backends/utils.py", line 99, in execute
    return super().execute(sql, params)
           ^^^^^^^^^^^^^^^^^^^^^^^^^^^^
  File "/Library/Frameworks/Python.framework/Versions/3.12/lib/python3.12/site-packages/django/db/backends/utils.py", line 67, in execute
    return self._execute_with_wrappers(sql, params, many=False, executor=self._execute)
           ^^^^^^^^^^^^^^^^^^^^^^^^^^^^^^^^^^^^^^^^^^^^^^^^^^^^^^^^^^^^^^^^^^^^^^^^^^^^
  File "/Library/Frameworks/Python.framework/Versions/3.12/lib/python3.12/site-packages/django/db/backends/utils.py", line 76, in _execute_with_wrappers
    return executor(sql, params, many, context)
           ^^^^^^^^^^^^^^^^^^^^^^^^^^^^^^^^^^^^
  File "/Library/Frameworks/Python.framework/Versions/3.12/lib/python3.12/site-packages/django/db/backends/utils.py", line 80, in _execute
    with self.db.wrap_database_errors:
  File "/Library/Frameworks/Python.framework/Versions/3.12/lib/python3.12/site-packages/django/db/utils.py", line 90, in __exit__
    raise dj_exc_value.with_traceback(traceback) from exc_value
  File "/Library/Frameworks/Python.framework/Versions/3.12/lib/python3.12/site-packages/django/db/backends/utils.py", line 85, in _execute
    return self.cursor.execute(sql, params)
           ^^^^^^^^^^^^^^^^^^^^^^^^^^^^^^^^
  File "/Library/Frameworks/Python.framework/Versions/3.12/lib/python3.12/site-packages/django/db/backends/sqlite3/base.py", line 416, in execute
    return Database.Cursor.execute(self, query, params)
           ^^^^^^^^^^^^^^^^^^^^^^^^^^^^^^^^^^^^^^^^^^^^
django.db.utils.OperationalError: no such column: workout_userchallenge.workout_id
2024-06-09 15:50:57,005 - DEBUG - GET request to login: 
2024-06-09 16:00:31,345 - DEBUG - GET request to login: 
2024-06-09 16:09:51,583 - DEBUG - GET request to login: 
2024-06-09 16:09:57,005 - ERROR - Internal Server Error: /admin/workout/workout/7/change/: 
Traceback (most recent call last):
  File "/Library/Frameworks/Python.framework/Versions/3.12/lib/python3.12/site-packages/django/db/backends/utils.py", line 85, in _execute
    return self.cursor.execute(sql, params)
           ^^^^^^^^^^^^^^^^^^^^^^^^^^^^^^^^
  File "/Library/Frameworks/Python.framework/Versions/3.12/lib/python3.12/site-packages/django/db/backends/sqlite3/base.py", line 416, in execute
    return Database.Cursor.execute(self, query, params)
           ^^^^^^^^^^^^^^^^^^^^^^^^^^^^^^^^^^^^^^^^^^^^
sqlite3.OperationalError: no such table: workout_challenge

The above exception was the direct cause of the following exception:

Traceback (most recent call last):
  File "/Library/Frameworks/Python.framework/Versions/3.12/lib/python3.12/site-packages/django/core/handlers/exception.py", line 47, in inner
    response = get_response(request)
               ^^^^^^^^^^^^^^^^^^^^^
  File "/Library/Frameworks/Python.framework/Versions/3.12/lib/python3.12/site-packages/django/core/handlers/base.py", line 204, in _get_response
    response = response.render()
               ^^^^^^^^^^^^^^^^^
  File "/Library/Frameworks/Python.framework/Versions/3.12/lib/python3.12/site-packages/django/template/response.py", line 105, in render
    self.content = self.rendered_content
                   ^^^^^^^^^^^^^^^^^^^^^
  File "/Library/Frameworks/Python.framework/Versions/3.12/lib/python3.12/site-packages/django/template/response.py", line 83, in rendered_content
    return template.render(context, self._request)
           ^^^^^^^^^^^^^^^^^^^^^^^^^^^^^^^^^^^^^^^
  File "/Library/Frameworks/Python.framework/Versions/3.12/lib/python3.12/site-packages/django/template/backends/django.py", line 61, in render
    return self.template.render(context)
           ^^^^^^^^^^^^^^^^^^^^^^^^^^^^^
  File "/Library/Frameworks/Python.framework/Versions/3.12/lib/python3.12/site-packages/django/template/base.py", line 176, in render
    return self._render(context)
           ^^^^^^^^^^^^^^^^^^^^^
  File "/Library/Frameworks/Python.framework/Versions/3.12/lib/python3.12/site-packages/django/template/base.py", line 168, in _render
    return self.nodelist.render(context)
           ^^^^^^^^^^^^^^^^^^^^^^^^^^^^^
  File "/Library/Frameworks/Python.framework/Versions/3.12/lib/python3.12/site-packages/django/template/base.py", line 978, in render
    node.render_annotated(context) for node in self
    ^^^^^^^^^^^^^^^^^^^^^^^^^^^^^^
  File "/Library/Frameworks/Python.framework/Versions/3.12/lib/python3.12/site-packages/django/template/base.py", line 938, in render_annotated
    return self.render(context)
           ^^^^^^^^^^^^^^^^^^^^
  File "/Library/Frameworks/Python.framework/Versions/3.12/lib/python3.12/site-packages/django/template/loader_tags.py", line 153, in render
    return compiled_parent._render(context)
           ^^^^^^^^^^^^^^^^^^^^^^^^^^^^^^^^
  File "/Library/Frameworks/Python.framework/Versions/3.12/lib/python3.12/site-packages/django/template/base.py", line 168, in _render
    return self.nodelist.render(context)
           ^^^^^^^^^^^^^^^^^^^^^^^^^^^^^
  File "/Library/Frameworks/Python.framework/Versions/3.12/lib/python3.12/site-packages/django/template/base.py", line 978, in render
    node.render_annotated(context) for node in self
    ^^^^^^^^^^^^^^^^^^^^^^^^^^^^^^
  File "/Library/Frameworks/Python.framework/Versions/3.12/lib/python3.12/site-packages/django/template/base.py", line 938, in render_annotated
    return self.render(context)
           ^^^^^^^^^^^^^^^^^^^^
  File "/Library/Frameworks/Python.framework/Versions/3.12/lib/python3.12/site-packages/django/template/loader_tags.py", line 153, in render
    return compiled_parent._render(context)
           ^^^^^^^^^^^^^^^^^^^^^^^^^^^^^^^^
  File "/Library/Frameworks/Python.framework/Versions/3.12/lib/python3.12/site-packages/django/template/base.py", line 168, in _render
    return self.nodelist.render(context)
           ^^^^^^^^^^^^^^^^^^^^^^^^^^^^^
  File "/Library/Frameworks/Python.framework/Versions/3.12/lib/python3.12/site-packages/django/template/base.py", line 978, in render
    node.render_annotated(context) for node in self
    ^^^^^^^^^^^^^^^^^^^^^^^^^^^^^^
  File "/Library/Frameworks/Python.framework/Versions/3.12/lib/python3.12/site-packages/django/template/base.py", line 938, in render_annotated
    return self.render(context)
           ^^^^^^^^^^^^^^^^^^^^
  File "/Library/Frameworks/Python.framework/Versions/3.12/lib/python3.12/site-packages/django/template/loader_tags.py", line 65, in render
    result = block.nodelist.render(context)
             ^^^^^^^^^^^^^^^^^^^^^^^^^^^^^^
  File "/Library/Frameworks/Python.framework/Versions/3.12/lib/python3.12/site-packages/django/template/base.py", line 978, in render
    node.render_annotated(context) for node in self
    ^^^^^^^^^^^^^^^^^^^^^^^^^^^^^^
  File "/Library/Frameworks/Python.framework/Versions/3.12/lib/python3.12/site-packages/django/template/base.py", line 938, in render_annotated
    return self.render(context)
           ^^^^^^^^^^^^^^^^^^^^
  File "/Library/Frameworks/Python.framework/Versions/3.12/lib/python3.12/site-packages/django/template/loader_tags.py", line 65, in render
    result = block.nodelist.render(context)
             ^^^^^^^^^^^^^^^^^^^^^^^^^^^^^^
  File "/Library/Frameworks/Python.framework/Versions/3.12/lib/python3.12/site-packages/django/template/base.py", line 978, in render
    node.render_annotated(context) for node in self
    ^^^^^^^^^^^^^^^^^^^^^^^^^^^^^^
  File "/Library/Frameworks/Python.framework/Versions/3.12/lib/python3.12/site-packages/django/template/base.py", line 938, in render_annotated
    return self.render(context)
           ^^^^^^^^^^^^^^^^^^^^
  File "/Library/Frameworks/Python.framework/Versions/3.12/lib/python3.12/site-packages/django/template/defaulttags.py", line 214, in render
    nodelist.append(node.render_annotated(context))
                    ^^^^^^^^^^^^^^^^^^^^^^^^^^^^^^
  File "/Library/Frameworks/Python.framework/Versions/3.12/lib/python3.12/site-packages/django/template/base.py", line 938, in render_annotated
    return self.render(context)
           ^^^^^^^^^^^^^^^^^^^^
  File "/Library/Frameworks/Python.framework/Versions/3.12/lib/python3.12/site-packages/django/template/loader_tags.py", line 201, in render
    return template.render(context)
           ^^^^^^^^^^^^^^^^^^^^^^^^
  File "/Library/Frameworks/Python.framework/Versions/3.12/lib/python3.12/site-packages/django/template/base.py", line 178, in render
    return self._render(context)
           ^^^^^^^^^^^^^^^^^^^^^
  File "/Library/Frameworks/Python.framework/Versions/3.12/lib/python3.12/site-packages/django/template/base.py", line 168, in _render
    return self.nodelist.render(context)
           ^^^^^^^^^^^^^^^^^^^^^^^^^^^^^
  File "/Library/Frameworks/Python.framework/Versions/3.12/lib/python3.12/site-packages/django/template/base.py", line 978, in render
    node.render_annotated(context) for node in self
    ^^^^^^^^^^^^^^^^^^^^^^^^^^^^^^
  File "/Library/Frameworks/Python.framework/Versions/3.12/lib/python3.12/site-packages/django/template/base.py", line 938, in render_annotated
    return self.render(context)
           ^^^^^^^^^^^^^^^^^^^^
  File "/Library/Frameworks/Python.framework/Versions/3.12/lib/python3.12/site-packages/django/template/defaulttags.py", line 214, in render
    nodelist.append(node.render_annotated(context))
                    ^^^^^^^^^^^^^^^^^^^^^^^^^^^^^^
  File "/Library/Frameworks/Python.framework/Versions/3.12/lib/python3.12/site-packages/django/template/base.py", line 938, in render_annotated
    return self.render(context)
           ^^^^^^^^^^^^^^^^^^^^
  File "/Library/Frameworks/Python.framework/Versions/3.12/lib/python3.12/site-packages/django/template/defaulttags.py", line 214, in render
    nodelist.append(node.render_annotated(context))
                    ^^^^^^^^^^^^^^^^^^^^^^^^^^^^^^
  File "/Library/Frameworks/Python.framework/Versions/3.12/lib/python3.12/site-packages/django/template/base.py", line 938, in render_annotated
    return self.render(context)
           ^^^^^^^^^^^^^^^^^^^^
  File "/Library/Frameworks/Python.framework/Versions/3.12/lib/python3.12/site-packages/django/template/defaulttags.py", line 295, in render
    return nodelist.render(context)
           ^^^^^^^^^^^^^^^^^^^^^^^^
  File "/Library/Frameworks/Python.framework/Versions/3.12/lib/python3.12/site-packages/django/template/base.py", line 978, in render
    node.render_annotated(context) for node in self
    ^^^^^^^^^^^^^^^^^^^^^^^^^^^^^^
  File "/Library/Frameworks/Python.framework/Versions/3.12/lib/python3.12/site-packages/django/template/base.py", line 938, in render_annotated
    return self.render(context)
           ^^^^^^^^^^^^^^^^^^^^
  File "/Library/Frameworks/Python.framework/Versions/3.12/lib/python3.12/site-packages/django/template/defaulttags.py", line 295, in render
    return nodelist.render(context)
           ^^^^^^^^^^^^^^^^^^^^^^^^
  File "/Library/Frameworks/Python.framework/Versions/3.12/lib/python3.12/site-packages/django/template/base.py", line 978, in render
    node.render_annotated(context) for node in self
    ^^^^^^^^^^^^^^^^^^^^^^^^^^^^^^
  File "/Library/Frameworks/Python.framework/Versions/3.12/lib/python3.12/site-packages/django/template/base.py", line 938, in render_annotated
    return self.render(context)
           ^^^^^^^^^^^^^^^^^^^^
  File "/Library/Frameworks/Python.framework/Versions/3.12/lib/python3.12/site-packages/django/template/base.py", line 1044, in render
    return render_value_in_context(output, context)
           ^^^^^^^^^^^^^^^^^^^^^^^^^^^^^^^^^^^^^^^^
  File "/Library/Frameworks/Python.framework/Versions/3.12/lib/python3.12/site-packages/django/template/base.py", line 1021, in render_value_in_context
    value = str(value)
            ^^^^^^^^^^
  File "/Library/Frameworks/Python.framework/Versions/3.12/lib/python3.12/site-packages/django/utils/html.py", line 377, in <lambda>
    klass.__str__ = lambda self: mark_safe(klass_str(self))
                                           ^^^^^^^^^^^^^^^
  File "/Library/Frameworks/Python.framework/Versions/3.12/lib/python3.12/site-packages/django/forms/boundfield.py", line 33, in __str__
    return self.as_widget()
           ^^^^^^^^^^^^^^^^
  File "/Library/Frameworks/Python.framework/Versions/3.12/lib/python3.12/site-packages/django/forms/boundfield.py", line 92, in as_widget
    return widget.render(
           ^^^^^^^^^^^^^^
  File "/Library/Frameworks/Python.framework/Versions/3.12/lib/python3.12/site-packages/django/forms/widgets.py", line 246, in render
    context = self.get_context(name, value, attrs)
              ^^^^^^^^^^^^^^^^^^^^^^^^^^^^^^^^^^^^
  File "/Library/Frameworks/Python.framework/Versions/3.12/lib/python3.12/site-packages/django/contrib/admin/widgets.py", line 283, in get_context
    'rendered_widget': self.widget.render(name, value, attrs),
                       ^^^^^^^^^^^^^^^^^^^^^^^^^^^^^^^^^^^^^^
  File "/Library/Frameworks/Python.framework/Versions/3.12/lib/python3.12/site-packages/django/forms/widgets.py", line 246, in render
    context = self.get_context(name, value, attrs)
              ^^^^^^^^^^^^^^^^^^^^^^^^^^^^^^^^^^^^
  File "/Library/Frameworks/Python.framework/Versions/3.12/lib/python3.12/site-packages/django/forms/widgets.py", line 681, in get_context
    context = super().get_context(name, value, attrs)
              ^^^^^^^^^^^^^^^^^^^^^^^^^^^^^^^^^^^^^^^
  File "/Library/Frameworks/Python.framework/Versions/3.12/lib/python3.12/site-packages/django/forms/widgets.py", line 642, in get_context
    context['widget']['optgroups'] = self.optgroups(name, context['widget']['value'], attrs)
                                     ^^^^^^^^^^^^^^^^^^^^^^^^^^^^^^^^^^^^^^^^^^^^^^^^^^^^^^^
  File "/Library/Frameworks/Python.framework/Versions/3.12/lib/python3.12/site-packages/django/forms/widgets.py", line 592, in optgroups
    for index, (option_value, option_label) in enumerate(self.choices):
  File "/Library/Frameworks/Python.framework/Versions/3.12/lib/python3.12/site-packages/django/forms/models.py", line 1190, in __iter__
    for obj in queryset:
  File "/Library/Frameworks/Python.framework/Versions/3.12/lib/python3.12/site-packages/django/db/models/query.py", line 357, in _iterator
    yield from self._iterable_class(self, chunked_fetch=use_chunked_fetch, chunk_size=chunk_size)
  File "/Library/Frameworks/Python.framework/Versions/3.12/lib/python3.12/site-packages/django/db/models/query.py", line 51, in __iter__
    results = compiler.execute_sql(chunked_fetch=self.chunked_fetch, chunk_size=self.chunk_size)
              ^^^^^^^^^^^^^^^^^^^^^^^^^^^^^^^^^^^^^^^^^^^^^^^^^^^^^^^^^^^^^^^^^^^^^^^^^^^^^^^^^^
  File "/Library/Frameworks/Python.framework/Versions/3.12/lib/python3.12/site-packages/django/db/models/sql/compiler.py", line 1202, in execute_sql
    cursor.execute(sql, params)
  File "/Library/Frameworks/Python.framework/Versions/3.12/lib/python3.12/site-packages/django/db/backends/utils.py", line 99, in execute
    return super().execute(sql, params)
           ^^^^^^^^^^^^^^^^^^^^^^^^^^^^
  File "/Library/Frameworks/Python.framework/Versions/3.12/lib/python3.12/site-packages/django/db/backends/utils.py", line 67, in execute
    return self._execute_with_wrappers(sql, params, many=False, executor=self._execute)
           ^^^^^^^^^^^^^^^^^^^^^^^^^^^^^^^^^^^^^^^^^^^^^^^^^^^^^^^^^^^^^^^^^^^^^^^^^^^^
  File "/Library/Frameworks/Python.framework/Versions/3.12/lib/python3.12/site-packages/django/db/backends/utils.py", line 76, in _execute_with_wrappers
    return executor(sql, params, many, context)
           ^^^^^^^^^^^^^^^^^^^^^^^^^^^^^^^^^^^^
  File "/Library/Frameworks/Python.framework/Versions/3.12/lib/python3.12/site-packages/django/db/backends/utils.py", line 80, in _execute
    with self.db.wrap_database_errors:
  File "/Library/Frameworks/Python.framework/Versions/3.12/lib/python3.12/site-packages/django/db/utils.py", line 90, in __exit__
    raise dj_exc_value.with_traceback(traceback) from exc_value
  File "/Library/Frameworks/Python.framework/Versions/3.12/lib/python3.12/site-packages/django/db/backends/utils.py", line 85, in _execute
    return self.cursor.execute(sql, params)
           ^^^^^^^^^^^^^^^^^^^^^^^^^^^^^^^^
  File "/Library/Frameworks/Python.framework/Versions/3.12/lib/python3.12/site-packages/django/db/backends/sqlite3/base.py", line 416, in execute
    return Database.Cursor.execute(self, query, params)
           ^^^^^^^^^^^^^^^^^^^^^^^^^^^^^^^^^^^^^^^^^^^^
django.db.utils.OperationalError: no such table: workout_challenge
2024-06-09 16:09:59,726 - ERROR - Internal Server Error: /admin/workout/workout/4/change/: 
Traceback (most recent call last):
  File "/Library/Frameworks/Python.framework/Versions/3.12/lib/python3.12/site-packages/django/db/backends/utils.py", line 85, in _execute
    return self.cursor.execute(sql, params)
           ^^^^^^^^^^^^^^^^^^^^^^^^^^^^^^^^
  File "/Library/Frameworks/Python.framework/Versions/3.12/lib/python3.12/site-packages/django/db/backends/sqlite3/base.py", line 416, in execute
    return Database.Cursor.execute(self, query, params)
           ^^^^^^^^^^^^^^^^^^^^^^^^^^^^^^^^^^^^^^^^^^^^
sqlite3.OperationalError: no such table: workout_challenge

The above exception was the direct cause of the following exception:

Traceback (most recent call last):
  File "/Library/Frameworks/Python.framework/Versions/3.12/lib/python3.12/site-packages/django/core/handlers/exception.py", line 47, in inner
    response = get_response(request)
               ^^^^^^^^^^^^^^^^^^^^^
  File "/Library/Frameworks/Python.framework/Versions/3.12/lib/python3.12/site-packages/django/core/handlers/base.py", line 204, in _get_response
    response = response.render()
               ^^^^^^^^^^^^^^^^^
  File "/Library/Frameworks/Python.framework/Versions/3.12/lib/python3.12/site-packages/django/template/response.py", line 105, in render
    self.content = self.rendered_content
                   ^^^^^^^^^^^^^^^^^^^^^
  File "/Library/Frameworks/Python.framework/Versions/3.12/lib/python3.12/site-packages/django/template/response.py", line 83, in rendered_content
    return template.render(context, self._request)
           ^^^^^^^^^^^^^^^^^^^^^^^^^^^^^^^^^^^^^^^
  File "/Library/Frameworks/Python.framework/Versions/3.12/lib/python3.12/site-packages/django/template/backends/django.py", line 61, in render
    return self.template.render(context)
           ^^^^^^^^^^^^^^^^^^^^^^^^^^^^^
  File "/Library/Frameworks/Python.framework/Versions/3.12/lib/python3.12/site-packages/django/template/base.py", line 176, in render
    return self._render(context)
           ^^^^^^^^^^^^^^^^^^^^^
  File "/Library/Frameworks/Python.framework/Versions/3.12/lib/python3.12/site-packages/django/template/base.py", line 168, in _render
    return self.nodelist.render(context)
           ^^^^^^^^^^^^^^^^^^^^^^^^^^^^^
  File "/Library/Frameworks/Python.framework/Versions/3.12/lib/python3.12/site-packages/django/template/base.py", line 978, in render
    node.render_annotated(context) for node in self
    ^^^^^^^^^^^^^^^^^^^^^^^^^^^^^^
  File "/Library/Frameworks/Python.framework/Versions/3.12/lib/python3.12/site-packages/django/template/base.py", line 938, in render_annotated
    return self.render(context)
           ^^^^^^^^^^^^^^^^^^^^
  File "/Library/Frameworks/Python.framework/Versions/3.12/lib/python3.12/site-packages/django/template/loader_tags.py", line 153, in render
    return compiled_parent._render(context)
           ^^^^^^^^^^^^^^^^^^^^^^^^^^^^^^^^
  File "/Library/Frameworks/Python.framework/Versions/3.12/lib/python3.12/site-packages/django/template/base.py", line 168, in _render
    return self.nodelist.render(context)
           ^^^^^^^^^^^^^^^^^^^^^^^^^^^^^
  File "/Library/Frameworks/Python.framework/Versions/3.12/lib/python3.12/site-packages/django/template/base.py", line 978, in render
    node.render_annotated(context) for node in self
    ^^^^^^^^^^^^^^^^^^^^^^^^^^^^^^
  File "/Library/Frameworks/Python.framework/Versions/3.12/lib/python3.12/site-packages/django/template/base.py", line 938, in render_annotated
    return self.render(context)
           ^^^^^^^^^^^^^^^^^^^^
  File "/Library/Frameworks/Python.framework/Versions/3.12/lib/python3.12/site-packages/django/template/loader_tags.py", line 153, in render
    return compiled_parent._render(context)
           ^^^^^^^^^^^^^^^^^^^^^^^^^^^^^^^^
  File "/Library/Frameworks/Python.framework/Versions/3.12/lib/python3.12/site-packages/django/template/base.py", line 168, in _render
    return self.nodelist.render(context)
           ^^^^^^^^^^^^^^^^^^^^^^^^^^^^^
  File "/Library/Frameworks/Python.framework/Versions/3.12/lib/python3.12/site-packages/django/template/base.py", line 978, in render
    node.render_annotated(context) for node in self
    ^^^^^^^^^^^^^^^^^^^^^^^^^^^^^^
  File "/Library/Frameworks/Python.framework/Versions/3.12/lib/python3.12/site-packages/django/template/base.py", line 938, in render_annotated
    return self.render(context)
           ^^^^^^^^^^^^^^^^^^^^
  File "/Library/Frameworks/Python.framework/Versions/3.12/lib/python3.12/site-packages/django/template/loader_tags.py", line 65, in render
    result = block.nodelist.render(context)
             ^^^^^^^^^^^^^^^^^^^^^^^^^^^^^^
  File "/Library/Frameworks/Python.framework/Versions/3.12/lib/python3.12/site-packages/django/template/base.py", line 978, in render
    node.render_annotated(context) for node in self
    ^^^^^^^^^^^^^^^^^^^^^^^^^^^^^^
  File "/Library/Frameworks/Python.framework/Versions/3.12/lib/python3.12/site-packages/django/template/base.py", line 938, in render_annotated
    return self.render(context)
           ^^^^^^^^^^^^^^^^^^^^
  File "/Library/Frameworks/Python.framework/Versions/3.12/lib/python3.12/site-packages/django/template/loader_tags.py", line 65, in render
    result = block.nodelist.render(context)
             ^^^^^^^^^^^^^^^^^^^^^^^^^^^^^^
  File "/Library/Frameworks/Python.framework/Versions/3.12/lib/python3.12/site-packages/django/template/base.py", line 978, in render
    node.render_annotated(context) for node in self
    ^^^^^^^^^^^^^^^^^^^^^^^^^^^^^^
  File "/Library/Frameworks/Python.framework/Versions/3.12/lib/python3.12/site-packages/django/template/base.py", line 938, in render_annotated
    return self.render(context)
           ^^^^^^^^^^^^^^^^^^^^
  File "/Library/Frameworks/Python.framework/Versions/3.12/lib/python3.12/site-packages/django/template/defaulttags.py", line 214, in render
    nodelist.append(node.render_annotated(context))
                    ^^^^^^^^^^^^^^^^^^^^^^^^^^^^^^
  File "/Library/Frameworks/Python.framework/Versions/3.12/lib/python3.12/site-packages/django/template/base.py", line 938, in render_annotated
    return self.render(context)
           ^^^^^^^^^^^^^^^^^^^^
  File "/Library/Frameworks/Python.framework/Versions/3.12/lib/python3.12/site-packages/django/template/loader_tags.py", line 201, in render
    return template.render(context)
           ^^^^^^^^^^^^^^^^^^^^^^^^
  File "/Library/Frameworks/Python.framework/Versions/3.12/lib/python3.12/site-packages/django/template/base.py", line 178, in render
    return self._render(context)
           ^^^^^^^^^^^^^^^^^^^^^
  File "/Library/Frameworks/Python.framework/Versions/3.12/lib/python3.12/site-packages/django/template/base.py", line 168, in _render
    return self.nodelist.render(context)
           ^^^^^^^^^^^^^^^^^^^^^^^^^^^^^
  File "/Library/Frameworks/Python.framework/Versions/3.12/lib/python3.12/site-packages/django/template/base.py", line 978, in render
    node.render_annotated(context) for node in self
    ^^^^^^^^^^^^^^^^^^^^^^^^^^^^^^
  File "/Library/Frameworks/Python.framework/Versions/3.12/lib/python3.12/site-packages/django/template/base.py", line 938, in render_annotated
    return self.render(context)
           ^^^^^^^^^^^^^^^^^^^^
  File "/Library/Frameworks/Python.framework/Versions/3.12/lib/python3.12/site-packages/django/template/defaulttags.py", line 214, in render
    nodelist.append(node.render_annotated(context))
                    ^^^^^^^^^^^^^^^^^^^^^^^^^^^^^^
  File "/Library/Frameworks/Python.framework/Versions/3.12/lib/python3.12/site-packages/django/template/base.py", line 938, in render_annotated
    return self.render(context)
           ^^^^^^^^^^^^^^^^^^^^
  File "/Library/Frameworks/Python.framework/Versions/3.12/lib/python3.12/site-packages/django/template/defaulttags.py", line 214, in render
    nodelist.append(node.render_annotated(context))
                    ^^^^^^^^^^^^^^^^^^^^^^^^^^^^^^
  File "/Library/Frameworks/Python.framework/Versions/3.12/lib/python3.12/site-packages/django/template/base.py", line 938, in render_annotated
    return self.render(context)
           ^^^^^^^^^^^^^^^^^^^^
  File "/Library/Frameworks/Python.framework/Versions/3.12/lib/python3.12/site-packages/django/template/defaulttags.py", line 295, in render
    return nodelist.render(context)
           ^^^^^^^^^^^^^^^^^^^^^^^^
  File "/Library/Frameworks/Python.framework/Versions/3.12/lib/python3.12/site-packages/django/template/base.py", line 978, in render
    node.render_annotated(context) for node in self
    ^^^^^^^^^^^^^^^^^^^^^^^^^^^^^^
  File "/Library/Frameworks/Python.framework/Versions/3.12/lib/python3.12/site-packages/django/template/base.py", line 938, in render_annotated
    return self.render(context)
           ^^^^^^^^^^^^^^^^^^^^
  File "/Library/Frameworks/Python.framework/Versions/3.12/lib/python3.12/site-packages/django/template/defaulttags.py", line 295, in render
    return nodelist.render(context)
           ^^^^^^^^^^^^^^^^^^^^^^^^
  File "/Library/Frameworks/Python.framework/Versions/3.12/lib/python3.12/site-packages/django/template/base.py", line 978, in render
    node.render_annotated(context) for node in self
    ^^^^^^^^^^^^^^^^^^^^^^^^^^^^^^
  File "/Library/Frameworks/Python.framework/Versions/3.12/lib/python3.12/site-packages/django/template/base.py", line 938, in render_annotated
    return self.render(context)
           ^^^^^^^^^^^^^^^^^^^^
  File "/Library/Frameworks/Python.framework/Versions/3.12/lib/python3.12/site-packages/django/template/base.py", line 1044, in render
    return render_value_in_context(output, context)
           ^^^^^^^^^^^^^^^^^^^^^^^^^^^^^^^^^^^^^^^^
  File "/Library/Frameworks/Python.framework/Versions/3.12/lib/python3.12/site-packages/django/template/base.py", line 1021, in render_value_in_context
    value = str(value)
            ^^^^^^^^^^
  File "/Library/Frameworks/Python.framework/Versions/3.12/lib/python3.12/site-packages/django/utils/html.py", line 377, in <lambda>
    klass.__str__ = lambda self: mark_safe(klass_str(self))
                                           ^^^^^^^^^^^^^^^
  File "/Library/Frameworks/Python.framework/Versions/3.12/lib/python3.12/site-packages/django/forms/boundfield.py", line 33, in __str__
    return self.as_widget()
           ^^^^^^^^^^^^^^^^
  File "/Library/Frameworks/Python.framework/Versions/3.12/lib/python3.12/site-packages/django/forms/boundfield.py", line 92, in as_widget
    return widget.render(
           ^^^^^^^^^^^^^^
  File "/Library/Frameworks/Python.framework/Versions/3.12/lib/python3.12/site-packages/django/forms/widgets.py", line 246, in render
    context = self.get_context(name, value, attrs)
              ^^^^^^^^^^^^^^^^^^^^^^^^^^^^^^^^^^^^
  File "/Library/Frameworks/Python.framework/Versions/3.12/lib/python3.12/site-packages/django/contrib/admin/widgets.py", line 283, in get_context
    'rendered_widget': self.widget.render(name, value, attrs),
                       ^^^^^^^^^^^^^^^^^^^^^^^^^^^^^^^^^^^^^^
  File "/Library/Frameworks/Python.framework/Versions/3.12/lib/python3.12/site-packages/django/forms/widgets.py", line 246, in render
    context = self.get_context(name, value, attrs)
              ^^^^^^^^^^^^^^^^^^^^^^^^^^^^^^^^^^^^
  File "/Library/Frameworks/Python.framework/Versions/3.12/lib/python3.12/site-packages/django/forms/widgets.py", line 681, in get_context
    context = super().get_context(name, value, attrs)
              ^^^^^^^^^^^^^^^^^^^^^^^^^^^^^^^^^^^^^^^
  File "/Library/Frameworks/Python.framework/Versions/3.12/lib/python3.12/site-packages/django/forms/widgets.py", line 642, in get_context
    context['widget']['optgroups'] = self.optgroups(name, context['widget']['value'], attrs)
                                     ^^^^^^^^^^^^^^^^^^^^^^^^^^^^^^^^^^^^^^^^^^^^^^^^^^^^^^^
  File "/Library/Frameworks/Python.framework/Versions/3.12/lib/python3.12/site-packages/django/forms/widgets.py", line 592, in optgroups
    for index, (option_value, option_label) in enumerate(self.choices):
  File "/Library/Frameworks/Python.framework/Versions/3.12/lib/python3.12/site-packages/django/forms/models.py", line 1190, in __iter__
    for obj in queryset:
  File "/Library/Frameworks/Python.framework/Versions/3.12/lib/python3.12/site-packages/django/db/models/query.py", line 357, in _iterator
    yield from self._iterable_class(self, chunked_fetch=use_chunked_fetch, chunk_size=chunk_size)
  File "/Library/Frameworks/Python.framework/Versions/3.12/lib/python3.12/site-packages/django/db/models/query.py", line 51, in __iter__
    results = compiler.execute_sql(chunked_fetch=self.chunked_fetch, chunk_size=self.chunk_size)
              ^^^^^^^^^^^^^^^^^^^^^^^^^^^^^^^^^^^^^^^^^^^^^^^^^^^^^^^^^^^^^^^^^^^^^^^^^^^^^^^^^^
  File "/Library/Frameworks/Python.framework/Versions/3.12/lib/python3.12/site-packages/django/db/models/sql/compiler.py", line 1202, in execute_sql
    cursor.execute(sql, params)
  File "/Library/Frameworks/Python.framework/Versions/3.12/lib/python3.12/site-packages/django/db/backends/utils.py", line 99, in execute
    return super().execute(sql, params)
           ^^^^^^^^^^^^^^^^^^^^^^^^^^^^
  File "/Library/Frameworks/Python.framework/Versions/3.12/lib/python3.12/site-packages/django/db/backends/utils.py", line 67, in execute
    return self._execute_with_wrappers(sql, params, many=False, executor=self._execute)
           ^^^^^^^^^^^^^^^^^^^^^^^^^^^^^^^^^^^^^^^^^^^^^^^^^^^^^^^^^^^^^^^^^^^^^^^^^^^^
  File "/Library/Frameworks/Python.framework/Versions/3.12/lib/python3.12/site-packages/django/db/backends/utils.py", line 76, in _execute_with_wrappers
    return executor(sql, params, many, context)
           ^^^^^^^^^^^^^^^^^^^^^^^^^^^^^^^^^^^^
  File "/Library/Frameworks/Python.framework/Versions/3.12/lib/python3.12/site-packages/django/db/backends/utils.py", line 80, in _execute
    with self.db.wrap_database_errors:
  File "/Library/Frameworks/Python.framework/Versions/3.12/lib/python3.12/site-packages/django/db/utils.py", line 90, in __exit__
    raise dj_exc_value.with_traceback(traceback) from exc_value
  File "/Library/Frameworks/Python.framework/Versions/3.12/lib/python3.12/site-packages/django/db/backends/utils.py", line 85, in _execute
    return self.cursor.execute(sql, params)
           ^^^^^^^^^^^^^^^^^^^^^^^^^^^^^^^^
  File "/Library/Frameworks/Python.framework/Versions/3.12/lib/python3.12/site-packages/django/db/backends/sqlite3/base.py", line 416, in execute
    return Database.Cursor.execute(self, query, params)
           ^^^^^^^^^^^^^^^^^^^^^^^^^^^^^^^^^^^^^^^^^^^^
django.db.utils.OperationalError: no such table: workout_challenge
2024-06-09 16:10:03,389 - ERROR - Internal Server Error: /admin/workout/workout/3/change/: 
Traceback (most recent call last):
  File "/Library/Frameworks/Python.framework/Versions/3.12/lib/python3.12/site-packages/django/db/backends/utils.py", line 85, in _execute
    return self.cursor.execute(sql, params)
           ^^^^^^^^^^^^^^^^^^^^^^^^^^^^^^^^
  File "/Library/Frameworks/Python.framework/Versions/3.12/lib/python3.12/site-packages/django/db/backends/sqlite3/base.py", line 416, in execute
    return Database.Cursor.execute(self, query, params)
           ^^^^^^^^^^^^^^^^^^^^^^^^^^^^^^^^^^^^^^^^^^^^
sqlite3.OperationalError: no such table: workout_challenge

The above exception was the direct cause of the following exception:

Traceback (most recent call last):
  File "/Library/Frameworks/Python.framework/Versions/3.12/lib/python3.12/site-packages/django/core/handlers/exception.py", line 47, in inner
    response = get_response(request)
               ^^^^^^^^^^^^^^^^^^^^^
  File "/Library/Frameworks/Python.framework/Versions/3.12/lib/python3.12/site-packages/django/core/handlers/base.py", line 204, in _get_response
    response = response.render()
               ^^^^^^^^^^^^^^^^^
  File "/Library/Frameworks/Python.framework/Versions/3.12/lib/python3.12/site-packages/django/template/response.py", line 105, in render
    self.content = self.rendered_content
                   ^^^^^^^^^^^^^^^^^^^^^
  File "/Library/Frameworks/Python.framework/Versions/3.12/lib/python3.12/site-packages/django/template/response.py", line 83, in rendered_content
    return template.render(context, self._request)
           ^^^^^^^^^^^^^^^^^^^^^^^^^^^^^^^^^^^^^^^
  File "/Library/Frameworks/Python.framework/Versions/3.12/lib/python3.12/site-packages/django/template/backends/django.py", line 61, in render
    return self.template.render(context)
           ^^^^^^^^^^^^^^^^^^^^^^^^^^^^^
  File "/Library/Frameworks/Python.framework/Versions/3.12/lib/python3.12/site-packages/django/template/base.py", line 176, in render
    return self._render(context)
           ^^^^^^^^^^^^^^^^^^^^^
  File "/Library/Frameworks/Python.framework/Versions/3.12/lib/python3.12/site-packages/django/template/base.py", line 168, in _render
    return self.nodelist.render(context)
           ^^^^^^^^^^^^^^^^^^^^^^^^^^^^^
  File "/Library/Frameworks/Python.framework/Versions/3.12/lib/python3.12/site-packages/django/template/base.py", line 978, in render
    node.render_annotated(context) for node in self
    ^^^^^^^^^^^^^^^^^^^^^^^^^^^^^^
  File "/Library/Frameworks/Python.framework/Versions/3.12/lib/python3.12/site-packages/django/template/base.py", line 938, in render_annotated
    return self.render(context)
           ^^^^^^^^^^^^^^^^^^^^
  File "/Library/Frameworks/Python.framework/Versions/3.12/lib/python3.12/site-packages/django/template/loader_tags.py", line 153, in render
    return compiled_parent._render(context)
           ^^^^^^^^^^^^^^^^^^^^^^^^^^^^^^^^
  File "/Library/Frameworks/Python.framework/Versions/3.12/lib/python3.12/site-packages/django/template/base.py", line 168, in _render
    return self.nodelist.render(context)
           ^^^^^^^^^^^^^^^^^^^^^^^^^^^^^
  File "/Library/Frameworks/Python.framework/Versions/3.12/lib/python3.12/site-packages/django/template/base.py", line 978, in render
    node.render_annotated(context) for node in self
    ^^^^^^^^^^^^^^^^^^^^^^^^^^^^^^
  File "/Library/Frameworks/Python.framework/Versions/3.12/lib/python3.12/site-packages/django/template/base.py", line 938, in render_annotated
    return self.render(context)
           ^^^^^^^^^^^^^^^^^^^^
  File "/Library/Frameworks/Python.framework/Versions/3.12/lib/python3.12/site-packages/django/template/loader_tags.py", line 153, in render
    return compiled_parent._render(context)
           ^^^^^^^^^^^^^^^^^^^^^^^^^^^^^^^^
  File "/Library/Frameworks/Python.framework/Versions/3.12/lib/python3.12/site-packages/django/template/base.py", line 168, in _render
    return self.nodelist.render(context)
           ^^^^^^^^^^^^^^^^^^^^^^^^^^^^^
  File "/Library/Frameworks/Python.framework/Versions/3.12/lib/python3.12/site-packages/django/template/base.py", line 978, in render
    node.render_annotated(context) for node in self
    ^^^^^^^^^^^^^^^^^^^^^^^^^^^^^^
  File "/Library/Frameworks/Python.framework/Versions/3.12/lib/python3.12/site-packages/django/template/base.py", line 938, in render_annotated
    return self.render(context)
           ^^^^^^^^^^^^^^^^^^^^
  File "/Library/Frameworks/Python.framework/Versions/3.12/lib/python3.12/site-packages/django/template/loader_tags.py", line 65, in render
    result = block.nodelist.render(context)
             ^^^^^^^^^^^^^^^^^^^^^^^^^^^^^^
  File "/Library/Frameworks/Python.framework/Versions/3.12/lib/python3.12/site-packages/django/template/base.py", line 978, in render
    node.render_annotated(context) for node in self
    ^^^^^^^^^^^^^^^^^^^^^^^^^^^^^^
  File "/Library/Frameworks/Python.framework/Versions/3.12/lib/python3.12/site-packages/django/template/base.py", line 938, in render_annotated
    return self.render(context)
           ^^^^^^^^^^^^^^^^^^^^
  File "/Library/Frameworks/Python.framework/Versions/3.12/lib/python3.12/site-packages/django/template/loader_tags.py", line 65, in render
    result = block.nodelist.render(context)
             ^^^^^^^^^^^^^^^^^^^^^^^^^^^^^^
  File "/Library/Frameworks/Python.framework/Versions/3.12/lib/python3.12/site-packages/django/template/base.py", line 978, in render
    node.render_annotated(context) for node in self
    ^^^^^^^^^^^^^^^^^^^^^^^^^^^^^^
  File "/Library/Frameworks/Python.framework/Versions/3.12/lib/python3.12/site-packages/django/template/base.py", line 938, in render_annotated
    return self.render(context)
           ^^^^^^^^^^^^^^^^^^^^
  File "/Library/Frameworks/Python.framework/Versions/3.12/lib/python3.12/site-packages/django/template/defaulttags.py", line 214, in render
    nodelist.append(node.render_annotated(context))
                    ^^^^^^^^^^^^^^^^^^^^^^^^^^^^^^
  File "/Library/Frameworks/Python.framework/Versions/3.12/lib/python3.12/site-packages/django/template/base.py", line 938, in render_annotated
    return self.render(context)
           ^^^^^^^^^^^^^^^^^^^^
  File "/Library/Frameworks/Python.framework/Versions/3.12/lib/python3.12/site-packages/django/template/loader_tags.py", line 201, in render
    return template.render(context)
           ^^^^^^^^^^^^^^^^^^^^^^^^
  File "/Library/Frameworks/Python.framework/Versions/3.12/lib/python3.12/site-packages/django/template/base.py", line 178, in render
    return self._render(context)
           ^^^^^^^^^^^^^^^^^^^^^
  File "/Library/Frameworks/Python.framework/Versions/3.12/lib/python3.12/site-packages/django/template/base.py", line 168, in _render
    return self.nodelist.render(context)
           ^^^^^^^^^^^^^^^^^^^^^^^^^^^^^
  File "/Library/Frameworks/Python.framework/Versions/3.12/lib/python3.12/site-packages/django/template/base.py", line 978, in render
    node.render_annotated(context) for node in self
    ^^^^^^^^^^^^^^^^^^^^^^^^^^^^^^
  File "/Library/Frameworks/Python.framework/Versions/3.12/lib/python3.12/site-packages/django/template/base.py", line 938, in render_annotated
    return self.render(context)
           ^^^^^^^^^^^^^^^^^^^^
  File "/Library/Frameworks/Python.framework/Versions/3.12/lib/python3.12/site-packages/django/template/defaulttags.py", line 214, in render
    nodelist.append(node.render_annotated(context))
                    ^^^^^^^^^^^^^^^^^^^^^^^^^^^^^^
  File "/Library/Frameworks/Python.framework/Versions/3.12/lib/python3.12/site-packages/django/template/base.py", line 938, in render_annotated
    return self.render(context)
           ^^^^^^^^^^^^^^^^^^^^
  File "/Library/Frameworks/Python.framework/Versions/3.12/lib/python3.12/site-packages/django/template/defaulttags.py", line 214, in render
    nodelist.append(node.render_annotated(context))
                    ^^^^^^^^^^^^^^^^^^^^^^^^^^^^^^
  File "/Library/Frameworks/Python.framework/Versions/3.12/lib/python3.12/site-packages/django/template/base.py", line 938, in render_annotated
    return self.render(context)
           ^^^^^^^^^^^^^^^^^^^^
  File "/Library/Frameworks/Python.framework/Versions/3.12/lib/python3.12/site-packages/django/template/defaulttags.py", line 295, in render
    return nodelist.render(context)
           ^^^^^^^^^^^^^^^^^^^^^^^^
  File "/Library/Frameworks/Python.framework/Versions/3.12/lib/python3.12/site-packages/django/template/base.py", line 978, in render
    node.render_annotated(context) for node in self
    ^^^^^^^^^^^^^^^^^^^^^^^^^^^^^^
  File "/Library/Frameworks/Python.framework/Versions/3.12/lib/python3.12/site-packages/django/template/base.py", line 938, in render_annotated
    return self.render(context)
           ^^^^^^^^^^^^^^^^^^^^
  File "/Library/Frameworks/Python.framework/Versions/3.12/lib/python3.12/site-packages/django/template/defaulttags.py", line 295, in render
    return nodelist.render(context)
           ^^^^^^^^^^^^^^^^^^^^^^^^
  File "/Library/Frameworks/Python.framework/Versions/3.12/lib/python3.12/site-packages/django/template/base.py", line 978, in render
    node.render_annotated(context) for node in self
    ^^^^^^^^^^^^^^^^^^^^^^^^^^^^^^
  File "/Library/Frameworks/Python.framework/Versions/3.12/lib/python3.12/site-packages/django/template/base.py", line 938, in render_annotated
    return self.render(context)
           ^^^^^^^^^^^^^^^^^^^^
  File "/Library/Frameworks/Python.framework/Versions/3.12/lib/python3.12/site-packages/django/template/base.py", line 1044, in render
    return render_value_in_context(output, context)
           ^^^^^^^^^^^^^^^^^^^^^^^^^^^^^^^^^^^^^^^^
  File "/Library/Frameworks/Python.framework/Versions/3.12/lib/python3.12/site-packages/django/template/base.py", line 1021, in render_value_in_context
    value = str(value)
            ^^^^^^^^^^
  File "/Library/Frameworks/Python.framework/Versions/3.12/lib/python3.12/site-packages/django/utils/html.py", line 377, in <lambda>
    klass.__str__ = lambda self: mark_safe(klass_str(self))
                                           ^^^^^^^^^^^^^^^
  File "/Library/Frameworks/Python.framework/Versions/3.12/lib/python3.12/site-packages/django/forms/boundfield.py", line 33, in __str__
    return self.as_widget()
           ^^^^^^^^^^^^^^^^
  File "/Library/Frameworks/Python.framework/Versions/3.12/lib/python3.12/site-packages/django/forms/boundfield.py", line 92, in as_widget
    return widget.render(
           ^^^^^^^^^^^^^^
  File "/Library/Frameworks/Python.framework/Versions/3.12/lib/python3.12/site-packages/django/forms/widgets.py", line 246, in render
    context = self.get_context(name, value, attrs)
              ^^^^^^^^^^^^^^^^^^^^^^^^^^^^^^^^^^^^
  File "/Library/Frameworks/Python.framework/Versions/3.12/lib/python3.12/site-packages/django/contrib/admin/widgets.py", line 283, in get_context
    'rendered_widget': self.widget.render(name, value, attrs),
                       ^^^^^^^^^^^^^^^^^^^^^^^^^^^^^^^^^^^^^^
  File "/Library/Frameworks/Python.framework/Versions/3.12/lib/python3.12/site-packages/django/forms/widgets.py", line 246, in render
    context = self.get_context(name, value, attrs)
              ^^^^^^^^^^^^^^^^^^^^^^^^^^^^^^^^^^^^
  File "/Library/Frameworks/Python.framework/Versions/3.12/lib/python3.12/site-packages/django/forms/widgets.py", line 681, in get_context
    context = super().get_context(name, value, attrs)
              ^^^^^^^^^^^^^^^^^^^^^^^^^^^^^^^^^^^^^^^
  File "/Library/Frameworks/Python.framework/Versions/3.12/lib/python3.12/site-packages/django/forms/widgets.py", line 642, in get_context
    context['widget']['optgroups'] = self.optgroups(name, context['widget']['value'], attrs)
                                     ^^^^^^^^^^^^^^^^^^^^^^^^^^^^^^^^^^^^^^^^^^^^^^^^^^^^^^^
  File "/Library/Frameworks/Python.framework/Versions/3.12/lib/python3.12/site-packages/django/forms/widgets.py", line 592, in optgroups
    for index, (option_value, option_label) in enumerate(self.choices):
  File "/Library/Frameworks/Python.framework/Versions/3.12/lib/python3.12/site-packages/django/forms/models.py", line 1190, in __iter__
    for obj in queryset:
  File "/Library/Frameworks/Python.framework/Versions/3.12/lib/python3.12/site-packages/django/db/models/query.py", line 357, in _iterator
    yield from self._iterable_class(self, chunked_fetch=use_chunked_fetch, chunk_size=chunk_size)
  File "/Library/Frameworks/Python.framework/Versions/3.12/lib/python3.12/site-packages/django/db/models/query.py", line 51, in __iter__
    results = compiler.execute_sql(chunked_fetch=self.chunked_fetch, chunk_size=self.chunk_size)
              ^^^^^^^^^^^^^^^^^^^^^^^^^^^^^^^^^^^^^^^^^^^^^^^^^^^^^^^^^^^^^^^^^^^^^^^^^^^^^^^^^^
  File "/Library/Frameworks/Python.framework/Versions/3.12/lib/python3.12/site-packages/django/db/models/sql/compiler.py", line 1202, in execute_sql
    cursor.execute(sql, params)
  File "/Library/Frameworks/Python.framework/Versions/3.12/lib/python3.12/site-packages/django/db/backends/utils.py", line 99, in execute
    return super().execute(sql, params)
           ^^^^^^^^^^^^^^^^^^^^^^^^^^^^
  File "/Library/Frameworks/Python.framework/Versions/3.12/lib/python3.12/site-packages/django/db/backends/utils.py", line 67, in execute
    return self._execute_with_wrappers(sql, params, many=False, executor=self._execute)
           ^^^^^^^^^^^^^^^^^^^^^^^^^^^^^^^^^^^^^^^^^^^^^^^^^^^^^^^^^^^^^^^^^^^^^^^^^^^^
  File "/Library/Frameworks/Python.framework/Versions/3.12/lib/python3.12/site-packages/django/db/backends/utils.py", line 76, in _execute_with_wrappers
    return executor(sql, params, many, context)
           ^^^^^^^^^^^^^^^^^^^^^^^^^^^^^^^^^^^^
  File "/Library/Frameworks/Python.framework/Versions/3.12/lib/python3.12/site-packages/django/db/backends/utils.py", line 80, in _execute
    with self.db.wrap_database_errors:
  File "/Library/Frameworks/Python.framework/Versions/3.12/lib/python3.12/site-packages/django/db/utils.py", line 90, in __exit__
    raise dj_exc_value.with_traceback(traceback) from exc_value
  File "/Library/Frameworks/Python.framework/Versions/3.12/lib/python3.12/site-packages/django/db/backends/utils.py", line 85, in _execute
    return self.cursor.execute(sql, params)
           ^^^^^^^^^^^^^^^^^^^^^^^^^^^^^^^^
  File "/Library/Frameworks/Python.framework/Versions/3.12/lib/python3.12/site-packages/django/db/backends/sqlite3/base.py", line 416, in execute
    return Database.Cursor.execute(self, query, params)
           ^^^^^^^^^^^^^^^^^^^^^^^^^^^^^^^^^^^^^^^^^^^^
django.db.utils.OperationalError: no such table: workout_challenge
2024-06-09 16:17:00,337 - INFO - /Users/janrydzewski/Developer/Studies/Django/workout_logger/workout/models.py changed, reloading.: 
2024-06-09 16:17:05,097 - INFO - /Users/janrydzewski/Developer/Studies/Django/workout_logger/workout/models.py changed, reloading.: 
2024-06-09 16:18:12,953 - DEBUG - GET request to login: 
2024-06-09 16:18:19,215 - DEBUG - POST request to login: 
2024-06-09 16:18:32,719 - DEBUG - GET request to login: 
2024-06-09 16:19:05,957 - INFO - /Users/janrydzewski/Developer/Studies/Django/workout_logger/workout/views.py changed, reloading.: 
2024-06-09 16:19:09,372 - INFO - /Users/janrydzewski/Developer/Studies/Django/workout_logger/workout/views.py changed, reloading.: 
2024-06-09 16:19:14,939 - INFO - /Users/janrydzewski/Developer/Studies/Django/workout_logger/workout/views.py changed, reloading.: 
2024-06-09 16:19:17,225 - INFO - /Users/janrydzewski/Developer/Studies/Django/workout_logger/workout/views.py changed, reloading.: 
2024-06-09 16:19:33,743 - INFO - /Users/janrydzewski/Developer/Studies/Django/workout_logger/workout/views.py changed, reloading.: 
2024-06-09 16:19:44,240 - INFO - /Users/janrydzewski/Developer/Studies/Django/workout_logger/workout/models.py changed, reloading.: 
2024-06-09 16:19:55,572 - DEBUG - GET request to login: 
2024-06-09 16:20:00,397 - ERROR - Internal Server Error: /challenge/7/join: 
Traceback (most recent call last):
  File "/Library/Frameworks/Python.framework/Versions/3.12/lib/python3.12/site-packages/django/db/models/query.py", line 588, in get_or_create
    return self.get(**kwargs), False
           ^^^^^^^^^^^^^^^^^^
  File "/Library/Frameworks/Python.framework/Versions/3.12/lib/python3.12/site-packages/django/db/models/query.py", line 439, in get
    raise self.model.DoesNotExist(
workout.models.UserChallenge.DoesNotExist: UserChallenge matching query does not exist.

During handling of the above exception, another exception occurred:

Traceback (most recent call last):
  File "/Library/Frameworks/Python.framework/Versions/3.12/lib/python3.12/site-packages/django/db/backends/utils.py", line 85, in _execute
    return self.cursor.execute(sql, params)
           ^^^^^^^^^^^^^^^^^^^^^^^^^^^^^^^^
  File "/Library/Frameworks/Python.framework/Versions/3.12/lib/python3.12/site-packages/django/db/backends/sqlite3/base.py", line 416, in execute
    return Database.Cursor.execute(self, query, params)
           ^^^^^^^^^^^^^^^^^^^^^^^^^^^^^^^^^^^^^^^^^^^^
sqlite3.IntegrityError: UNIQUE constraint failed: workout_userchallenge.user_id, workout_userchallenge.challenge_id

The above exception was the direct cause of the following exception:

Traceback (most recent call last):
  File "/Library/Frameworks/Python.framework/Versions/3.12/lib/python3.12/site-packages/django/core/handlers/exception.py", line 47, in inner
    response = get_response(request)
               ^^^^^^^^^^^^^^^^^^^^^
  File "/Library/Frameworks/Python.framework/Versions/3.12/lib/python3.12/site-packages/django/core/handlers/base.py", line 181, in _get_response
    response = wrapped_callback(request, *callback_args, **callback_kwargs)
               ^^^^^^^^^^^^^^^^^^^^^^^^^^^^^^^^^^^^^^^^^^^^^^^^^^^^^^^^^^^^
  File "/Users/janrydzewski/Developer/Studies/Django/workout_logger/workout/views.py", line 254, in join_challenge
    user_challenge, created = UserChallenge.objects.get_or_create(user=user, challenge=challenge, workout=workout)
                              ^^^^^^^^^^^^^^^^^^^^^^^^^^^^^^^^^^^^^^^^^^^^^^^^^^^^^^^^^^^^^^^^^^^^^^^^^^^^^^^^^^^^
  File "/Library/Frameworks/Python.framework/Versions/3.12/lib/python3.12/site-packages/django/db/models/manager.py", line 85, in manager_method
    return getattr(self.get_queryset(), name)(*args, **kwargs)
           ^^^^^^^^^^^^^^^^^^^^^^^^^^^^^^^^^^^^^^^^^^^^^^^^^^^
  File "/Library/Frameworks/Python.framework/Versions/3.12/lib/python3.12/site-packages/django/db/models/query.py", line 595, in get_or_create
    return self.create(**params), True
           ^^^^^^^^^^^^^^^^^^^^^
  File "/Library/Frameworks/Python.framework/Versions/3.12/lib/python3.12/site-packages/django/db/models/query.py", line 457, in create
    obj.save(force_insert=True, using=self.db)
  File "/Library/Frameworks/Python.framework/Versions/3.12/lib/python3.12/site-packages/django/db/models/base.py", line 743, in save
    self.save_base(using=using, force_insert=force_insert,
  File "/Library/Frameworks/Python.framework/Versions/3.12/lib/python3.12/site-packages/django/db/models/base.py", line 780, in save_base
    updated = self._save_table(
              ^^^^^^^^^^^^^^^^^
  File "/Library/Frameworks/Python.framework/Versions/3.12/lib/python3.12/site-packages/django/db/models/base.py", line 885, in _save_table
    results = self._do_insert(cls._base_manager, using, fields, returning_fields, raw)
              ^^^^^^^^^^^^^^^^^^^^^^^^^^^^^^^^^^^^^^^^^^^^^^^^^^^^^^^^^^^^^^^^^^^^^^^^
  File "/Library/Frameworks/Python.framework/Versions/3.12/lib/python3.12/site-packages/django/db/models/base.py", line 923, in _do_insert
    return manager._insert(
           ^^^^^^^^^^^^^^^^
  File "/Library/Frameworks/Python.framework/Versions/3.12/lib/python3.12/site-packages/django/db/models/manager.py", line 85, in manager_method
    return getattr(self.get_queryset(), name)(*args, **kwargs)
           ^^^^^^^^^^^^^^^^^^^^^^^^^^^^^^^^^^^^^^^^^^^^^^^^^^^
  File "/Library/Frameworks/Python.framework/Versions/3.12/lib/python3.12/site-packages/django/db/models/query.py", line 1301, in _insert
    return query.get_compiler(using=using).execute_sql(returning_fields)
           ^^^^^^^^^^^^^^^^^^^^^^^^^^^^^^^^^^^^^^^^^^^^^^^^^^^^^^^^^^^^^
  File "/Library/Frameworks/Python.framework/Versions/3.12/lib/python3.12/site-packages/django/db/models/sql/compiler.py", line 1441, in execute_sql
    cursor.execute(sql, params)
  File "/Library/Frameworks/Python.framework/Versions/3.12/lib/python3.12/site-packages/django/db/backends/utils.py", line 99, in execute
    return super().execute(sql, params)
           ^^^^^^^^^^^^^^^^^^^^^^^^^^^^
  File "/Library/Frameworks/Python.framework/Versions/3.12/lib/python3.12/site-packages/django/db/backends/utils.py", line 67, in execute
    return self._execute_with_wrappers(sql, params, many=False, executor=self._execute)
           ^^^^^^^^^^^^^^^^^^^^^^^^^^^^^^^^^^^^^^^^^^^^^^^^^^^^^^^^^^^^^^^^^^^^^^^^^^^^
  File "/Library/Frameworks/Python.framework/Versions/3.12/lib/python3.12/site-packages/django/db/backends/utils.py", line 76, in _execute_with_wrappers
    return executor(sql, params, many, context)
           ^^^^^^^^^^^^^^^^^^^^^^^^^^^^^^^^^^^^
  File "/Library/Frameworks/Python.framework/Versions/3.12/lib/python3.12/site-packages/django/db/backends/utils.py", line 80, in _execute
    with self.db.wrap_database_errors:
  File "/Library/Frameworks/Python.framework/Versions/3.12/lib/python3.12/site-packages/django/db/utils.py", line 90, in __exit__
    raise dj_exc_value.with_traceback(traceback) from exc_value
  File "/Library/Frameworks/Python.framework/Versions/3.12/lib/python3.12/site-packages/django/db/backends/utils.py", line 85, in _execute
    return self.cursor.execute(sql, params)
           ^^^^^^^^^^^^^^^^^^^^^^^^^^^^^^^^
  File "/Library/Frameworks/Python.framework/Versions/3.12/lib/python3.12/site-packages/django/db/backends/sqlite3/base.py", line 416, in execute
    return Database.Cursor.execute(self, query, params)
           ^^^^^^^^^^^^^^^^^^^^^^^^^^^^^^^^^^^^^^^^^^^^
django.db.utils.IntegrityError: UNIQUE constraint failed: workout_userchallenge.user_id, workout_userchallenge.challenge_id
2024-06-09 16:21:12,669 - INFO - /Users/janrydzewski/Developer/Studies/Django/workout_logger/workout/models.py changed, reloading.: 
2024-06-09 16:21:26,185 - INFO - /Users/janrydzewski/Developer/Studies/Django/workout_logger/workout/views.py changed, reloading.: 
2024-06-09 16:21:27,532 - INFO - /Users/janrydzewski/Developer/Studies/Django/workout_logger/workout/views.py changed, reloading.: 
2024-06-09 16:21:29,522 - ERROR - Internal Server Error: /challenge/7/join: 
Traceback (most recent call last):
  File "/Library/Frameworks/Python.framework/Versions/3.12/lib/python3.12/site-packages/django/db/models/query.py", line 588, in get_or_create
    return self.get(**kwargs), False
           ^^^^^^^^^^^^^^^^^^
  File "/Library/Frameworks/Python.framework/Versions/3.12/lib/python3.12/site-packages/django/db/models/query.py", line 439, in get
    raise self.model.DoesNotExist(
workout.models.UserChallenge.DoesNotExist: UserChallenge matching query does not exist.

During handling of the above exception, another exception occurred:

Traceback (most recent call last):
  File "/Library/Frameworks/Python.framework/Versions/3.12/lib/python3.12/site-packages/django/db/backends/utils.py", line 85, in _execute
    return self.cursor.execute(sql, params)
           ^^^^^^^^^^^^^^^^^^^^^^^^^^^^^^^^
  File "/Library/Frameworks/Python.framework/Versions/3.12/lib/python3.12/site-packages/django/db/backends/sqlite3/base.py", line 416, in execute
    return Database.Cursor.execute(self, query, params)
           ^^^^^^^^^^^^^^^^^^^^^^^^^^^^^^^^^^^^^^^^^^^^
sqlite3.IntegrityError: UNIQUE constraint failed: workout_userchallenge.user_id, workout_userchallenge.challenge_id

The above exception was the direct cause of the following exception:

Traceback (most recent call last):
  File "/Library/Frameworks/Python.framework/Versions/3.12/lib/python3.12/site-packages/django/core/handlers/exception.py", line 47, in inner
    response = get_response(request)
               ^^^^^^^^^^^^^^^^^^^^^
  File "/Library/Frameworks/Python.framework/Versions/3.12/lib/python3.12/site-packages/django/core/handlers/base.py", line 181, in _get_response
    response = wrapped_callback(request, *callback_args, **callback_kwargs)
               ^^^^^^^^^^^^^^^^^^^^^^^^^^^^^^^^^^^^^^^^^^^^^^^^^^^^^^^^^^^^
  File "/Users/janrydzewski/Developer/Studies/Django/workout_logger/workout/views.py", line 255, in join_challenge
    user_challenge, created = UserChallenge.objects.get_or_create(user=user, challenge=challenge, workout=workout)
                              ^^^^^^^^^^^^^^^^^^^^^^^^^^^^^^^^^^^^^^^^^^^^^^^^^^^^^^^^^^^^^^^^^^^^^^^^^^^^^^^^^^^^
  File "/Library/Frameworks/Python.framework/Versions/3.12/lib/python3.12/site-packages/django/db/models/manager.py", line 85, in manager_method
    return getattr(self.get_queryset(), name)(*args, **kwargs)
           ^^^^^^^^^^^^^^^^^^^^^^^^^^^^^^^^^^^^^^^^^^^^^^^^^^^
  File "/Library/Frameworks/Python.framework/Versions/3.12/lib/python3.12/site-packages/django/db/models/query.py", line 595, in get_or_create
    return self.create(**params), True
           ^^^^^^^^^^^^^^^^^^^^^
  File "/Library/Frameworks/Python.framework/Versions/3.12/lib/python3.12/site-packages/django/db/models/query.py", line 457, in create
    obj.save(force_insert=True, using=self.db)
  File "/Library/Frameworks/Python.framework/Versions/3.12/lib/python3.12/site-packages/django/db/models/base.py", line 743, in save
    self.save_base(using=using, force_insert=force_insert,
  File "/Library/Frameworks/Python.framework/Versions/3.12/lib/python3.12/site-packages/django/db/models/base.py", line 780, in save_base
    updated = self._save_table(
              ^^^^^^^^^^^^^^^^^
  File "/Library/Frameworks/Python.framework/Versions/3.12/lib/python3.12/site-packages/django/db/models/base.py", line 885, in _save_table
    results = self._do_insert(cls._base_manager, using, fields, returning_fields, raw)
              ^^^^^^^^^^^^^^^^^^^^^^^^^^^^^^^^^^^^^^^^^^^^^^^^^^^^^^^^^^^^^^^^^^^^^^^^
  File "/Library/Frameworks/Python.framework/Versions/3.12/lib/python3.12/site-packages/django/db/models/base.py", line 923, in _do_insert
    return manager._insert(
           ^^^^^^^^^^^^^^^^
  File "/Library/Frameworks/Python.framework/Versions/3.12/lib/python3.12/site-packages/django/db/models/manager.py", line 85, in manager_method
    return getattr(self.get_queryset(), name)(*args, **kwargs)
           ^^^^^^^^^^^^^^^^^^^^^^^^^^^^^^^^^^^^^^^^^^^^^^^^^^^
  File "/Library/Frameworks/Python.framework/Versions/3.12/lib/python3.12/site-packages/django/db/models/query.py", line 1301, in _insert
    return query.get_compiler(using=using).execute_sql(returning_fields)
           ^^^^^^^^^^^^^^^^^^^^^^^^^^^^^^^^^^^^^^^^^^^^^^^^^^^^^^^^^^^^^
  File "/Library/Frameworks/Python.framework/Versions/3.12/lib/python3.12/site-packages/django/db/models/sql/compiler.py", line 1441, in execute_sql
    cursor.execute(sql, params)
  File "/Library/Frameworks/Python.framework/Versions/3.12/lib/python3.12/site-packages/django/db/backends/utils.py", line 99, in execute
    return super().execute(sql, params)
           ^^^^^^^^^^^^^^^^^^^^^^^^^^^^
  File "/Library/Frameworks/Python.framework/Versions/3.12/lib/python3.12/site-packages/django/db/backends/utils.py", line 67, in execute
    return self._execute_with_wrappers(sql, params, many=False, executor=self._execute)
           ^^^^^^^^^^^^^^^^^^^^^^^^^^^^^^^^^^^^^^^^^^^^^^^^^^^^^^^^^^^^^^^^^^^^^^^^^^^^
  File "/Library/Frameworks/Python.framework/Versions/3.12/lib/python3.12/site-packages/django/db/backends/utils.py", line 76, in _execute_with_wrappers
    return executor(sql, params, many, context)
           ^^^^^^^^^^^^^^^^^^^^^^^^^^^^^^^^^^^^
  File "/Library/Frameworks/Python.framework/Versions/3.12/lib/python3.12/site-packages/django/db/backends/utils.py", line 80, in _execute
    with self.db.wrap_database_errors:
  File "/Library/Frameworks/Python.framework/Versions/3.12/lib/python3.12/site-packages/django/db/utils.py", line 90, in __exit__
    raise dj_exc_value.with_traceback(traceback) from exc_value
  File "/Library/Frameworks/Python.framework/Versions/3.12/lib/python3.12/site-packages/django/db/backends/utils.py", line 85, in _execute
    return self.cursor.execute(sql, params)
           ^^^^^^^^^^^^^^^^^^^^^^^^^^^^^^^^
  File "/Library/Frameworks/Python.framework/Versions/3.12/lib/python3.12/site-packages/django/db/backends/sqlite3/base.py", line 416, in execute
    return Database.Cursor.execute(self, query, params)
           ^^^^^^^^^^^^^^^^^^^^^^^^^^^^^^^^^^^^^^^^^^^^
django.db.utils.IntegrityError: UNIQUE constraint failed: workout_userchallenge.user_id, workout_userchallenge.challenge_id
2024-06-09 16:26:17,655 - WARNING - Not Found: /challenge/: 
