2024-06-15 09:59:01,684 - INFO - /Users/janrydzewski/Developer/Studies/Django/workout_logger/workout/models.py changed, reloading.: 
2024-06-15 09:59:10,819 - DEBUG - GET request to new workout: 
2024-06-15 09:59:34,634 - DEBUG - GET request to edit workout: 
2024-06-15 10:01:04,448 - INFO - /Users/janrydzewski/Developer/Studies/Django/workout_logger/workout/urls.py changed, reloading.: 
2024-06-15 10:01:21,400 - ERROR - Internal Server Error: /challenge/: 
Traceback (most recent call last):
  File "/Library/Frameworks/Python.framework/Versions/3.12/lib/python3.12/site-packages/django/db/models/fields/__init__.py", line 1822, in get_prep_value
    return int(value)
           ^^^^^^^^^^
ValueError: invalid literal for int() with base 10: ''

The above exception was the direct cause of the following exception:

Traceback (most recent call last):
  File "/Library/Frameworks/Python.framework/Versions/3.12/lib/python3.12/site-packages/django/core/handlers/exception.py", line 47, in inner
    response = get_response(request)
               ^^^^^^^^^^^^^^^^^^^^^
  File "/Library/Frameworks/Python.framework/Versions/3.12/lib/python3.12/site-packages/django/core/handlers/base.py", line 181, in _get_response
    response = wrapped_callback(request, *callback_args, **callback_kwargs)
               ^^^^^^^^^^^^^^^^^^^^^^^^^^^^^^^^^^^^^^^^^^^^^^^^^^^^^^^^^^^^
  File "/Users/janrydzewski/Developer/Studies/Django/workout_logger/workout/views.py", line 648, in workout
    workout = Workout.objects.get(id=id)
              ^^^^^^^^^^^^^^^^^^^^^^^^^^
  File "/Library/Frameworks/Python.framework/Versions/3.12/lib/python3.12/site-packages/django/db/models/manager.py", line 85, in manager_method
    return getattr(self.get_queryset(), name)(*args, **kwargs)
           ^^^^^^^^^^^^^^^^^^^^^^^^^^^^^^^^^^^^^^^^^^^^^^^^^^^
  File "/Library/Frameworks/Python.framework/Versions/3.12/lib/python3.12/site-packages/django/db/models/query.py", line 428, in get
    clone = self._chain() if self.query.combinator else self.filter(*args, **kwargs)
                                                        ^^^^^^^^^^^^^^^^^^^^^^^^^^^^
  File "/Library/Frameworks/Python.framework/Versions/3.12/lib/python3.12/site-packages/django/db/models/query.py", line 974, in filter
    return self._filter_or_exclude(False, args, kwargs)
           ^^^^^^^^^^^^^^^^^^^^^^^^^^^^^^^^^^^^^^^^^^^^
  File "/Library/Frameworks/Python.framework/Versions/3.12/lib/python3.12/site-packages/django/db/models/query.py", line 992, in _filter_or_exclude
    clone._filter_or_exclude_inplace(negate, args, kwargs)
  File "/Library/Frameworks/Python.framework/Versions/3.12/lib/python3.12/site-packages/django/db/models/query.py", line 999, in _filter_or_exclude_inplace
    self._query.add_q(Q(*args, **kwargs))
  File "/Library/Frameworks/Python.framework/Versions/3.12/lib/python3.12/site-packages/django/db/models/sql/query.py", line 1375, in add_q
    clause, _ = self._add_q(q_object, self.used_aliases)
                ^^^^^^^^^^^^^^^^^^^^^^^^^^^^^^^^^^^^^^^^
  File "/Library/Frameworks/Python.framework/Versions/3.12/lib/python3.12/site-packages/django/db/models/sql/query.py", line 1396, in _add_q
    child_clause, needed_inner = self.build_filter(
                                 ^^^^^^^^^^^^^^^^^^
  File "/Library/Frameworks/Python.framework/Versions/3.12/lib/python3.12/site-packages/django/db/models/sql/query.py", line 1329, in build_filter
    condition = self.build_lookup(lookups, col, value)
                ^^^^^^^^^^^^^^^^^^^^^^^^^^^^^^^^^^^^^^
  File "/Library/Frameworks/Python.framework/Versions/3.12/lib/python3.12/site-packages/django/db/models/sql/query.py", line 1180, in build_lookup
    lookup = lookup_class(lhs, rhs)
             ^^^^^^^^^^^^^^^^^^^^^^
  File "/Library/Frameworks/Python.framework/Versions/3.12/lib/python3.12/site-packages/django/db/models/lookups.py", line 22, in __init__
    self.rhs = self.get_prep_lookup()
               ^^^^^^^^^^^^^^^^^^^^^^
  File "/Library/Frameworks/Python.framework/Versions/3.12/lib/python3.12/site-packages/django/db/models/lookups.py", line 79, in get_prep_lookup
    return self.lhs.output_field.get_prep_value(self.rhs)
           ^^^^^^^^^^^^^^^^^^^^^^^^^^^^^^^^^^^^^^^^^^^^^^
  File "/Library/Frameworks/Python.framework/Versions/3.12/lib/python3.12/site-packages/django/db/models/fields/__init__.py", line 1824, in get_prep_value
    raise e.__class__(
ValueError: Field 'id' expected a number but got ''.
2024-06-15 10:01:41,266 - ERROR - Internal Server Error: /challenge/1: 
Traceback (most recent call last):
  File "/Library/Frameworks/Python.framework/Versions/3.12/lib/python3.12/site-packages/django/core/handlers/exception.py", line 47, in inner
    response = get_response(request)
               ^^^^^^^^^^^^^^^^^^^^^
  File "/Library/Frameworks/Python.framework/Versions/3.12/lib/python3.12/site-packages/django/core/handlers/base.py", line 181, in _get_response
    response = wrapped_callback(request, *callback_args, **callback_kwargs)
               ^^^^^^^^^^^^^^^^^^^^^^^^^^^^^^^^^^^^^^^^^^^^^^^^^^^^^^^^^^^^
  File "/Users/janrydzewski/Developer/Studies/Django/workout_logger/workout/views.py", line 648, in workout
    workout = Workout.objects.get(id=id)
              ^^^^^^^^^^^^^^^^^^^^^^^^^^
  File "/Library/Frameworks/Python.framework/Versions/3.12/lib/python3.12/site-packages/django/db/models/manager.py", line 85, in manager_method
    return getattr(self.get_queryset(), name)(*args, **kwargs)
           ^^^^^^^^^^^^^^^^^^^^^^^^^^^^^^^^^^^^^^^^^^^^^^^^^^^
  File "/Library/Frameworks/Python.framework/Versions/3.12/lib/python3.12/site-packages/django/db/models/query.py", line 439, in get
    raise self.model.DoesNotExist(
workout.models.Workout.DoesNotExist: Workout matching query does not exist.
2024-06-15 10:02:11,988 - DEBUG - GET request to login: 
2024-06-15 10:02:24,900 - INFO - User has been logged out.: 
2024-06-15 10:02:24,910 - DEBUG - GET request to login: 
2024-06-15 10:02:27,896 - WARNING - User must be logged in to view 'dashboard'.: 
2024-06-15 10:02:27,904 - DEBUG - GET request to login: 
2024-06-15 10:02:33,768 - DEBUG - POST request to login: 
2024-06-15 10:03:52,995 - ERROR - Internal Server Error: /challenge/: 
Traceback (most recent call last):
  File "/Library/Frameworks/Python.framework/Versions/3.12/lib/python3.12/site-packages/django/db/models/fields/__init__.py", line 1822, in get_prep_value
    return int(value)
           ^^^^^^^^^^
ValueError: invalid literal for int() with base 10: ''

The above exception was the direct cause of the following exception:

Traceback (most recent call last):
  File "/Library/Frameworks/Python.framework/Versions/3.12/lib/python3.12/site-packages/django/core/handlers/exception.py", line 47, in inner
    response = get_response(request)
               ^^^^^^^^^^^^^^^^^^^^^
  File "/Library/Frameworks/Python.framework/Versions/3.12/lib/python3.12/site-packages/django/core/handlers/base.py", line 181, in _get_response
    response = wrapped_callback(request, *callback_args, **callback_kwargs)
               ^^^^^^^^^^^^^^^^^^^^^^^^^^^^^^^^^^^^^^^^^^^^^^^^^^^^^^^^^^^^
  File "/Users/janrydzewski/Developer/Studies/Django/workout_logger/workout/views.py", line 648, in workout
    workout = Workout.objects.get(id=id)
              ^^^^^^^^^^^^^^^^^^^^^^^^^^
  File "/Library/Frameworks/Python.framework/Versions/3.12/lib/python3.12/site-packages/django/db/models/manager.py", line 85, in manager_method
    return getattr(self.get_queryset(), name)(*args, **kwargs)
           ^^^^^^^^^^^^^^^^^^^^^^^^^^^^^^^^^^^^^^^^^^^^^^^^^^^
  File "/Library/Frameworks/Python.framework/Versions/3.12/lib/python3.12/site-packages/django/db/models/query.py", line 428, in get
    clone = self._chain() if self.query.combinator else self.filter(*args, **kwargs)
                                                        ^^^^^^^^^^^^^^^^^^^^^^^^^^^^
  File "/Library/Frameworks/Python.framework/Versions/3.12/lib/python3.12/site-packages/django/db/models/query.py", line 974, in filter
    return self._filter_or_exclude(False, args, kwargs)
           ^^^^^^^^^^^^^^^^^^^^^^^^^^^^^^^^^^^^^^^^^^^^
  File "/Library/Frameworks/Python.framework/Versions/3.12/lib/python3.12/site-packages/django/db/models/query.py", line 992, in _filter_or_exclude
    clone._filter_or_exclude_inplace(negate, args, kwargs)
  File "/Library/Frameworks/Python.framework/Versions/3.12/lib/python3.12/site-packages/django/db/models/query.py", line 999, in _filter_or_exclude_inplace
    self._query.add_q(Q(*args, **kwargs))
  File "/Library/Frameworks/Python.framework/Versions/3.12/lib/python3.12/site-packages/django/db/models/sql/query.py", line 1375, in add_q
    clause, _ = self._add_q(q_object, self.used_aliases)
                ^^^^^^^^^^^^^^^^^^^^^^^^^^^^^^^^^^^^^^^^
  File "/Library/Frameworks/Python.framework/Versions/3.12/lib/python3.12/site-packages/django/db/models/sql/query.py", line 1396, in _add_q
    child_clause, needed_inner = self.build_filter(
                                 ^^^^^^^^^^^^^^^^^^
  File "/Library/Frameworks/Python.framework/Versions/3.12/lib/python3.12/site-packages/django/db/models/sql/query.py", line 1329, in build_filter
    condition = self.build_lookup(lookups, col, value)
                ^^^^^^^^^^^^^^^^^^^^^^^^^^^^^^^^^^^^^^
  File "/Library/Frameworks/Python.framework/Versions/3.12/lib/python3.12/site-packages/django/db/models/sql/query.py", line 1180, in build_lookup
    lookup = lookup_class(lhs, rhs)
             ^^^^^^^^^^^^^^^^^^^^^^
  File "/Library/Frameworks/Python.framework/Versions/3.12/lib/python3.12/site-packages/django/db/models/lookups.py", line 22, in __init__
    self.rhs = self.get_prep_lookup()
               ^^^^^^^^^^^^^^^^^^^^^^
  File "/Library/Frameworks/Python.framework/Versions/3.12/lib/python3.12/site-packages/django/db/models/lookups.py", line 79, in get_prep_lookup
    return self.lhs.output_field.get_prep_value(self.rhs)
           ^^^^^^^^^^^^^^^^^^^^^^^^^^^^^^^^^^^^^^^^^^^^^^
  File "/Library/Frameworks/Python.framework/Versions/3.12/lib/python3.12/site-packages/django/db/models/fields/__init__.py", line 1824, in get_prep_value
    raise e.__class__(
ValueError: Field 'id' expected a number but got ''.
2024-06-15 10:04:19,611 - ERROR - Internal Server Error: /challenge/: 
Traceback (most recent call last):
  File "/Library/Frameworks/Python.framework/Versions/3.12/lib/python3.12/site-packages/django/db/models/fields/__init__.py", line 1822, in get_prep_value
    return int(value)
           ^^^^^^^^^^
ValueError: invalid literal for int() with base 10: ''

The above exception was the direct cause of the following exception:

Traceback (most recent call last):
  File "/Library/Frameworks/Python.framework/Versions/3.12/lib/python3.12/site-packages/django/core/handlers/exception.py", line 47, in inner
    response = get_response(request)
               ^^^^^^^^^^^^^^^^^^^^^
  File "/Library/Frameworks/Python.framework/Versions/3.12/lib/python3.12/site-packages/django/core/handlers/base.py", line 181, in _get_response
    response = wrapped_callback(request, *callback_args, **callback_kwargs)
               ^^^^^^^^^^^^^^^^^^^^^^^^^^^^^^^^^^^^^^^^^^^^^^^^^^^^^^^^^^^^
  File "/Users/janrydzewski/Developer/Studies/Django/workout_logger/workout/views.py", line 648, in workout
    workout = Workout.objects.get(id=id)
              ^^^^^^^^^^^^^^^^^^^^^^^^^^
  File "/Library/Frameworks/Python.framework/Versions/3.12/lib/python3.12/site-packages/django/db/models/manager.py", line 85, in manager_method
    return getattr(self.get_queryset(), name)(*args, **kwargs)
           ^^^^^^^^^^^^^^^^^^^^^^^^^^^^^^^^^^^^^^^^^^^^^^^^^^^
  File "/Library/Frameworks/Python.framework/Versions/3.12/lib/python3.12/site-packages/django/db/models/query.py", line 428, in get
    clone = self._chain() if self.query.combinator else self.filter(*args, **kwargs)
                                                        ^^^^^^^^^^^^^^^^^^^^^^^^^^^^
  File "/Library/Frameworks/Python.framework/Versions/3.12/lib/python3.12/site-packages/django/db/models/query.py", line 974, in filter
    return self._filter_or_exclude(False, args, kwargs)
           ^^^^^^^^^^^^^^^^^^^^^^^^^^^^^^^^^^^^^^^^^^^^
  File "/Library/Frameworks/Python.framework/Versions/3.12/lib/python3.12/site-packages/django/db/models/query.py", line 992, in _filter_or_exclude
    clone._filter_or_exclude_inplace(negate, args, kwargs)
  File "/Library/Frameworks/Python.framework/Versions/3.12/lib/python3.12/site-packages/django/db/models/query.py", line 999, in _filter_or_exclude_inplace
    self._query.add_q(Q(*args, **kwargs))
  File "/Library/Frameworks/Python.framework/Versions/3.12/lib/python3.12/site-packages/django/db/models/sql/query.py", line 1375, in add_q
    clause, _ = self._add_q(q_object, self.used_aliases)
                ^^^^^^^^^^^^^^^^^^^^^^^^^^^^^^^^^^^^^^^^
  File "/Library/Frameworks/Python.framework/Versions/3.12/lib/python3.12/site-packages/django/db/models/sql/query.py", line 1396, in _add_q
    child_clause, needed_inner = self.build_filter(
                                 ^^^^^^^^^^^^^^^^^^
  File "/Library/Frameworks/Python.framework/Versions/3.12/lib/python3.12/site-packages/django/db/models/sql/query.py", line 1329, in build_filter
    condition = self.build_lookup(lookups, col, value)
                ^^^^^^^^^^^^^^^^^^^^^^^^^^^^^^^^^^^^^^
  File "/Library/Frameworks/Python.framework/Versions/3.12/lib/python3.12/site-packages/django/db/models/sql/query.py", line 1180, in build_lookup
    lookup = lookup_class(lhs, rhs)
             ^^^^^^^^^^^^^^^^^^^^^^
  File "/Library/Frameworks/Python.framework/Versions/3.12/lib/python3.12/site-packages/django/db/models/lookups.py", line 22, in __init__
    self.rhs = self.get_prep_lookup()
               ^^^^^^^^^^^^^^^^^^^^^^
  File "/Library/Frameworks/Python.framework/Versions/3.12/lib/python3.12/site-packages/django/db/models/lookups.py", line 79, in get_prep_lookup
    return self.lhs.output_field.get_prep_value(self.rhs)
           ^^^^^^^^^^^^^^^^^^^^^^^^^^^^^^^^^^^^^^^^^^^^^^
  File "/Library/Frameworks/Python.framework/Versions/3.12/lib/python3.12/site-packages/django/db/models/fields/__init__.py", line 1824, in get_prep_value
    raise e.__class__(
ValueError: Field 'id' expected a number but got ''.
2024-06-15 10:04:21,935 - ERROR - Internal Server Error: /challenge/1: 
Traceback (most recent call last):
  File "/Library/Frameworks/Python.framework/Versions/3.12/lib/python3.12/site-packages/django/core/handlers/exception.py", line 47, in inner
    response = get_response(request)
               ^^^^^^^^^^^^^^^^^^^^^
  File "/Library/Frameworks/Python.framework/Versions/3.12/lib/python3.12/site-packages/django/core/handlers/base.py", line 181, in _get_response
    response = wrapped_callback(request, *callback_args, **callback_kwargs)
               ^^^^^^^^^^^^^^^^^^^^^^^^^^^^^^^^^^^^^^^^^^^^^^^^^^^^^^^^^^^^
  File "/Users/janrydzewski/Developer/Studies/Django/workout_logger/workout/views.py", line 648, in workout
    workout = Workout.objects.get(id=id)
              ^^^^^^^^^^^^^^^^^^^^^^^^^^
  File "/Library/Frameworks/Python.framework/Versions/3.12/lib/python3.12/site-packages/django/db/models/manager.py", line 85, in manager_method
    return getattr(self.get_queryset(), name)(*args, **kwargs)
           ^^^^^^^^^^^^^^^^^^^^^^^^^^^^^^^^^^^^^^^^^^^^^^^^^^^
  File "/Library/Frameworks/Python.framework/Versions/3.12/lib/python3.12/site-packages/django/db/models/query.py", line 439, in get
    raise self.model.DoesNotExist(
workout.models.Workout.DoesNotExist: Workout matching query does not exist.
2024-06-15 10:06:10,372 - INFO - /Users/janrydzewski/Developer/Studies/Django/workout_logger/workout/views.py changed, reloading.: 
2024-06-15 10:06:13,795 - INFO - /Users/janrydzewski/Developer/Studies/Django/workout_logger/workout/views.py changed, reloading.: 
2024-06-15 10:06:18,107 - INFO - /Users/janrydzewski/Developer/Studies/Django/workout_logger/workout/views.py changed, reloading.: 
2024-06-15 10:06:25,451 - INFO - /Users/janrydzewski/Developer/Studies/Django/workout_logger/workout/urls.py changed, reloading.: 
2024-06-15 10:07:26,498 - INFO - /Users/janrydzewski/Developer/Studies/Django/workout_logger/workout/views.py changed, reloading.: 
2024-06-15 10:07:29,945 - INFO - /Users/janrydzewski/Developer/Studies/Django/workout_logger/workout/views.py changed, reloading.: 
2024-06-15 10:11:51,291 - INFO - /Users/janrydzewski/Developer/Studies/Django/workout_logger/workout/views.py changed, reloading.: 
2024-06-15 10:12:04,064 - INFO - /Users/janrydzewski/Developer/Studies/Django/workout_logger/workout/views.py changed, reloading.: 
2024-06-15 10:12:34,734 - INFO - /Users/janrydzewski/Developer/Studies/Django/workout_logger/workout/views.py changed, reloading.: 
2024-06-15 10:12:48,181 - INFO - /Users/janrydzewski/Developer/Studies/Django/workout_logger/workout/views.py changed, reloading.: 
2024-06-15 10:12:51,590 - INFO - /Users/janrydzewski/Developer/Studies/Django/workout_logger/workout/views.py changed, reloading.: 
2024-06-15 10:13:01,969 - INFO - /Users/janrydzewski/Developer/Studies/Django/workout_logger/workout/views.py changed, reloading.: 
2024-06-15 10:13:31,758 - INFO - /Users/janrydzewski/Developer/Studies/Django/workout_logger/workout/views.py changed, reloading.: 
2024-06-15 10:13:34,274 - INFO - /Users/janrydzewski/Developer/Studies/Django/workout_logger/workout/views.py changed, reloading.: 
2024-06-15 10:13:40,605 - INFO - /Users/janrydzewski/Developer/Studies/Django/workout_logger/workout/views.py changed, reloading.: 
2024-06-15 10:16:02,231 - INFO - /Users/janrydzewski/Developer/Studies/Django/workout_logger/workout/views.py changed, reloading.: 
2024-06-15 10:16:06,635 - INFO - /Users/janrydzewski/Developer/Studies/Django/workout_logger/workout/views.py changed, reloading.: 
2024-06-15 10:16:15,031 - INFO - /Users/janrydzewski/Developer/Studies/Django/workout_logger/workout/views.py changed, reloading.: 
2024-06-15 10:16:23,399 - INFO - /Users/janrydzewski/Developer/Studies/Django/workout_logger/workout/views.py changed, reloading.: 
2024-06-15 10:16:32,980 - INFO - /Users/janrydzewski/Developer/Studies/Django/workout_logger/workout/views.py changed, reloading.: 
2024-06-15 10:16:47,409 - INFO - /Users/janrydzewski/Developer/Studies/Django/workout_logger/workout/views.py changed, reloading.: 
2024-06-15 10:16:49,692 - INFO - /Users/janrydzewski/Developer/Studies/Django/workout_logger/workout/views.py changed, reloading.: 
2024-06-15 10:17:44,636 - INFO - /Users/janrydzewski/Developer/Studies/Django/workout_logger/workout/views.py changed, reloading.: 
2024-06-15 10:17:45,991 - INFO - /Users/janrydzewski/Developer/Studies/Django/workout_logger/workout/views.py changed, reloading.: 
2024-06-15 10:17:49,298 - INFO - /Users/janrydzewski/Developer/Studies/Django/workout_logger/workout/views.py changed, reloading.: 
2024-06-15 10:17:51,592 - INFO - /Users/janrydzewski/Developer/Studies/Django/workout_logger/workout/views.py changed, reloading.: 
2024-06-15 10:18:06,032 - INFO - /Users/janrydzewski/Developer/Studies/Django/workout_logger/workout/views.py changed, reloading.: 
2024-06-15 10:18:08,766 - ERROR - Internal Server Error: /challenge/3: 
Traceback (most recent call last):
  File "/Library/Frameworks/Python.framework/Versions/3.12/lib/python3.12/site-packages/django/db/models/fields/__init__.py", line 1822, in get_prep_value
    return int(value)
           ^^^^^^^^^^
TypeError: int() argument must be a string, a bytes-like object or a real number, not 'Workout'

The above exception was the direct cause of the following exception:

Traceback (most recent call last):
  File "/Library/Frameworks/Python.framework/Versions/3.12/lib/python3.12/site-packages/django/core/handlers/exception.py", line 47, in inner
    response = get_response(request)
               ^^^^^^^^^^^^^^^^^^^^^
  File "/Library/Frameworks/Python.framework/Versions/3.12/lib/python3.12/site-packages/django/core/handlers/base.py", line 181, in _get_response
    response = wrapped_callback(request, *callback_args, **callback_kwargs)
               ^^^^^^^^^^^^^^^^^^^^^^^^^^^^^^^^^^^^^^^^^^^^^^^^^^^^^^^^^^^^
  File "/Users/janrydzewski/Developer/Studies/Django/workout_logger/workout/views.py", line 300, in view_challenge
    workout = Workout.objects.get(id=user_challenge.workout)
              ^^^^^^^^^^^^^^^^^^^^^^^^^^^^^^^^^^^^^^^^^^^^^^
  File "/Library/Frameworks/Python.framework/Versions/3.12/lib/python3.12/site-packages/django/db/models/manager.py", line 85, in manager_method
    return getattr(self.get_queryset(), name)(*args, **kwargs)
           ^^^^^^^^^^^^^^^^^^^^^^^^^^^^^^^^^^^^^^^^^^^^^^^^^^^
  File "/Library/Frameworks/Python.framework/Versions/3.12/lib/python3.12/site-packages/django/db/models/query.py", line 428, in get
    clone = self._chain() if self.query.combinator else self.filter(*args, **kwargs)
                                                        ^^^^^^^^^^^^^^^^^^^^^^^^^^^^
  File "/Library/Frameworks/Python.framework/Versions/3.12/lib/python3.12/site-packages/django/db/models/query.py", line 974, in filter
    return self._filter_or_exclude(False, args, kwargs)
           ^^^^^^^^^^^^^^^^^^^^^^^^^^^^^^^^^^^^^^^^^^^^
  File "/Library/Frameworks/Python.framework/Versions/3.12/lib/python3.12/site-packages/django/db/models/query.py", line 992, in _filter_or_exclude
    clone._filter_or_exclude_inplace(negate, args, kwargs)
  File "/Library/Frameworks/Python.framework/Versions/3.12/lib/python3.12/site-packages/django/db/models/query.py", line 999, in _filter_or_exclude_inplace
    self._query.add_q(Q(*args, **kwargs))
  File "/Library/Frameworks/Python.framework/Versions/3.12/lib/python3.12/site-packages/django/db/models/sql/query.py", line 1375, in add_q
    clause, _ = self._add_q(q_object, self.used_aliases)
                ^^^^^^^^^^^^^^^^^^^^^^^^^^^^^^^^^^^^^^^^
  File "/Library/Frameworks/Python.framework/Versions/3.12/lib/python3.12/site-packages/django/db/models/sql/query.py", line 1396, in _add_q
    child_clause, needed_inner = self.build_filter(
                                 ^^^^^^^^^^^^^^^^^^
  File "/Library/Frameworks/Python.framework/Versions/3.12/lib/python3.12/site-packages/django/db/models/sql/query.py", line 1329, in build_filter
    condition = self.build_lookup(lookups, col, value)
                ^^^^^^^^^^^^^^^^^^^^^^^^^^^^^^^^^^^^^^
  File "/Library/Frameworks/Python.framework/Versions/3.12/lib/python3.12/site-packages/django/db/models/sql/query.py", line 1180, in build_lookup
    lookup = lookup_class(lhs, rhs)
             ^^^^^^^^^^^^^^^^^^^^^^
  File "/Library/Frameworks/Python.framework/Versions/3.12/lib/python3.12/site-packages/django/db/models/lookups.py", line 22, in __init__
    self.rhs = self.get_prep_lookup()
               ^^^^^^^^^^^^^^^^^^^^^^
  File "/Library/Frameworks/Python.framework/Versions/3.12/lib/python3.12/site-packages/django/db/models/lookups.py", line 79, in get_prep_lookup
    return self.lhs.output_field.get_prep_value(self.rhs)
           ^^^^^^^^^^^^^^^^^^^^^^^^^^^^^^^^^^^^^^^^^^^^^^
  File "/Library/Frameworks/Python.framework/Versions/3.12/lib/python3.12/site-packages/django/db/models/fields/__init__.py", line 1824, in get_prep_value
    raise e.__class__(
TypeError: Field 'id' expected a number but got <Workout: testowy challenge workout>.
2024-06-15 10:18:32,733 - INFO - /Users/janrydzewski/Developer/Studies/Django/workout_logger/workout/views.py changed, reloading.: 
2024-06-15 10:18:34,087 - INFO - /Users/janrydzewski/Developer/Studies/Django/workout_logger/workout/views.py changed, reloading.: 
2024-06-15 10:18:37,009 - ERROR - User does not have permission to view workout.: 
2024-06-15 10:18:37,020 - DEBUG - GET request to new workout: 
2024-06-15 10:18:52,606 - INFO - /Users/janrydzewski/Developer/Studies/Django/workout_logger/workout/views.py changed, reloading.: 
2024-06-15 10:18:53,885 - DEBUG - GET request to new workout: 
2024-06-15 10:19:56,753 - INFO - /Users/janrydzewski/Developer/Studies/Django/workout_logger/workout/views.py changed, reloading.: 
2024-06-15 10:26:47,239 - DEBUG - GET request to new workout: 
2024-06-15 10:29:40,450 - INFO - /Users/janrydzewski/Developer/Studies/Django/workout_logger/workout/views.py changed, reloading.: 
2024-06-15 10:30:03,864 - ERROR - Internal Server Error: /challenge/3: 
Traceback (most recent call last):
  File "/Library/Frameworks/Python.framework/Versions/3.12/lib/python3.12/site-packages/django/core/handlers/exception.py", line 47, in inner
    response = get_response(request)
               ^^^^^^^^^^^^^^^^^^^^^
  File "/Library/Frameworks/Python.framework/Versions/3.12/lib/python3.12/site-packages/django/core/handlers/base.py", line 181, in _get_response
    response = wrapped_callback(request, *callback_args, **callback_kwargs)
               ^^^^^^^^^^^^^^^^^^^^^^^^^^^^^^^^^^^^^^^^^^^^^^^^^^^^^^^^^^^^
  File "/Users/janrydzewski/Developer/Studies/Django/workout_logger/workout/views.py", line 336, in view_challenge
    return render(request, "workout/view_challenge.html", data)
           ^^^^^^^^^^^^^^^^^^^^^^^^^^^^^^^^^^^^^^^^^^^^^^^^^^^^
  File "/Library/Frameworks/Python.framework/Versions/3.12/lib/python3.12/site-packages/django/shortcuts.py", line 19, in render
    content = loader.render_to_string(template_name, context, request, using=using)
              ^^^^^^^^^^^^^^^^^^^^^^^^^^^^^^^^^^^^^^^^^^^^^^^^^^^^^^^^^^^^^^^^^^^^^
  File "/Library/Frameworks/Python.framework/Versions/3.12/lib/python3.12/site-packages/django/template/loader.py", line 61, in render_to_string
    template = get_template(template_name, using=using)
               ^^^^^^^^^^^^^^^^^^^^^^^^^^^^^^^^^^^^^^^^
  File "/Library/Frameworks/Python.framework/Versions/3.12/lib/python3.12/site-packages/django/template/loader.py", line 15, in get_template
    return engine.get_template(template_name)
           ^^^^^^^^^^^^^^^^^^^^^^^^^^^^^^^^^^
  File "/Library/Frameworks/Python.framework/Versions/3.12/lib/python3.12/site-packages/django/template/backends/django.py", line 34, in get_template
    return Template(self.engine.get_template(template_name), self)
                    ^^^^^^^^^^^^^^^^^^^^^^^^^^^^^^^^^^^^^^^
  File "/Library/Frameworks/Python.framework/Versions/3.12/lib/python3.12/site-packages/django/template/engine.py", line 163, in get_template
    template, origin = self.find_template(template_name)
                       ^^^^^^^^^^^^^^^^^^^^^^^^^^^^^^^^^
  File "/Library/Frameworks/Python.framework/Versions/3.12/lib/python3.12/site-packages/django/template/engine.py", line 145, in find_template
    template = loader.get_template(name, skip=skip)
               ^^^^^^^^^^^^^^^^^^^^^^^^^^^^^^^^^^^^
  File "/Library/Frameworks/Python.framework/Versions/3.12/lib/python3.12/site-packages/django/template/loaders/base.py", line 29, in get_template
    return Template(
           ^^^^^^^^^
  File "/Library/Frameworks/Python.framework/Versions/3.12/lib/python3.12/site-packages/django/template/base.py", line 155, in __init__
    self.nodelist = self.compile_nodelist()
                    ^^^^^^^^^^^^^^^^^^^^^^^
  File "/Library/Frameworks/Python.framework/Versions/3.12/lib/python3.12/site-packages/django/template/base.py", line 199, in compile_nodelist
    return parser.parse()
           ^^^^^^^^^^^^^^
  File "/Library/Frameworks/Python.framework/Versions/3.12/lib/python3.12/site-packages/django/template/base.py", line 508, in parse
    raise self.error(token, e)
  File "/Library/Frameworks/Python.framework/Versions/3.12/lib/python3.12/site-packages/django/template/base.py", line 506, in parse
    compiled_result = compile_func(self, token)
                      ^^^^^^^^^^^^^^^^^^^^^^^^^
  File "/Library/Frameworks/Python.framework/Versions/3.12/lib/python3.12/site-packages/django/template/defaulttags.py", line 905, in do_if
    nodelist = parser.parse(('elif', 'else', 'endif'))
               ^^^^^^^^^^^^^^^^^^^^^^^^^^^^^^^^^^^^^^^
  File "/Library/Frameworks/Python.framework/Versions/3.12/lib/python3.12/site-packages/django/template/base.py", line 508, in parse
    raise self.error(token, e)
  File "/Library/Frameworks/Python.framework/Versions/3.12/lib/python3.12/site-packages/django/template/base.py", line 506, in parse
    compiled_result = compile_func(self, token)
                      ^^^^^^^^^^^^^^^^^^^^^^^^^
  File "/Library/Frameworks/Python.framework/Versions/3.12/lib/python3.12/site-packages/django/template/defaulttags.py", line 809, in do_for
    sequence = parser.compile_filter(bits[in_index + 1])
               ^^^^^^^^^^^^^^^^^^^^^^^^^^^^^^^^^^^^^^^^^
  File "/Library/Frameworks/Python.framework/Versions/3.12/lib/python3.12/site-packages/django/template/base.py", line 593, in compile_filter
    return FilterExpression(token, self)
           ^^^^^^^^^^^^^^^^^^^^^^^^^^^^^
  File "/Library/Frameworks/Python.framework/Versions/3.12/lib/python3.12/site-packages/django/template/base.py", line 687, in __init__
    filter_func = parser.find_filter(filter_name)
                  ^^^^^^^^^^^^^^^^^^^^^^^^^^^^^^^
  File "/Library/Frameworks/Python.framework/Versions/3.12/lib/python3.12/site-packages/django/template/base.py", line 599, in find_filter
    raise TemplateSyntaxError("Invalid filter: '%s'" % filter_name)
django.template.exceptions.TemplateSyntaxError: Invalid filter: 'zip'
2024-06-15 10:30:10,450 - ERROR - Internal Server Error: /challenge/3: 
Traceback (most recent call last):
  File "/Library/Frameworks/Python.framework/Versions/3.12/lib/python3.12/site-packages/django/core/handlers/exception.py", line 47, in inner
    response = get_response(request)
               ^^^^^^^^^^^^^^^^^^^^^
  File "/Library/Frameworks/Python.framework/Versions/3.12/lib/python3.12/site-packages/django/core/handlers/base.py", line 181, in _get_response
    response = wrapped_callback(request, *callback_args, **callback_kwargs)
               ^^^^^^^^^^^^^^^^^^^^^^^^^^^^^^^^^^^^^^^^^^^^^^^^^^^^^^^^^^^^
  File "/Users/janrydzewski/Developer/Studies/Django/workout_logger/workout/views.py", line 336, in view_challenge
    return render(request, "workout/view_challenge.html", data)
           ^^^^^^^^^^^^^^^^^^^^^^^^^^^^^^^^^^^^^^^^^^^^^^^^^^^^
  File "/Library/Frameworks/Python.framework/Versions/3.12/lib/python3.12/site-packages/django/shortcuts.py", line 19, in render
    content = loader.render_to_string(template_name, context, request, using=using)
              ^^^^^^^^^^^^^^^^^^^^^^^^^^^^^^^^^^^^^^^^^^^^^^^^^^^^^^^^^^^^^^^^^^^^^
  File "/Library/Frameworks/Python.framework/Versions/3.12/lib/python3.12/site-packages/django/template/loader.py", line 61, in render_to_string
    template = get_template(template_name, using=using)
               ^^^^^^^^^^^^^^^^^^^^^^^^^^^^^^^^^^^^^^^^
  File "/Library/Frameworks/Python.framework/Versions/3.12/lib/python3.12/site-packages/django/template/loader.py", line 15, in get_template
    return engine.get_template(template_name)
           ^^^^^^^^^^^^^^^^^^^^^^^^^^^^^^^^^^
  File "/Library/Frameworks/Python.framework/Versions/3.12/lib/python3.12/site-packages/django/template/backends/django.py", line 34, in get_template
    return Template(self.engine.get_template(template_name), self)
                    ^^^^^^^^^^^^^^^^^^^^^^^^^^^^^^^^^^^^^^^
  File "/Library/Frameworks/Python.framework/Versions/3.12/lib/python3.12/site-packages/django/template/engine.py", line 163, in get_template
    template, origin = self.find_template(template_name)
                       ^^^^^^^^^^^^^^^^^^^^^^^^^^^^^^^^^
  File "/Library/Frameworks/Python.framework/Versions/3.12/lib/python3.12/site-packages/django/template/engine.py", line 145, in find_template
    template = loader.get_template(name, skip=skip)
               ^^^^^^^^^^^^^^^^^^^^^^^^^^^^^^^^^^^^
  File "/Library/Frameworks/Python.framework/Versions/3.12/lib/python3.12/site-packages/django/template/loaders/base.py", line 29, in get_template
    return Template(
           ^^^^^^^^^
  File "/Library/Frameworks/Python.framework/Versions/3.12/lib/python3.12/site-packages/django/template/base.py", line 155, in __init__
    self.nodelist = self.compile_nodelist()
                    ^^^^^^^^^^^^^^^^^^^^^^^
  File "/Library/Frameworks/Python.framework/Versions/3.12/lib/python3.12/site-packages/django/template/base.py", line 199, in compile_nodelist
    return parser.parse()
           ^^^^^^^^^^^^^^
  File "/Library/Frameworks/Python.framework/Versions/3.12/lib/python3.12/site-packages/django/template/base.py", line 508, in parse
    raise self.error(token, e)
  File "/Library/Frameworks/Python.framework/Versions/3.12/lib/python3.12/site-packages/django/template/base.py", line 506, in parse
    compiled_result = compile_func(self, token)
                      ^^^^^^^^^^^^^^^^^^^^^^^^^
  File "/Library/Frameworks/Python.framework/Versions/3.12/lib/python3.12/site-packages/django/template/defaulttags.py", line 905, in do_if
    nodelist = parser.parse(('elif', 'else', 'endif'))
               ^^^^^^^^^^^^^^^^^^^^^^^^^^^^^^^^^^^^^^^
  File "/Library/Frameworks/Python.framework/Versions/3.12/lib/python3.12/site-packages/django/template/base.py", line 508, in parse
    raise self.error(token, e)
  File "/Library/Frameworks/Python.framework/Versions/3.12/lib/python3.12/site-packages/django/template/base.py", line 506, in parse
    compiled_result = compile_func(self, token)
                      ^^^^^^^^^^^^^^^^^^^^^^^^^
  File "/Library/Frameworks/Python.framework/Versions/3.12/lib/python3.12/site-packages/django/template/defaulttags.py", line 809, in do_for
    sequence = parser.compile_filter(bits[in_index + 1])
               ^^^^^^^^^^^^^^^^^^^^^^^^^^^^^^^^^^^^^^^^^
  File "/Library/Frameworks/Python.framework/Versions/3.12/lib/python3.12/site-packages/django/template/base.py", line 593, in compile_filter
    return FilterExpression(token, self)
           ^^^^^^^^^^^^^^^^^^^^^^^^^^^^^
  File "/Library/Frameworks/Python.framework/Versions/3.12/lib/python3.12/site-packages/django/template/base.py", line 687, in __init__
    filter_func = parser.find_filter(filter_name)
                  ^^^^^^^^^^^^^^^^^^^^^^^^^^^^^^^
  File "/Library/Frameworks/Python.framework/Versions/3.12/lib/python3.12/site-packages/django/template/base.py", line 599, in find_filter
    raise TemplateSyntaxError("Invalid filter: '%s'" % filter_name)
django.template.exceptions.TemplateSyntaxError: Invalid filter: 'zip'
2024-06-15 10:32:01,592 - ERROR - Internal Server Error: /challenge/3: 
Traceback (most recent call last):
  File "/Library/Frameworks/Python.framework/Versions/3.12/lib/python3.12/site-packages/django/core/handlers/exception.py", line 47, in inner
    response = get_response(request)
               ^^^^^^^^^^^^^^^^^^^^^
  File "/Library/Frameworks/Python.framework/Versions/3.12/lib/python3.12/site-packages/django/core/handlers/base.py", line 181, in _get_response
    response = wrapped_callback(request, *callback_args, **callback_kwargs)
               ^^^^^^^^^^^^^^^^^^^^^^^^^^^^^^^^^^^^^^^^^^^^^^^^^^^^^^^^^^^^
  File "/Users/janrydzewski/Developer/Studies/Django/workout_logger/workout/views.py", line 336, in view_challenge
    return render(request, "workout/view_challenge.html", data)
           ^^^^^^^^^^^^^^^^^^^^^^^^^^^^^^^^^^^^^^^^^^^^^^^^^^^^
  File "/Library/Frameworks/Python.framework/Versions/3.12/lib/python3.12/site-packages/django/shortcuts.py", line 19, in render
    content = loader.render_to_string(template_name, context, request, using=using)
              ^^^^^^^^^^^^^^^^^^^^^^^^^^^^^^^^^^^^^^^^^^^^^^^^^^^^^^^^^^^^^^^^^^^^^
  File "/Library/Frameworks/Python.framework/Versions/3.12/lib/python3.12/site-packages/django/template/loader.py", line 61, in render_to_string
    template = get_template(template_name, using=using)
               ^^^^^^^^^^^^^^^^^^^^^^^^^^^^^^^^^^^^^^^^
  File "/Library/Frameworks/Python.framework/Versions/3.12/lib/python3.12/site-packages/django/template/loader.py", line 15, in get_template
    return engine.get_template(template_name)
           ^^^^^^^^^^^^^^^^^^^^^^^^^^^^^^^^^^
  File "/Library/Frameworks/Python.framework/Versions/3.12/lib/python3.12/site-packages/django/template/backends/django.py", line 34, in get_template
    return Template(self.engine.get_template(template_name), self)
                    ^^^^^^^^^^^^^^^^^^^^^^^^^^^^^^^^^^^^^^^
  File "/Library/Frameworks/Python.framework/Versions/3.12/lib/python3.12/site-packages/django/template/engine.py", line 163, in get_template
    template, origin = self.find_template(template_name)
                       ^^^^^^^^^^^^^^^^^^^^^^^^^^^^^^^^^
  File "/Library/Frameworks/Python.framework/Versions/3.12/lib/python3.12/site-packages/django/template/engine.py", line 145, in find_template
    template = loader.get_template(name, skip=skip)
               ^^^^^^^^^^^^^^^^^^^^^^^^^^^^^^^^^^^^
  File "/Library/Frameworks/Python.framework/Versions/3.12/lib/python3.12/site-packages/django/template/loaders/base.py", line 29, in get_template
    return Template(
           ^^^^^^^^^
  File "/Library/Frameworks/Python.framework/Versions/3.12/lib/python3.12/site-packages/django/template/base.py", line 155, in __init__
    self.nodelist = self.compile_nodelist()
                    ^^^^^^^^^^^^^^^^^^^^^^^
  File "/Library/Frameworks/Python.framework/Versions/3.12/lib/python3.12/site-packages/django/template/base.py", line 199, in compile_nodelist
    return parser.parse()
           ^^^^^^^^^^^^^^
  File "/Library/Frameworks/Python.framework/Versions/3.12/lib/python3.12/site-packages/django/template/base.py", line 508, in parse
    raise self.error(token, e)
  File "/Library/Frameworks/Python.framework/Versions/3.12/lib/python3.12/site-packages/django/template/base.py", line 506, in parse
    compiled_result = compile_func(self, token)
                      ^^^^^^^^^^^^^^^^^^^^^^^^^
  File "/Library/Frameworks/Python.framework/Versions/3.12/lib/python3.12/site-packages/django/template/defaulttags.py", line 905, in do_if
    nodelist = parser.parse(('elif', 'else', 'endif'))
               ^^^^^^^^^^^^^^^^^^^^^^^^^^^^^^^^^^^^^^^
  File "/Library/Frameworks/Python.framework/Versions/3.12/lib/python3.12/site-packages/django/template/base.py", line 508, in parse
    raise self.error(token, e)
  File "/Library/Frameworks/Python.framework/Versions/3.12/lib/python3.12/site-packages/django/template/base.py", line 506, in parse
    compiled_result = compile_func(self, token)
                      ^^^^^^^^^^^^^^^^^^^^^^^^^
  File "/Library/Frameworks/Python.framework/Versions/3.12/lib/python3.12/site-packages/django/template/defaulttags.py", line 809, in do_for
    sequence = parser.compile_filter(bits[in_index + 1])
               ^^^^^^^^^^^^^^^^^^^^^^^^^^^^^^^^^^^^^^^^^
  File "/Library/Frameworks/Python.framework/Versions/3.12/lib/python3.12/site-packages/django/template/base.py", line 593, in compile_filter
    return FilterExpression(token, self)
           ^^^^^^^^^^^^^^^^^^^^^^^^^^^^^
  File "/Library/Frameworks/Python.framework/Versions/3.12/lib/python3.12/site-packages/django/template/base.py", line 687, in __init__
    filter_func = parser.find_filter(filter_name)
                  ^^^^^^^^^^^^^^^^^^^^^^^^^^^^^^^
  File "/Library/Frameworks/Python.framework/Versions/3.12/lib/python3.12/site-packages/django/template/base.py", line 599, in find_filter
    raise TemplateSyntaxError("Invalid filter: '%s'" % filter_name)
django.template.exceptions.TemplateSyntaxError: Invalid filter: 'zip'
2024-06-15 10:33:21,572 - INFO - /Users/janrydzewski/Developer/Studies/Django/workout_logger/workout/views.py changed, reloading.: 
2024-06-15 10:33:23,608 - ERROR - Internal Server Error: /challenge/3: 
Traceback (most recent call last):
  File "/Library/Frameworks/Python.framework/Versions/3.12/lib/python3.12/site-packages/django/core/handlers/exception.py", line 47, in inner
    response = get_response(request)
               ^^^^^^^^^^^^^^^^^^^^^
  File "/Library/Frameworks/Python.framework/Versions/3.12/lib/python3.12/site-packages/django/core/handlers/base.py", line 181, in _get_response
    response = wrapped_callback(request, *callback_args, **callback_kwargs)
               ^^^^^^^^^^^^^^^^^^^^^^^^^^^^^^^^^^^^^^^^^^^^^^^^^^^^^^^^^^^^
  File "/Users/janrydzewski/Developer/Studies/Django/workout_logger/workout/views.py", line 336, in view_challenge
    return render(request, "workout/view_challenge.html", data)
           ^^^^^^^^^^^^^^^^^^^^^^^^^^^^^^^^^^^^^^^^^^^^^^^^^^^^
  File "/Library/Frameworks/Python.framework/Versions/3.12/lib/python3.12/site-packages/django/shortcuts.py", line 19, in render
    content = loader.render_to_string(template_name, context, request, using=using)
              ^^^^^^^^^^^^^^^^^^^^^^^^^^^^^^^^^^^^^^^^^^^^^^^^^^^^^^^^^^^^^^^^^^^^^
  File "/Library/Frameworks/Python.framework/Versions/3.12/lib/python3.12/site-packages/django/template/loader.py", line 61, in render_to_string
    template = get_template(template_name, using=using)
               ^^^^^^^^^^^^^^^^^^^^^^^^^^^^^^^^^^^^^^^^
  File "/Library/Frameworks/Python.framework/Versions/3.12/lib/python3.12/site-packages/django/template/loader.py", line 15, in get_template
    return engine.get_template(template_name)
           ^^^^^^^^^^^^^^^^^^^^^^^^^^^^^^^^^^
  File "/Library/Frameworks/Python.framework/Versions/3.12/lib/python3.12/site-packages/django/template/backends/django.py", line 34, in get_template
    return Template(self.engine.get_template(template_name), self)
                    ^^^^^^^^^^^^^^^^^^^^^^^^^^^^^^^^^^^^^^^
  File "/Library/Frameworks/Python.framework/Versions/3.12/lib/python3.12/site-packages/django/template/engine.py", line 163, in get_template
    template, origin = self.find_template(template_name)
                       ^^^^^^^^^^^^^^^^^^^^^^^^^^^^^^^^^
  File "/Library/Frameworks/Python.framework/Versions/3.12/lib/python3.12/site-packages/django/template/engine.py", line 145, in find_template
    template = loader.get_template(name, skip=skip)
               ^^^^^^^^^^^^^^^^^^^^^^^^^^^^^^^^^^^^
  File "/Library/Frameworks/Python.framework/Versions/3.12/lib/python3.12/site-packages/django/template/loaders/base.py", line 29, in get_template
    return Template(
           ^^^^^^^^^
  File "/Library/Frameworks/Python.framework/Versions/3.12/lib/python3.12/site-packages/django/template/base.py", line 155, in __init__
    self.nodelist = self.compile_nodelist()
                    ^^^^^^^^^^^^^^^^^^^^^^^
  File "/Library/Frameworks/Python.framework/Versions/3.12/lib/python3.12/site-packages/django/template/base.py", line 199, in compile_nodelist
    return parser.parse()
           ^^^^^^^^^^^^^^
  File "/Library/Frameworks/Python.framework/Versions/3.12/lib/python3.12/site-packages/django/template/base.py", line 508, in parse
    raise self.error(token, e)
  File "/Library/Frameworks/Python.framework/Versions/3.12/lib/python3.12/site-packages/django/template/base.py", line 506, in parse
    compiled_result = compile_func(self, token)
                      ^^^^^^^^^^^^^^^^^^^^^^^^^
  File "/Library/Frameworks/Python.framework/Versions/3.12/lib/python3.12/site-packages/django/template/defaulttags.py", line 905, in do_if
    nodelist = parser.parse(('elif', 'else', 'endif'))
               ^^^^^^^^^^^^^^^^^^^^^^^^^^^^^^^^^^^^^^^
  File "/Library/Frameworks/Python.framework/Versions/3.12/lib/python3.12/site-packages/django/template/base.py", line 508, in parse
    raise self.error(token, e)
  File "/Library/Frameworks/Python.framework/Versions/3.12/lib/python3.12/site-packages/django/template/base.py", line 506, in parse
    compiled_result = compile_func(self, token)
                      ^^^^^^^^^^^^^^^^^^^^^^^^^
  File "/Library/Frameworks/Python.framework/Versions/3.12/lib/python3.12/site-packages/django/template/defaulttags.py", line 809, in do_for
    sequence = parser.compile_filter(bits[in_index + 1])
               ^^^^^^^^^^^^^^^^^^^^^^^^^^^^^^^^^^^^^^^^^
  File "/Library/Frameworks/Python.framework/Versions/3.12/lib/python3.12/site-packages/django/template/base.py", line 593, in compile_filter
    return FilterExpression(token, self)
           ^^^^^^^^^^^^^^^^^^^^^^^^^^^^^
  File "/Library/Frameworks/Python.framework/Versions/3.12/lib/python3.12/site-packages/django/template/base.py", line 687, in __init__
    filter_func = parser.find_filter(filter_name)
                  ^^^^^^^^^^^^^^^^^^^^^^^^^^^^^^^
  File "/Library/Frameworks/Python.framework/Versions/3.12/lib/python3.12/site-packages/django/template/base.py", line 599, in find_filter
    raise TemplateSyntaxError("Invalid filter: '%s'" % filter_name)
django.template.exceptions.TemplateSyntaxError: Invalid filter: 'zip'
2024-06-15 10:33:26,252 - ERROR - Internal Server Error: /challenge/3: 
Traceback (most recent call last):
  File "/Library/Frameworks/Python.framework/Versions/3.12/lib/python3.12/site-packages/django/core/handlers/exception.py", line 47, in inner
    response = get_response(request)
               ^^^^^^^^^^^^^^^^^^^^^
  File "/Library/Frameworks/Python.framework/Versions/3.12/lib/python3.12/site-packages/django/core/handlers/base.py", line 181, in _get_response
    response = wrapped_callback(request, *callback_args, **callback_kwargs)
               ^^^^^^^^^^^^^^^^^^^^^^^^^^^^^^^^^^^^^^^^^^^^^^^^^^^^^^^^^^^^
  File "/Users/janrydzewski/Developer/Studies/Django/workout_logger/workout/views.py", line 336, in view_challenge
    return render(request, "workout/view_challenge.html", data)
           ^^^^^^^^^^^^^^^^^^^^^^^^^^^^^^^^^^^^^^^^^^^^^^^^^^^^
  File "/Library/Frameworks/Python.framework/Versions/3.12/lib/python3.12/site-packages/django/shortcuts.py", line 19, in render
    content = loader.render_to_string(template_name, context, request, using=using)
              ^^^^^^^^^^^^^^^^^^^^^^^^^^^^^^^^^^^^^^^^^^^^^^^^^^^^^^^^^^^^^^^^^^^^^
  File "/Library/Frameworks/Python.framework/Versions/3.12/lib/python3.12/site-packages/django/template/loader.py", line 61, in render_to_string
    template = get_template(template_name, using=using)
               ^^^^^^^^^^^^^^^^^^^^^^^^^^^^^^^^^^^^^^^^
  File "/Library/Frameworks/Python.framework/Versions/3.12/lib/python3.12/site-packages/django/template/loader.py", line 15, in get_template
    return engine.get_template(template_name)
           ^^^^^^^^^^^^^^^^^^^^^^^^^^^^^^^^^^
  File "/Library/Frameworks/Python.framework/Versions/3.12/lib/python3.12/site-packages/django/template/backends/django.py", line 34, in get_template
    return Template(self.engine.get_template(template_name), self)
                    ^^^^^^^^^^^^^^^^^^^^^^^^^^^^^^^^^^^^^^^
  File "/Library/Frameworks/Python.framework/Versions/3.12/lib/python3.12/site-packages/django/template/engine.py", line 163, in get_template
    template, origin = self.find_template(template_name)
                       ^^^^^^^^^^^^^^^^^^^^^^^^^^^^^^^^^
  File "/Library/Frameworks/Python.framework/Versions/3.12/lib/python3.12/site-packages/django/template/engine.py", line 145, in find_template
    template = loader.get_template(name, skip=skip)
               ^^^^^^^^^^^^^^^^^^^^^^^^^^^^^^^^^^^^
  File "/Library/Frameworks/Python.framework/Versions/3.12/lib/python3.12/site-packages/django/template/loaders/base.py", line 29, in get_template
    return Template(
           ^^^^^^^^^
  File "/Library/Frameworks/Python.framework/Versions/3.12/lib/python3.12/site-packages/django/template/base.py", line 155, in __init__
    self.nodelist = self.compile_nodelist()
                    ^^^^^^^^^^^^^^^^^^^^^^^
  File "/Library/Frameworks/Python.framework/Versions/3.12/lib/python3.12/site-packages/django/template/base.py", line 199, in compile_nodelist
    return parser.parse()
           ^^^^^^^^^^^^^^
  File "/Library/Frameworks/Python.framework/Versions/3.12/lib/python3.12/site-packages/django/template/base.py", line 508, in parse
    raise self.error(token, e)
  File "/Library/Frameworks/Python.framework/Versions/3.12/lib/python3.12/site-packages/django/template/base.py", line 506, in parse
    compiled_result = compile_func(self, token)
                      ^^^^^^^^^^^^^^^^^^^^^^^^^
  File "/Library/Frameworks/Python.framework/Versions/3.12/lib/python3.12/site-packages/django/template/defaulttags.py", line 905, in do_if
    nodelist = parser.parse(('elif', 'else', 'endif'))
               ^^^^^^^^^^^^^^^^^^^^^^^^^^^^^^^^^^^^^^^
  File "/Library/Frameworks/Python.framework/Versions/3.12/lib/python3.12/site-packages/django/template/base.py", line 508, in parse
    raise self.error(token, e)
  File "/Library/Frameworks/Python.framework/Versions/3.12/lib/python3.12/site-packages/django/template/base.py", line 506, in parse
    compiled_result = compile_func(self, token)
                      ^^^^^^^^^^^^^^^^^^^^^^^^^
  File "/Library/Frameworks/Python.framework/Versions/3.12/lib/python3.12/site-packages/django/template/defaulttags.py", line 809, in do_for
    sequence = parser.compile_filter(bits[in_index + 1])
               ^^^^^^^^^^^^^^^^^^^^^^^^^^^^^^^^^^^^^^^^^
  File "/Library/Frameworks/Python.framework/Versions/3.12/lib/python3.12/site-packages/django/template/base.py", line 593, in compile_filter
    return FilterExpression(token, self)
           ^^^^^^^^^^^^^^^^^^^^^^^^^^^^^
  File "/Library/Frameworks/Python.framework/Versions/3.12/lib/python3.12/site-packages/django/template/base.py", line 687, in __init__
    filter_func = parser.find_filter(filter_name)
                  ^^^^^^^^^^^^^^^^^^^^^^^^^^^^^^^
  File "/Library/Frameworks/Python.framework/Versions/3.12/lib/python3.12/site-packages/django/template/base.py", line 599, in find_filter
    raise TemplateSyntaxError("Invalid filter: '%s'" % filter_name)
django.template.exceptions.TemplateSyntaxError: Invalid filter: 'zip'
2024-06-15 10:34:38,924 - INFO - /Users/janrydzewski/Developer/Studies/Django/workout_logger/workout/views.py changed, reloading.: 
2024-06-15 10:34:56,507 - ERROR - Internal Server Error: /challenge/3: 
Traceback (most recent call last):
  File "/Library/Frameworks/Python.framework/Versions/3.12/lib/python3.12/site-packages/django/core/handlers/exception.py", line 47, in inner
    response = get_response(request)
               ^^^^^^^^^^^^^^^^^^^^^
  File "/Library/Frameworks/Python.framework/Versions/3.12/lib/python3.12/site-packages/django/core/handlers/base.py", line 181, in _get_response
    response = wrapped_callback(request, *callback_args, **callback_kwargs)
               ^^^^^^^^^^^^^^^^^^^^^^^^^^^^^^^^^^^^^^^^^^^^^^^^^^^^^^^^^^^^
  File "/Users/janrydzewski/Developer/Studies/Django/workout_logger/workout/views.py", line 323, in view_challenge
    exercise_status = user_challenge.exercise_status[exercises.index(exercise)]
                      ~~~~~~~~~~~~~~~~~~~~~~~~~~~~~~^^^^^^^^^^^^^^^^^^^^^^^^^^^
IndexError: list index out of range
2024-06-15 10:39:05,241 - DEBUG - GET request to login: 
2024-06-15 10:39:11,100 - ERROR - Internal Server Error: /challenge/3: 
Traceback (most recent call last):
  File "/Library/Frameworks/Python.framework/Versions/3.12/lib/python3.12/site-packages/django/core/handlers/exception.py", line 47, in inner
    response = get_response(request)
               ^^^^^^^^^^^^^^^^^^^^^
  File "/Library/Frameworks/Python.framework/Versions/3.12/lib/python3.12/site-packages/django/core/handlers/base.py", line 181, in _get_response
    response = wrapped_callback(request, *callback_args, **callback_kwargs)
               ^^^^^^^^^^^^^^^^^^^^^^^^^^^^^^^^^^^^^^^^^^^^^^^^^^^^^^^^^^^^
  File "/Users/janrydzewski/Developer/Studies/Django/workout_logger/workout/views.py", line 323, in view_challenge
    exercise_status = user_challenge.exercise_status[exercises.index(exercise)]
                      ~~~~~~~~~~~~~~~~~~~~~~~~~~~~~~^^^^^^^^^^^^^^^^^^^^^^^^^^^
IndexError: list index out of range
2024-06-15 10:39:15,377 - ERROR - Internal Server Error: /challenge/3: 
Traceback (most recent call last):
  File "/Library/Frameworks/Python.framework/Versions/3.12/lib/python3.12/site-packages/django/core/handlers/exception.py", line 47, in inner
    response = get_response(request)
               ^^^^^^^^^^^^^^^^^^^^^
  File "/Library/Frameworks/Python.framework/Versions/3.12/lib/python3.12/site-packages/django/core/handlers/base.py", line 181, in _get_response
    response = wrapped_callback(request, *callback_args, **callback_kwargs)
               ^^^^^^^^^^^^^^^^^^^^^^^^^^^^^^^^^^^^^^^^^^^^^^^^^^^^^^^^^^^^
  File "/Users/janrydzewski/Developer/Studies/Django/workout_logger/workout/views.py", line 323, in view_challenge
    exercise_status = user_challenge.exercise_status[exercises.index(exercise)]
                      ~~~~~~~~~~~~~~~~~~~~~~~~~~~~~~^^^^^^^^^^^^^^^^^^^^^^^^^^^
IndexError: list index out of range
2024-06-15 10:39:37,861 - ERROR - Internal Server Error: /challenge/3: 
Traceback (most recent call last):
  File "/Library/Frameworks/Python.framework/Versions/3.12/lib/python3.12/site-packages/django/core/handlers/exception.py", line 47, in inner
    response = get_response(request)
               ^^^^^^^^^^^^^^^^^^^^^
  File "/Library/Frameworks/Python.framework/Versions/3.12/lib/python3.12/site-packages/django/core/handlers/base.py", line 181, in _get_response
    response = wrapped_callback(request, *callback_args, **callback_kwargs)
               ^^^^^^^^^^^^^^^^^^^^^^^^^^^^^^^^^^^^^^^^^^^^^^^^^^^^^^^^^^^^
  File "/Users/janrydzewski/Developer/Studies/Django/workout_logger/workout/views.py", line 311, in view_challenge
    return redirect('view_challenge', id=id)
           ^^^^^^^^^^^^^^^^^^^^^^^^^^^^^^^^^
  File "/Library/Frameworks/Python.framework/Versions/3.12/lib/python3.12/site-packages/django/shortcuts.py", line 41, in redirect
    return redirect_class(resolve_url(to, *args, **kwargs))
                          ^^^^^^^^^^^^^^^^^^^^^^^^^^^^^^^^
  File "/Library/Frameworks/Python.framework/Versions/3.12/lib/python3.12/site-packages/django/shortcuts.py", line 130, in resolve_url
    return reverse(to, args=args, kwargs=kwargs)
           ^^^^^^^^^^^^^^^^^^^^^^^^^^^^^^^^^^^^^
  File "/Library/Frameworks/Python.framework/Versions/3.12/lib/python3.12/site-packages/django/urls/base.py", line 86, in reverse
    return resolver._reverse_with_prefix(view, prefix, *args, **kwargs)
           ^^^^^^^^^^^^^^^^^^^^^^^^^^^^^^^^^^^^^^^^^^^^^^^^^^^^^^^^^^^^
  File "/Library/Frameworks/Python.framework/Versions/3.12/lib/python3.12/site-packages/django/urls/resolvers.py", line 729, in _reverse_with_prefix
    raise NoReverseMatch(msg)
django.urls.exceptions.NoReverseMatch: Reverse for 'view_challenge' not found. 'view_challenge' is not a valid view function or pattern name.
2024-06-15 10:41:25,073 - INFO - /Users/janrydzewski/Developer/Studies/Django/workout_logger/workout/views.py changed, reloading.: 
2024-06-15 10:41:30,150 - DEBUG - GET request to new workout: 
2024-06-15 10:43:03,628 - DEBUG - GET request to new workout: 
2024-06-15 10:48:23,131 - INFO - /Users/janrydzewski/Developer/Studies/Django/workout_logger/workout/views.py changed, reloading.: 
2024-06-15 10:48:35,650 - INFO - /Users/janrydzewski/Developer/Studies/Django/workout_logger/workout/views.py changed, reloading.: 
2024-06-15 10:48:39,031 - INFO - /Users/janrydzewski/Developer/Studies/Django/workout_logger/workout/views.py changed, reloading.: 
2024-06-15 10:48:43,340 - INFO - /Users/janrydzewski/Developer/Studies/Django/workout_logger/workout/views.py changed, reloading.: 
2024-06-15 10:48:44,641 - INFO - /Users/janrydzewski/Developer/Studies/Django/workout_logger/workout/views.py changed, reloading.: 
2024-06-15 10:48:45,907 - INFO - /Users/janrydzewski/Developer/Studies/Django/workout_logger/workout/views.py changed, reloading.: 
2024-06-15 10:48:50,233 - INFO - /Users/janrydzewski/Developer/Studies/Django/workout_logger/workout/views.py changed, reloading.: 
2024-06-15 10:48:57,851 - INFO - /Users/janrydzewski/Developer/Studies/Django/workout_logger/workout/views.py changed, reloading.: 
2024-06-15 10:49:17,159 - INFO - /Users/janrydzewski/Developer/Studies/Django/workout_logger/workout/views.py changed, reloading.: 
2024-06-15 10:49:55,531 - ERROR - Internal Server Error: /challenge/3: 
Traceback (most recent call last):
  File "/Library/Frameworks/Python.framework/Versions/3.12/lib/python3.12/site-packages/django/core/handlers/exception.py", line 47, in inner
    response = get_response(request)
               ^^^^^^^^^^^^^^^^^^^^^
  File "/Library/Frameworks/Python.framework/Versions/3.12/lib/python3.12/site-packages/django/core/handlers/base.py", line 181, in _get_response
    response = wrapped_callback(request, *callback_args, **callback_kwargs)
               ^^^^^^^^^^^^^^^^^^^^^^^^^^^^^^^^^^^^^^^^^^^^^^^^^^^^^^^^^^^^
  File "/Users/janrydzewski/Developer/Studies/Django/workout_logger/workout/views.py", line 340, in view_challenge
    exercise_status = user_challenge.exercise_status[exercises.index(exercise)]
                      ~~~~~~~~~~~~~~~~~~~~~~~~~~~~~~^^^^^^^^^^^^^^^^^^^^^^^^^^^
IndexError: list index out of range
2024-06-15 10:50:19,252 - INFO - /Users/janrydzewski/Developer/Studies/Django/workout_logger/workout/views.py changed, reloading.: 
2024-06-15 10:50:46,978 - ERROR - Internal Server Error: /challenge/3: 
Traceback (most recent call last):
  File "/Library/Frameworks/Python.framework/Versions/3.12/lib/python3.12/site-packages/django/core/handlers/exception.py", line 47, in inner
    response = get_response(request)
               ^^^^^^^^^^^^^^^^^^^^^
  File "/Library/Frameworks/Python.framework/Versions/3.12/lib/python3.12/site-packages/django/core/handlers/base.py", line 181, in _get_response
    response = wrapped_callback(request, *callback_args, **callback_kwargs)
               ^^^^^^^^^^^^^^^^^^^^^^^^^^^^^^^^^^^^^^^^^^^^^^^^^^^^^^^^^^^^
  File "/Users/janrydzewski/Developer/Studies/Django/workout_logger/workout/views.py", line 323, in view_challenge
    exercise_status = user_challenge.exercise_status[exercises.index(exercise)]
                      ~~~~~~~~~~~~~~~~~~~~~~~~~~~~~~^^^^^^^^^^^^^^^^^^^^^^^^^^^
IndexError: list index out of range
2024-06-15 10:51:26,439 - ERROR - Internal Server Error: /challenge/3: 
Traceback (most recent call last):
  File "/Library/Frameworks/Python.framework/Versions/3.12/lib/python3.12/site-packages/django/core/handlers/exception.py", line 47, in inner
    response = get_response(request)
               ^^^^^^^^^^^^^^^^^^^^^
  File "/Library/Frameworks/Python.framework/Versions/3.12/lib/python3.12/site-packages/django/core/handlers/base.py", line 181, in _get_response
    response = wrapped_callback(request, *callback_args, **callback_kwargs)
               ^^^^^^^^^^^^^^^^^^^^^^^^^^^^^^^^^^^^^^^^^^^^^^^^^^^^^^^^^^^^
  File "/Users/janrydzewski/Developer/Studies/Django/workout_logger/workout/views.py", line 323, in view_challenge
    exercise_status = user_challenge.exercise_status[exercises.index(exercise)]
                      ~~~~~~~~~~~~~~~~~~~~~~~~~~~~~~^^^^^^^^^^^^^^^^^^^^^^^^^^^
IndexError: list index out of range
2024-06-15 10:51:28,444 - ERROR - Internal Server Error: /challenge/3: 
Traceback (most recent call last):
  File "/Library/Frameworks/Python.framework/Versions/3.12/lib/python3.12/site-packages/django/core/handlers/exception.py", line 47, in inner
    response = get_response(request)
               ^^^^^^^^^^^^^^^^^^^^^
  File "/Library/Frameworks/Python.framework/Versions/3.12/lib/python3.12/site-packages/django/core/handlers/base.py", line 181, in _get_response
    response = wrapped_callback(request, *callback_args, **callback_kwargs)
               ^^^^^^^^^^^^^^^^^^^^^^^^^^^^^^^^^^^^^^^^^^^^^^^^^^^^^^^^^^^^
  File "/Users/janrydzewski/Developer/Studies/Django/workout_logger/workout/views.py", line 323, in view_challenge
    exercise_status = user_challenge.exercise_status[exercises.index(exercise)]
                      ~~~~~~~~~~~~~~~~~~~~~~~~~~~~~~^^^^^^^^^^^^^^^^^^^^^^^^^^^
IndexError: list index out of range
2024-06-15 10:53:07,706 - INFO - /Users/janrydzewski/Developer/Studies/Django/workout_logger/workout/views.py changed, reloading.: 
2024-06-15 10:53:26,290 - INFO - /Users/janrydzewski/Developer/Studies/Django/workout_logger/workout/views.py changed, reloading.: 
2024-06-15 10:53:34,730 - INFO - /Users/janrydzewski/Developer/Studies/Django/workout_logger/workout/views.py changed, reloading.: 
2024-06-15 10:54:25,658 - INFO - /Users/janrydzewski/Developer/Studies/Django/workout_logger/workout/views.py changed, reloading.: 
2024-06-15 14:48:02,076 - DEBUG - GET request to login: 
2024-06-15 14:49:11,213 - INFO - C:\Users\rsien\Desktop\python-django\workout_logger\workout\views.py changed, reloading.: 
2024-06-15 14:50:17,321 - ERROR - Internal Server Error: /admin/: 
Traceback (most recent call last):
  File "C:\Users\rsien\miniconda3\Lib\site-packages\django\core\handlers\exception.py", line 55, in inner
    response = get_response(request)
               ^^^^^^^^^^^^^^^^^^^^^
  File "C:\Users\rsien\miniconda3\Lib\site-packages\django\core\handlers\base.py", line 197, in _get_response
    response = wrapped_callback(request, *callback_args, **callback_kwargs)
               ^^^^^^^^^^^^^^^^^^^^^^^^^^^^^^^^^^^^^^^^^^^^^^^^^^^^^^^^^^^^
  File "C:\Users\rsien\Desktop\python-django\workout_logger\workout\views.py", line 1308, in redirect_to_dashboard
    if request.startswith('admin'):
       ^^^^^^^^^^^^^^^^^^
AttributeError: 'WSGIRequest' object has no attribute 'startswith'
2024-06-15 14:50:17,494 - ERROR - Internal Server Error: /favicon.ico: 
Traceback (most recent call last):
  File "C:\Users\rsien\miniconda3\Lib\site-packages\django\core\handlers\exception.py", line 55, in inner
    response = get_response(request)
               ^^^^^^^^^^^^^^^^^^^^^
  File "C:\Users\rsien\miniconda3\Lib\site-packages\django\core\handlers\base.py", line 197, in _get_response
    response = wrapped_callback(request, *callback_args, **callback_kwargs)
               ^^^^^^^^^^^^^^^^^^^^^^^^^^^^^^^^^^^^^^^^^^^^^^^^^^^^^^^^^^^^
  File "C:\Users\rsien\Desktop\python-django\workout_logger\workout\views.py", line 1308, in redirect_to_dashboard
    if request.startswith('admin'):
       ^^^^^^^^^^^^^^^^^^
AttributeError: 'WSGIRequest' object has no attribute 'startswith'
2024-06-15 14:51:01,934 - INFO - C:\Users\rsien\Desktop\python-django\workout_logger\workout\views.py changed, reloading.: 
2024-06-15 14:51:17,662 - INFO - C:\Users\rsien\Desktop\python-django\workout_logger\workout\views.py changed, reloading.: 
2024-06-15 14:51:20,956 - INFO - C:\Users\rsien\Desktop\python-django\workout_logger\workout\views.py changed, reloading.: 
2024-06-15 14:52:02,945 - INFO - C:\Users\rsien\Desktop\python-django\workout_logger\workout\views.py changed, reloading.: 
2024-06-15 14:52:06,175 - INFO - C:\Users\rsien\Desktop\python-django\workout_logger\workout\views.py changed, reloading.: 
2024-06-15 14:55:25,744 - INFO - C:\Users\rsien\Desktop\python-django\workout_logger\workout\urls.py changed, reloading.: 
2024-06-15 14:55:30,734 - WARNING - Not Found: /favicon.ico: 
2024-06-15 14:56:40,976 - INFO - C:\Users\rsien\Desktop\python-django\workout_logger\workout\urls.py changed, reloading.: 
2024-06-15 14:56:45,701 - INFO - User has been logged out.: 
2024-06-15 14:56:45,729 - WARNING - User must be logged in to view 'dashboard'.: 
2024-06-15 14:56:45,736 - WARNING - User must be logged in to view 'dashboard'.: 
2024-06-15 14:56:45,743 - WARNING - User must be logged in to view 'dashboard'.: 
2024-06-15 14:56:45,750 - WARNING - User must be logged in to view 'dashboard'.: 
2024-06-15 14:56:45,757 - WARNING - User must be logged in to view 'dashboard'.: 
2024-06-15 14:56:45,764 - WARNING - User must be logged in to view 'dashboard'.: 
2024-06-15 14:56:45,772 - WARNING - User must be logged in to view 'dashboard'.: 
2024-06-15 14:56:45,779 - WARNING - User must be logged in to view 'dashboard'.: 
2024-06-15 14:56:45,786 - WARNING - User must be logged in to view 'dashboard'.: 
2024-06-15 14:56:45,793 - WARNING - User must be logged in to view 'dashboard'.: 
2024-06-15 14:56:45,800 - WARNING - User must be logged in to view 'dashboard'.: 
2024-06-15 14:56:45,806 - WARNING - User must be logged in to view 'dashboard'.: 
2024-06-15 14:56:45,813 - WARNING - User must be logged in to view 'dashboard'.: 
2024-06-15 14:56:45,819 - WARNING - User must be logged in to view 'dashboard'.: 
2024-06-15 14:56:45,826 - WARNING - User must be logged in to view 'dashboard'.: 
2024-06-15 14:56:45,832 - WARNING - User must be logged in to view 'dashboard'.: 
2024-06-15 14:56:45,839 - WARNING - User must be logged in to view 'dashboard'.: 
2024-06-15 14:56:45,846 - WARNING - User must be logged in to view 'dashboard'.: 
2024-06-15 14:56:45,853 - WARNING - User must be logged in to view 'dashboard'.: 
2024-06-15 14:56:46,893 - WARNING - User must be logged in to view 'dashboard'.: 
2024-06-15 14:56:46,900 - WARNING - User must be logged in to view 'dashboard'.: 
2024-06-15 14:56:46,909 - WARNING - User must be logged in to view 'dashboard'.: 
2024-06-15 14:56:46,917 - WARNING - User must be logged in to view 'dashboard'.: 
2024-06-15 14:56:46,925 - WARNING - User must be logged in to view 'dashboard'.: 
2024-06-15 14:56:46,933 - WARNING - User must be logged in to view 'dashboard'.: 
2024-06-15 14:56:46,940 - WARNING - User must be logged in to view 'dashboard'.: 
2024-06-15 14:56:46,948 - WARNING - User must be logged in to view 'dashboard'.: 
2024-06-15 14:56:46,956 - WARNING - User must be logged in to view 'dashboard'.: 
2024-06-15 14:56:46,962 - WARNING - User must be logged in to view 'dashboard'.: 
2024-06-15 14:56:46,971 - WARNING - User must be logged in to view 'dashboard'.: 
2024-06-15 14:56:46,978 - WARNING - User must be logged in to view 'dashboard'.: 
2024-06-15 14:56:46,986 - WARNING - User must be logged in to view 'dashboard'.: 
2024-06-15 14:56:46,994 - WARNING - User must be logged in to view 'dashboard'.: 
2024-06-15 14:56:47,001 - WARNING - User must be logged in to view 'dashboard'.: 
2024-06-15 14:56:47,007 - WARNING - User must be logged in to view 'dashboard'.: 
2024-06-15 14:56:47,015 - WARNING - User must be logged in to view 'dashboard'.: 
2024-06-15 14:56:47,022 - WARNING - User must be logged in to view 'dashboard'.: 
2024-06-15 14:56:47,030 - WARNING - User must be logged in to view 'dashboard'.: 
2024-06-15 14:56:47,036 - WARNING - User must be logged in to view 'dashboard'.: 
2024-06-15 14:56:50,942 - WARNING - User must be logged in to view 'dashboard'.: 
2024-06-15 14:56:50,950 - WARNING - User must be logged in to view 'dashboard'.: 
2024-06-15 14:56:50,957 - WARNING - User must be logged in to view 'dashboard'.: 
2024-06-15 14:56:50,964 - WARNING - User must be logged in to view 'dashboard'.: 
2024-06-15 14:56:50,971 - WARNING - User must be logged in to view 'dashboard'.: 
2024-06-15 14:56:50,978 - WARNING - User must be logged in to view 'dashboard'.: 
2024-06-15 14:56:50,987 - WARNING - User must be logged in to view 'dashboard'.: 
2024-06-15 14:56:50,994 - WARNING - User must be logged in to view 'dashboard'.: 
2024-06-15 14:56:51,001 - WARNING - User must be logged in to view 'dashboard'.: 
2024-06-15 14:56:51,007 - WARNING - User must be logged in to view 'dashboard'.: 
2024-06-15 14:56:51,014 - WARNING - User must be logged in to view 'dashboard'.: 
2024-06-15 14:56:51,020 - WARNING - User must be logged in to view 'dashboard'.: 
2024-06-15 14:56:51,027 - WARNING - User must be logged in to view 'dashboard'.: 
2024-06-15 14:56:51,033 - WARNING - User must be logged in to view 'dashboard'.: 
2024-06-15 14:56:51,040 - WARNING - User must be logged in to view 'dashboard'.: 
2024-06-15 14:56:51,047 - WARNING - User must be logged in to view 'dashboard'.: 
2024-06-15 14:56:51,053 - WARNING - User must be logged in to view 'dashboard'.: 
2024-06-15 14:56:51,060 - WARNING - User must be logged in to view 'dashboard'.: 
2024-06-15 14:56:51,068 - WARNING - User must be logged in to view 'dashboard'.: 
2024-06-15 14:56:51,074 - WARNING - User must be logged in to view 'dashboard'.: 
2024-06-15 14:56:56,118 - WARNING - User must be logged in to view 'dashboard'.: 
2024-06-15 14:56:56,126 - WARNING - User must be logged in to view 'dashboard'.: 
2024-06-15 14:56:56,134 - WARNING - User must be logged in to view 'dashboard'.: 
2024-06-15 14:56:56,141 - WARNING - User must be logged in to view 'dashboard'.: 
2024-06-15 14:56:56,148 - WARNING - User must be logged in to view 'dashboard'.: 
2024-06-15 14:56:56,157 - WARNING - User must be logged in to view 'dashboard'.: 
2024-06-15 14:56:56,166 - WARNING - User must be logged in to view 'dashboard'.: 
2024-06-15 14:56:56,173 - WARNING - User must be logged in to view 'dashboard'.: 
2024-06-15 14:56:56,181 - WARNING - User must be logged in to view 'dashboard'.: 
2024-06-15 14:56:56,188 - WARNING - User must be logged in to view 'dashboard'.: 
2024-06-15 14:56:56,196 - WARNING - User must be logged in to view 'dashboard'.: 
2024-06-15 14:56:56,205 - WARNING - User must be logged in to view 'dashboard'.: 
2024-06-15 14:56:56,214 - WARNING - User must be logged in to view 'dashboard'.: 
2024-06-15 14:56:56,221 - WARNING - User must be logged in to view 'dashboard'.: 
2024-06-15 14:56:56,228 - WARNING - User must be logged in to view 'dashboard'.: 
2024-06-15 14:56:56,235 - WARNING - User must be logged in to view 'dashboard'.: 
2024-06-15 14:56:56,243 - WARNING - User must be logged in to view 'dashboard'.: 
2024-06-15 14:56:56,251 - WARNING - User must be logged in to view 'dashboard'.: 
2024-06-15 14:56:56,259 - WARNING - User must be logged in to view 'dashboard'.: 
2024-06-15 14:56:56,266 - WARNING - User must be logged in to view 'dashboard'.: 
2024-06-15 14:56:58,682 - WARNING - User must be logged in to view 'dashboard'.: 
2024-06-15 14:56:58,690 - WARNING - User must be logged in to view 'dashboard'.: 
2024-06-15 14:56:58,697 - WARNING - User must be logged in to view 'dashboard'.: 
2024-06-15 14:56:58,704 - WARNING - User must be logged in to view 'dashboard'.: 
2024-06-15 14:56:58,714 - WARNING - User must be logged in to view 'dashboard'.: 
2024-06-15 14:56:58,722 - WARNING - User must be logged in to view 'dashboard'.: 
2024-06-15 14:56:58,729 - WARNING - User must be logged in to view 'dashboard'.: 
2024-06-15 14:56:58,737 - WARNING - User must be logged in to view 'dashboard'.: 
2024-06-15 14:56:58,744 - WARNING - User must be logged in to view 'dashboard'.: 
2024-06-15 14:56:58,752 - WARNING - User must be logged in to view 'dashboard'.: 
2024-06-15 14:56:58,759 - WARNING - User must be logged in to view 'dashboard'.: 
2024-06-15 14:56:58,766 - WARNING - User must be logged in to view 'dashboard'.: 
2024-06-15 14:56:58,773 - WARNING - User must be logged in to view 'dashboard'.: 
2024-06-15 14:56:58,781 - WARNING - User must be logged in to view 'dashboard'.: 
2024-06-15 14:56:58,787 - WARNING - User must be logged in to view 'dashboard'.: 
2024-06-15 14:56:58,794 - WARNING - User must be logged in to view 'dashboard'.: 
2024-06-15 14:56:58,802 - WARNING - User must be logged in to view 'dashboard'.: 
2024-06-15 14:56:58,808 - WARNING - User must be logged in to view 'dashboard'.: 
2024-06-15 14:56:58,816 - WARNING - User must be logged in to view 'dashboard'.: 
2024-06-15 14:56:58,822 - WARNING - User must be logged in to view 'dashboard'.: 
2024-06-15 14:56:59,027 - INFO - C:\Users\rsien\Desktop\python-django\workout_logger\workout\urls.py changed, reloading.: 
2024-06-15 14:57:00,996 - DEBUG - GET request to login: 
2024-06-15 14:57:05,195 - DEBUG - GET request to login: 
2024-06-15 14:57:06,660 - DEBUG - POST request to login: 
2024-06-15 14:58:43,738 - INFO - C:\Users\rsien\Desktop\python-django\workout_logger\workout\urls.py changed, reloading.: 
2024-06-15 14:58:49,120 - INFO - C:\Users\rsien\Desktop\python-django\workout_logger\workout_logger\urls.py changed, reloading.: 
2024-06-15 14:59:08,323 - INFO - C:\Users\rsien\Desktop\python-django\workout_logger\workout\views.py changed, reloading.: 
2024-06-15 14:59:30,644 - ERROR - Internal Server Error: /challenge/1/join: 
Traceback (most recent call last):
  File "C:\Users\rsien\miniconda3\Lib\site-packages\django\core\handlers\exception.py", line 55, in inner
    response = get_response(request)
               ^^^^^^^^^^^^^^^^^^^^^
  File "C:\Users\rsien\miniconda3\Lib\site-packages\django\core\handlers\base.py", line 197, in _get_response
    response = wrapped_callback(request, *callback_args, **callback_kwargs)
               ^^^^^^^^^^^^^^^^^^^^^^^^^^^^^^^^^^^^^^^^^^^^^^^^^^^^^^^^^^^^
  File "C:\Users\rsien\Desktop\python-django\workout_logger\workout\views.py", line 257, in join_challenge
    workout = Workout.objects.get(id=challenge_id)
              ^^^^^^^^^^^^^^^^^^^^^^^^^^^^^^^^^^^^
  File "C:\Users\rsien\miniconda3\Lib\site-packages\django\db\models\manager.py", line 87, in manager_method
    return getattr(self.get_queryset(), name)(*args, **kwargs)
           ^^^^^^^^^^^^^^^^^^^^^^^^^^^^^^^^^^^^^^^^^^^^^^^^^^^
  File "C:\Users\rsien\miniconda3\Lib\site-packages\django\db\models\query.py", line 637, in get
    raise self.model.DoesNotExist(
workout.models.Workout.DoesNotExist: Workout matching query does not exist.
2024-06-15 14:59:41,939 - DEBUG - GET request to edit profile: 
2024-06-15 14:59:49,109 - ERROR - Internal Server Error: /workout/: 
Traceback (most recent call last):
  File "C:\Users\rsien\miniconda3\Lib\site-packages\django\db\models\fields\__init__.py", line 2053, in get_prep_value
    return int(value)
           ^^^^^^^^^^
ValueError: invalid literal for int() with base 10: ''

The above exception was the direct cause of the following exception:

Traceback (most recent call last):
  File "C:\Users\rsien\miniconda3\Lib\site-packages\django\core\handlers\exception.py", line 55, in inner
    response = get_response(request)
               ^^^^^^^^^^^^^^^^^^^^^
  File "C:\Users\rsien\miniconda3\Lib\site-packages\django\core\handlers\base.py", line 197, in _get_response
    response = wrapped_callback(request, *callback_args, **callback_kwargs)
               ^^^^^^^^^^^^^^^^^^^^^^^^^^^^^^^^^^^^^^^^^^^^^^^^^^^^^^^^^^^^
  File "C:\Users\rsien\Desktop\python-django\workout_logger\workout\views.py", line 721, in workout
    workout = Workout.objects.get(id=id)
              ^^^^^^^^^^^^^^^^^^^^^^^^^^
  File "C:\Users\rsien\miniconda3\Lib\site-packages\django\db\models\manager.py", line 87, in manager_method
    return getattr(self.get_queryset(), name)(*args, **kwargs)
           ^^^^^^^^^^^^^^^^^^^^^^^^^^^^^^^^^^^^^^^^^^^^^^^^^^^
  File "C:\Users\rsien\miniconda3\Lib\site-packages\django\db\models\query.py", line 623, in get
    clone = self._chain() if self.query.combinator else self.filter(*args, **kwargs)
                                                        ^^^^^^^^^^^^^^^^^^^^^^^^^^^^
  File "C:\Users\rsien\miniconda3\Lib\site-packages\django\db\models\query.py", line 1436, in filter
    return self._filter_or_exclude(False, args, kwargs)
           ^^^^^^^^^^^^^^^^^^^^^^^^^^^^^^^^^^^^^^^^^^^^
  File "C:\Users\rsien\miniconda3\Lib\site-packages\django\db\models\query.py", line 1454, in _filter_or_exclude
    clone._filter_or_exclude_inplace(negate, args, kwargs)
  File "C:\Users\rsien\miniconda3\Lib\site-packages\django\db\models\query.py", line 1461, in _filter_or_exclude_inplace
    self._query.add_q(Q(*args, **kwargs))
  File "C:\Users\rsien\miniconda3\Lib\site-packages\django\db\models\sql\query.py", line 1546, in add_q
    clause, _ = self._add_q(q_object, self.used_aliases)
                ^^^^^^^^^^^^^^^^^^^^^^^^^^^^^^^^^^^^^^^^
  File "C:\Users\rsien\miniconda3\Lib\site-packages\django\db\models\sql\query.py", line 1577, in _add_q
    child_clause, needed_inner = self.build_filter(
                                 ^^^^^^^^^^^^^^^^^^
  File "C:\Users\rsien\miniconda3\Lib\site-packages\django\db\models\sql\query.py", line 1492, in build_filter
    condition = self.build_lookup(lookups, col, value)
                ^^^^^^^^^^^^^^^^^^^^^^^^^^^^^^^^^^^^^^
  File "C:\Users\rsien\miniconda3\Lib\site-packages\django\db\models\sql\query.py", line 1319, in build_lookup
    lookup = lookup_class(lhs, rhs)
             ^^^^^^^^^^^^^^^^^^^^^^
  File "C:\Users\rsien\miniconda3\Lib\site-packages\django\db\models\lookups.py", line 27, in __init__
    self.rhs = self.get_prep_lookup()
               ^^^^^^^^^^^^^^^^^^^^^^
  File "C:\Users\rsien\miniconda3\Lib\site-packages\django\db\models\lookups.py", line 341, in get_prep_lookup
    return super().get_prep_lookup()
           ^^^^^^^^^^^^^^^^^^^^^^^^^
  File "C:\Users\rsien\miniconda3\Lib\site-packages\django\db\models\lookups.py", line 85, in get_prep_lookup
    return self.lhs.output_field.get_prep_value(self.rhs)
           ^^^^^^^^^^^^^^^^^^^^^^^^^^^^^^^^^^^^^^^^^^^^^^
  File "C:\Users\rsien\miniconda3\Lib\site-packages\django\db\models\fields\__init__.py", line 2055, in get_prep_value
    raise e.__class__(
ValueError: Field 'id' expected a number but got ''.
2024-06-15 15:00:31,795 - DEBUG - GET request to edit profile: 
2024-06-15 15:00:41,086 - DEBUG - GET request to edit profile: 
2024-06-15 15:00:42,141 - DEBUG - GET request to edit profile: 
2024-06-15 15:00:45,609 - DEBUG - GET request to edit profile: 
2024-06-15 15:02:06,186 - DEBUG - GET request to edit profile: 
2024-06-15 15:02:07,009 - DEBUG - GET request to edit profile: 
2024-06-15 15:02:22,933 - DEBUG - GET request to edit profile: 
2024-06-15 15:02:33,233 - DEBUG - GET request to edit profile: 
2024-06-15 15:03:17,477 - DEBUG - GET request to edit profile: 
2024-06-15 15:03:18,156 - DEBUG - GET request to edit profile: 
2024-06-15 15:03:18,870 - DEBUG - GET request to edit profile: 
2024-06-15 15:04:33,057 - DEBUG - GET request to edit profile: 
2024-06-15 14:18:26,093 - DEBUG - GET request to login: 
2024-06-15 14:18:32,972 - DEBUG - POST request to login: 
2024-06-15 14:20:34,510 - INFO - /Users/janrydzewski/Developer/Studies/Django/workout_logger/workout/views.py changed, reloading.: 
2024-06-15 14:20:37,937 - INFO - /Users/janrydzewski/Developer/Studies/Django/workout_logger/workout/views.py changed, reloading.: 
2024-06-15 14:21:51,240 - INFO - /Users/janrydzewski/Developer/Studies/Django/workout_logger/workout/views.py changed, reloading.: 
2024-06-15 14:21:57,673 - INFO - /Users/janrydzewski/Developer/Studies/Django/workout_logger/workout/views.py changed, reloading.: 
2024-06-15 14:22:06,184 - INFO - /Users/janrydzewski/Developer/Studies/Django/workout_logger/workout/views.py changed, reloading.: 
2024-06-15 14:22:21,765 - INFO - /Users/janrydzewski/Developer/Studies/Django/workout_logger/workout/views.py changed, reloading.: 
2024-06-15 14:22:28,173 - INFO - /Users/janrydzewski/Developer/Studies/Django/workout_logger/workout/views.py changed, reloading.: 
2024-06-15 14:22:30,460 - INFO - /Users/janrydzewski/Developer/Studies/Django/workout_logger/workout/views.py changed, reloading.: 
2024-06-15 14:22:35,820 - INFO - /Users/janrydzewski/Developer/Studies/Django/workout_logger/workout/views.py changed, reloading.: 
2024-06-15 14:23:09,483 - INFO - /Users/janrydzewski/Developer/Studies/Django/workout_logger/workout/views.py changed, reloading.: 
2024-06-15 14:23:28,095 - INFO - /Users/janrydzewski/Developer/Studies/Django/workout_logger/workout/views.py changed, reloading.: 
2024-06-15 14:23:45,515 - DEBUG - GET request to new workout: 
2024-06-15 14:24:21,988 - DEBUG - GET request to login: 
2024-06-15 14:25:05,578 - DEBUG - GET request to new workout: 
2024-06-15 14:25:13,602 - DEBUG - GET request to new workout: 
2024-06-15 14:27:02,220 - ERROR - Internal Server Error: /challenge/8/join: 
Traceback (most recent call last):
  File "/Library/Frameworks/Python.framework/Versions/3.12/lib/python3.12/site-packages/django/db/models/query.py", line 588, in get_or_create
    return self.get(**kwargs), False
           ^^^^^^^^^^^^^^^^^^
  File "/Library/Frameworks/Python.framework/Versions/3.12/lib/python3.12/site-packages/django/db/models/query.py", line 439, in get
    raise self.model.DoesNotExist(
workout.models.UserChallenge.DoesNotExist: UserChallenge matching query does not exist.

During handling of the above exception, another exception occurred:

Traceback (most recent call last):
  File "/Library/Frameworks/Python.framework/Versions/3.12/lib/python3.12/site-packages/django/core/handlers/exception.py", line 47, in inner
    response = get_response(request)
               ^^^^^^^^^^^^^^^^^^^^^
  File "/Library/Frameworks/Python.framework/Versions/3.12/lib/python3.12/site-packages/django/core/handlers/base.py", line 181, in _get_response
    response = wrapped_callback(request, *callback_args, **callback_kwargs)
               ^^^^^^^^^^^^^^^^^^^^^^^^^^^^^^^^^^^^^^^^^^^^^^^^^^^^^^^^^^^^
  File "/Users/janrydzewski/Developer/Studies/Django/workout_logger/workout/views.py", line 269, in join_challenge
    user_challenge, created = UserChallenge.objects.get_or_create(user=user, challenge=challenge, workout=workout)
                              ^^^^^^^^^^^^^^^^^^^^^^^^^^^^^^^^^^^^^^^^^^^^^^^^^^^^^^^^^^^^^^^^^^^^^^^^^^^^^^^^^^^^
  File "/Library/Frameworks/Python.framework/Versions/3.12/lib/python3.12/site-packages/django/db/models/manager.py", line 85, in manager_method
    return getattr(self.get_queryset(), name)(*args, **kwargs)
           ^^^^^^^^^^^^^^^^^^^^^^^^^^^^^^^^^^^^^^^^^^^^^^^^^^^
  File "/Library/Frameworks/Python.framework/Versions/3.12/lib/python3.12/site-packages/django/db/models/query.py", line 595, in get_or_create
    return self.create(**params), True
           ^^^^^^^^^^^^^^^^^^^^^
  File "/Library/Frameworks/Python.framework/Versions/3.12/lib/python3.12/site-packages/django/db/models/query.py", line 457, in create
    obj.save(force_insert=True, using=self.db)
  File "/Users/janrydzewski/Developer/Studies/Django/workout_logger/workout/models.py", line 960, in save
    exercises_count = self.workout.exercise_set.count()
                      ^^^^^^^^^^^^^^^^^^^^^^^^^
AttributeError: 'Workout' object has no attribute 'exercise_set'
2024-06-15 14:27:06,017 - ERROR - Internal Server Error: /challenge/8/join: 
Traceback (most recent call last):
  File "/Library/Frameworks/Python.framework/Versions/3.12/lib/python3.12/site-packages/django/db/models/query.py", line 588, in get_or_create
    return self.get(**kwargs), False
           ^^^^^^^^^^^^^^^^^^
  File "/Library/Frameworks/Python.framework/Versions/3.12/lib/python3.12/site-packages/django/db/models/query.py", line 439, in get
    raise self.model.DoesNotExist(
workout.models.UserChallenge.DoesNotExist: UserChallenge matching query does not exist.

During handling of the above exception, another exception occurred:

Traceback (most recent call last):
  File "/Library/Frameworks/Python.framework/Versions/3.12/lib/python3.12/site-packages/django/core/handlers/exception.py", line 47, in inner
    response = get_response(request)
               ^^^^^^^^^^^^^^^^^^^^^
  File "/Library/Frameworks/Python.framework/Versions/3.12/lib/python3.12/site-packages/django/core/handlers/base.py", line 181, in _get_response
    response = wrapped_callback(request, *callback_args, **callback_kwargs)
               ^^^^^^^^^^^^^^^^^^^^^^^^^^^^^^^^^^^^^^^^^^^^^^^^^^^^^^^^^^^^
  File "/Users/janrydzewski/Developer/Studies/Django/workout_logger/workout/views.py", line 269, in join_challenge
    user_challenge, created = UserChallenge.objects.get_or_create(user=user, challenge=challenge, workout=workout)
                              ^^^^^^^^^^^^^^^^^^^^^^^^^^^^^^^^^^^^^^^^^^^^^^^^^^^^^^^^^^^^^^^^^^^^^^^^^^^^^^^^^^^^
  File "/Library/Frameworks/Python.framework/Versions/3.12/lib/python3.12/site-packages/django/db/models/manager.py", line 85, in manager_method
    return getattr(self.get_queryset(), name)(*args, **kwargs)
           ^^^^^^^^^^^^^^^^^^^^^^^^^^^^^^^^^^^^^^^^^^^^^^^^^^^
  File "/Library/Frameworks/Python.framework/Versions/3.12/lib/python3.12/site-packages/django/db/models/query.py", line 595, in get_or_create
    return self.create(**params), True
           ^^^^^^^^^^^^^^^^^^^^^
  File "/Library/Frameworks/Python.framework/Versions/3.12/lib/python3.12/site-packages/django/db/models/query.py", line 457, in create
    obj.save(force_insert=True, using=self.db)
  File "/Users/janrydzewski/Developer/Studies/Django/workout_logger/workout/models.py", line 960, in save
    exercises_count = self.workout.exercise_set.count()
                      ^^^^^^^^^^^^^^^^^^^^^^^^^
AttributeError: 'Workout' object has no attribute 'exercise_set'
2024-06-15 14:28:24,185 - INFO - /Users/janrydzewski/Developer/Studies/Django/workout_logger/workout/views.py changed, reloading.: 
2024-06-15 14:28:25,624 - INFO - /Users/janrydzewski/Developer/Studies/Django/workout_logger/workout/views.py changed, reloading.: 
2024-06-15 14:29:00,325 - INFO - /Users/janrydzewski/Developer/Studies/Django/workout_logger/workout/views.py changed, reloading.: 
2024-06-15 14:29:20,967 - INFO - /Users/janrydzewski/Developer/Studies/Django/workout_logger/workout/views.py changed, reloading.: 
2024-06-15 14:29:28,399 - INFO - /Users/janrydzewski/Developer/Studies/Django/workout_logger/workout/views.py changed, reloading.: 
2024-06-15 14:29:33,746 - INFO - /Users/janrydzewski/Developer/Studies/Django/workout_logger/workout/views.py changed, reloading.: 
2024-06-15 14:29:54,277 - INFO - /Users/janrydzewski/Developer/Studies/Django/workout_logger/workout/views.py changed, reloading.: 
2024-06-15 14:31:06,497 - INFO - /Users/janrydzewski/Developer/Studies/Django/workout_logger/workout/views.py changed, reloading.: 
2024-06-15 14:31:24,318 - INFO - /Users/janrydzewski/Developer/Studies/Django/workout_logger/workout/views.py changed, reloading.: 
2024-06-15 14:32:57,395 - INFO - /Users/janrydzewski/Developer/Studies/Django/workout_logger/workout/views.py changed, reloading.: 
2024-06-15 14:32:58,675 - INFO - /Users/janrydzewski/Developer/Studies/Django/workout_logger/workout/views.py changed, reloading.: 
2024-06-15 14:33:00,980 - INFO - /Users/janrydzewski/Developer/Studies/Django/workout_logger/workout/views.py changed, reloading.: 
2024-06-15 14:33:02,285 - INFO - /Users/janrydzewski/Developer/Studies/Django/workout_logger/workout/views.py changed, reloading.: 
2024-06-15 14:33:04,557 - INFO - /Users/janrydzewski/Developer/Studies/Django/workout_logger/workout/views.py changed, reloading.: 
2024-06-15 14:33:06,849 - INFO - /Users/janrydzewski/Developer/Studies/Django/workout_logger/workout/views.py changed, reloading.: 
2024-06-15 14:33:53,681 - INFO - /Users/janrydzewski/Developer/Studies/Django/workout_logger/workout/views.py changed, reloading.: 
2024-06-15 14:33:56,099 - INFO - /Users/janrydzewski/Developer/Studies/Django/workout_logger/workout/views.py changed, reloading.: 
2024-06-15 14:33:57,439 - INFO - /Users/janrydzewski/Developer/Studies/Django/workout_logger/workout/views.py changed, reloading.: 
2024-06-15 14:33:58,736 - INFO - /Users/janrydzewski/Developer/Studies/Django/workout_logger/workout/views.py changed, reloading.: 
2024-06-15 14:34:01,015 - INFO - /Users/janrydzewski/Developer/Studies/Django/workout_logger/workout/views.py changed, reloading.: 
2024-06-15 14:35:53,324 - ERROR - Internal Server Error: /challenge/8/join: 
Traceback (most recent call last):
  File "/Library/Frameworks/Python.framework/Versions/3.12/lib/python3.12/site-packages/django/core/handlers/exception.py", line 47, in inner
    response = get_response(request)
               ^^^^^^^^^^^^^^^^^^^^^
  File "/Library/Frameworks/Python.framework/Versions/3.12/lib/python3.12/site-packages/django/core/handlers/base.py", line 181, in _get_response
    response = wrapped_callback(request, *callback_args, **callback_kwargs)
               ^^^^^^^^^^^^^^^^^^^^^^^^^^^^^^^^^^^^^^^^^^^^^^^^^^^^^^^^^^^^
  File "/Users/janrydzewski/Developer/Studies/Django/workout_logger/workout/views.py", line 266, in join_challenge
    joined_at=datetime.now(),
              ^^^^^^^^^^^^
AttributeError: module 'datetime' has no attribute 'now'
2024-06-15 14:36:10,894 - INFO - /Users/janrydzewski/Developer/Studies/Django/workout_logger/workout/views.py changed, reloading.: 
2024-06-15 14:36:15,364 - ERROR - Internal Server Error: /challenge/8/join: 
Traceback (most recent call last):
  File "/Library/Frameworks/Python.framework/Versions/3.12/lib/python3.12/site-packages/django/core/handlers/exception.py", line 47, in inner
    response = get_response(request)
               ^^^^^^^^^^^^^^^^^^^^^
  File "/Library/Frameworks/Python.framework/Versions/3.12/lib/python3.12/site-packages/django/core/handlers/base.py", line 181, in _get_response
    response = wrapped_callback(request, *callback_args, **callback_kwargs)
               ^^^^^^^^^^^^^^^^^^^^^^^^^^^^^^^^^^^^^^^^^^^^^^^^^^^^^^^^^^^^
  File "/Users/janrydzewski/Developer/Studies/Django/workout_logger/workout/views.py", line 269, in join_challenge
    user_challenge.save()
  File "/Users/janrydzewski/Developer/Studies/Django/workout_logger/workout/models.py", line 960, in save
    exercises_count = self.workout.exercise_set.count()
                      ^^^^^^^^^^^^^^^^^^^^^^^^^
AttributeError: 'Workout' object has no attribute 'exercise_set'
2024-06-15 14:36:55,954 - INFO - /Users/janrydzewski/Developer/Studies/Django/workout_logger/workout/models.py changed, reloading.: 
2024-06-15 14:37:09,057 - ERROR - Internal Server Error: /challenge/8/join: 
Traceback (most recent call last):
  File "/Library/Frameworks/Python.framework/Versions/3.12/lib/python3.12/site-packages/django/core/handlers/exception.py", line 47, in inner
    response = get_response(request)
               ^^^^^^^^^^^^^^^^^^^^^
  File "/Library/Frameworks/Python.framework/Versions/3.12/lib/python3.12/site-packages/django/core/handlers/base.py", line 188, in _get_response
    self.check_response(response, callback)
  File "/Library/Frameworks/Python.framework/Versions/3.12/lib/python3.12/site-packages/django/core/handlers/base.py", line 309, in check_response
    raise ValueError(
ValueError: The view workout.views.join_challenge didn't return an HttpResponse object. It returned None instead.
2024-06-15 14:37:23,755 - INFO - /Users/janrydzewski/Developer/Studies/Django/workout_logger/workout/views.py changed, reloading.: 
2024-06-15 14:37:29,201 - INFO - /Users/janrydzewski/Developer/Studies/Django/workout_logger/workout/views.py changed, reloading.: 
2024-06-15 14:38:03,986 - DEBUG - GET request to login: 
2024-06-15 14:38:09,019 - DEBUG - POST request to login: 
2024-06-15 14:38:27,318 - INFO - /Users/janrydzewski/Developer/Studies/Django/workout_logger/workout/views.py changed, reloading.: 
2024-06-15 14:38:29,730 - INFO - /Users/janrydzewski/Developer/Studies/Django/workout_logger/workout/views.py changed, reloading.: 
2024-06-15 14:38:34,638 - ERROR - Internal Server Error: /challenge/8/join: 
Traceback (most recent call last):
  File "/Library/Frameworks/Python.framework/Versions/3.12/lib/python3.12/site-packages/django/db/backends/utils.py", line 85, in _execute
    return self.cursor.execute(sql, params)
           ^^^^^^^^^^^^^^^^^^^^^^^^^^^^^^^^
  File "/Library/Frameworks/Python.framework/Versions/3.12/lib/python3.12/site-packages/django/db/backends/sqlite3/base.py", line 416, in execute
    return Database.Cursor.execute(self, query, params)
           ^^^^^^^^^^^^^^^^^^^^^^^^^^^^^^^^^^^^^^^^^^^^
sqlite3.IntegrityError: UNIQUE constraint failed: workout_userchallenge.user_id, workout_userchallenge.challenge_id

The above exception was the direct cause of the following exception:

Traceback (most recent call last):
  File "/Library/Frameworks/Python.framework/Versions/3.12/lib/python3.12/site-packages/django/core/handlers/exception.py", line 47, in inner
    response = get_response(request)
               ^^^^^^^^^^^^^^^^^^^^^
  File "/Library/Frameworks/Python.framework/Versions/3.12/lib/python3.12/site-packages/django/core/handlers/base.py", line 181, in _get_response
    response = wrapped_callback(request, *callback_args, **callback_kwargs)
               ^^^^^^^^^^^^^^^^^^^^^^^^^^^^^^^^^^^^^^^^^^^^^^^^^^^^^^^^^^^^
  File "/Users/janrydzewski/Developer/Studies/Django/workout_logger/workout/views.py", line 269, in join_challenge
    user_challenge.save()
  File "/Library/Frameworks/Python.framework/Versions/3.12/lib/python3.12/site-packages/django/db/models/base.py", line 743, in save
    self.save_base(using=using, force_insert=force_insert,
  File "/Library/Frameworks/Python.framework/Versions/3.12/lib/python3.12/site-packages/django/db/models/base.py", line 780, in save_base
    updated = self._save_table(
              ^^^^^^^^^^^^^^^^^
  File "/Library/Frameworks/Python.framework/Versions/3.12/lib/python3.12/site-packages/django/db/models/base.py", line 885, in _save_table
    results = self._do_insert(cls._base_manager, using, fields, returning_fields, raw)
              ^^^^^^^^^^^^^^^^^^^^^^^^^^^^^^^^^^^^^^^^^^^^^^^^^^^^^^^^^^^^^^^^^^^^^^^^
  File "/Library/Frameworks/Python.framework/Versions/3.12/lib/python3.12/site-packages/django/db/models/base.py", line 923, in _do_insert
    return manager._insert(
           ^^^^^^^^^^^^^^^^
  File "/Library/Frameworks/Python.framework/Versions/3.12/lib/python3.12/site-packages/django/db/models/manager.py", line 85, in manager_method
    return getattr(self.get_queryset(), name)(*args, **kwargs)
           ^^^^^^^^^^^^^^^^^^^^^^^^^^^^^^^^^^^^^^^^^^^^^^^^^^^
  File "/Library/Frameworks/Python.framework/Versions/3.12/lib/python3.12/site-packages/django/db/models/query.py", line 1301, in _insert
    return query.get_compiler(using=using).execute_sql(returning_fields)
           ^^^^^^^^^^^^^^^^^^^^^^^^^^^^^^^^^^^^^^^^^^^^^^^^^^^^^^^^^^^^^
  File "/Library/Frameworks/Python.framework/Versions/3.12/lib/python3.12/site-packages/django/db/models/sql/compiler.py", line 1441, in execute_sql
    cursor.execute(sql, params)
  File "/Library/Frameworks/Python.framework/Versions/3.12/lib/python3.12/site-packages/django/db/backends/utils.py", line 99, in execute
    return super().execute(sql, params)
           ^^^^^^^^^^^^^^^^^^^^^^^^^^^^
  File "/Library/Frameworks/Python.framework/Versions/3.12/lib/python3.12/site-packages/django/db/backends/utils.py", line 67, in execute
    return self._execute_with_wrappers(sql, params, many=False, executor=self._execute)
           ^^^^^^^^^^^^^^^^^^^^^^^^^^^^^^^^^^^^^^^^^^^^^^^^^^^^^^^^^^^^^^^^^^^^^^^^^^^^
  File "/Library/Frameworks/Python.framework/Versions/3.12/lib/python3.12/site-packages/django/db/backends/utils.py", line 76, in _execute_with_wrappers
    return executor(sql, params, many, context)
           ^^^^^^^^^^^^^^^^^^^^^^^^^^^^^^^^^^^^
  File "/Library/Frameworks/Python.framework/Versions/3.12/lib/python3.12/site-packages/django/db/backends/utils.py", line 80, in _execute
    with self.db.wrap_database_errors:
  File "/Library/Frameworks/Python.framework/Versions/3.12/lib/python3.12/site-packages/django/db/utils.py", line 90, in __exit__
    raise dj_exc_value.with_traceback(traceback) from exc_value
  File "/Library/Frameworks/Python.framework/Versions/3.12/lib/python3.12/site-packages/django/db/backends/utils.py", line 85, in _execute
    return self.cursor.execute(sql, params)
           ^^^^^^^^^^^^^^^^^^^^^^^^^^^^^^^^
  File "/Library/Frameworks/Python.framework/Versions/3.12/lib/python3.12/site-packages/django/db/backends/sqlite3/base.py", line 416, in execute
    return Database.Cursor.execute(self, query, params)
           ^^^^^^^^^^^^^^^^^^^^^^^^^^^^^^^^^^^^^^^^^^^^
django.db.utils.IntegrityError: UNIQUE constraint failed: workout_userchallenge.user_id, workout_userchallenge.challenge_id
2024-06-15 14:38:39,153 - ERROR - Internal Server Error: /challenge/7/join: 
Traceback (most recent call last):
  File "/Library/Frameworks/Python.framework/Versions/3.12/lib/python3.12/site-packages/django/db/backends/utils.py", line 85, in _execute
    return self.cursor.execute(sql, params)
           ^^^^^^^^^^^^^^^^^^^^^^^^^^^^^^^^
  File "/Library/Frameworks/Python.framework/Versions/3.12/lib/python3.12/site-packages/django/db/backends/sqlite3/base.py", line 416, in execute
    return Database.Cursor.execute(self, query, params)
           ^^^^^^^^^^^^^^^^^^^^^^^^^^^^^^^^^^^^^^^^^^^^
sqlite3.IntegrityError: UNIQUE constraint failed: workout_userchallenge.user_id, workout_userchallenge.challenge_id

The above exception was the direct cause of the following exception:

Traceback (most recent call last):
  File "/Library/Frameworks/Python.framework/Versions/3.12/lib/python3.12/site-packages/django/core/handlers/exception.py", line 47, in inner
    response = get_response(request)
               ^^^^^^^^^^^^^^^^^^^^^
  File "/Library/Frameworks/Python.framework/Versions/3.12/lib/python3.12/site-packages/django/core/handlers/base.py", line 181, in _get_response
    response = wrapped_callback(request, *callback_args, **callback_kwargs)
               ^^^^^^^^^^^^^^^^^^^^^^^^^^^^^^^^^^^^^^^^^^^^^^^^^^^^^^^^^^^^
  File "/Users/janrydzewski/Developer/Studies/Django/workout_logger/workout/views.py", line 269, in join_challenge
    user_challenge.save()
  File "/Library/Frameworks/Python.framework/Versions/3.12/lib/python3.12/site-packages/django/db/models/base.py", line 743, in save
    self.save_base(using=using, force_insert=force_insert,
  File "/Library/Frameworks/Python.framework/Versions/3.12/lib/python3.12/site-packages/django/db/models/base.py", line 780, in save_base
    updated = self._save_table(
              ^^^^^^^^^^^^^^^^^
  File "/Library/Frameworks/Python.framework/Versions/3.12/lib/python3.12/site-packages/django/db/models/base.py", line 885, in _save_table
    results = self._do_insert(cls._base_manager, using, fields, returning_fields, raw)
              ^^^^^^^^^^^^^^^^^^^^^^^^^^^^^^^^^^^^^^^^^^^^^^^^^^^^^^^^^^^^^^^^^^^^^^^^
  File "/Library/Frameworks/Python.framework/Versions/3.12/lib/python3.12/site-packages/django/db/models/base.py", line 923, in _do_insert
    return manager._insert(
           ^^^^^^^^^^^^^^^^
  File "/Library/Frameworks/Python.framework/Versions/3.12/lib/python3.12/site-packages/django/db/models/manager.py", line 85, in manager_method
    return getattr(self.get_queryset(), name)(*args, **kwargs)
           ^^^^^^^^^^^^^^^^^^^^^^^^^^^^^^^^^^^^^^^^^^^^^^^^^^^
  File "/Library/Frameworks/Python.framework/Versions/3.12/lib/python3.12/site-packages/django/db/models/query.py", line 1301, in _insert
    return query.get_compiler(using=using).execute_sql(returning_fields)
           ^^^^^^^^^^^^^^^^^^^^^^^^^^^^^^^^^^^^^^^^^^^^^^^^^^^^^^^^^^^^^
  File "/Library/Frameworks/Python.framework/Versions/3.12/lib/python3.12/site-packages/django/db/models/sql/compiler.py", line 1441, in execute_sql
    cursor.execute(sql, params)
  File "/Library/Frameworks/Python.framework/Versions/3.12/lib/python3.12/site-packages/django/db/backends/utils.py", line 99, in execute
    return super().execute(sql, params)
           ^^^^^^^^^^^^^^^^^^^^^^^^^^^^
  File "/Library/Frameworks/Python.framework/Versions/3.12/lib/python3.12/site-packages/django/db/backends/utils.py", line 67, in execute
    return self._execute_with_wrappers(sql, params, many=False, executor=self._execute)
           ^^^^^^^^^^^^^^^^^^^^^^^^^^^^^^^^^^^^^^^^^^^^^^^^^^^^^^^^^^^^^^^^^^^^^^^^^^^^
  File "/Library/Frameworks/Python.framework/Versions/3.12/lib/python3.12/site-packages/django/db/backends/utils.py", line 76, in _execute_with_wrappers
    return executor(sql, params, many, context)
           ^^^^^^^^^^^^^^^^^^^^^^^^^^^^^^^^^^^^
  File "/Library/Frameworks/Python.framework/Versions/3.12/lib/python3.12/site-packages/django/db/backends/utils.py", line 80, in _execute
    with self.db.wrap_database_errors:
  File "/Library/Frameworks/Python.framework/Versions/3.12/lib/python3.12/site-packages/django/db/utils.py", line 90, in __exit__
    raise dj_exc_value.with_traceback(traceback) from exc_value
  File "/Library/Frameworks/Python.framework/Versions/3.12/lib/python3.12/site-packages/django/db/backends/utils.py", line 85, in _execute
    return self.cursor.execute(sql, params)
           ^^^^^^^^^^^^^^^^^^^^^^^^^^^^^^^^
  File "/Library/Frameworks/Python.framework/Versions/3.12/lib/python3.12/site-packages/django/db/backends/sqlite3/base.py", line 416, in execute
    return Database.Cursor.execute(self, query, params)
           ^^^^^^^^^^^^^^^^^^^^^^^^^^^^^^^^^^^^^^^^^^^^
django.db.utils.IntegrityError: UNIQUE constraint failed: workout_userchallenge.user_id, workout_userchallenge.challenge_id
2024-06-15 14:39:24,750 - INFO - /Users/janrydzewski/Developer/Studies/Django/workout_logger/workout/views.py changed, reloading.: 
2024-06-15 14:41:07,482 - INFO - /Users/janrydzewski/Developer/Studies/Django/workout_logger/workout/views.py changed, reloading.: 
2024-06-15 14:41:14,200 - INFO - /Users/janrydzewski/Developer/Studies/Django/workout_logger/workout/views.py changed, reloading.: 
2024-06-15 14:41:29,686 - INFO - /Users/janrydzewski/Developer/Studies/Django/workout_logger/workout/views.py changed, reloading.: 
2024-06-15 14:43:54,047 - ERROR - Internal Server Error: /challenge/7/join: 
Traceback (most recent call last):
  File "/Library/Frameworks/Python.framework/Versions/3.12/lib/python3.12/site-packages/django/core/handlers/exception.py", line 47, in inner
    response = get_response(request)
               ^^^^^^^^^^^^^^^^^^^^^
  File "/Library/Frameworks/Python.framework/Versions/3.12/lib/python3.12/site-packages/django/core/handlers/base.py", line 188, in _get_response
    self.check_response(response, callback)
  File "/Library/Frameworks/Python.framework/Versions/3.12/lib/python3.12/site-packages/django/core/handlers/base.py", line 309, in check_response
    raise ValueError(
ValueError: The view workout.views.join_challenge didn't return an HttpResponse object. It returned None instead.
2024-06-15 14:44:29,972 - DEBUG - GET request to new workout: 
2024-06-15 14:44:45,642 - DEBUG - GET request to new workout: 
2024-06-15 14:45:55,973 - INFO - /Users/janrydzewski/Developer/Studies/Django/workout_logger/workout/views.py changed, reloading.: 
2024-06-15 14:45:59,388 - INFO - /Users/janrydzewski/Developer/Studies/Django/workout_logger/workout/views.py changed, reloading.: 
2024-06-15 14:46:12,828 - INFO - /Users/janrydzewski/Developer/Studies/Django/workout_logger/workout/views.py changed, reloading.: 
2024-06-15 14:46:26,301 - INFO - /Users/janrydzewski/Developer/Studies/Django/workout_logger/workout/views.py changed, reloading.: 
2024-06-15 14:46:41,807 - INFO - /Users/janrydzewski/Developer/Studies/Django/workout_logger/workout/views.py changed, reloading.: 
2024-06-15 14:47:23,609 - INFO - /Users/janrydzewski/Developer/Studies/Django/workout_logger/workout/views.py changed, reloading.: 
2024-06-15 14:47:25,998 - INFO - /Users/janrydzewski/Developer/Studies/Django/workout_logger/workout/views.py changed, reloading.: 
2024-06-15 14:47:28,298 - INFO - /Users/janrydzewski/Developer/Studies/Django/workout_logger/workout/views.py changed, reloading.: 
2024-06-15 14:47:39,697 - INFO - /Users/janrydzewski/Developer/Studies/Django/workout_logger/workout/views.py changed, reloading.: 
2024-06-15 14:48:26,594 - INFO - /Users/janrydzewski/Developer/Studies/Django/workout_logger/workout/views.py changed, reloading.: 
2024-06-15 14:48:29,977 - INFO - /Users/janrydzewski/Developer/Studies/Django/workout_logger/workout/views.py changed, reloading.: 
2024-06-15 14:48:31,244 - INFO - /Users/janrydzewski/Developer/Studies/Django/workout_logger/workout/views.py changed, reloading.: 
2024-06-15 14:48:34,544 - INFO - /Users/janrydzewski/Developer/Studies/Django/workout_logger/workout/views.py changed, reloading.: 
2024-06-15 14:48:39,863 - INFO - /Users/janrydzewski/Developer/Studies/Django/workout_logger/workout/views.py changed, reloading.: 
2024-06-15 14:48:50,618 - INFO - /Users/janrydzewski/Developer/Studies/Django/workout_logger/workout/views.py changed, reloading.: 
2024-06-15 14:48:59,957 - INFO - /Users/janrydzewski/Developer/Studies/Django/workout_logger/workout/urls.py changed, reloading.: 
2024-06-15 14:49:07,346 - INFO - /Users/janrydzewski/Developer/Studies/Django/workout_logger/workout/urls.py changed, reloading.: 
2024-06-15 14:49:09,654 - INFO - /Users/janrydzewski/Developer/Studies/Django/workout_logger/workout/urls.py changed, reloading.: 
2024-06-15 14:50:11,563 - INFO - /Users/janrydzewski/Developer/Studies/Django/workout_logger/workout/urls.py changed, reloading.: 
2024-06-15 14:50:14,971 - INFO - /Users/janrydzewski/Developer/Studies/Django/workout_logger/workout/urls.py changed, reloading.: 
2024-06-15 14:50:17,239 - INFO - /Users/janrydzewski/Developer/Studies/Django/workout_logger/workout/urls.py changed, reloading.: 
2024-06-15 14:50:21,336 - DEBUG - GET request to new workout: 
2024-06-15 14:51:16,204 - INFO - /Users/janrydzewski/Developer/Studies/Django/workout_logger/workout/views.py changed, reloading.: 
2024-06-15 14:51:18,610 - INFO - /Users/janrydzewski/Developer/Studies/Django/workout_logger/workout/views.py changed, reloading.: 
2024-06-15 14:51:22,927 - INFO - /Users/janrydzewski/Developer/Studies/Django/workout_logger/workout/views.py changed, reloading.: 
2024-06-15 14:51:27,216 - INFO - /Users/janrydzewski/Developer/Studies/Django/workout_logger/workout/views.py changed, reloading.: 
2024-06-15 14:51:31,682 - ERROR - Internal Server Error: /prechallenge/3: 
Traceback (most recent call last):
  File "/Library/Frameworks/Python.framework/Versions/3.12/lib/python3.12/site-packages/django/core/handlers/exception.py", line 47, in inner
    response = get_response(request)
               ^^^^^^^^^^^^^^^^^^^^^
  File "/Library/Frameworks/Python.framework/Versions/3.12/lib/python3.12/site-packages/django/core/handlers/base.py", line 181, in _get_response
    response = wrapped_callback(request, *callback_args, **callback_kwargs)
               ^^^^^^^^^^^^^^^^^^^^^^^^^^^^^^^^^^^^^^^^^^^^^^^^^^^^^^^^^^^^
  File "/Users/janrydzewski/Developer/Studies/Django/workout_logger/workout/views.py", line 362, in preview_challenge
    challenge = Challenge.objects.get(id=workout.challenge_id)
                ^^^^^^^^^^^^^^^^^^^^^^^^^^^^^^^^^^^^^^^^^^^^^^
  File "/Library/Frameworks/Python.framework/Versions/3.12/lib/python3.12/site-packages/django/db/models/manager.py", line 85, in manager_method
    return getattr(self.get_queryset(), name)(*args, **kwargs)
           ^^^^^^^^^^^^^^^^^^^^^^^^^^^^^^^^^^^^^^^^^^^^^^^^^^^
  File "/Library/Frameworks/Python.framework/Versions/3.12/lib/python3.12/site-packages/django/db/models/query.py", line 439, in get
    raise self.model.DoesNotExist(
workout.models.Challenge.DoesNotExist: Challenge matching query does not exist.
2024-06-15 14:51:34,982 - ERROR - Internal Server Error: /prechallenge/3: 
Traceback (most recent call last):
  File "/Library/Frameworks/Python.framework/Versions/3.12/lib/python3.12/site-packages/django/core/handlers/exception.py", line 47, in inner
    response = get_response(request)
               ^^^^^^^^^^^^^^^^^^^^^
  File "/Library/Frameworks/Python.framework/Versions/3.12/lib/python3.12/site-packages/django/core/handlers/base.py", line 181, in _get_response
    response = wrapped_callback(request, *callback_args, **callback_kwargs)
               ^^^^^^^^^^^^^^^^^^^^^^^^^^^^^^^^^^^^^^^^^^^^^^^^^^^^^^^^^^^^
  File "/Users/janrydzewski/Developer/Studies/Django/workout_logger/workout/views.py", line 362, in preview_challenge
    challenge = Challenge.objects.get(id=workout.challenge_id)
                ^^^^^^^^^^^^^^^^^^^^^^^^^^^^^^^^^^^^^^^^^^^^^^
  File "/Library/Frameworks/Python.framework/Versions/3.12/lib/python3.12/site-packages/django/db/models/manager.py", line 85, in manager_method
    return getattr(self.get_queryset(), name)(*args, **kwargs)
           ^^^^^^^^^^^^^^^^^^^^^^^^^^^^^^^^^^^^^^^^^^^^^^^^^^^
  File "/Library/Frameworks/Python.framework/Versions/3.12/lib/python3.12/site-packages/django/db/models/query.py", line 439, in get
    raise self.model.DoesNotExist(
workout.models.Challenge.DoesNotExist: Challenge matching query does not exist.
2024-06-15 14:52:29,241 - INFO - /Users/janrydzewski/Developer/Studies/Django/workout_logger/workout/views.py changed, reloading.: 
2024-06-15 14:52:40,724 - INFO - /Users/janrydzewski/Developer/Studies/Django/workout_logger/workout/views.py changed, reloading.: 
2024-06-15 14:52:43,412 - ERROR - Internal Server Error: /prechallenge/3: 
Traceback (most recent call last):
  File "/Library/Frameworks/Python.framework/Versions/3.12/lib/python3.12/site-packages/django/core/handlers/exception.py", line 47, in inner
    response = get_response(request)
               ^^^^^^^^^^^^^^^^^^^^^
  File "/Library/Frameworks/Python.framework/Versions/3.12/lib/python3.12/site-packages/django/core/handlers/base.py", line 181, in _get_response
    response = wrapped_callback(request, *callback_args, **callback_kwargs)
               ^^^^^^^^^^^^^^^^^^^^^^^^^^^^^^^^^^^^^^^^^^^^^^^^^^^^^^^^^^^^
  File "/Users/janrydzewski/Developer/Studies/Django/workout_logger/workout/views.py", line 350, in preview_challenge
    challenge = Challenge.objects.get(id=workout.challenge_id)
                ^^^^^^^^^^^^^^^^^^^^^^^^^^^^^^^^^^^^^^^^^^^^^^
  File "/Library/Frameworks/Python.framework/Versions/3.12/lib/python3.12/site-packages/django/db/models/manager.py", line 85, in manager_method
    return getattr(self.get_queryset(), name)(*args, **kwargs)
           ^^^^^^^^^^^^^^^^^^^^^^^^^^^^^^^^^^^^^^^^^^^^^^^^^^^
  File "/Library/Frameworks/Python.framework/Versions/3.12/lib/python3.12/site-packages/django/db/models/query.py", line 439, in get
    raise self.model.DoesNotExist(
workout.models.Challenge.DoesNotExist: Challenge matching query does not exist.
2024-06-15 14:52:59,356 - INFO - /Users/janrydzewski/Developer/Studies/Django/workout_logger/workout/views.py changed, reloading.: 
2024-06-15 14:53:04,844 - INFO - /Users/janrydzewski/Developer/Studies/Django/workout_logger/workout/views.py changed, reloading.: 
2024-06-15 14:53:24,421 - INFO - /Users/janrydzewski/Developer/Studies/Django/workout_logger/workout/views.py changed, reloading.: 
2024-06-15 14:53:25,513 - ERROR - Internal Server Error: /prechallenge/3: 
Traceback (most recent call last):
  File "/Library/Frameworks/Python.framework/Versions/3.12/lib/python3.12/site-packages/django/core/handlers/exception.py", line 47, in inner
    response = get_response(request)
               ^^^^^^^^^^^^^^^^^^^^^
  File "/Library/Frameworks/Python.framework/Versions/3.12/lib/python3.12/site-packages/django/core/handlers/base.py", line 181, in _get_response
    response = wrapped_callback(request, *callback_args, **callback_kwargs)
               ^^^^^^^^^^^^^^^^^^^^^^^^^^^^^^^^^^^^^^^^^^^^^^^^^^^^^^^^^^^^
  File "/Users/janrydzewski/Developer/Studies/Django/workout_logger/workout/views.py", line 350, in preview_challenge
    challenge = Challenge.objects.get(id=workout.challenge_id)
                ^^^^^^^^^^^^^^^^^^^^^^^^^^^^^^^^^^^^^^^^^^^^^^
  File "/Library/Frameworks/Python.framework/Versions/3.12/lib/python3.12/site-packages/django/db/models/manager.py", line 85, in manager_method
    return getattr(self.get_queryset(), name)(*args, **kwargs)
           ^^^^^^^^^^^^^^^^^^^^^^^^^^^^^^^^^^^^^^^^^^^^^^^^^^^
  File "/Library/Frameworks/Python.framework/Versions/3.12/lib/python3.12/site-packages/django/db/models/query.py", line 439, in get
    raise self.model.DoesNotExist(
workout.models.Challenge.DoesNotExist: Challenge matching query does not exist.
2024-06-15 14:53:31,325 - ERROR - Internal Server Error: /prechallenge/3: 
Traceback (most recent call last):
  File "/Library/Frameworks/Python.framework/Versions/3.12/lib/python3.12/site-packages/django/core/handlers/exception.py", line 47, in inner
    response = get_response(request)
               ^^^^^^^^^^^^^^^^^^^^^
  File "/Library/Frameworks/Python.framework/Versions/3.12/lib/python3.12/site-packages/django/core/handlers/base.py", line 181, in _get_response
    response = wrapped_callback(request, *callback_args, **callback_kwargs)
               ^^^^^^^^^^^^^^^^^^^^^^^^^^^^^^^^^^^^^^^^^^^^^^^^^^^^^^^^^^^^
  File "/Users/janrydzewski/Developer/Studies/Django/workout_logger/workout/views.py", line 350, in preview_challenge
    challenge = Challenge.objects.get(id=workout.challenge_id)
                ^^^^^^^^^^^^^^^^^^^^^^^^^^^^^^^^^^^^^^^^^^^^^^
  File "/Library/Frameworks/Python.framework/Versions/3.12/lib/python3.12/site-packages/django/db/models/manager.py", line 85, in manager_method
    return getattr(self.get_queryset(), name)(*args, **kwargs)
           ^^^^^^^^^^^^^^^^^^^^^^^^^^^^^^^^^^^^^^^^^^^^^^^^^^^
  File "/Library/Frameworks/Python.framework/Versions/3.12/lib/python3.12/site-packages/django/db/models/query.py", line 439, in get
    raise self.model.DoesNotExist(
workout.models.Challenge.DoesNotExist: Challenge matching query does not exist.
2024-06-15 14:53:32,829 - ERROR - Internal Server Error: /prechallenge/3: 
Traceback (most recent call last):
  File "/Library/Frameworks/Python.framework/Versions/3.12/lib/python3.12/site-packages/django/core/handlers/exception.py", line 47, in inner
    response = get_response(request)
               ^^^^^^^^^^^^^^^^^^^^^
  File "/Library/Frameworks/Python.framework/Versions/3.12/lib/python3.12/site-packages/django/core/handlers/base.py", line 181, in _get_response
    response = wrapped_callback(request, *callback_args, **callback_kwargs)
               ^^^^^^^^^^^^^^^^^^^^^^^^^^^^^^^^^^^^^^^^^^^^^^^^^^^^^^^^^^^^
  File "/Users/janrydzewski/Developer/Studies/Django/workout_logger/workout/views.py", line 350, in preview_challenge
    challenge = Challenge.objects.get(id=workout.challenge_id)
                ^^^^^^^^^^^^^^^^^^^^^^^^^^^^^^^^^^^^^^^^^^^^^^
  File "/Library/Frameworks/Python.framework/Versions/3.12/lib/python3.12/site-packages/django/db/models/manager.py", line 85, in manager_method
    return getattr(self.get_queryset(), name)(*args, **kwargs)
           ^^^^^^^^^^^^^^^^^^^^^^^^^^^^^^^^^^^^^^^^^^^^^^^^^^^
  File "/Library/Frameworks/Python.framework/Versions/3.12/lib/python3.12/site-packages/django/db/models/query.py", line 439, in get
    raise self.model.DoesNotExist(
workout.models.Challenge.DoesNotExist: Challenge matching query does not exist.
2024-06-15 14:53:55,098 - INFO - /Users/janrydzewski/Developer/Studies/Django/workout_logger/workout/views.py changed, reloading.: 
2024-06-15 15:01:19,614 - ERROR - Internal Server Error: /challenge/3: 
Traceback (most recent call last):
  File "/Library/Frameworks/Python.framework/Versions/3.12/lib/python3.12/site-packages/django/core/handlers/exception.py", line 47, in inner
    response = get_response(request)
               ^^^^^^^^^^^^^^^^^^^^^
  File "/Library/Frameworks/Python.framework/Versions/3.12/lib/python3.12/site-packages/django/core/handlers/base.py", line 181, in _get_response
    response = wrapped_callback(request, *callback_args, **callback_kwargs)
               ^^^^^^^^^^^^^^^^^^^^^^^^^^^^^^^^^^^^^^^^^^^^^^^^^^^^^^^^^^^^
  File "/Users/janrydzewski/Developer/Studies/Django/workout_logger/workout/views.py", line 303, in view_challenge
    user_challenge = UserChallenge.objects.get(id=1)
                     ^^^^^^^^^^^^^^^^^^^^^^^^^^^^^^^
  File "/Library/Frameworks/Python.framework/Versions/3.12/lib/python3.12/site-packages/django/db/models/manager.py", line 85, in manager_method
    return getattr(self.get_queryset(), name)(*args, **kwargs)
           ^^^^^^^^^^^^^^^^^^^^^^^^^^^^^^^^^^^^^^^^^^^^^^^^^^^
  File "/Library/Frameworks/Python.framework/Versions/3.12/lib/python3.12/site-packages/django/db/models/query.py", line 439, in get
    raise self.model.DoesNotExist(
workout.models.UserChallenge.DoesNotExist: UserChallenge matching query does not exist.
2024-06-15 15:01:25,881 - ERROR - Internal Server Error: /challenge/3: 
Traceback (most recent call last):
  File "/Library/Frameworks/Python.framework/Versions/3.12/lib/python3.12/site-packages/django/core/handlers/exception.py", line 47, in inner
    response = get_response(request)
               ^^^^^^^^^^^^^^^^^^^^^
  File "/Library/Frameworks/Python.framework/Versions/3.12/lib/python3.12/site-packages/django/core/handlers/base.py", line 181, in _get_response
    response = wrapped_callback(request, *callback_args, **callback_kwargs)
               ^^^^^^^^^^^^^^^^^^^^^^^^^^^^^^^^^^^^^^^^^^^^^^^^^^^^^^^^^^^^
  File "/Users/janrydzewski/Developer/Studies/Django/workout_logger/workout/views.py", line 303, in view_challenge
    user_challenge = UserChallenge.objects.get(id=1)
                     ^^^^^^^^^^^^^^^^^^^^^^^^^^^^^^^
  File "/Library/Frameworks/Python.framework/Versions/3.12/lib/python3.12/site-packages/django/db/models/manager.py", line 85, in manager_method
    return getattr(self.get_queryset(), name)(*args, **kwargs)
           ^^^^^^^^^^^^^^^^^^^^^^^^^^^^^^^^^^^^^^^^^^^^^^^^^^^
  File "/Library/Frameworks/Python.framework/Versions/3.12/lib/python3.12/site-packages/django/db/models/query.py", line 439, in get
    raise self.model.DoesNotExist(
workout.models.UserChallenge.DoesNotExist: UserChallenge matching query does not exist.
2024-06-15 15:01:36,803 - ERROR - Internal Server Error: /challenge/3: 
Traceback (most recent call last):
  File "/Library/Frameworks/Python.framework/Versions/3.12/lib/python3.12/site-packages/django/core/handlers/exception.py", line 47, in inner
    response = get_response(request)
               ^^^^^^^^^^^^^^^^^^^^^
  File "/Library/Frameworks/Python.framework/Versions/3.12/lib/python3.12/site-packages/django/core/handlers/base.py", line 181, in _get_response
    response = wrapped_callback(request, *callback_args, **callback_kwargs)
               ^^^^^^^^^^^^^^^^^^^^^^^^^^^^^^^^^^^^^^^^^^^^^^^^^^^^^^^^^^^^
  File "/Users/janrydzewski/Developer/Studies/Django/workout_logger/workout/views.py", line 303, in view_challenge
    user_challenge = UserChallenge.objects.get(id=1)
                     ^^^^^^^^^^^^^^^^^^^^^^^^^^^^^^^
  File "/Library/Frameworks/Python.framework/Versions/3.12/lib/python3.12/site-packages/django/db/models/manager.py", line 85, in manager_method
    return getattr(self.get_queryset(), name)(*args, **kwargs)
           ^^^^^^^^^^^^^^^^^^^^^^^^^^^^^^^^^^^^^^^^^^^^^^^^^^^
  File "/Library/Frameworks/Python.framework/Versions/3.12/lib/python3.12/site-packages/django/db/models/query.py", line 439, in get
    raise self.model.DoesNotExist(
workout.models.UserChallenge.DoesNotExist: UserChallenge matching query does not exist.
2024-06-15 15:02:24,449 - ERROR - Internal Server Error: /challenge/: 
Traceback (most recent call last):
  File "/Library/Frameworks/Python.framework/Versions/3.12/lib/python3.12/site-packages/django/core/handlers/exception.py", line 47, in inner
    response = get_response(request)
               ^^^^^^^^^^^^^^^^^^^^^
  File "/Library/Frameworks/Python.framework/Versions/3.12/lib/python3.12/site-packages/django/core/handlers/base.py", line 181, in _get_response
    response = wrapped_callback(request, *callback_args, **callback_kwargs)
               ^^^^^^^^^^^^^^^^^^^^^^^^^^^^^^^^^^^^^^^^^^^^^^^^^^^^^^^^^^^^
  File "/Users/janrydzewski/Developer/Studies/Django/workout_logger/workout/views.py", line 303, in view_challenge
    user_challenge = UserChallenge.objects.get(id=1)
                     ^^^^^^^^^^^^^^^^^^^^^^^^^^^^^^^
  File "/Library/Frameworks/Python.framework/Versions/3.12/lib/python3.12/site-packages/django/db/models/manager.py", line 85, in manager_method
    return getattr(self.get_queryset(), name)(*args, **kwargs)
           ^^^^^^^^^^^^^^^^^^^^^^^^^^^^^^^^^^^^^^^^^^^^^^^^^^^
  File "/Library/Frameworks/Python.framework/Versions/3.12/lib/python3.12/site-packages/django/db/models/query.py", line 439, in get
    raise self.model.DoesNotExist(
workout.models.UserChallenge.DoesNotExist: UserChallenge matching query does not exist.
2024-06-15 15:03:24,875 - ERROR - Internal Server Error: /challenge/7: 
Traceback (most recent call last):
  File "/Library/Frameworks/Python.framework/Versions/3.12/lib/python3.12/site-packages/django/core/handlers/exception.py", line 47, in inner
    response = get_response(request)
               ^^^^^^^^^^^^^^^^^^^^^
  File "/Library/Frameworks/Python.framework/Versions/3.12/lib/python3.12/site-packages/django/core/handlers/base.py", line 181, in _get_response
    response = wrapped_callback(request, *callback_args, **callback_kwargs)
               ^^^^^^^^^^^^^^^^^^^^^^^^^^^^^^^^^^^^^^^^^^^^^^^^^^^^^^^^^^^^
  File "/Users/janrydzewski/Developer/Studies/Django/workout_logger/workout/views.py", line 303, in view_challenge
    user_challenge = UserChallenge.objects.get(id=1)
                     ^^^^^^^^^^^^^^^^^^^^^^^^^^^^^^^
  File "/Library/Frameworks/Python.framework/Versions/3.12/lib/python3.12/site-packages/django/db/models/manager.py", line 85, in manager_method
    return getattr(self.get_queryset(), name)(*args, **kwargs)
           ^^^^^^^^^^^^^^^^^^^^^^^^^^^^^^^^^^^^^^^^^^^^^^^^^^^
  File "/Library/Frameworks/Python.framework/Versions/3.12/lib/python3.12/site-packages/django/db/models/query.py", line 439, in get
    raise self.model.DoesNotExist(
workout.models.UserChallenge.DoesNotExist: UserChallenge matching query does not exist.
2024-06-15 15:03:29,418 - ERROR - Internal Server Error: /challenge/7: 
Traceback (most recent call last):
  File "/Library/Frameworks/Python.framework/Versions/3.12/lib/python3.12/site-packages/django/core/handlers/exception.py", line 47, in inner
    response = get_response(request)
               ^^^^^^^^^^^^^^^^^^^^^
  File "/Library/Frameworks/Python.framework/Versions/3.12/lib/python3.12/site-packages/django/core/handlers/base.py", line 181, in _get_response
    response = wrapped_callback(request, *callback_args, **callback_kwargs)
               ^^^^^^^^^^^^^^^^^^^^^^^^^^^^^^^^^^^^^^^^^^^^^^^^^^^^^^^^^^^^
  File "/Users/janrydzewski/Developer/Studies/Django/workout_logger/workout/views.py", line 303, in view_challenge
    user_challenge = UserChallenge.objects.get(id=1)
                     ^^^^^^^^^^^^^^^^^^^^^^^^^^^^^^^
  File "/Library/Frameworks/Python.framework/Versions/3.12/lib/python3.12/site-packages/django/db/models/manager.py", line 85, in manager_method
    return getattr(self.get_queryset(), name)(*args, **kwargs)
           ^^^^^^^^^^^^^^^^^^^^^^^^^^^^^^^^^^^^^^^^^^^^^^^^^^^
  File "/Library/Frameworks/Python.framework/Versions/3.12/lib/python3.12/site-packages/django/db/models/query.py", line 439, in get
    raise self.model.DoesNotExist(
workout.models.UserChallenge.DoesNotExist: UserChallenge matching query does not exist.
2024-06-15 15:05:13,997 - ERROR - Internal Server Error: /challenge/7: 
Traceback (most recent call last):
  File "/Library/Frameworks/Python.framework/Versions/3.12/lib/python3.12/site-packages/django/core/handlers/exception.py", line 47, in inner
    response = get_response(request)
               ^^^^^^^^^^^^^^^^^^^^^
  File "/Library/Frameworks/Python.framework/Versions/3.12/lib/python3.12/site-packages/django/core/handlers/base.py", line 181, in _get_response
    response = wrapped_callback(request, *callback_args, **callback_kwargs)
               ^^^^^^^^^^^^^^^^^^^^^^^^^^^^^^^^^^^^^^^^^^^^^^^^^^^^^^^^^^^^
  File "/Users/janrydzewski/Developer/Studies/Django/workout_logger/workout/views.py", line 303, in view_challenge
    user_challenge = UserChallenge.objects.get(id=1)
                     ^^^^^^^^^^^^^^^^^^^^^^^^^^^^^^^
  File "/Library/Frameworks/Python.framework/Versions/3.12/lib/python3.12/site-packages/django/db/models/manager.py", line 85, in manager_method
    return getattr(self.get_queryset(), name)(*args, **kwargs)
           ^^^^^^^^^^^^^^^^^^^^^^^^^^^^^^^^^^^^^^^^^^^^^^^^^^^
  File "/Library/Frameworks/Python.framework/Versions/3.12/lib/python3.12/site-packages/django/db/models/query.py", line 439, in get
    raise self.model.DoesNotExist(
workout.models.UserChallenge.DoesNotExist: UserChallenge matching query does not exist.
2024-06-15 15:06:09,101 - INFO - /Users/janrydzewski/Developer/Studies/Django/workout_logger/workout/views.py changed, reloading.: 
2024-06-15 15:06:11,625 - ERROR - Internal Server Error: /challenge/7: 
Traceback (most recent call last):
  File "/Library/Frameworks/Python.framework/Versions/3.12/lib/python3.12/site-packages/django/core/handlers/exception.py", line 47, in inner
    response = get_response(request)
               ^^^^^^^^^^^^^^^^^^^^^
  File "/Library/Frameworks/Python.framework/Versions/3.12/lib/python3.12/site-packages/django/core/handlers/base.py", line 181, in _get_response
    response = wrapped_callback(request, *callback_args, **callback_kwargs)
               ^^^^^^^^^^^^^^^^^^^^^^^^^^^^^^^^^^^^^^^^^^^^^^^^^^^^^^^^^^^^
  File "/Users/janrydzewski/Developer/Studies/Django/workout_logger/workout/views.py", line 303, in view_challenge
    user_challenge = UserChallenge.objects.get(id=id)
                     ^^^^^^^^^^^^^^^^^^^^^^^^^^^^^^^^
  File "/Library/Frameworks/Python.framework/Versions/3.12/lib/python3.12/site-packages/django/db/models/manager.py", line 85, in manager_method
    return getattr(self.get_queryset(), name)(*args, **kwargs)
           ^^^^^^^^^^^^^^^^^^^^^^^^^^^^^^^^^^^^^^^^^^^^^^^^^^^
  File "/Library/Frameworks/Python.framework/Versions/3.12/lib/python3.12/site-packages/django/db/models/query.py", line 439, in get
    raise self.model.DoesNotExist(
workout.models.UserChallenge.DoesNotExist: UserChallenge matching query does not exist.
2024-06-15 15:06:15,085 - ERROR - Internal Server Error: /challenge/7: 
Traceback (most recent call last):
  File "/Library/Frameworks/Python.framework/Versions/3.12/lib/python3.12/site-packages/django/core/handlers/exception.py", line 47, in inner
    response = get_response(request)
               ^^^^^^^^^^^^^^^^^^^^^
  File "/Library/Frameworks/Python.framework/Versions/3.12/lib/python3.12/site-packages/django/core/handlers/base.py", line 181, in _get_response
    response = wrapped_callback(request, *callback_args, **callback_kwargs)
               ^^^^^^^^^^^^^^^^^^^^^^^^^^^^^^^^^^^^^^^^^^^^^^^^^^^^^^^^^^^^
  File "/Users/janrydzewski/Developer/Studies/Django/workout_logger/workout/views.py", line 303, in view_challenge
    user_challenge = UserChallenge.objects.get(id=id)
                     ^^^^^^^^^^^^^^^^^^^^^^^^^^^^^^^^
  File "/Library/Frameworks/Python.framework/Versions/3.12/lib/python3.12/site-packages/django/db/models/manager.py", line 85, in manager_method
    return getattr(self.get_queryset(), name)(*args, **kwargs)
           ^^^^^^^^^^^^^^^^^^^^^^^^^^^^^^^^^^^^^^^^^^^^^^^^^^^
  File "/Library/Frameworks/Python.framework/Versions/3.12/lib/python3.12/site-packages/django/db/models/query.py", line 439, in get
    raise self.model.DoesNotExist(
workout.models.UserChallenge.DoesNotExist: UserChallenge matching query does not exist.
2024-06-15 15:07:55,965 - INFO - /Users/janrydzewski/Developer/Studies/Django/workout_logger/workout/views.py changed, reloading.: 
2024-06-15 15:08:10,506 - INFO - /Users/janrydzewski/Developer/Studies/Django/workout_logger/workout/views.py changed, reloading.: 
2024-06-15 15:08:23,080 - ERROR - Internal Server Error: /challenge/7: 
Traceback (most recent call last):
  File "/Library/Frameworks/Python.framework/Versions/3.12/lib/python3.12/site-packages/django/core/handlers/exception.py", line 47, in inner
    response = get_response(request)
               ^^^^^^^^^^^^^^^^^^^^^
  File "/Library/Frameworks/Python.framework/Versions/3.12/lib/python3.12/site-packages/django/core/handlers/base.py", line 181, in _get_response
    response = wrapped_callback(request, *callback_args, **callback_kwargs)
               ^^^^^^^^^^^^^^^^^^^^^^^^^^^^^^^^^^^^^^^^^^^^^^^^^^^^^^^^^^^^
  File "/Users/janrydzewski/Developer/Studies/Django/workout_logger/workout/views.py", line 302, in view_challenge
    user_challenge = UserChallenge.objects.get(challenge_id=id)
                     ^^^^^^^^^^^^^^^^^^^^^^^^^^^^^^^^^^^^^^^^^^
  File "/Library/Frameworks/Python.framework/Versions/3.12/lib/python3.12/site-packages/django/db/models/manager.py", line 85, in manager_method
    return getattr(self.get_queryset(), name)(*args, **kwargs)
           ^^^^^^^^^^^^^^^^^^^^^^^^^^^^^^^^^^^^^^^^^^^^^^^^^^^
  File "/Library/Frameworks/Python.framework/Versions/3.12/lib/python3.12/site-packages/django/db/models/query.py", line 439, in get
    raise self.model.DoesNotExist(
workout.models.UserChallenge.DoesNotExist: UserChallenge matching query does not exist.
2024-06-15 15:08:41,230 - INFO - /Users/janrydzewski/Developer/Studies/Django/workout_logger/workout/views.py changed, reloading.: 
2024-06-15 15:10:07,707 - ERROR - Internal Server Error: /challenge/7: 
Traceback (most recent call last):
  File "/Library/Frameworks/Python.framework/Versions/3.12/lib/python3.12/site-packages/django/core/handlers/exception.py", line 47, in inner
    response = get_response(request)
               ^^^^^^^^^^^^^^^^^^^^^
  File "/Library/Frameworks/Python.framework/Versions/3.12/lib/python3.12/site-packages/django/core/handlers/base.py", line 181, in _get_response
    response = wrapped_callback(request, *callback_args, **callback_kwargs)
               ^^^^^^^^^^^^^^^^^^^^^^^^^^^^^^^^^^^^^^^^^^^^^^^^^^^^^^^^^^^^
  File "/Users/janrydzewski/Developer/Studies/Django/workout_logger/workout/views.py", line 302, in view_challenge
    user_challenge = UserChallenge.objects.get(challenge_id=id)
                     ^^^^^^^^^^^^^^^^^^^^^^^^^^^^^^^^^^^^^^^^^^
  File "/Library/Frameworks/Python.framework/Versions/3.12/lib/python3.12/site-packages/django/db/models/manager.py", line 85, in manager_method
    return getattr(self.get_queryset(), name)(*args, **kwargs)
           ^^^^^^^^^^^^^^^^^^^^^^^^^^^^^^^^^^^^^^^^^^^^^^^^^^^
  File "/Library/Frameworks/Python.framework/Versions/3.12/lib/python3.12/site-packages/django/db/models/query.py", line 439, in get
    raise self.model.DoesNotExist(
workout.models.UserChallenge.DoesNotExist: UserChallenge matching query does not exist.
2024-06-15 15:10:44,210 - INFO - /Users/janrydzewski/Developer/Studies/Django/workout_logger/workout/views.py changed, reloading.: 
2024-06-15 15:10:50,646 - INFO - /Users/janrydzewski/Developer/Studies/Django/workout_logger/workout/views.py changed, reloading.: 
2024-06-15 15:10:52,987 - INFO - /Users/janrydzewski/Developer/Studies/Django/workout_logger/workout/views.py changed, reloading.: 
2024-06-15 15:11:02,355 - INFO - /Users/janrydzewski/Developer/Studies/Django/workout_logger/workout/views.py changed, reloading.: 
2024-06-15 15:11:05,665 - INFO - /Users/janrydzewski/Developer/Studies/Django/workout_logger/workout/views.py changed, reloading.: 
2024-06-15 15:11:11,986 - INFO - /Users/janrydzewski/Developer/Studies/Django/workout_logger/workout/views.py changed, reloading.: 
2024-06-15 15:11:14,268 - INFO - /Users/janrydzewski/Developer/Studies/Django/workout_logger/workout/views.py changed, reloading.: 
2024-06-15 15:11:15,570 - INFO - /Users/janrydzewski/Developer/Studies/Django/workout_logger/workout/views.py changed, reloading.: 
2024-06-15 15:11:16,837 - INFO - /Users/janrydzewski/Developer/Studies/Django/workout_logger/workout/views.py changed, reloading.: 
2024-06-15 15:14:01,348 - INFO - /Users/janrydzewski/Developer/Studies/Django/workout_logger/workout/views.py changed, reloading.: 
2024-06-15 15:14:03,778 - INFO - /Users/janrydzewski/Developer/Studies/Django/workout_logger/workout/views.py changed, reloading.: 
2024-06-15 15:16:22,460 - ERROR - Internal Server Error: /challenge/7: 
Traceback (most recent call last):
  File "/Library/Frameworks/Python.framework/Versions/3.12/lib/python3.12/site-packages/django/core/handlers/exception.py", line 47, in inner
    response = get_response(request)
               ^^^^^^^^^^^^^^^^^^^^^
  File "/Library/Frameworks/Python.framework/Versions/3.12/lib/python3.12/site-packages/django/core/handlers/base.py", line 181, in _get_response
    response = wrapped_callback(request, *callback_args, **callback_kwargs)
               ^^^^^^^^^^^^^^^^^^^^^^^^^^^^^^^^^^^^^^^^^^^^^^^^^^^^^^^^^^^^
  File "/Users/janrydzewski/Developer/Studies/Django/workout_logger/workout/views.py", line 327, in view_challenge
    exercise_status = user_challenge.exercise_status[exercises.index(exercise)]
                      ~~~~~~~~~~~~~~~~~~~~~~~~~~~~~~^^^^^^^^^^^^^^^^^^^^^^^^^^^
IndexError: list index out of range
2024-06-15 15:16:52,832 - ERROR - Internal Server Error: /challenge/7: 
Traceback (most recent call last):
  File "/Library/Frameworks/Python.framework/Versions/3.12/lib/python3.12/site-packages/django/core/handlers/exception.py", line 47, in inner
    response = get_response(request)
               ^^^^^^^^^^^^^^^^^^^^^
  File "/Library/Frameworks/Python.framework/Versions/3.12/lib/python3.12/site-packages/django/core/handlers/base.py", line 181, in _get_response
    response = wrapped_callback(request, *callback_args, **callback_kwargs)
               ^^^^^^^^^^^^^^^^^^^^^^^^^^^^^^^^^^^^^^^^^^^^^^^^^^^^^^^^^^^^
  File "/Users/janrydzewski/Developer/Studies/Django/workout_logger/workout/views.py", line 327, in view_challenge
    exercise_status = user_challenge.exercise_status[exercises.index(exercise)]
                      ~~~~~~~~~~~~~~~~~~~~~~~~~~~~~~^^^^^^^^^^^^^^^^^^^^^^^^^^^
IndexError: list index out of range
2024-06-15 15:17:04,498 - ERROR - Internal Server Error: /challenge/7/join: 
Traceback (most recent call last):
  File "/Library/Frameworks/Python.framework/Versions/3.12/lib/python3.12/site-packages/django/db/backends/utils.py", line 85, in _execute
    return self.cursor.execute(sql, params)
           ^^^^^^^^^^^^^^^^^^^^^^^^^^^^^^^^
  File "/Library/Frameworks/Python.framework/Versions/3.12/lib/python3.12/site-packages/django/db/backends/sqlite3/base.py", line 416, in execute
    return Database.Cursor.execute(self, query, params)
           ^^^^^^^^^^^^^^^^^^^^^^^^^^^^^^^^^^^^^^^^^^^^
sqlite3.OperationalError: database is locked

The above exception was the direct cause of the following exception:

Traceback (most recent call last):
  File "/Library/Frameworks/Python.framework/Versions/3.12/lib/python3.12/site-packages/django/core/handlers/exception.py", line 47, in inner
    response = get_response(request)
               ^^^^^^^^^^^^^^^^^^^^^
  File "/Library/Frameworks/Python.framework/Versions/3.12/lib/python3.12/site-packages/django/core/handlers/base.py", line 181, in _get_response
    response = wrapped_callback(request, *callback_args, **callback_kwargs)
               ^^^^^^^^^^^^^^^^^^^^^^^^^^^^^^^^^^^^^^^^^^^^^^^^^^^^^^^^^^^^
  File "/Users/janrydzewski/Developer/Studies/Django/workout_logger/workout/views.py", line 275, in join_challenge
    user_challenge.delete()
  File "/Library/Frameworks/Python.framework/Versions/3.12/lib/python3.12/site-packages/django/db/models/base.py", line 971, in delete
    return collector.delete()
           ^^^^^^^^^^^^^^^^^^
  File "/Library/Frameworks/Python.framework/Versions/3.12/lib/python3.12/site-packages/django/db/models/deletion.py", line 398, in delete
    count = sql.DeleteQuery(model).delete_batch([instance.pk], self.using)
            ^^^^^^^^^^^^^^^^^^^^^^^^^^^^^^^^^^^^^^^^^^^^^^^^^^^^^^^^^^^^^^
  File "/Library/Frameworks/Python.framework/Versions/3.12/lib/python3.12/site-packages/django/db/models/sql/subqueries.py", line 44, in delete_batch
    num_deleted += self.do_query(self.get_meta().db_table, self.where, using=using)
                   ^^^^^^^^^^^^^^^^^^^^^^^^^^^^^^^^^^^^^^^^^^^^^^^^^^^^^^^^^^^^^^^^
  File "/Library/Frameworks/Python.framework/Versions/3.12/lib/python3.12/site-packages/django/db/models/sql/subqueries.py", line 22, in do_query
    cursor = self.get_compiler(using).execute_sql(CURSOR)
             ^^^^^^^^^^^^^^^^^^^^^^^^^^^^^^^^^^^^^^^^^^^^
  File "/Library/Frameworks/Python.framework/Versions/3.12/lib/python3.12/site-packages/django/db/models/sql/compiler.py", line 1202, in execute_sql
    cursor.execute(sql, params)
  File "/Library/Frameworks/Python.framework/Versions/3.12/lib/python3.12/site-packages/django/db/backends/utils.py", line 99, in execute
    return super().execute(sql, params)
           ^^^^^^^^^^^^^^^^^^^^^^^^^^^^
  File "/Library/Frameworks/Python.framework/Versions/3.12/lib/python3.12/site-packages/django/db/backends/utils.py", line 67, in execute
    return self._execute_with_wrappers(sql, params, many=False, executor=self._execute)
           ^^^^^^^^^^^^^^^^^^^^^^^^^^^^^^^^^^^^^^^^^^^^^^^^^^^^^^^^^^^^^^^^^^^^^^^^^^^^
  File "/Library/Frameworks/Python.framework/Versions/3.12/lib/python3.12/site-packages/django/db/backends/utils.py", line 76, in _execute_with_wrappers
    return executor(sql, params, many, context)
           ^^^^^^^^^^^^^^^^^^^^^^^^^^^^^^^^^^^^
  File "/Library/Frameworks/Python.framework/Versions/3.12/lib/python3.12/site-packages/django/db/backends/utils.py", line 80, in _execute
    with self.db.wrap_database_errors:
  File "/Library/Frameworks/Python.framework/Versions/3.12/lib/python3.12/site-packages/django/db/utils.py", line 90, in __exit__
    raise dj_exc_value.with_traceback(traceback) from exc_value
  File "/Library/Frameworks/Python.framework/Versions/3.12/lib/python3.12/site-packages/django/db/backends/utils.py", line 85, in _execute
    return self.cursor.execute(sql, params)
           ^^^^^^^^^^^^^^^^^^^^^^^^^^^^^^^^
  File "/Library/Frameworks/Python.framework/Versions/3.12/lib/python3.12/site-packages/django/db/backends/sqlite3/base.py", line 416, in execute
    return Database.Cursor.execute(self, query, params)
           ^^^^^^^^^^^^^^^^^^^^^^^^^^^^^^^^^^^^^^^^^^^^
django.db.utils.OperationalError: database is locked
2024-06-15 15:17:05,430 - ERROR - Internal Server Error: /challenge/8/join: 
Traceback (most recent call last):
  File "/Library/Frameworks/Python.framework/Versions/3.12/lib/python3.12/site-packages/django/db/backends/utils.py", line 85, in _execute
    return self.cursor.execute(sql, params)
           ^^^^^^^^^^^^^^^^^^^^^^^^^^^^^^^^
  File "/Library/Frameworks/Python.framework/Versions/3.12/lib/python3.12/site-packages/django/db/backends/sqlite3/base.py", line 416, in execute
    return Database.Cursor.execute(self, query, params)
           ^^^^^^^^^^^^^^^^^^^^^^^^^^^^^^^^^^^^^^^^^^^^
sqlite3.OperationalError: database is locked

The above exception was the direct cause of the following exception:

Traceback (most recent call last):
  File "/Library/Frameworks/Python.framework/Versions/3.12/lib/python3.12/site-packages/django/core/handlers/exception.py", line 47, in inner
    response = get_response(request)
               ^^^^^^^^^^^^^^^^^^^^^
  File "/Library/Frameworks/Python.framework/Versions/3.12/lib/python3.12/site-packages/django/core/handlers/base.py", line 181, in _get_response
    response = wrapped_callback(request, *callback_args, **callback_kwargs)
               ^^^^^^^^^^^^^^^^^^^^^^^^^^^^^^^^^^^^^^^^^^^^^^^^^^^^^^^^^^^^
  File "/Users/janrydzewski/Developer/Studies/Django/workout_logger/workout/views.py", line 275, in join_challenge
    user_challenge.delete()
  File "/Library/Frameworks/Python.framework/Versions/3.12/lib/python3.12/site-packages/django/db/models/base.py", line 971, in delete
    return collector.delete()
           ^^^^^^^^^^^^^^^^^^
  File "/Library/Frameworks/Python.framework/Versions/3.12/lib/python3.12/site-packages/django/db/models/deletion.py", line 398, in delete
    count = sql.DeleteQuery(model).delete_batch([instance.pk], self.using)
            ^^^^^^^^^^^^^^^^^^^^^^^^^^^^^^^^^^^^^^^^^^^^^^^^^^^^^^^^^^^^^^
  File "/Library/Frameworks/Python.framework/Versions/3.12/lib/python3.12/site-packages/django/db/models/sql/subqueries.py", line 44, in delete_batch
    num_deleted += self.do_query(self.get_meta().db_table, self.where, using=using)
                   ^^^^^^^^^^^^^^^^^^^^^^^^^^^^^^^^^^^^^^^^^^^^^^^^^^^^^^^^^^^^^^^^
  File "/Library/Frameworks/Python.framework/Versions/3.12/lib/python3.12/site-packages/django/db/models/sql/subqueries.py", line 22, in do_query
    cursor = self.get_compiler(using).execute_sql(CURSOR)
             ^^^^^^^^^^^^^^^^^^^^^^^^^^^^^^^^^^^^^^^^^^^^
  File "/Library/Frameworks/Python.framework/Versions/3.12/lib/python3.12/site-packages/django/db/models/sql/compiler.py", line 1202, in execute_sql
    cursor.execute(sql, params)
  File "/Library/Frameworks/Python.framework/Versions/3.12/lib/python3.12/site-packages/django/db/backends/utils.py", line 99, in execute
    return super().execute(sql, params)
           ^^^^^^^^^^^^^^^^^^^^^^^^^^^^
  File "/Library/Frameworks/Python.framework/Versions/3.12/lib/python3.12/site-packages/django/db/backends/utils.py", line 67, in execute
    return self._execute_with_wrappers(sql, params, many=False, executor=self._execute)
           ^^^^^^^^^^^^^^^^^^^^^^^^^^^^^^^^^^^^^^^^^^^^^^^^^^^^^^^^^^^^^^^^^^^^^^^^^^^^
  File "/Library/Frameworks/Python.framework/Versions/3.12/lib/python3.12/site-packages/django/db/backends/utils.py", line 76, in _execute_with_wrappers
    return executor(sql, params, many, context)
           ^^^^^^^^^^^^^^^^^^^^^^^^^^^^^^^^^^^^
  File "/Library/Frameworks/Python.framework/Versions/3.12/lib/python3.12/site-packages/django/db/backends/utils.py", line 80, in _execute
    with self.db.wrap_database_errors:
  File "/Library/Frameworks/Python.framework/Versions/3.12/lib/python3.12/site-packages/django/db/utils.py", line 90, in __exit__
    raise dj_exc_value.with_traceback(traceback) from exc_value
  File "/Library/Frameworks/Python.framework/Versions/3.12/lib/python3.12/site-packages/django/db/backends/utils.py", line 85, in _execute
    return self.cursor.execute(sql, params)
           ^^^^^^^^^^^^^^^^^^^^^^^^^^^^^^^^
  File "/Library/Frameworks/Python.framework/Versions/3.12/lib/python3.12/site-packages/django/db/backends/sqlite3/base.py", line 416, in execute
    return Database.Cursor.execute(self, query, params)
           ^^^^^^^^^^^^^^^^^^^^^^^^^^^^^^^^^^^^^^^^^^^^
django.db.utils.OperationalError: database is locked
2024-06-15 15:17:06,148 - ERROR - Internal Server Error: /challenge/7/join: 
Traceback (most recent call last):
  File "/Library/Frameworks/Python.framework/Versions/3.12/lib/python3.12/site-packages/django/db/backends/utils.py", line 85, in _execute
    return self.cursor.execute(sql, params)
           ^^^^^^^^^^^^^^^^^^^^^^^^^^^^^^^^
  File "/Library/Frameworks/Python.framework/Versions/3.12/lib/python3.12/site-packages/django/db/backends/sqlite3/base.py", line 416, in execute
    return Database.Cursor.execute(self, query, params)
           ^^^^^^^^^^^^^^^^^^^^^^^^^^^^^^^^^^^^^^^^^^^^
sqlite3.OperationalError: database is locked

The above exception was the direct cause of the following exception:

Traceback (most recent call last):
  File "/Library/Frameworks/Python.framework/Versions/3.12/lib/python3.12/site-packages/django/core/handlers/exception.py", line 47, in inner
    response = get_response(request)
               ^^^^^^^^^^^^^^^^^^^^^
  File "/Library/Frameworks/Python.framework/Versions/3.12/lib/python3.12/site-packages/django/core/handlers/base.py", line 181, in _get_response
    response = wrapped_callback(request, *callback_args, **callback_kwargs)
               ^^^^^^^^^^^^^^^^^^^^^^^^^^^^^^^^^^^^^^^^^^^^^^^^^^^^^^^^^^^^
  File "/Users/janrydzewski/Developer/Studies/Django/workout_logger/workout/views.py", line 275, in join_challenge
    user_challenge.delete()
  File "/Library/Frameworks/Python.framework/Versions/3.12/lib/python3.12/site-packages/django/db/models/base.py", line 971, in delete
    return collector.delete()
           ^^^^^^^^^^^^^^^^^^
  File "/Library/Frameworks/Python.framework/Versions/3.12/lib/python3.12/site-packages/django/db/models/deletion.py", line 398, in delete
    count = sql.DeleteQuery(model).delete_batch([instance.pk], self.using)
            ^^^^^^^^^^^^^^^^^^^^^^^^^^^^^^^^^^^^^^^^^^^^^^^^^^^^^^^^^^^^^^
  File "/Library/Frameworks/Python.framework/Versions/3.12/lib/python3.12/site-packages/django/db/models/sql/subqueries.py", line 44, in delete_batch
    num_deleted += self.do_query(self.get_meta().db_table, self.where, using=using)
                   ^^^^^^^^^^^^^^^^^^^^^^^^^^^^^^^^^^^^^^^^^^^^^^^^^^^^^^^^^^^^^^^^
  File "/Library/Frameworks/Python.framework/Versions/3.12/lib/python3.12/site-packages/django/db/models/sql/subqueries.py", line 22, in do_query
    cursor = self.get_compiler(using).execute_sql(CURSOR)
             ^^^^^^^^^^^^^^^^^^^^^^^^^^^^^^^^^^^^^^^^^^^^
  File "/Library/Frameworks/Python.framework/Versions/3.12/lib/python3.12/site-packages/django/db/models/sql/compiler.py", line 1202, in execute_sql
    cursor.execute(sql, params)
  File "/Library/Frameworks/Python.framework/Versions/3.12/lib/python3.12/site-packages/django/db/backends/utils.py", line 99, in execute
    return super().execute(sql, params)
           ^^^^^^^^^^^^^^^^^^^^^^^^^^^^
  File "/Library/Frameworks/Python.framework/Versions/3.12/lib/python3.12/site-packages/django/db/backends/utils.py", line 67, in execute
    return self._execute_with_wrappers(sql, params, many=False, executor=self._execute)
           ^^^^^^^^^^^^^^^^^^^^^^^^^^^^^^^^^^^^^^^^^^^^^^^^^^^^^^^^^^^^^^^^^^^^^^^^^^^^
  File "/Library/Frameworks/Python.framework/Versions/3.12/lib/python3.12/site-packages/django/db/backends/utils.py", line 76, in _execute_with_wrappers
    return executor(sql, params, many, context)
           ^^^^^^^^^^^^^^^^^^^^^^^^^^^^^^^^^^^^
  File "/Library/Frameworks/Python.framework/Versions/3.12/lib/python3.12/site-packages/django/db/backends/utils.py", line 80, in _execute
    with self.db.wrap_database_errors:
  File "/Library/Frameworks/Python.framework/Versions/3.12/lib/python3.12/site-packages/django/db/utils.py", line 90, in __exit__
    raise dj_exc_value.with_traceback(traceback) from exc_value
  File "/Library/Frameworks/Python.framework/Versions/3.12/lib/python3.12/site-packages/django/db/backends/utils.py", line 85, in _execute
    return self.cursor.execute(sql, params)
           ^^^^^^^^^^^^^^^^^^^^^^^^^^^^^^^^
  File "/Library/Frameworks/Python.framework/Versions/3.12/lib/python3.12/site-packages/django/db/backends/sqlite3/base.py", line 416, in execute
    return Database.Cursor.execute(self, query, params)
           ^^^^^^^^^^^^^^^^^^^^^^^^^^^^^^^^^^^^^^^^^^^^
django.db.utils.OperationalError: database is locked
2024-06-15 15:17:35,100 - ERROR - Internal Server Error: /challenge/3: 
Traceback (most recent call last):
  File "/Library/Frameworks/Python.framework/Versions/3.12/lib/python3.12/site-packages/django/core/handlers/exception.py", line 47, in inner
    response = get_response(request)
               ^^^^^^^^^^^^^^^^^^^^^
  File "/Library/Frameworks/Python.framework/Versions/3.12/lib/python3.12/site-packages/django/core/handlers/base.py", line 181, in _get_response
    response = wrapped_callback(request, *callback_args, **callback_kwargs)
               ^^^^^^^^^^^^^^^^^^^^^^^^^^^^^^^^^^^^^^^^^^^^^^^^^^^^^^^^^^^^
  File "/Users/janrydzewski/Developer/Studies/Django/workout_logger/workout/views.py", line 303, in view_challenge
    user_challenge = UserChallenge.objects.get(workout_id=id)
                     ^^^^^^^^^^^^^^^^^^^^^^^^^^^^^^^^^^^^^^^^
  File "/Library/Frameworks/Python.framework/Versions/3.12/lib/python3.12/site-packages/django/db/models/manager.py", line 85, in manager_method
    return getattr(self.get_queryset(), name)(*args, **kwargs)
           ^^^^^^^^^^^^^^^^^^^^^^^^^^^^^^^^^^^^^^^^^^^^^^^^^^^
  File "/Library/Frameworks/Python.framework/Versions/3.12/lib/python3.12/site-packages/django/db/models/query.py", line 439, in get
    raise self.model.DoesNotExist(
workout.models.UserChallenge.DoesNotExist: UserChallenge matching query does not exist.
2024-06-15 15:17:39,500 - ERROR - Internal Server Error: /challenge/3: 
Traceback (most recent call last):
  File "/Library/Frameworks/Python.framework/Versions/3.12/lib/python3.12/site-packages/django/core/handlers/exception.py", line 47, in inner
    response = get_response(request)
               ^^^^^^^^^^^^^^^^^^^^^
  File "/Library/Frameworks/Python.framework/Versions/3.12/lib/python3.12/site-packages/django/core/handlers/base.py", line 181, in _get_response
    response = wrapped_callback(request, *callback_args, **callback_kwargs)
               ^^^^^^^^^^^^^^^^^^^^^^^^^^^^^^^^^^^^^^^^^^^^^^^^^^^^^^^^^^^^
  File "/Users/janrydzewski/Developer/Studies/Django/workout_logger/workout/views.py", line 303, in view_challenge
    user_challenge = UserChallenge.objects.get(workout_id=id)
                     ^^^^^^^^^^^^^^^^^^^^^^^^^^^^^^^^^^^^^^^^
  File "/Library/Frameworks/Python.framework/Versions/3.12/lib/python3.12/site-packages/django/db/models/manager.py", line 85, in manager_method
    return getattr(self.get_queryset(), name)(*args, **kwargs)
           ^^^^^^^^^^^^^^^^^^^^^^^^^^^^^^^^^^^^^^^^^^^^^^^^^^^
  File "/Library/Frameworks/Python.framework/Versions/3.12/lib/python3.12/site-packages/django/db/models/query.py", line 439, in get
    raise self.model.DoesNotExist(
workout.models.UserChallenge.DoesNotExist: UserChallenge matching query does not exist.
2024-06-15 15:20:50,671 - DEBUG - GET request to login: 
2024-06-15 15:21:32,162 - ERROR - Internal Server Error: /challenge/11: 
Traceback (most recent call last):
  File "/Library/Frameworks/Python.framework/Versions/3.12/lib/python3.12/site-packages/django/core/handlers/exception.py", line 47, in inner
    response = get_response(request)
               ^^^^^^^^^^^^^^^^^^^^^
  File "/Library/Frameworks/Python.framework/Versions/3.12/lib/python3.12/site-packages/django/core/handlers/base.py", line 181, in _get_response
    response = wrapped_callback(request, *callback_args, **callback_kwargs)
               ^^^^^^^^^^^^^^^^^^^^^^^^^^^^^^^^^^^^^^^^^^^^^^^^^^^^^^^^^^^^
  File "/Users/janrydzewski/Developer/Studies/Django/workout_logger/workout/views.py", line 303, in view_challenge
    user_challenge = UserChallenge.objects.get(workout_id=id)
                     ^^^^^^^^^^^^^^^^^^^^^^^^^^^^^^^^^^^^^^^^
  File "/Library/Frameworks/Python.framework/Versions/3.12/lib/python3.12/site-packages/django/db/models/manager.py", line 85, in manager_method
    return getattr(self.get_queryset(), name)(*args, **kwargs)
           ^^^^^^^^^^^^^^^^^^^^^^^^^^^^^^^^^^^^^^^^^^^^^^^^^^^
  File "/Library/Frameworks/Python.framework/Versions/3.12/lib/python3.12/site-packages/django/db/models/query.py", line 439, in get
    raise self.model.DoesNotExist(
workout.models.UserChallenge.DoesNotExist: UserChallenge matching query does not exist.
2024-06-15 15:21:34,842 - ERROR - Internal Server Error: /challenge/12: 
Traceback (most recent call last):
  File "/Library/Frameworks/Python.framework/Versions/3.12/lib/python3.12/site-packages/django/core/handlers/exception.py", line 47, in inner
    response = get_response(request)
               ^^^^^^^^^^^^^^^^^^^^^
  File "/Library/Frameworks/Python.framework/Versions/3.12/lib/python3.12/site-packages/django/core/handlers/base.py", line 181, in _get_response
    response = wrapped_callback(request, *callback_args, **callback_kwargs)
               ^^^^^^^^^^^^^^^^^^^^^^^^^^^^^^^^^^^^^^^^^^^^^^^^^^^^^^^^^^^^
  File "/Users/janrydzewski/Developer/Studies/Django/workout_logger/workout/views.py", line 303, in view_challenge
    user_challenge = UserChallenge.objects.get(workout_id=id)
                     ^^^^^^^^^^^^^^^^^^^^^^^^^^^^^^^^^^^^^^^^
  File "/Library/Frameworks/Python.framework/Versions/3.12/lib/python3.12/site-packages/django/db/models/manager.py", line 85, in manager_method
    return getattr(self.get_queryset(), name)(*args, **kwargs)
           ^^^^^^^^^^^^^^^^^^^^^^^^^^^^^^^^^^^^^^^^^^^^^^^^^^^
  File "/Library/Frameworks/Python.framework/Versions/3.12/lib/python3.12/site-packages/django/db/models/query.py", line 439, in get
    raise self.model.DoesNotExist(
workout.models.UserChallenge.DoesNotExist: UserChallenge matching query does not exist.
2024-06-15 15:21:46,722 - ERROR - Internal Server Error: /challenge/2: 
Traceback (most recent call last):
  File "/Library/Frameworks/Python.framework/Versions/3.12/lib/python3.12/site-packages/django/core/handlers/exception.py", line 47, in inner
    response = get_response(request)
               ^^^^^^^^^^^^^^^^^^^^^
  File "/Library/Frameworks/Python.framework/Versions/3.12/lib/python3.12/site-packages/django/core/handlers/base.py", line 181, in _get_response
    response = wrapped_callback(request, *callback_args, **callback_kwargs)
               ^^^^^^^^^^^^^^^^^^^^^^^^^^^^^^^^^^^^^^^^^^^^^^^^^^^^^^^^^^^^
  File "/Users/janrydzewski/Developer/Studies/Django/workout_logger/workout/views.py", line 303, in view_challenge
    user_challenge = UserChallenge.objects.get(workout_id=id)
                     ^^^^^^^^^^^^^^^^^^^^^^^^^^^^^^^^^^^^^^^^
  File "/Library/Frameworks/Python.framework/Versions/3.12/lib/python3.12/site-packages/django/db/models/manager.py", line 85, in manager_method
    return getattr(self.get_queryset(), name)(*args, **kwargs)
           ^^^^^^^^^^^^^^^^^^^^^^^^^^^^^^^^^^^^^^^^^^^^^^^^^^^
  File "/Library/Frameworks/Python.framework/Versions/3.12/lib/python3.12/site-packages/django/db/models/query.py", line 439, in get
    raise self.model.DoesNotExist(
workout.models.UserChallenge.DoesNotExist: UserChallenge matching query does not exist.
2024-06-15 15:22:22,741 - DEBUG - GET request to new workout: 
2024-06-15 15:23:38,048 - DEBUG - GET request to new workout: 
2024-06-15 15:24:14,660 - DEBUG - GET request to new workout: 
2024-06-15 15:24:18,002 - DEBUG - GET request to new workout: 
2024-06-15 15:24:18,587 - DEBUG - GET request to new workout: 
2024-06-15 15:24:22,047 - ERROR - Internal Server Error: /challenge/7: 
Traceback (most recent call last):
  File "/Library/Frameworks/Python.framework/Versions/3.12/lib/python3.12/site-packages/django/core/handlers/exception.py", line 47, in inner
    response = get_response(request)
               ^^^^^^^^^^^^^^^^^^^^^
  File "/Library/Frameworks/Python.framework/Versions/3.12/lib/python3.12/site-packages/django/core/handlers/base.py", line 181, in _get_response
    response = wrapped_callback(request, *callback_args, **callback_kwargs)
               ^^^^^^^^^^^^^^^^^^^^^^^^^^^^^^^^^^^^^^^^^^^^^^^^^^^^^^^^^^^^
  File "/Users/janrydzewski/Developer/Studies/Django/workout_logger/workout/views.py", line 327, in view_challenge
    exercise_status = user_challenge.exercise_status[exercises.index(exercise)]
                      ~~~~~~~~~~~~~~~~~~~~~~~~~~~~~~^^^^^^^^^^^^^^^^^^^^^^^^^^^
IndexError: list index out of range
2024-06-15 15:24:27,555 - ERROR - Internal Server Error: /challenge/7: 
Traceback (most recent call last):
  File "/Library/Frameworks/Python.framework/Versions/3.12/lib/python3.12/site-packages/django/core/handlers/exception.py", line 47, in inner
    response = get_response(request)
               ^^^^^^^^^^^^^^^^^^^^^
  File "/Library/Frameworks/Python.framework/Versions/3.12/lib/python3.12/site-packages/django/core/handlers/base.py", line 181, in _get_response
    response = wrapped_callback(request, *callback_args, **callback_kwargs)
               ^^^^^^^^^^^^^^^^^^^^^^^^^^^^^^^^^^^^^^^^^^^^^^^^^^^^^^^^^^^^
  File "/Users/janrydzewski/Developer/Studies/Django/workout_logger/workout/views.py", line 327, in view_challenge
    exercise_status = user_challenge.exercise_status[exercises.index(exercise)]
                      ~~~~~~~~~~~~~~~~~~~~~~~~~~~~~~^^^^^^^^^^^^^^^^^^^^^^^^^^^
IndexError: list index out of range
2024-06-15 15:24:39,338 - ERROR - Internal Server Error: /challenge/7: 
Traceback (most recent call last):
  File "/Library/Frameworks/Python.framework/Versions/3.12/lib/python3.12/site-packages/django/core/handlers/exception.py", line 47, in inner
    response = get_response(request)
               ^^^^^^^^^^^^^^^^^^^^^
  File "/Library/Frameworks/Python.framework/Versions/3.12/lib/python3.12/site-packages/django/core/handlers/base.py", line 181, in _get_response
    response = wrapped_callback(request, *callback_args, **callback_kwargs)
               ^^^^^^^^^^^^^^^^^^^^^^^^^^^^^^^^^^^^^^^^^^^^^^^^^^^^^^^^^^^^
  File "/Users/janrydzewski/Developer/Studies/Django/workout_logger/workout/views.py", line 327, in view_challenge
    exercise_status = user_challenge.exercise_status[exercises.index(exercise)]
                      ~~~~~~~~~~~~~~~~~~~~~~~~~~~~~~^^^^^^^^^^^^^^^^^^^^^^^^^^^
IndexError: list index out of range
2024-06-15 15:26:42,771 - ERROR - Internal Server Error: /challenge/7: 
Traceback (most recent call last):
  File "/Library/Frameworks/Python.framework/Versions/3.12/lib/python3.12/site-packages/django/core/handlers/exception.py", line 47, in inner
    response = get_response(request)
               ^^^^^^^^^^^^^^^^^^^^^
  File "/Library/Frameworks/Python.framework/Versions/3.12/lib/python3.12/site-packages/django/core/handlers/base.py", line 181, in _get_response
    response = wrapped_callback(request, *callback_args, **callback_kwargs)
               ^^^^^^^^^^^^^^^^^^^^^^^^^^^^^^^^^^^^^^^^^^^^^^^^^^^^^^^^^^^^
  File "/Users/janrydzewski/Developer/Studies/Django/workout_logger/workout/views.py", line 327, in view_challenge
    exercise_status = user_challenge.exercise_status[exercises.index(exercise)]
                      ~~~~~~~~~~~~~~~~~~~~~~~~~~~~~~^^^^^^^^^^^^^^^^^^^^^^^^^^^
IndexError: list index out of range
2024-06-16 11:40:48,046 - INFO - /Users/janrydzewski/Developer/Studies/Django/workout_logger/workout/views.py changed, reloading.: 
