2024-06-08 10:51:55,540 - DEBUG - GET request to login: 
2024-06-08 10:51:55,774 - WARNING - Not Found: /favicon.ico: 
2024-06-08 10:51:57,646 - DEBUG - POST request to login: 
2024-06-08 10:52:09,856 - WARNING - Not Found: /profile: 
2024-06-08 10:52:12,818 - ERROR - Internal Server Error: /history: 
Traceback (most recent call last):
  File "C:\Users\rsien\miniconda3\Lib\site-packages\django\core\handlers\exception.py", line 55, in inner
    response = get_response(request)
               ^^^^^^^^^^^^^^^^^^^^^
  File "C:\Users\rsien\miniconda3\Lib\site-packages\django\core\handlers\base.py", line 197, in _get_response
    response = wrapped_callback(request, *callback_args, **callback_kwargs)
               ^^^^^^^^^^^^^^^^^^^^^^^^^^^^^^^^^^^^^^^^^^^^^^^^^^^^^^^^^^^^
  File "C:\Users\rsien\Desktop\python-django\workout_logger\apps\workout\views.py", line 129, in view_all
    mg_list = MuscleGroup.objects.filter(user__id=user.id)
              ^^^^^^^^^^^^^^^^^^^^^^^^^^^^^^^^^^^^^^^^^^^^
  File "C:\Users\rsien\miniconda3\Lib\site-packages\django\db\models\manager.py", line 87, in manager_method
    return getattr(self.get_queryset(), name)(*args, **kwargs)
           ^^^^^^^^^^^^^^^^^^^^^^^^^^^^^^^^^^^^^^^^^^^^^^^^^^^
  File "C:\Users\rsien\miniconda3\Lib\site-packages\django\db\models\query.py", line 1436, in filter
    return self._filter_or_exclude(False, args, kwargs)
           ^^^^^^^^^^^^^^^^^^^^^^^^^^^^^^^^^^^^^^^^^^^^
  File "C:\Users\rsien\miniconda3\Lib\site-packages\django\db\models\query.py", line 1454, in _filter_or_exclude
    clone._filter_or_exclude_inplace(negate, args, kwargs)
  File "C:\Users\rsien\miniconda3\Lib\site-packages\django\db\models\query.py", line 1461, in _filter_or_exclude_inplace
    self._query.add_q(Q(*args, **kwargs))
  File "C:\Users\rsien\miniconda3\Lib\site-packages\django\db\models\sql\query.py", line 1546, in add_q
    clause, _ = self._add_q(q_object, self.used_aliases)
                ^^^^^^^^^^^^^^^^^^^^^^^^^^^^^^^^^^^^^^^^
  File "C:\Users\rsien\miniconda3\Lib\site-packages\django\db\models\sql\query.py", line 1577, in _add_q
    child_clause, needed_inner = self.build_filter(
                                 ^^^^^^^^^^^^^^^^^^
  File "C:\Users\rsien\miniconda3\Lib\site-packages\django\db\models\sql\query.py", line 1427, in build_filter
    lookups, parts, reffed_expression = self.solve_lookup_type(arg, summarize)
                                        ^^^^^^^^^^^^^^^^^^^^^^^^^^^^^^^^^^^^^^
  File "C:\Users\rsien\miniconda3\Lib\site-packages\django\db\models\sql\query.py", line 1237, in solve_lookup_type
    _, field, _, lookup_parts = self.names_to_path(lookup_splitted, self.get_meta())
                                ^^^^^^^^^^^^^^^^^^^^^^^^^^^^^^^^^^^^^^^^^^^^^^^^^^^^
  File "C:\Users\rsien\miniconda3\Lib\site-packages\django\db\models\sql\query.py", line 1725, in names_to_path
    raise FieldError(
django.core.exceptions.FieldError: Cannot resolve keyword 'user' into field. Choices are: balanceexercise, created_at, description, endurancetrainingexercise, flexibilityexercise, id, name, strengthtrainingexercise, updated_at
2024-06-08 10:53:25,236 - DEBUG - GET request to login: 
2024-06-08 10:53:26,416 - DEBUG - POST request to login: 
2024-06-08 10:53:29,841 - WARNING - Not Found: /user/profile: 
2024-06-08 10:53:40,796 - WARNING - Not Found: /musclegroup: 
2024-06-08 10:54:48,682 - INFO - C:\Users\rsien\Desktop\python-django\workout_logger\apps\workout\urls.py changed, reloading.: 
2024-06-08 10:54:53,974 - INFO - C:\Users\rsien\Desktop\python-django\workout_logger\apps\workout\urls.py changed, reloading.: 
2024-06-08 10:55:04,351 - INFO - C:\Users\rsien\Desktop\python-django\workout_logger\apps\workout\urls.py changed, reloading.: 
2024-06-08 10:55:48,816 - INFO - C:\Users\rsien\Desktop\python-django\workout_logger\apps\workout\views.py changed, reloading.: 
2024-06-08 10:56:03,300 - INFO - C:\Users\rsien\Desktop\python-django\workout_logger\apps\workout\views.py changed, reloading.: 
2024-06-08 10:56:21,876 - INFO - C:\Users\rsien\Desktop\python-django\workout_logger\apps\workout\urls.py changed, reloading.: 
2024-06-08 10:56:39,246 - ERROR - Internal Server Error: /musclegroup: 
Traceback (most recent call last):
  File "C:\Users\rsien\miniconda3\Lib\site-packages\django\core\handlers\exception.py", line 55, in inner
    response = get_response(request)
               ^^^^^^^^^^^^^^^^^^^^^
  File "C:\Users\rsien\miniconda3\Lib\site-packages\django\core\handlers\base.py", line 197, in _get_response
    response = wrapped_callback(request, *callback_args, **callback_kwargs)
               ^^^^^^^^^^^^^^^^^^^^^^^^^^^^^^^^^^^^^^^^^^^^^^^^^^^^^^^^^^^^
TypeError: muscle_group() missing 1 required positional argument: 'id'
2024-06-08 10:57:08,729 - INFO - C:\Users\rsien\Desktop\python-django\workout_logger\apps\workout\views.py changed, reloading.: 
2024-06-08 10:57:17,095 - INFO - C:\Users\rsien\Desktop\python-django\workout_logger\apps\workout\views.py changed, reloading.: 
2024-06-08 10:57:29,580 - INFO - C:\Users\rsien\Desktop\python-django\workout_logger\apps\workout\views.py changed, reloading.: 
2024-06-08 10:57:32,924 - INFO - C:\Users\rsien\Desktop\python-django\workout_logger\apps\workout\views.py changed, reloading.: 
2024-06-08 10:57:33,945 - ERROR - Internal Server Error: /musclegroup: 
Traceback (most recent call last):
  File "C:\Users\rsien\miniconda3\Lib\site-packages\django\core\handlers\exception.py", line 55, in inner
    response = get_response(request)
               ^^^^^^^^^^^^^^^^^^^^^
  File "C:\Users\rsien\miniconda3\Lib\site-packages\django\core\handlers\base.py", line 197, in _get_response
    response = wrapped_callback(request, *callback_args, **callback_kwargs)
               ^^^^^^^^^^^^^^^^^^^^^^^^^^^^^^^^^^^^^^^^^^^^^^^^^^^^^^^^^^^^
TypeError: muscle_group() missing 1 required positional argument: 'id'
2024-06-08 10:57:55,905 - INFO - C:\Users\rsien\Desktop\python-django\workout_logger\apps\workout\views.py changed, reloading.: 
2024-06-08 10:57:57,006 - ERROR - Internal Server Error: /musclegroup: 
Traceback (most recent call last):
  File "C:\Users\rsien\miniconda3\Lib\site-packages\django\core\handlers\exception.py", line 55, in inner
    response = get_response(request)
               ^^^^^^^^^^^^^^^^^^^^^
  File "C:\Users\rsien\miniconda3\Lib\site-packages\django\core\handlers\base.py", line 197, in _get_response
    response = wrapped_callback(request, *callback_args, **callback_kwargs)
               ^^^^^^^^^^^^^^^^^^^^^^^^^^^^^^^^^^^^^^^^^^^^^^^^^^^^^^^^^^^^
TypeError: muscle_group() missing 1 required positional argument: 'id'
2024-06-08 10:58:28,054 - INFO - C:\Users\rsien\Desktop\python-django\workout_logger\apps\workout\views.py changed, reloading.: 
2024-06-08 10:58:39,533 - INFO - C:\Users\rsien\Desktop\python-django\workout_logger\apps\workout\views.py changed, reloading.: 
2024-06-08 10:58:42,864 - INFO - C:\Users\rsien\Desktop\python-django\workout_logger\apps\workout\views.py changed, reloading.: 
2024-06-08 10:58:47,097 - INFO - C:\Users\rsien\Desktop\python-django\workout_logger\apps\workout\views.py changed, reloading.: 
2024-06-08 10:59:15,962 - INFO - C:\Users\rsien\Desktop\python-django\workout_logger\apps\workout\views.py changed, reloading.: 
2024-06-08 10:59:23,316 - INFO - C:\Users\rsien\Desktop\python-django\workout_logger\apps\workout\views.py changed, reloading.: 
2024-06-08 10:59:33,765 - INFO - C:\Users\rsien\Desktop\python-django\workout_logger\apps\workout\views.py changed, reloading.: 
2024-06-08 10:59:36,499 - ERROR - Internal Server Error: /musclegroup: 
Traceback (most recent call last):
  File "C:\Users\rsien\miniconda3\Lib\site-packages\django\template\backends\django.py", line 61, in render
    return self.template.render(context)
           ^^^^^^^^^^^^^^^^^^^^^^^^^^^^^
  File "C:\Users\rsien\miniconda3\Lib\site-packages\django\template\base.py", line 175, in render
    return self._render(context)
           ^^^^^^^^^^^^^^^^^^^^^
  File "C:\Users\rsien\miniconda3\Lib\site-packages\django\template\base.py", line 167, in _render
    return self.nodelist.render(context)
           ^^^^^^^^^^^^^^^^^^^^^^^^^^^^^
  File "C:\Users\rsien\miniconda3\Lib\site-packages\django\template\base.py", line 1005, in render
    return SafeString("".join([node.render_annotated(context) for node in self]))
                              ^^^^^^^^^^^^^^^^^^^^^^^^^^^^^^^^^^^^^^^^^^^^^^^^^
  File "C:\Users\rsien\miniconda3\Lib\site-packages\django\template\base.py", line 1005, in <listcomp>
    return SafeString("".join([node.render_annotated(context) for node in self]))
                               ^^^^^^^^^^^^^^^^^^^^^^^^^^^^^^
  File "C:\Users\rsien\miniconda3\Lib\site-packages\django\template\base.py", line 966, in render_annotated
    return self.render(context)
           ^^^^^^^^^^^^^^^^^^^^
  File "C:\Users\rsien\miniconda3\Lib\site-packages\django\template\loader_tags.py", line 197, in render
    template = context.template.engine.select_template(template_name)
               ^^^^^^^^^^^^^^^^^^^^^^^^^^^^^^^^^^^^^^^^^^^^^^^^^^^^^^
  File "C:\Users\rsien\miniconda3\Lib\site-packages\django\template\engine.py", line 212, in select_template
    raise TemplateDoesNotExist(", ".join(not_found))
django.template.exceptions.TemplateDoesNotExist: workout/header.html

The above exception was the direct cause of the following exception:

Traceback (most recent call last):
  File "C:\Users\rsien\miniconda3\Lib\site-packages\django\core\handlers\exception.py", line 55, in inner
    response = get_response(request)
               ^^^^^^^^^^^^^^^^^^^^^
  File "C:\Users\rsien\miniconda3\Lib\site-packages\django\core\handlers\base.py", line 197, in _get_response
    response = wrapped_callback(request, *callback_args, **callback_kwargs)
               ^^^^^^^^^^^^^^^^^^^^^^^^^^^^^^^^^^^^^^^^^^^^^^^^^^^^^^^^^^^^
  File "C:\Users\rsien\Desktop\python-django\workout_logger\apps\workout\views.py", line 172, in muscle_group
    return render(request, "workout/muscle_group.html", data)
           ^^^^^^^^^^^^^^^^^^^^^^^^^^^^^^^^^^^^^^^^^^^^^^^^^^
  File "C:\Users\rsien\miniconda3\Lib\site-packages\django\shortcuts.py", line 24, in render
    content = loader.render_to_string(template_name, context, request, using=using)
              ^^^^^^^^^^^^^^^^^^^^^^^^^^^^^^^^^^^^^^^^^^^^^^^^^^^^^^^^^^^^^^^^^^^^^
  File "C:\Users\rsien\miniconda3\Lib\site-packages\django\template\loader.py", line 62, in render_to_string
    return template.render(context, request)
           ^^^^^^^^^^^^^^^^^^^^^^^^^^^^^^^^^
  File "C:\Users\rsien\miniconda3\Lib\site-packages\django\template\backends\django.py", line 63, in render
    reraise(exc, self.backend)
  File "C:\Users\rsien\miniconda3\Lib\site-packages\django\template\backends\django.py", line 84, in reraise
    raise new from exc
django.template.exceptions.TemplateDoesNotExist: workout/header.html
2024-06-08 10:59:47,498 - INFO - C:\Users\rsien\Desktop\python-django\workout_logger\apps\workout\views.py changed, reloading.: 
2024-06-08 10:59:50,775 - INFO - C:\Users\rsien\Desktop\python-django\workout_logger\apps\workout\views.py changed, reloading.: 
2024-06-08 10:59:53,834 - ERROR - Internal Server Error: /musclegroup: 
Traceback (most recent call last):
  File "C:\Users\rsien\miniconda3\Lib\site-packages\django\core\handlers\exception.py", line 55, in inner
    response = get_response(request)
               ^^^^^^^^^^^^^^^^^^^^^
  File "C:\Users\rsien\miniconda3\Lib\site-packages\django\core\handlers\base.py", line 197, in _get_response
    response = wrapped_callback(request, *callback_args, **callback_kwargs)
               ^^^^^^^^^^^^^^^^^^^^^^^^^^^^^^^^^^^^^^^^^^^^^^^^^^^^^^^^^^^^
  File "C:\Users\rsien\Desktop\python-django\workout_logger\apps\workout\views.py", line 163, in muscle_group
    muscle_group = MuscleGroup.objects.all().order_by('-updated_at')
                   ^^^^^^^^^^^^^^^^^^^^^^^^^^^^^^^^^^^^^^^^^^^^^^^^^^
  File "C:\Users\rsien\miniconda3\Lib\site-packages\django\db\models\query.py", line 1436, in filter
    return self._filter_or_exclude(False, args, kwargs)
           ^^^^^^^^^^^^^^^^^^^^^^^^^^^^^^^^^^^^^^^^^^^^
  File "C:\Users\rsien\miniconda3\Lib\site-packages\django\db\models\query.py", line 1454, in _filter_or_exclude
    clone._filter_or_exclude_inplace(negate, args, kwargs)
  File "C:\Users\rsien\miniconda3\Lib\site-packages\django\db\models\query.py", line 1461, in _filter_or_exclude_inplace
    self._query.add_q(Q(*args, **kwargs))
  File "C:\Users\rsien\miniconda3\Lib\site-packages\django\db\models\sql\query.py", line 1546, in add_q
    clause, _ = self._add_q(q_object, self.used_aliases)
                ^^^^^^^^^^^^^^^^^^^^^^^^^^^^^^^^^^^^^^^^
  File "C:\Users\rsien\miniconda3\Lib\site-packages\django\db\models\sql\query.py", line 1577, in _add_q
    child_clause, needed_inner = self.build_filter(
                                 ^^^^^^^^^^^^^^^^^^
  File "C:\Users\rsien\miniconda3\Lib\site-packages\django\db\models\sql\query.py", line 1427, in build_filter
    lookups, parts, reffed_expression = self.solve_lookup_type(arg, summarize)
                                        ^^^^^^^^^^^^^^^^^^^^^^^^^^^^^^^^^^^^^^
  File "C:\Users\rsien\miniconda3\Lib\site-packages\django\db\models\sql\query.py", line 1237, in solve_lookup_type
    _, field, _, lookup_parts = self.names_to_path(lookup_splitted, self.get_meta())
                                ^^^^^^^^^^^^^^^^^^^^^^^^^^^^^^^^^^^^^^^^^^^^^^^^^^^^
  File "C:\Users\rsien\miniconda3\Lib\site-packages\django\db\models\sql\query.py", line 1725, in names_to_path
    raise FieldError(
django.core.exceptions.FieldError: Cannot resolve keyword 'user' into field. Choices are: balanceexercise, created_at, description, endurancetrainingexercise, flexibilityexercise, id, name, strengthtrainingexercise, updated_at
2024-06-08 10:59:54,180 - INFO - C:\Users\rsien\Desktop\python-django\workout_logger\apps\workout\views.py changed, reloading.: 
2024-06-08 10:59:58,562 - ERROR - Internal Server Error: /musclegroup: 
Traceback (most recent call last):
  File "C:\Users\rsien\miniconda3\Lib\site-packages\django\template\backends\django.py", line 61, in render
    return self.template.render(context)
           ^^^^^^^^^^^^^^^^^^^^^^^^^^^^^
  File "C:\Users\rsien\miniconda3\Lib\site-packages\django\template\base.py", line 175, in render
    return self._render(context)
           ^^^^^^^^^^^^^^^^^^^^^
  File "C:\Users\rsien\miniconda3\Lib\site-packages\django\template\base.py", line 167, in _render
    return self.nodelist.render(context)
           ^^^^^^^^^^^^^^^^^^^^^^^^^^^^^
  File "C:\Users\rsien\miniconda3\Lib\site-packages\django\template\base.py", line 1005, in render
    return SafeString("".join([node.render_annotated(context) for node in self]))
                              ^^^^^^^^^^^^^^^^^^^^^^^^^^^^^^^^^^^^^^^^^^^^^^^^^
  File "C:\Users\rsien\miniconda3\Lib\site-packages\django\template\base.py", line 1005, in <listcomp>
    return SafeString("".join([node.render_annotated(context) for node in self]))
                               ^^^^^^^^^^^^^^^^^^^^^^^^^^^^^^
  File "C:\Users\rsien\miniconda3\Lib\site-packages\django\template\base.py", line 966, in render_annotated
    return self.render(context)
           ^^^^^^^^^^^^^^^^^^^^
  File "C:\Users\rsien\miniconda3\Lib\site-packages\django\template\loader_tags.py", line 197, in render
    template = context.template.engine.select_template(template_name)
               ^^^^^^^^^^^^^^^^^^^^^^^^^^^^^^^^^^^^^^^^^^^^^^^^^^^^^^
  File "C:\Users\rsien\miniconda3\Lib\site-packages\django\template\engine.py", line 212, in select_template
    raise TemplateDoesNotExist(", ".join(not_found))
django.template.exceptions.TemplateDoesNotExist: workout/header.html

The above exception was the direct cause of the following exception:

Traceback (most recent call last):
  File "C:\Users\rsien\miniconda3\Lib\site-packages\django\core\handlers\exception.py", line 55, in inner
    response = get_response(request)
               ^^^^^^^^^^^^^^^^^^^^^
  File "C:\Users\rsien\miniconda3\Lib\site-packages\django\core\handlers\base.py", line 197, in _get_response
    response = wrapped_callback(request, *callback_args, **callback_kwargs)
               ^^^^^^^^^^^^^^^^^^^^^^^^^^^^^^^^^^^^^^^^^^^^^^^^^^^^^^^^^^^^
  File "C:\Users\rsien\Desktop\python-django\workout_logger\apps\workout\views.py", line 172, in muscle_group
    return render(request, "workout/muscle_group.html", data)
           ^^^^^^^^^^^^^^^^^^^^^^^^^^^^^^^^^^^^^^^^^^^^^^^^^^
  File "C:\Users\rsien\miniconda3\Lib\site-packages\django\shortcuts.py", line 24, in render
    content = loader.render_to_string(template_name, context, request, using=using)
              ^^^^^^^^^^^^^^^^^^^^^^^^^^^^^^^^^^^^^^^^^^^^^^^^^^^^^^^^^^^^^^^^^^^^^
  File "C:\Users\rsien\miniconda3\Lib\site-packages\django\template\loader.py", line 62, in render_to_string
    return template.render(context, request)
           ^^^^^^^^^^^^^^^^^^^^^^^^^^^^^^^^^
  File "C:\Users\rsien\miniconda3\Lib\site-packages\django\template\backends\django.py", line 63, in render
    reraise(exc, self.backend)
  File "C:\Users\rsien\miniconda3\Lib\site-packages\django\template\backends\django.py", line 84, in reraise
    raise new from exc
django.template.exceptions.TemplateDoesNotExist: workout/header.html
2024-06-08 11:02:39,338 - ERROR - Internal Server Error: /musclegroup: 
Traceback (most recent call last):
  File "C:\Users\rsien\miniconda3\Lib\site-packages\django\template\backends\django.py", line 61, in render
    return self.template.render(context)
           ^^^^^^^^^^^^^^^^^^^^^^^^^^^^^
  File "C:\Users\rsien\miniconda3\Lib\site-packages\django\template\base.py", line 175, in render
    return self._render(context)
           ^^^^^^^^^^^^^^^^^^^^^
  File "C:\Users\rsien\miniconda3\Lib\site-packages\django\template\base.py", line 167, in _render
    return self.nodelist.render(context)
           ^^^^^^^^^^^^^^^^^^^^^^^^^^^^^
  File "C:\Users\rsien\miniconda3\Lib\site-packages\django\template\base.py", line 1005, in render
    return SafeString("".join([node.render_annotated(context) for node in self]))
                              ^^^^^^^^^^^^^^^^^^^^^^^^^^^^^^^^^^^^^^^^^^^^^^^^^
  File "C:\Users\rsien\miniconda3\Lib\site-packages\django\template\base.py", line 1005, in <listcomp>
    return SafeString("".join([node.render_annotated(context) for node in self]))
                               ^^^^^^^^^^^^^^^^^^^^^^^^^^^^^^
  File "C:\Users\rsien\miniconda3\Lib\site-packages\django\template\base.py", line 966, in render_annotated
    return self.render(context)
           ^^^^^^^^^^^^^^^^^^^^
  File "C:\Users\rsien\miniconda3\Lib\site-packages\django\template\loader_tags.py", line 197, in render
    template = context.template.engine.select_template(template_name)
               ^^^^^^^^^^^^^^^^^^^^^^^^^^^^^^^^^^^^^^^^^^^^^^^^^^^^^^
  File "C:\Users\rsien\miniconda3\Lib\site-packages\django\template\engine.py", line 212, in select_template
    raise TemplateDoesNotExist(", ".join(not_found))
django.template.exceptions.TemplateDoesNotExist: workout/items/muscle_groups_list.html

The above exception was the direct cause of the following exception:

Traceback (most recent call last):
  File "C:\Users\rsien\miniconda3\Lib\site-packages\django\core\handlers\exception.py", line 55, in inner
    response = get_response(request)
               ^^^^^^^^^^^^^^^^^^^^^
  File "C:\Users\rsien\miniconda3\Lib\site-packages\django\core\handlers\base.py", line 197, in _get_response
    response = wrapped_callback(request, *callback_args, **callback_kwargs)
               ^^^^^^^^^^^^^^^^^^^^^^^^^^^^^^^^^^^^^^^^^^^^^^^^^^^^^^^^^^^^
  File "C:\Users\rsien\Desktop\python-django\workout_logger\apps\workout\views.py", line 172, in muscle_group
    return render(request, "workout/muscle_group.html", data)
           ^^^^^^^^^^^^^^^^^^^^^^^^^^^^^^^^^^^^^^^^^^^^^^^^^^
  File "C:\Users\rsien\miniconda3\Lib\site-packages\django\shortcuts.py", line 24, in render
    content = loader.render_to_string(template_name, context, request, using=using)
              ^^^^^^^^^^^^^^^^^^^^^^^^^^^^^^^^^^^^^^^^^^^^^^^^^^^^^^^^^^^^^^^^^^^^^
  File "C:\Users\rsien\miniconda3\Lib\site-packages\django\template\loader.py", line 62, in render_to_string
    return template.render(context, request)
           ^^^^^^^^^^^^^^^^^^^^^^^^^^^^^^^^^
  File "C:\Users\rsien\miniconda3\Lib\site-packages\django\template\backends\django.py", line 63, in render
    reraise(exc, self.backend)
  File "C:\Users\rsien\miniconda3\Lib\site-packages\django\template\backends\django.py", line 84, in reraise
    raise new from exc
django.template.exceptions.TemplateDoesNotExist: workout/items/muscle_groups_list.html
2024-06-08 11:14:35,441 - INFO - User has been logged out.: 
2024-06-08 11:14:35,465 - DEBUG - GET request to login: 
2024-06-08 11:14:39,270 - DEBUG - GET request to login: 
2024-06-08 11:14:55,524 - DEBUG - GET request to login: 
2024-06-08 11:14:55,680 - WARNING - Not Found: /favicon.ico: 
2024-06-08 11:14:57,097 - DEBUG - GET request to login: 
2024-06-08 11:14:57,337 - WARNING - Not Found: /favicon.ico: 
2024-06-08 11:15:07,236 - DEBUG - GET request to login: 
2024-06-08 11:15:07,387 - WARNING - Not Found: /favicon.ico: 
2024-06-08 11:15:08,193 - DEBUG - GET request to login: 
2024-06-08 11:15:08,340 - WARNING - Not Found: /favicon.ico: 
2024-06-08 11:15:13,027 - DEBUG - GET request to login: 
2024-06-08 11:15:14,403 - DEBUG - GET request to login: 
2024-06-08 11:15:14,649 - WARNING - Not Found: /favicon.ico: 
2024-06-08 11:17:38,371 - DEBUG - GET request to login: 
2024-06-08 11:17:38,661 - WARNING - Not Found: /favicon.ico: 
2024-06-08 11:18:29,308 - DEBUG - GET request to login: 
2024-06-08 11:18:29,596 - WARNING - Not Found: /favicon.ico: 
2024-06-08 11:19:00,632 - DEBUG - GET request to login: 
2024-06-08 11:19:00,905 - WARNING - Not Found: /favicon.ico: 
2024-06-08 11:19:16,970 - DEBUG - GET request to login: 
2024-06-08 11:19:17,226 - WARNING - Not Found: /favicon.ico: 
2024-06-08 11:19:19,111 - DEBUG - GET request to login: 
2024-06-08 11:19:19,259 - WARNING - Not Found: /favicon.ico: 
2024-06-08 11:35:23,356 - DEBUG - GET request to login: 
2024-06-08 11:35:38,253 - DEBUG - POST request to login: 
2024-06-08 11:38:58,262 - WARNING - Not Found: /profile: 
2024-06-08 11:42:00,582 - INFO - User has been logged out.: 
2024-06-08 11:42:00,613 - DEBUG - GET request to login: 
2024-06-08 11:42:00,725 - WARNING - Not Found: /favicon.ico: 
2024-06-08 11:42:50,772 - DEBUG - POST request to login: 
2024-06-08 11:42:51,768 - DEBUG - POST request to login: 
2024-06-08 11:45:37,218 - WARNING - Not Found: /profile: 
2024-06-08 11:46:48,821 - INFO - C:\Users\rsien\Desktop\python-django\workout_logger\apps\workout\views.py changed, reloading.: 
2024-06-08 11:46:51,015 - INFO - C:\Users\rsien\Desktop\python-django\workout_logger\apps\workout\views.py changed, reloading.: 
2024-06-08 11:47:00,489 - INFO - C:\Users\rsien\Desktop\python-django\workout_logger\apps\workout\views.py changed, reloading.: 
2024-06-08 11:58:25,004 - INFO - C:\Users\rsien\Desktop\python-django\workout_logger\apps\workout\views.py changed, reloading.: 
2024-06-08 11:58:27,194 - INFO - C:\Users\rsien\Desktop\python-django\workout_logger\apps\workout\views.py changed, reloading.: 
2024-06-08 11:58:32,484 - INFO - C:\Users\rsien\Desktop\python-django\workout_logger\apps\workout\views.py changed, reloading.: 
2024-06-08 11:58:43,967 - INFO - C:\Users\rsien\Desktop\python-django\workout_logger\apps\workout\views.py changed, reloading.: 
